Workbook

Sheet Step-by-Step Instructions

Sheet Typical Target Crash Types
B2: Target Crash Type Guidance - Section Treatments
C4: Countermeasure | D4: Target-1 | E4: Target-2 | F4: Target Subset | G4: Other | H4: Target-1 Crash* | I4: Target-2 Crash | J4: Notes
C5: Clear Zone Improvements | D5: Y | H5: Lane Departure Crashes (Type 1 or 2)
C6: Closed Loop Signal System | D6: Y | E6: Y | H6: Frontal Impact Crashes in the treated intersections | I6: Rear End Crashes on the treated corridor
C7: Congestion Detection System | D7: Y | H7: Rear End Crashes
C8: Curve Wedging and Resurfacing / Curve Superelevation Improvements | D8: Y | H8: Lane Departure Crashes (Type 1 or 2)
C9: Drainage Improvements | D9: Y | F9: Y | H9: Wet Crashes (Road Codes 2-6) (precipitation data analysis also needed) | J9: Wet L.D. Crashes (Road Codes 2-6) should also be included within the additional information table.
C10: Guardrail - (Shoulder, Culvert or Bridge Approach) | D10: Y | G10: Y | H10: Lane Departure Crashes (Type 1 or 2) | J10: Guardrail Hit Crashes should also be included within the additional information table.
C11: Horizontal Alignment Improvements | D11: Y | H11: Lane Departure Crashes (Type 1 or 2)
C12: Lighting | D12: Y | F12: ? | H12: Night Crashes (Light Codes 4-6) | J12: Night L.D. Crashes (Light Codes 4-6) may also need to be included within the additional information table depending on the countermeasure
C13: Median Guardrail | D13: Y | F13: Y | G13: Y | H13: Lane Departure Crashes (Type 2) involving vehicle Running Off Road toward the median side of roadway | J13: Cross Median Crashes (this is a subset of L.D. crashes) and Median Guardrail Hit Crashes should be included within the additional information table
C14: Pavement Markings (i.e. Wider Lane Lines) | D14: Y | F14: Y | H14: Lane Departure Crashes (Type 1 or 2) | J14: Night L.D. Crashes (Light Codes 4-6) should also be included within the additional information table
C15: Resurfacing | D15: Y | F15: Y | H15: Wet Crashes (Road Codes 2-6) (precipitation data analysis also needed) | J15: Wet L.D. Crashes (Road Codes 2-6) should also be included within the additional information table. Examples of this countermeasure: Open Graded Friction Course, High Friction Surface Treatment, Nova Chip, etc.
C16: Road Diet (i.e. 4-Lane to 3-Lane) | D16: Y | E16: Y | H16: Rear End Crashes | I16: Left Turn Same Roadway Crashes | J16: If 4-Lane Cross-Section before, may need to break out Rear End Crashes in Inner Lanes for Target-1
C17: Rumble Strips - Centerline | D17: Y | F17: Y | H17: Lane Departure Crashes (Type 1 or 2) | J17: Correctable L.D. Crashes need to be included within the additional information table. Lane Departure Crashes are considered correctable if: the first event involved at least one vehicle crossing the centerline; it was not caused by a vehicle swerving to avoid a vehicle, person, animal, or other object in the roadway; it was not caused by mechanical problems, blown tires, or a medical problem with the driver; it was not caused by the weather, such as hydroplaning or sliding on ice; and it was not clear from the crash diagram/narrative that the driver lost control prior to crossing the roadway centerline.
C18: Rumble Strips - Shoulder | D18: Y | F18: Y | H18: Lane Departure Crashes (Type 1 or 2) | J18: Correctable L.D. Crashes need to be included within the additional information table. Lane Departure Crashes are considered correctable if: the first event involved at least one vehicle crossing the edgeline; it was not caused by a vehicle swerving to avoid a vehicle, person, animal, or other object in the roadway; it was not caused by mechanical problems, blown tires, or a medical problem with the driver; it was not caused by the weather, such as hydroplaning or sliding on ice; and it was not clear from the crash diagram/narrative that the driver lost control prior to crossing the roadway edgeline.
C19: Truck countermeasures | D19: Y | H19: Truck Crashes | J19: Truck codes may vary by project but typical Truck codes are 10-16. "Heavy" truck codes are 12-16. Use the assumptions email to confirm which Truck definition is most appropriate for the project.
C20: Widening for Paved Shoulders | D20: Y | F20: ? | H20: Lane Departure Crashes (Type 1 or 2) | J20: Wet L.D. Crashes (Road Codes 2-6) may need to be included within the additional information table if resurfacing was part of project
C21: Widening for Two-Way Center Turn Lane (i.e. 2-Lane to 3-Lane) | D21: Y | E21: Y | H21: Rear End Crashes | I21: Left Turn Same Roadway Crashes | J21: If 4-Lane Cross-Section before, may need to break out Rear End Crashes in Inner Lanes for Target-1
B23: Comments on Typical Target Crashes
B24: ● | C24: *Lane Departure Crashes (Type 1 - Use for Two Lane Facilities) = Ran Off Road (Left, Right or Straight), Overturn/Rollover, Fixed Object, Head On, Sideswipe Opposite Direction. Side street run through crashes are not considered targets.
B25: ● | C25: *Lane Departure Crashes (Type 2 - Use for Multilane Facilities) = Ran Off Road (Left, Right or Straight), Overturn/Rollover, Fixed Object, Head On, Sideswipe Same Direction, Sideswipe Opposite Direction. Side street run through crashes are not considered targets.
B27: ● | C27: The selection of target crashes should be confirmed in the assumptions email prior to starting the analysis. Additionally, any other crash types or other information that need be mentioned in the additional information table should also be noted in the assumptions email.

Sheet Evaluation Set-up
B2: Date Range Calculator | J2: Section AADT Calculator - Weighted Average by Sub-Section
C4: Most recent TEAAS date | D4: 46173 | F4: Color Key | J4: Comments/Instructions on AADT Calculator Use: | AI4: Representative Years Selection:
C5: Construction Period Length (Give Value in Months) | D5: 14 | F5: Cells that need to be edited | J5: ● | K5: In cells AJ5 -> AK6, select the last year within each period that has available volume data (i.e. actual collected volume data, not estimated/interpolated data) | AI5: Select Before Period Year | AL5: 2018 | BJ5: cells needed for calcs:
F6: Auto-calculated cells | J6: ● | K6: When inputting volume data into this tool, use Black font color for values taken directly from the available volume data | AI6: Select After Period Year | AL6: 2024
J7: ● | K7: When inputting volume data into this tool, use Red font color for values that need to be calculated, interpolated, or assumed | BL7: Total # of months in between
C8: Time Period | D8: Start Date | E8: End Date | F8: # of Years | G8: # of Months | J8: ● | K8: Input AADTs for each calendar year within the study period. You do not need to input volumes for years outside the study date range | AI8: Representative Volumes: | BJ8: =YEAR(E9) -> 2020 | BK8: =MONTH(E9) -> 4 | BL8: =(YEAR(D10)-YEAR(D9))*12+MONTH(D10)-MONTH(D9) -> 59
C9: Before Period | D9: =DATE(BJ8-F11,BK8-G11+1,1) -> 42156 | E9: =D10-1 -> 43951 | F9: =ROUNDDOWN(BL8/12,0) -> 4 | G9: =BL8-12*F9 -> 11 | J9: ● | K9: Make sure you enter in the beginning and ending MP for each sub-section | AI9: Before Period Volume: | AL9: =ROUND(HLOOKUP(AL5, $O$16:$AM$42, 27, 0), -2) -> 8100 | BJ9: =YEAR(E10) -> 2021 | BK9: =MONTH(E10) -> 6 | BL9: =(YEAR(D11)-YEAR(D10))*12+MONTH(D11)-MONTH(D10) -> 14
C10: Construction Period | D10: =DATE(BJ9,BK9-(D5-1),1) -> 43952 | E10: 44377 | F10: =ROUNDDOWN(BL9/12,0) -> 1 | G10: =BL9-12*F10 -> 2 | J10: ● | K10: If more than one volume count is available within the study section, give each count location a coresponing sub-section and a mile post range that it is responsible for | AI10: After Period Volume: | AL10: =ROUND(HLOOKUP(AL6, $O$16:$AM$42, 27, 0), -2) -> 8700 | BK10: =E11+1 -> 46174 | BL10: =(YEAR(BK10)-YEAR(D11))*12+MONTH(BK10)-MONTH(D11) -> 59
C11: After Period | D11: =E10+1 -> 44378 | E11: =D4 -> 46173 | F11: =ROUNDDOWN(BL10/12,0) -> 4 | G11: =BL10-12*F11 -> 11 | J11: ● | K11: If only one volume count is available for a section, just use the 1st row of this calculator and leave the other rows blank.
J12: ● | K12: Do not select 2020 as a representative year for a particular time period, due to the effects of the COVID-19 pandemic, even if it is the last year with available AADT data within said time period.
B13: Comments/Instructions on Date Range Calculator Use:
B14: ● | C14: Use a typical 3-month Construction Period unless you have specific information to the contrary (ex. construction start/end dates were provided, info from satellite views, etc.) | K14: Sub-Section Information | O14: AADTs for every year within the study period
B16: ● | C16: You CAN input the construction start date directly into cell D10 or simply just enter in the construction period length into cells D5 & D6 | K16: # | L16: Begin MP | M16: End MP | N16: Length | O16: 2006 | P16: 2007 | Q16: 2008 | R16: 2009 | S16: 2010 | T16: 2011 | U16: 2012 | V16: 2013 | W16: 2014 | X16: 2015 | Y16: 2016 | Z16: 2017 | AA16: 2018 | AB16: 2019 | AC16: 2020 | AD16: 2021 | AE16: 2022 | AF16: 2023 | AG16: 2024 | AH16: 2025 | AI16: 2026 | AJ16: 2027 | AK16: 2028 | AL16: 2029 | AM16: 2030
K17: 1 | L17: 17.691 | M17: 17.811 | N17: =ABS(M17-L17) -> 0.12 | U17: 3600 | V17: 4100 | W17: 4600 | X17: 5100 | Y17: 5600 | Z17: =AVERAGE(Y17,AA17) -> 6850 | AA17: 8100 | AB17: 8000 | AC17: 7500 | AD17: 8000 | AE17: 8300 | AF17: 8500 | AG17: 8700 | AH17: 8700 | AI17: 8700
B18: ● | C18: This tool only works in WHOLE MONTHS. Construction start dates should be rounded up to the first of the month and construction end dates should be rounded down to the end the month | K18: 2 | N18: =IF(ABS(M18-L18) = 0, "", ABS(M18-L18))
K19: 3 | N19: =IF(ABS(M19-L19) = 0, "", ABS(M19-L19))
K20: 4 | N20: =IF(ABS(M20-L20) = 0, "", ABS(M20-L20))
K21: 5 | N21: =IF(ABS(M21-L21) = 0, "", ABS(M21-L21))
K22: 6 | N22: =IF(ABS(M22-L22) = 0, "", ABS(M22-L22))
K23: 7 | N23: =IF(ABS(M23-L23) = 0, "", ABS(M23-L23))
K24: 8 | N24: =IF(ABS(M24-L24) = 0, "", ABS(M24-L24))
K25: 9 | N25: =IF(ABS(M25-L25) = 0, "", ABS(M25-L25))
K26: 10 | N26: =IF(ABS(M26-L26) = 0, "", ABS(M26-L26))
K27: 11 | N27: =IF(ABS(M27-L27) = 0, "", ABS(M27-L27))
K28: 12 | N28: =IF(ABS(M28-L28) = 0, "", ABS(M28-L28))
K29: 13 | N29: =IF(ABS(M29-L29) = 0, "", ABS(M29-L29))
K30: 14 | N30: =IF(ABS(M30-L30) = 0, "", ABS(M30-L30))
... K41: 25 | N41: =IF(ABS(M41-L41) = 0, "", ABS(M41-L41))
K42: Sum | L42: -- | M42: -- | N42: =SUM(N17:N41) -> 0.12 | O42: =IF(O17="", "", O75) | P42: =IF(P17="", "", P75) | Q42: =IF(Q17="", "", Q75) | R42: =IF(R17="", "", R75) | S42: =IF(S17="", "", S75) | T42: =IF(T17="", "", T75) | U42: =IF(U17="", "", U75) -> 3600 | V42: =IF(V17="", "", V75) -> 4100 | ... AM42: =IF(AM17="", "", AM75)
M48: Year-by-Year AADTs - For multi-project tracking by Safety Evaluation Group
M49: Section | N49: weight | O49: 2006 | P49: 2007 | Q49: 2008 | R49: 2009 | S49: 2010 | T49: 2011 | U49: 2012 | V49: 2013 | W49: 2014 | X49: 2015 | Y49: 2016 | Z49: 2017 | AA49: 2018 | AB49: 2019 | AC49: 2020 | AD49: 2021 | AE49: 2022 | AF49: 2023 | AG49: 2024 | AH49: 2025 | AI49: 2026 | AJ49: 2027 | AK49: 2028 | AL49: 2029 | AM49: 2030
M50: 1 | N50: =IFERROR(N17/$N$42, "") -> 1 | O50: =IF(O17="", "", O17*$N50) | P50: =IF(P17="", "", P17*$N50) | Q50: =IF(Q17="", "", Q17*$N50) | R50: =IF(R17="", "", R17*$N50) | S50: =IF(S17="", "", S17*$N50) | T50: =IF(T17="", "", T17*$N50) | U50: =IF(U17="", "", U17*$N50) -> 3600 | V50: =IF(V17="", "", V17*$N50) -> 4100 | ... AM50: =IF(AM17="", "", AM17*$N50)
M51: 2 | N51: =IFERROR(N18/$N$42, "") | O51: =IF(O18="", "", O18*$N51) | P51: =IF(P18="", "", P18*$N51) | Q51: =IF(Q18="", "", Q18*$N51) | R51: =IF(R18="", "", R18*$N51) | S51: =IF(S18="", "", S18*$N51) | T51: =IF(T18="", "", T18*$N51) | U51: =IF(U18="", "", U18*$N51) | V51: =IF(V18="", "", V18*$N51) | ... AM51: =IF(AM18="", "", AM18*$N51)
M52: 3 | N52: =IFERROR(N19/$N$42, "") | O52: =IF(O19="", "", O19*$N52) | P52: =IF(P19="", "", P19*$N52) | Q52: =IF(Q19="", "", Q19*$N52) | R52: =IF(R19="", "", R19*$N52) | S52: =IF(S19="", "", S19*$N52) | T52: =IF(T19="", "", T19*$N52) | U52: =IF(U19="", "", U19*$N52) | V52: =IF(V19="", "", V19*$N52) | ... AM52: =IF(AM19="", "", AM19*$N52)
M53: 4 | N53: =IFERROR(N20/$N$42, "") | O53: =IF(O20="", "", O20*$N53) | P53: =IF(P20="", "", P20*$N53) | Q53: =IF(Q20="", "", Q20*$N53) | R53: =IF(R20="", "", R20*$N53) | S53: =IF(S20="", "", S20*$N53) | T53: =IF(T20="", "", T20*$N53) | U53: =IF(U20="", "", U20*$N53) | V53: =IF(V20="", "", V20*$N53) | ... AM53: =IF(AM20="", "", AM20*$N53)
M54: 5 | N54: =IFERROR(N21/$N$42, "") | O54: =IF(O21="", "", O21*$N54) | P54: =IF(P21="", "", P21*$N54) | Q54: =IF(Q21="", "", Q21*$N54) | R54: =IF(R21="", "", R21*$N54) | S54: =IF(S21="", "", S21*$N54) | T54: =IF(T21="", "", T21*$N54) | U54: =IF(U21="", "", U21*$N54) | V54: =IF(V21="", "", V21*$N54) | ... AM54: =IF(AM21="", "", AM21*$N54)
M55: 6 | N55: =IFERROR(N22/$N$42, "") | O55: =IF(O22="", "", O22*$N55) | P55: =IF(P22="", "", P22*$N55) | Q55: =IF(Q22="", "", Q22*$N55) | R55: =IF(R22="", "", R22*$N55) | S55: =IF(S22="", "", S22*$N55) | T55: =IF(T22="", "", T22*$N55) | U55: =IF(U22="", "", U22*$N55) | V55: =IF(V22="", "", V22*$N55) | ... AM55: =IF(AM22="", "", AM22*$N55)
M56: 7 | N56: =IFERROR(N23/$N$42, "") | O56: =IF(O23="", "", O23*$N56) | P56: =IF(P23="", "", P23*$N56) | Q56: =IF(Q23="", "", Q23*$N56) | R56: =IF(R23="", "", R23*$N56) | S56: =IF(S23="", "", S23*$N56) | T56: =IF(T23="", "", T23*$N56) | U56: =IF(U23="", "", U23*$N56) | V56: =IF(V23="", "", V23*$N56) | ... AM56: =IF(AM23="", "", AM23*$N56)
M57: 8 | N57: =IFERROR(N24/$N$42, "") | O57: =IF(O24="", "", O24*$N57) | P57: =IF(P24="", "", P24*$N57) | Q57: =IF(Q24="", "", Q24*$N57) | R57: =IF(R24="", "", R24*$N57) | S57: =IF(S24="", "", S24*$N57) | T57: =IF(T24="", "", T24*$N57) | U57: =IF(U24="", "", U24*$N57) | V57: =IF(V24="", "", V24*$N57) | ... AM57: =IF(AM24="", "", AM24*$N57)
M58: 9 | N58: =IFERROR(N25/$N$42, "") | O58: =IF(O25="", "", O25*$N58) | P58: =IF(P25="", "", P25*$N58) | Q58: =IF(Q25="", "", Q25*$N58) | R58: =IF(R25="", "", R25*$N58) | S58: =IF(S25="", "", S25*$N58) | T58: =IF(T25="", "", T25*$N58) | U58: =IF(U25="", "", U25*$N58) | V58: =IF(V25="", "", V25*$N58) | ... AM58: =IF(AM25="", "", AM25*$N58)
...

Sheet Intersection Mileposts
B2: Intersection Milepost Table (Used for Multi-Project Tracking)
C4: # | D4: Intersecting Road Name | E4: Milepost of Intersection | F4: -250' | G4: +250' | I4: Comments/Instructions on Intersection Milepost Table:
C5: #1 | D5: SR 1716 | E5: 17.691 | F5: =IF(D5="", "", E5-250/5280) -> 17.643652 | G5: =IF(D5="", "", E5+250/5280) -> 17.738348 | I5: ● | J5: Please enter in the intersections within your study's Milepost Limits on the Features reports
C6: #2 | D6: SR 2638 | E6: 17.811 | F6: =IF(D6="", "", E6-250/5280) -> 17.763652 | G6: =IF(D6="", "", E6+250/5280) -> 17.858348 | I6: ● | J6: Don't enter in the names/mileposts for non-intersections (etc. bridges, structures, etc.)
C7: #3 | F7: =IF(D7="", "", E7-250/5280) | G7: =IF(D7="", "", E7+250/5280) | I7: ● | J7: Enter in the name of the road into the cells in column D
C8: #4 | F8: =IF(D8="", "", E8-250/5280) | G8: =IF(D8="", "", E8+250/5280) | I8: ● | J8: Enter in the Milepost from the features report into the cells in column E
C9: #5 | F9: =IF(D9="", "", E9-250/5280) | G9: =IF(D9="", "", E9+250/5280) | I9: ● | J9: If you adjusted a milepost of an intersection during your review, enter that value instead of the milepost from the features report
C10: #6 | F10: =IF(D10="", "", E10-250/5280) | G10: =IF(D10="", "", E10+250/5280)
C11: #7 | F11: =IF(D11="", "", E11-250/5280) | G11: =IF(D11="", "", E11+250/5280) | I11: ● | J11: Each row within the table to the left should correspond to one intersection along the study section. There should only be one milepost per intersection. You do not need to use multiple rows for intersections with crossing routes with multiple names
C12: #8 | F12: =IF(D12="", "", E12-250/5280) | G12: =IF(D12="", "", E12+250/5280)
C13: #9 | F13: =IF(D13="", "", E13-250/5280) | G13: =IF(D13="", "", E13+250/5280)
C14: #10 | F14: =IF(D14="", "", E14-250/5280) | G14: =IF(D14="", "", E14+250/5280) | I14: ● | J14: If the number of intersections exceeds 35, before entering data into this tab, contact SEG staff to determine whether this step needs to be completed
C15: #11 | F15: =IF(D15="", "", E15-250/5280) | G15: =IF(D15="", "", E15+250/5280)
C16: #12 | F16: =IF(D16="", "", E16-250/5280) | G16: =IF(D16="", "", E16+250/5280) | I16: ● | J16: DO NOT DRAG/SHIFT/MOVE CELLS in this table. Formulas within the Tracking tab at the end of this workbook (tracking tab is for internal NCDOT staff) use the information in this table for annual crash counting calculations. Any dragging or deleting of cells will break these formulas and cause errors.
C17: #13 | F17: =IF(D17="", "", E17-250/5280) | G17: =IF(D17="", "", E17+250/5280)
C18: #14 | F18: =IF(D18="", "", E18-250/5280) | G18: =IF(D18="", "", E18+250/5280)
C19: #15 | F19: =IF(D19="", "", E19-250/5280) | G19: =IF(D19="", "", E19+250/5280)
C20: #16 | F20: =IF(D20="", "", E20-250/5280) | G20: =IF(D20="", "", E20+250/5280)
C21: #17 | F21: =IF(D21="", "", E21-250/5280) | G21: =IF(D21="", "", E21+250/5280)
C22: #18 | F22: =IF(D22="", "", E22-250/5280) | G22: =IF(D22="", "", E22+250/5280)
C23: #19 | F23: =IF(D23="", "", E23-250/5280) | G23: =IF(D23="", "", E23+250/5280)
C24: #20 | F24: =IF(D24="", "", E24-250/5280) | G24: =IF(D24="", "", E24+250/5280)
C25: #21 | F25: =IF(D25="", "", E25-250/5280) | G25: =IF(D25="", "", E25+250/5280)
C26: #22 | F26: =IF(D26="", "", E26-250/5280) | G26: =IF(D26="", "", E26+250/5280)
C27: #23 | F27: =IF(D27="", "", E27-250/5280) | G27: =IF(D27="", "", E27+250/5280)
C28: #24 | F28: =IF(D28="", "", E28-250/5280) | G28: =IF(D28="", "", E28+250/5280)
... C39: #35 | F39: =IF(D39="", "", E39-250/5280) | G39: =IF(D39="", "", E39+250/5280)

Sheet OriginalFiche
A1: North Carolina Department of Transportation Traffic Engineering Accident Analysis System Fiche Report
A2: County | B2: County Code | C2: Division | D2: Municipality | E2: Municipality Code | F2: Begin Date | G2: End Date | H2: Years | I2: Y-Line Feet
B3: JOHNSTON | C3: 51 | D3: 4 | E3: All and Rural | G3: 41609 | H3: 46173 | I3: 12.5 | J3: 0
A4: Road Name | B4: Road Code
A5: SR 1003 | B5: 40001003
A6: BUFFALO | B6: 50004182
A7: WENDELL | B7: 50032464
A8: LAKE WENDELL | B8: 50016884
A9: SR 1701 | B9: 40001701
A10: EAGLE ROCK | B10: 50009137
A11: SR 2638 | B11: 40002638
A12: SR 1716 | B12: 40001716
A13: 46217 | B13: Page 1 of 74
A14: Muni. Code | B14: On Road | C14: Miles / Dir From | D14: From Road | E14: Toward Road | F14: Milepost Road | G14: MP | H14: MA | I14: Crash ID | J14: Date | K14: T | L14: C | M14: F | N14: L | O14: S
A15: 491 | B15: BUFFALO | C15: 0 | D15: S | E15: *LCL 3862 BUFFALO RD | F15: *LCL 3862 BUFFALO RD | H15: 999.999 | J15: 105904161 | K15: 43637 | L15: 1 | M15: 1 | N15: 0 | O15: 1 | P15: O
A16: 491 | B16: BUFFALO | C16: 0 | E16: *LCL 4407 BUFFALO RD | F16: OLD BEULAH | H16: 999.999 | J16: 105977928 | K16: 43708 | L16: 28 | M16: 1 | N16: 0 | O16: 1 | P16: A
A17: 0 | B17: PVA ARCHER LODGE MS | C17: 0 | E17: SR 1701 | F17: SR 1747 | H17: 999.999 | J17: 108447557 | K17: 46106 | L17: 20 | M17: 1 | N17: 7 | O17: 1 | P17: O
A18: 0 | B18: PVA FLOWERS STORE | C18: 0 | E18: SR 1003 | F18: NC 42 | H18: 999.999 | J18: 106714400 | K18: 44470 | L18: 30 | M18: 1 | N18: 8 | O18: 1 | P18: O
A19: 0 | B19: SR 1003 | C19: 0.1 | D19: W | E19: *LCL ARCHER LODGE RD | F19: SR 1700 | H19: 999.999 | J19: 105514109 | K19: 43267 | L19: 19 | M19: 1 | N19: 0 | O19: 1 | P19: C
A20: 0 | B20: SR 1003 | C20: 0 | E20: *LCL CLARK POND RD | F20: NC 42 | H20: 999.999 | J20: 104668391 | K20: 42418 | L20: 21 | M20: 1 | N20: 8 | O20: 1 | P20: C
A21: 0 | B21: SR 1003 | C21: 0 | E21: *LCL DEMILT DRIVE | F21: SR 1770 | H21: 999.999 | J21: 105783353 | K21: 43518 | L21: 17 | M21: 2 | N21: 0 | O21: 5 | P21: O
A22: 0 | B22: SR 1003 | C22: 0 | E22: *LCL PVA HARRIS TEETER | F22: NC 42 | H22: 999.999 | J22: 105979361 | K22: 43709 | L22: 24 | M22: 1 | N22: 8 | O22: 1 | P22: O
A23: 0 | B23: SR 1003 | C23: 0 | E23: *LCL RIVER DELL ELEMENTARY | F23: NC 42 | H23: 999.999 | J23: 104853929 | K23: 42632 | L23: 24 | M23: 2 | N23: 8 | O23: 1 | P23: C
A24: 0 | B24: SR 1003 | C24: 0 | E24: *LCL RIVER DELL RUN | F24: SR 1908 | H24: 999.999 | J24: 106005393 | K24: 43736 | L24: 21 | M24: 1 | N24: 8 | O24: 1 | P24: C
A25: 0 | B25: SR 1003 | C25: 0 | E25: *LCL RIVER DELL TOWNES DR | F25: NC 42 | H25: 999.999 | J25: 105502153 | K25: 43256 | L25: 24 | M25: 1 | N25: 7 | O25: 1 | P25: O
A26: 0 | B26: SR 1003 | C26: 0 | E26: *LCL SAM & HELEN PL | F26: NC 42 | H26: 999.999 | J26: 107411745 | K26: 45136 | L26: 21 | M26: 1 | N26: 0 | O26: 5 | P26: O
A27: 0 | B27: SR 1003 | C27: 0.2 | D27: S | E27: *LCL SHAWAN RD | F27: SR 1718 | H27: 999.999 | J27: 108023560 | K27: 45705 | L27: 21 | M27: 1 | N27: 0 | O27: 1 | P27: O
A28: 0 | B28: SR 1003 | C28: 0.009 | D28: E | E28: *PP 9411 BUFFALO RD | F28: DEAD END | H28: 999.999 | J28: 108245867 | K28: 45928 | L28: 19 | M28: 1 | N28: 0 | O28: 8 | P28: O
A29: 0 | B29: SR 1003 | C29: 0 | E29: PVA PERCY FLOWERS | F29: NC 42 | H29: 999.999 | J29: 105493825 | K29: 43246 | L29: 24 | M29: 1 | N29: 4 | O29: 1 | P29: O
A30: 0 | B30: SR 1003 | C30: 0 | E30: PVA PETCO | F30: SR 1735 | H30: 999.999 | J30: 107283353 | K30: 45009 | L30: 26 | M30: 1 | N30: 4 | O30: 1 | P30: O
A31: 0 | B31: SR 1003 | C31: 0 | E31: PVA RIVER DELL ELEMENTARY | F31: SR 1700 | H31: 999.999 | J31: 104835084 | K31: 42612 | L31: 28 | M31: 1 | N31: 0 | O31: 1 | P31: O
A32: 0 | B32: SR 1003 | C32: 0 | E32: PVA RIVER DELL ELEMENTARY | F32: SR 2659 | H32: 999.999 | J32: 104250924 | K32: 41992 | L32: 24 | M32: 1 | N32: 8 | O32: 1 | P32: C
A33: 0 | B33: SR 1003 | C33: 0 | E33: PVA THE GROCERY BAG | F33: SR 1735 | H33: 999.999 | J33: 105686525 | K33: 43424 | L33: 26 | M33: 1 | N33: 4 | O33: 5 | P33: O
A34: 0 | B34: SR 1701 | C34: 0 | E34: *LCL ETOWAH DR | F34: SR 1747 | H34: 999.999 | J34: 107054643 | K34: 44795 | L34: 30 | M34: 1 | N34: 0 | O34: 1 | P34: O
B35: SR 1701 | C35: 0 | E35: *LCL ETOWAH DR | F35: SR 1700 | H35: 999.999 | J35: 107749066 | K35: 45446 | L35: 21 | M35: 2 | N35: 0 | O35: 1 | P35: C
A36: 721 | B36: SR 1701 | C36: 0 | E36: *LCL TAST DR | F36: AUTUMN RIDGE | H36: 999.999 | J36: 105799174 | K36: 43535 | L36: 24 | M36: 1 | N36: 8 | O36: 1 | P36: O
A37: 0 | B37: SR 1701 | C37: 0.004 | D37: N | E37: *LCL TAST DRIVE | F37: SR 1716 | H37: 999.999 | J37: 105466442 | K37: 43221 | L37: 21 | M37: 1 | N37: 8 | O37: 1 | P37: C
A38: 0 | B38: SR 1701 | C38: 0 | E38: PVA ARCHER LODGE MIDDLE | F38: SR 1747 | H38: 999.999 | J38: 107868345 | K38: 45560 | L38: 23 | M38: 1 | N38: 7 | O38: 1 | P38: O
A39: 0 | B39: SR 1701 | C39: 0 | E39: PVA ARCHER LODGE PVA | F39: SR 1747 | H39: 999.999 | J39: 105818152 | K39: 43552 | L39: 22 | M39: 1 | N39: 7 | O39: 1 | P39: O
A40: 0 | B40: SR 1716 | C40: 0 | E40: PVA CORINTH HOLDERS | F40: NC 96 | H40: 999.999 | J40: 107563566 | K40: 45273 | L40: 30 | M40: 1 | N40: 4 | O40: 1 | P40: O
...

Sheet Filtered Fiche
A1: Muni. Code | B1: On Road | C1: Miles | D1: Dir From | E1: From Road | F1: Toward Road | G1: Milepost Road | H1: MP | I1: IS | J1: New MP | K1: MA | L1: Crash ID | M1: Date | N1: T | O1: C | P1: F | Q1: L | R1: S | S1: Comments
A2: IN STUDY
A3: 721 | B3: SR 1003 | C3: 0 | E3: SR 1702 | F3: SR 1701 | G3: SR 1003 | H3: 15.154 | I3: IS | L3: 105084916 | M3: 42841 | N3: 30 | O3: 1 | P3: 7 | Q3: 2 | R3: C | S3: Angle, EB at fault, struck SB, RAN STOP
A4: 0 | B4: SR 1003 | C4: 0 | E4: SR 1702 | F4: SR 1003 | G4: SR 1003 | H4: 15.154 | I4: IS | L4: 104510364 | M4: 42282 | N4: 30 | O4: 2 | P4: 7 | Q4: 1 | R4: C | S4: Angle, EB at fault, struck NB, RAN STOP
A5: 721 | B5: SR 1003 | C5: 0 | E5: SR 1702 | F5: SR 1701 | G5: SR 1003 | H5: 15.154 | I5: IS | L5: 106669379 | M5: 44433 | N5: 30 | O5: 1 | P5: 7 | Q5: 1 | R5: O | S5: Angle, WB at fault, struck NB, failure to yield
A6: 721 | B6: SR 1003 | C6: 0 | E6: SR 1702 | F6: SR 1701 | G6: SR 1003 | H6: 15.154 | I6: IS | L6: 105977989 | M6: 43707 | N6: 30 | O6: 1 | P6: 7 | Q6: 1 | R6: C | S6: Angle, WB at fault, struck SB, failure to yield
A7: 721 | B7: SR 1003 | C7: 0 | E7: SR 1702 | F7: SR 1700 | G7: SR 1003 | H7: 15.154 | I7: IS | L7: 106651431 | M7: 44413 | N7: 24 | O7: 1 | P7: 7 | Q7: 1 | R7: B | S7: LTDR, EB at fault, struck NB, failure to yield
A8: 721 | B8: SR 1003 | C8: 0 | E8: SR 1702 | F8: SR 1701 | G8: SR 1003 | H8: 15.154 | I8: IS | L8: 106879035 | M8: 44622 | N8: 30 | O8: 1 | P8: 7 | Q8: 4 | R8: O | S8: Angle, SB at fault, struck WB, failure to yield
A9: 0 | B9: SR 1003 | C9: 0 | E9: SR 1702 | F9: SR 1700 | G9: SR 1003 | H9: 15.154 | I9: IS | L9: 104017975 | M9: 41723 | N9: 30 | O9: 2 | P9: 7 | Q9: 1 | R9: C | S9: Angle, WB at fault, struck NB, RAN STOP
A10: 0 | B10: SR 1003 | C10: 0 | E10: SR 1702 | G10: SR 1003 | H10: 15.154 | I10: IS | L10: 104480315 | M10: 42249 | N10: 30 | O10: 1 | P10: 7 | Q10: 1 | R10: O | S10: Angle, EB at fault, struck SB, failure to yield
A11: 0 | B11: SR 1003 | C11: 0 | E11: SR 1702 | F11: SR 1700 | G11: SR 1003 | H11: 15.154 | I11: IS | L11: 105954288 | M11: 43686 | N11: 30 | O11: 1 | P11: 7 | Q11: 1 | R11: C | S11: Angle, WB at fault, struck SB, failure to yield
A12: 0 | B12: SR 1003 | C12: 0 | E12: SR 1702 | F12: SR 1703 | G12: SR 1003 | H12: 15.154 | I12: IS | L12: 105013146 | M12: 42783 | N12: 30 | O12: 1 | P12: 7 | Q12: 1 | R12: C | S12: Angle, WB at fault, struck NB, failure to yield
A13: 721 | B13: SR 1003 | C13: 0 | E13: SR 1702 | F13: SR 1700 | G13: SR 1003 | H13: 15.154 | I13: IS | L13: 105628937 | M13: 43379 | N13: 30 | O13: 1 | P13: 7 | Q13: 4 | R13: C | S13: Angle, WB at fault, struck SB, failure to yield
A14: 721 | B14: SR 1003 | C14: 0 | E14: SR 1702 | F14: SR 1701 | G14: SR 1003 | H14: 15.154 | I14: IS | L14: 106587177 | M14: 44343 | N14: 30 | O14: 1 | P14: 7 | Q14: 1 | R14: O | S14: Angle, EB at fault, struck NB, failure to yield
A15: 721 | B15: SR 1003 | C15: 0 | E15: SR 1702 | F15: SR 1770 | G15: SR 1003 | H15: 15.154 | I15: IS | L15: 106736743 | M15: 44489 | N15: 23 | O15: 1 | P15: 7 | Q15: 1 | R15: O | S15: LTSR, WB at fault, struck EB
A16: 721 | B16: SR 1003 | C16: 0 | E16: SR 1702 | F16: SR 1701 | G16: SR 1003 | H16: 15.154 | I16: IS | L16: 105565522 | M16: 43316 | N16: 30 | O16: 1 | P16: 7 | Q16: 1 | R16: B | S16: Angle, WB at fault, struck NB, RAN STOP
A17: 721 | B17: SR 1003 | C17: 0 | E17: SR 1702 | F17: SR 1702 | G17: SR 1003 | H17: 15.154 | I17: IS | L17: 106271226 | M17: 44019 | N17: 30 | O17: 1 | P17: 7 | Q17: 1 | R17: O | S17: Angle, WB at fault, struck NB, failure to yield
A18: 0 | B18: SR 1003 | C18: 0 | E18: SR 1702 | F18: SR 1700 | G18: SR 1003 | H18: 15.154 | I18: IS | L18: 104978168 | M18: 42748 | N18: 24 | O18: 1 | P18: 8 | Q18: 1 | R18: C | S18: LTDR, EB at fault, struck SB, failure to yield
A19: 721 | B19: SR 1003 | C19: 0 | E19: SR 1702 | F19: SR 1700 | G19: SR 1003 | H19: 15.154 | I19: IS | L19: 104852963 | M19: 42628 | N19: 30 | O19: 1 | P19: 0 | Q19: 1 | R19: C | S19: Angle, EB at fault, struck SB, RAN STOP
A20: 721 | B20: SR 1003 | C20: 0 | E20: SR 1702 | F20: SR 1701 | G20: SR 1003 | H20: 15.154 | I20: IS | L20: 106384474 | M20: 44130 | N20: 5 | O20: 1 | P20: 7 | Q20: 1 | R20: B | S20: Overturn, SB
B21: SR 1003 | C21: 0 | E21: SR 1702 | F21: SR 1770 | G21: SR 1003 | H21: 15.154 | I21: IS | L21: 108354952 | M21: 46018 | N21: 30 | O21: 1 | P21: 7 | Q21: 1 | R21: B | S21: Angle, NB at fault, struck EB, RAN STOP
A22: 0 | B22: SR 1003 | C22: 0 | E22: SR 1702 | F22: SR 1770 | G22: SR 1003 | H22: 15.154 | I22: IS | L22: 108053908 | M22: 45734 | N22: 30 | O22: 1 | P22: 7 | Q22: 4 | R22: O | S22: Angle, SB at fault, struck WB, RAN STOP
A23: 0 | B23: SR 1003 | C23: 0 | E23: SR 1702 | F23: SR 1700 | G23: SR 1003 | H23: 15.154 | I23: IS | L23: 108068543 | M23: 45749 | N23: 30 | O23: 1 | P23: 7 | Q23: 4 | R23: O | S23: Angle, SB at fault, struck WB, failure to yield
A24: 0 | B24: SR 1003 | C24: 0 | E24: SR 1702 | F24: SR 1700 | G24: SR 1003 | H24: 15.154 | I24: IS | L24: 107922235 | M24: 45611 | N24: 30 | O24: 1 | P24: 7 | Q24: 4 | R24: O | S24: Angle, SB at fault, struck WB, RAN STOP
A25: 0 | B25: SR 1003 | C25: 0 | E25: SR 1702 | F25: SR 1770 | G25: SR 1003 | H25: 15.154 | I25: IS | L25: 107781158 | M25: 45485 | N25: 30 | O25: 2 | P25: 7 | Q25: 1 | R25: B | S25: Angle, WB at fault, struck NB, failure to yield
B26: SR 1003 | C26: 0 | E26: SR 1702 | F26: SR 1701 | G26: SR 1003 | H26: 15.154 | I26: IS | L26: 107423856 | M26: 45148 | N26: 30 | O26: 1 | P26: 7 | Q26: 1 | R26: B | S26: Angle, EB at fault, struck SB, failure to yield
A27: 721 | B27: SR 1003 | C27: 0.008 | D27: N | E27: SR 1702 | F27: SR 3552 | G27: SR 1003 | H27: 15.162 | I27: IS | L27: 108148651 | M27: 45829 | N27: 17 | O27: 1 | P27: 0 | Q27: 5 | R27: O | S27: Animal, NB
A28: 0 | B28: SR 1003 | C28: 0.009 | D28: W | E28: SR 1702 | F28: SR 1770 | G28: SR 1003 | H28: 15.163 | I28: IS | L28: 107113927 | M28: 44848 | N28: 21 | O28: 1 | P28: 0 | Q28: 1 | R28: O | S28: Rear end, SB
A29: 721 | B29: SR 1003 | C29: 0.2 | D29: N | E29: SR 1701 | F29: SR 1702 | G29: SR 1003 | H29: 15.226 | I29: IS | L29: 107137613 | M29: 44847 | N29: 21 | O29: 2 | P29: 0 | Q29: 3 | R29: C | S29: Rear end, NB
A30: 721 | B30: SR 1003 | C30: 0.1 | D30: N | E30: SR 1702 | F30: SR 1770 | G30: SR 1003 | H30: 15.254 | I30: IS | L30: 105340880 | M30: 43104 | N30: 2 | O30: 5 | P30: 0 | Q30: 1 | R30: C | S30: ROR left, SB, snow
A31: 0 | B31: SR 1003 | C31: 0.1 | D31: N | E31: SR 1702 | F31: SR 1770 | G31: SR 1003 | H31: 15.254 | I31: IS | L31: 106801086 | M31: 44543 | N31: 19 | O31: 1 | P31: 0 | Q31: 1 | R31: O | S31: ROR right, SB
A32: 721 | B32: SR 1003 | C32: 0.3 | D32: N | E32: SR 1701 | F32: SR 1770 | G32: SR 1003 | H32: 15.326 | I32: IS | L32: 104011474 | M32: 41717 | N32: 23 | O32: 2 | P32: 5 | Q32: 1 | R32: O | S32: Sideswipe, same, NB, pass attempt
A33: 721 | B33: SR 1003 | C33: 0.2 | D33: N | E33: SR 1702 | F33: SR 1770 | G33: SR 1003 | H33: 15.354 | I33: IS | L33: 106619579 | M33: 44367 | N33: 19 | O33: 1 | P33: 0 | Q33: 1 | R33: O | S33: ROR right, SB
A34: 0 | B34: SR 1003 | C34: 0.2 | D34: N | E34: SR 1702 | F34: SR 1770 | G34: SR 1003 | H34: 15.354 | I34: IS | L34: 105711314 | M34: 43448 | N34: 19 | O34: 2 | P34: 0 | Q34: 1 | R34: O | S34: ROR right, NB
A35: 721 | B35: SR 1003 | C35: 0.2 | D35: N | E35: SR 1702 | F35: SR 1770 | G35: SR 1003 | H35: 15.354 | I35: IS | L35: 106397767 | M35: 44142 | N35: 29 | O35: 1 | P35: 0 | Q35: 1 | R35: B | S35: Sideswipe, opp, SB at fault
A36: 721 | B36: SR 1003 | C36: 0.23 | D36: N | E36: SR 1702 | F36: SR 1716 | G36: SR 1003 | H36: 15.384 | I36: IS | L36: 105055163 | M36: 42822 | N36: 19 | O36: 2 | P36: 0 | Q36: 1 | R36: C | S36: ROR right, SB, overturn
B37: SR 1003 | C37: 0.27 | D37: NW | E37: SR 1702 | F37: SR 1770 | G37: SR 1003 | H37: 15.424 | I37: IS | L37: 106433774 | M37: 44177 | N37: 19 | O37: 1 | P37: 0 | Q37: 1 | R37: O | S37: ROR right, SB, overturn
B38: SR 1003 | C38: 0.4 | D38: W | E38: SR 1701 | F38: SR 1716 | G38: SR 1003 | H38: 15.426 | I38: IS | L38: 105664891 | M38: 43407 | N38: 19 | O38: 1 | P38: 0 | Q38: 1 | R38: O | S38: ROR left, SB, medical episode
A39: 0 | B39: SR 1003 | C39: 0.3 | D39: N | E39: SR 1702 | F39: SR 1716 | G39: SR 1003 | H39: 15.454 | I39: IS | L39: 104581173 | M39: 42345 | N39: 19 | O39: 2 | P39: 0 | Q39: 1 | R39: O | S39: ROR right, NB
A40: 721 | B40: SR 1003 | C40: 0.3 | D40: N | E40: SR 1702 | F40: SR 1770 | G40: SR 1003 | H40: 15.454 | I40: IS | L40: 107607426 | M40: 45319 | N40: 19 | O40: 2 | P40: 0 | Q40: 1 | R40: B | S40: ROR right, NB
...

Sheet Binned Crashes
A1: Muni. Code | B1: On Road | C1: Miles | D1: Dir From | E1: From Road | F1: Toward Road | G1: Milepost Road | H1: MP | I1: IS | J1: New MP | K1: MA | L1: Crash ID | M1: Date | N1: T | O1: C | P1: F | Q1: L | R1: S | S1: Comments
A2: NOT IN STUDY - BEFORE STUDY LIMITS
A3: 0 | B3: SR 1003 | C3: 0 | E3: SR 1716 | F3: SR 1715 | G3: SR 1003 | H3: 17.691 | I3: RE | J3: 17.811 | L3: 104029773 | M3: 41738 | N3: 23 | O3: 1 | P3: 8 | Q3: 1 | R3: B | S3: LTSR, NB at fault, struck SB
A4: 0 | B4: SR 1716 | C4: 0 | E4: SR 1003 | F4: SR 1716 | G4: SR 1716 | H4: 999.999 | I4: ADD | J4: 17.691 | L4: 104194817 | M4: 41936 | N4: 19 | O4: 1 | P4: 8 | Q4: 1 | R4: O | S4: Run through int at SR 1716
A5: 0 | B5: SR 1003 | C5: 0.002 | D5: E | E5: SR 2638 | F5: SR 1716 | G5: SR 1003 | H5: 17.809 | I5: IS | J5: 17.809 | L5: 104233621 | M5: 41978 | N5: 21 | O5: 1 | P5: 0 | Q5: 5 | R5: O | S5: Rear end, NB, waiting for left turn
A6: 0 | B6: SR 1003 | C6: 0 | E6: SR 1716 | F6: SR 1717 | G6: SR 1003 | H6: 17.691 | I6: RE | J6: 17.811 | L6: 104385210 | M6: 42143 | N6: 23 | O6: 1 | P6: 8 | Q6: 1 | R6: A | S6: LTSR, NB at fault, struck SB
A7: BEFORE PERIOD: 6/1/2015 - 4/30/2020
A8: 0 | B8: SR 1716 | C8: 0 | E8: SR 1003 | F8: SR 1718 | G8: SR 1716 | H8: 999.999 | I8: ADD | J8: 17.691 | L8: 104509841 | M8: 42276 | N8: 19 | O8: 2 | P8: 0 | Q8: 5 | R8: O | S8: Run through int at SR 1716
A9: 0 | B9: SR 1003 | C9: 0 | E9: SR 1716 | F9: SR 1715 | G9: SR 1003 | H9: 17.691 | I9: RE | J9: 17.811 | L9: 104515269 | M9: 42284 | N9: 23 | O9: 1 | P9: 8 | Q9: 5 | R9: O | S9: LTSR, NB at fault, struck SB
A10: 0 | B10: SR 1003 | C10: 0.1 | D10: N | E10: SR 1716 | F10: SR 1717 | G10: SR 1003 | H10: 17.791 | I10: IS | J10: 17.791 | L10: 105381930 | M10: 42371 | N10: 17 | O10: 1 | P10: 0 | Q10: 5 | R10: O | S10: Animal, SB
A11: 0 | B11: SR 1716 | C11: 0 | E11: SR 1003 | F11: SR 1715 | G11: SR 2638 | H11: 1.44 | I11: RE | J11: 17.691 | K11: Y | L11: 104781542 | M11: 42556 | N11: 19 | O11: 1 | P11: 8 | Q11: 5 | S11: Run through int at SR 1716
A12: 0 | B12: SR 1716 | C12: 0 | E12: SR 1003 | F12: SR 1716 | G12: SR 1716 | H12: 999.999 | I12: ADD | J12: 17.811 | L12: 104830578 | M12: 42608 | N12: 19 | O12: 1 | P12: 8 | Q12: 5 | R12: O | S12: Run through int at SR 2638
A13: 0 | B13: SR 1716 | C13: 0 | E13: SR 1003 | F13: SR 1717 | G13: SR 1716 | H13: 999.999 | I13: ADD | J13: 17.811 | L13: 104866057 | M13: 42636 | N13: 24 | O13: 1 | P13: 9 | Q13: 1 | R13: O | S13: LTDR, EB at fault, struck SB, at SR 2638
A14: 0 | B14: SR 1003 | C14: 0 | E14: SR 1716 | F14: SR 1716 | G14: SR 1003 | H14: 17.691 | I14: RE | J14: 17.811 | L14: 104895997 | M14: 42670 | N14: 23 | O14: 1 | P14: 8 | Q14: 3 | R14: C | S14: LTSR, NB at fault, struck SB
A15: 0 | B15: SR 1003 | C15: 0 | E15: SR 1716 | F15: SR 1715 | G15: SR 1003 | H15: 17.691 | I15: RE | J15: 17.811 | L15: 104990692 | M15: 42765 | N15: 24 | O15: 1 | P15: 8 | Q15: 5 | R15: O | S15: LTSR, NB at fault, struck SB
A16: 0 | B16: SR 1003 | C16: 0 | E16: SR 2638 | F16: SR 1716 | G16: SR 1003 | H16: 17.811 | I16: IS | J16: 17.811 | L16: 105002026 | M16: 42773 | N16: 24 | O16: 1 | P16: 8 | Q16: 1 | R16: C | S16: LTSR, NB at fault, struck SB
A17: 0 | B17: SR 1003 | C17: 0 | E17: SR 1003 | F17: SR 1717 | G17: SR 1003 | H17: 999.999 | I17: ADD | J17: 17.691 | L17: 105014768 | M17: 42783 | N17: 23 | O17: 1 | P17: 0 | Q17: 1 | R17: C | S17: LTSR, SB at fault, struck NB at SR 1716
A18: 0 | B18: SR 1716 | C18: 0.009 | D18: W | E18: SR 1003 | F18: SR 1715 | G18: SR 2638 | H18: 1.431 | I18: ADD | J18: 17.691 | K18: Y | L18: 105286496 | M18: 43047 | N18: 19 | O18: 2 | P18: 8 | Q18: 1 | R18: O | S18: Run through int at SR 1716
A19: 0 | B19: SR 1003 | C19: 0 | E19: SR 1716 | F19: SR 1716 | G19: SR 1003 | H19: 17.691 | I19: IS | J19: 17.691 | L19: 105342823 | M19: 43103 | N19: 29 | O19: 4 | P19: 0 | Q19: 5 | R19: O | S19: Sideswipe, opp, SB at fault
A20: 0 | B20: SR 1003 | C20: 0 | E20: SR 1716 | F20: SR 1717 | G20: SR 1003 | H20: 17.691 | I20: RE | J20: 17.811 | L20: 105479722 | M20: 43230 | N20: 23 | O20: 1 | P20: 8 | Q20: 1 | R20: B | S20: LTSR, NB at fault, struck SB
A21: 0 | B21: SR 1003 | C21: 0.009 | D21: W | E21: SR 1716 | F21: PRIVATE PROPERTY | G21: SR 1003 | H21: 17.7 | I21: IS | J21: 17.7 | L21: 105559557 | M21: 43309 | N21: 19 | O21: 1 | P21: 8 | Q21: 1 | R21: O | S21: Run through int at SR 1716
A22: 0 | B22: SR 1003 | C22: 0 | E22: SR 1716 | F22: SR 1716 | G22: SR 1003 | H22: 17.691 | I22: RE | J22: 17.811 | L22: 105647086 | M22: 43396 | N22: 23 | O22: 1 | P22: 9 | Q22: 5 | R22: C | S22: LTSR, NB at fault, struck SB
A23: 0 | B23: SR 1003 | C23: 0 | E23: SR 1716 | F23: SR 2637 | G23: SR 1003 | H23: 17.691 | I23: IS | J23: 17.691 | L23: 105714555 | M23: 43449 | N23: 23 | O23: 2 | P23: 8 | Q23: 5 | R23: A | S23: LTSR, SB at fault, struck NB
A24: 0 | B24: SR 1716 | C24: 0 | E24: SR 1003 | F24: SR 1716 | G24: SR 1716 | H24: 999.999 | I24: ADD | J24: 17.691 | L24: 105723251 | M24: 43460 | N24: 19 | O24: 1 | P24: 8 | Q24: 5 | R24: B | S24: Run through int at SR 1716
A25: 0 | B25: SR 1003 | C25: 0 | E25: SR 1716 | F25: SR 1718 | G25: SR 1003 | H25: 17.691 | I25: RE | J25: 17.811 | L25: 105740600 | M25: 43473 | N25: 24 | O25: 1 | P25: 8 | Q25: 1 | R25: C | S25: LTSR, NB at fault, struck SB
A26: 0 | B26: SR 1003 | C26: 0 | E26: SR 1716 | F26: SR 1716 | G26: SR 1003 | H26: 17.691 | I26: RE | J26: 17.811 | L26: 105736892 | M26: 43474 | N26: 23 | O26: 1 | P26: 8 | Q26: 5 | R26: C | S26: LTSR, NB at fault, struck SB
A27: 0 | B27: SR 1003 | C27: 0 | E27: SR 1716 | F27: SR 1702 | G27: SR 1003 | H27: 17.691 | I27: RE | J27: 17.811 | L27: 105765030 | M27: 43499 | N27: 29 | O27: 1 | P27: 8 | Q27: 5 | R27: C | S27: Sideswipe, opp, fault not determined
A28: 0 | B28: SR 1003 | C28: 0 | E28: SR 1716 | F28: SR 1716 | G28: SR 1003 | H28: 17.691 | I28: RE | J28: 17.811 | L28: 105771630 | M28: 43507 | N28: 23 | O28: 2 | P28: 8 | Q28: 5 | R28: O | S28: LTSR, NB at fault, struck SB
A29: 0 | B29: SR 1003 | C29: 0 | E29: SR 1716 | F29: SR 1716 | G29: SR 1003 | H29: 17.691 | I29: RE | J29: 17.811 | L29: 105801434 | M29: 43535 | N29: 23 | O29: 1 | P29: 8 | Q29: 1 | R29: B | S29: LTSR, NB at fault, struck SB
A30: 0 | B30: SR 1003 | C30: 0 | E30: SR 1716 | F30: SR 1700 | G30: SR 1003 | H30: 17.691 | I30: RE | J30: 17.811 | L30: 105827464 | M30: 43563 | N30: 23 | O30: 2 | P30: 8 | Q30: 5 | R30: C | S30: LTSR, NB at fault, struck SB
A31: 0 | B31: SR 1003 | C31: 0 | E31: SR 1716 | F31: SR 1717 | G31: SR 1003 | H31: 17.691 | I31: RE | J31: 17.811 | L31: 105832371 | M31: 43567 | N31: 23 | O31: 2 | P31: 8 | Q31: 1 | R31: O | S31: LTSR, NB at fault, struck SB
A32: 0 | B32: SR 1003 | C32: 0 | E32: SR 1716 | F32: SR 1715 | G32: SR 1003 | H32: 17.691 | I32: RE | J32: 17.811 | L32: 105926749 | M32: 43661 | N32: 24 | O32: 1 | P32: 9 | Q32: 1 | R32: O | S32: LTSR, NB at fault, struck SB
A33: 0 | B33: SR 1003 | C33: 0 | E33: SR 1716 | F33: SR 1716 | G33: SR 1003 | H33: 17.691 | I33: RE | J33: 17.811 | L33: 105960507 | M33: 43692 | N33: 23 | O33: 1 | P33: 8 | Q33: 1 | R33: C | S33: LTSR, NB at fault, struck SB
... A49: 0 | B49: SR 1003 | C49: 0 | E49: SR 1716 | F49: SR 1716 | G49: SR 1003 | H49: 17.691 | I49: RE | J49: 17.811 | L49: 106196146 | M49: 43908 | N49: 23 | O49: 1 | P49: 9 | Q49: 2 | R49: C | S49: LTSR, NB at fault, struck SB
A50: CONSTRUCTION PERIOD: 5/1/2020 - 6/30/2021
A51: Z | B51: SR 1003 | C51: 0 | E51: SR 1716 | F51: SR 1717 | G51: SR 1003 | H51: 17.691 | I51: RE | J51: 17.811 | L51: 106232720 | M51: 43973 | N51: 31 | O51: 1 | P51: 8 | Q51: 1 | R51: O | S51: Backing up, NB
A52: 0 | B52: SR 1003 | C52: 0 | E52: SR 1716 | F52: SR 1715 | G52: SR 1003 | H52: 17.691 | I52: RE | J52: 17.811 | L52: 106269515 | M52: 44014 | N52: 23 | O52: 1 | P52: 9 | Q52: 1 | R52: O | S52: LTSR, NB at fault, struck SB
A53: 0 | B53: SR 1003 | C53: 0 | E53: SR 1716 | F53: SR 1717 | G53: SR 1003 | H53: 17.691 | I53: RE | J53: 17.811 | L53: 106272366 | M53: 44020 | N53: 30 | O53: 1 | P53: 8 | Q53: 5 | R53: B | S53: LTDR, EB at fault, struck NB, RAN STOP
A54: 0 | B54: SR 1003 | C54: 0 | E54: SR 1716 | F54: SR 1715 | G54: SR 1003 | H54: 17.691 | I54: RE | J54: 17.811 | L54: 106283202 | M54: 44033 | N54: 24 | O54: 1 | P54: 9 | Q54: 1 | R54: O | S54: LTSR, NB at fault, struck SB
A55: 0 | B55: SR 1003 | C55: 0.1 | D55: N | E55: SR 1716 | F55: SR 1716 | G55: SR 1003 | H55: 17.791 | I55: IS | J55: 17.791 | L55: 106338374 | M55: 44090 | N55: 19 | O55: 1 | P55: 0 | Q55: 5 | R55: O | S55: ROR left, NB
...

Sheet Sheet4
A1: 104509841 | B1: =A1&"|" -> 104509841| | C1: 17.691 | F1: 106966487 | G1: =F1&"|" -> 106966487| | H1: 17.691 | M1: CRASH ID | N1: ON RD CD | O1: SVRTY | P1: DATE | Q1: TYPE
A2: 104515269 | B2: =A2&"|" -> 104515269| | C2: 17.811 | F2: 107194517 | G2: =F2&"|" -> 107194517| | H2: 17.748 | M2: 106879035 | N2: 40001003 | O2: 5 | P2: 44622.826 | Q2: 30
A3: 105381930 | B3: =A3&"|" -> 105381930| | C3: 17.791 | F3: 107422984 | G3: =F3&"|" -> 107422984| | H3: 17.811 | M3: 107423856 | N3: 40001003 | O3: 3 | P3: 45148.692 | Q3: 30
A4: 104781542 | B4: =A4&"|" -> 104781542| | C4: 17.691 | F4: 107628588 | G4: =F4&"|" -> 107628588| | H4: 17.811 | M4: 107781158 | N4: 40001003 | O4: 3 | P4: 45485.573 | Q4: 30
A5: 104830578 | B5: =A5&"|" -> 104830578| | C5: 17.811 | F5: 107653866 | G5: =F5&"|" -> 107653866| | H5: 17.811 | M5: 107922235 | N5: 40001003 | O5: 5 | P5: 45611.815 | Q5: 30
A6: 104866057 | B6: =A6&"|" -> 104866057| | C6: 17.811 | F6: 107693756 | G6: =F6&"|" -> 107693756| | H6: 17.811 | M6: 107948352 | N6: 40001702 | O6: 4 | P6: 45632.865 | Q6: 30
A7: 104895997 | B7: =A7&"|" -> 104895997| | C7: 17.811 | F7: 107863508 | G7: =F7&"|" -> 107863508| | H7: 17.811 | M7: 108053908 | N7: 40001003 | O7: 5 | P7: 45734.84 | Q7: 30
A8: 104990692 | B8: =A8&"|" -> 104990692| | C8: 17.811 | F8: 107867161 | G8: =F8&"|" -> 107867161| | H8: 17.811 | M8: 108068543 | N8: 40001003 | O8: 5 | P8: 45749.957 | Q8: 30
A9: 105002026 | B9: =A9&"|" -> 105002026| | C9: 17.811 | F9: 107896873 | G9: =F9&"|" -> 107896873| | H9: 17.811 | M9: 108354952 | N9: 40001003 | O9: 3 | P9: 46018.685 | Q9: 30
A10: 105014768 | B10: =A10&"|" -> 105014768| | C10: 17.691 | F10: 107897875 | G10: =F10&"|" -> 107897875| | H10: 17.811 | M10: 108148651 | N10: 40001003 | O10: 5 | P10: 45829.034 | Q10: 17
A11: 105286496 | B11: =A11&"|" -> 105286496| | C11: 17.691 | F11: 107899978 | G11: =F11&"|" -> 107899978| | H11: 17.811 | M11: 107113927 | N11: 40001003 | O11: 5 | P11: 44848.658 | Q11: 21
A12: 105342823 | B12: =A12&"|" -> 105342823| | C12: 17.691 | F12: 107954933 | G12: =F12&"|" -> 107954933| | H12: 17.811 | M12: 107137613 | N12: 40001003 | O12: 4 | P12: 44847.319 | Q12: 21
A13: 105479722 | B13: =A13&"|" -> 105479722| | C13: 17.811 | F13: 108305597 | G13: =F13&"|" -> 108305597| | H13: 17.719 | M13: 107607426 | N13: 40001003 | O13: 3 | P13: 45319.383 | Q13: 19
... A17: 105723251 | B17: =A17&"|" -> 105723251| | C17: 17.691 | F17: 108401181 | G17: =F17&"|" -> 108401181| | H17: 17.811 | M17: 107444969 | N17: 40001003 | O17: 5 | P17: 45171.262 | Q17: 19
A18: 105740600 | B18: =A18&"|" -> 105740600| | C18: 17.811 | M18: 106830764 | N18: 40001003 | O18: 5 | P18: 44573.687 | Q18: 19
A19: 105736892 | B19: =A19&"|" -> 105736892| | C19: 17.811 | M19: 108430843 | N19: 40001003 | O19: 4 | P19: 46086.923 | Q19: 5
A20: 105765030 | B20: =A20&"|" -> 105765030| | C20: 17.811 | M20: 107557759 | N20: 40001003 | O20: 5 | P20: 45270.122 | Q20: 19
A21: 105771630 | B21: =A21&"|" -> 105771630| | C21: 17.811 | M21: 107797447 | N21: 40001003 | O21: 6 | P21: 45499.864 | Q21: 19
A22: 105801434 | B22: =A22&"|" -> 105801434| | C22: 17.811 | M22: 107640861 | N22: 40001003 | O22: 5 | P22: 45350.901 | Q22: 19
A23: 105827464 | B23: =A23&"|" -> 105827464| | C23: 17.811 | M23: 107122747 | N23: 40001003 | O23: 5 | P23: 44856.452 | Q23: 17
A24: 105832371 | B24: =A24&"|" -> 105832371| | C24: 17.811 | M24: 108218394 | N24: 40001003 | O24: 5 | P24: 45898.69 | Q24: 19
A25: 105926749 | B25: =A25&"|" -> 105926749| | C25: 17.811 | M25: 107017689 | N25: 40001003 | O25: 5 | P25: 44748.624 | Q25: 19
A26: 105960507 | B26: =A26&"|" -> 105960507| | C26: 17.811 | M26: 107140545 | N26: 40001003 | O26: 2 | P26: 44864.399 | Q26: 19
A27: 105967757 | B27: =A27&"|" -> 105967757| | C27: 17.811 | M27: 107549464 | N27: 40001003 | O27: 4 | P27: 45262.817 | Q27: 17
A28: 105998918 | B28: =A28&"|" -> 105998918| | C28: 17.691 | M28: 106891729 | N28: 40001003 | O28: 5 | P28: 44632.467 | Q28: 19
A29: 106005220 | B29: =A29&"|" -> 106005220| | C29: 17.811 | M29: 108207667 | N29: 40001003 | O29: 5 | P29: 45888.69 | Q29: 19
... A42: 106196146 | B42: =A42&"|" -> 106196146| | C42: 17.811 | M42: 107249049 | N42: 40001003 | O42: 5 | P42: 44971.265 | Q42: 21
M43: 108049386 | N43: 40001003 | O43: 3 | P43: 45731.673 | Q43: 5
M44: 107576053 | N44: 40001003 | O44: 5 | P44: 45281.465 | Q44: 19
M45: 107237915 | N45: 40001003 | O45: 5 | P45: 44964.815 | Q45: 19
M46: 106950839 | N46: 40001003 | O46: 5 | P46: 44690.719 | Q46: 18
M47: 107270207 | N47: 40001003 | O47: 4 | P47: 44995.539 | Q47: 29
M48: 107270251 | N48: 40001003 | O48: 5 | P48: 44995.54 | Q48: 19
M49: 107730387 | N49: 40001003 | O49: 5 | P49: 45436.653 | Q49: 19
M50: 108492561 | N50: 40001003 | O50: 4 | P50: 46150.715 | Q50: 28
M51: 108077755 | N51: 40001003 | O51: 5 | P51: 45760.027 | Q51: 17
M52: 107417559 | N52: 40001003 | O52: 5 | P52: 45139.878 | Q52: 19
M53: 108268106 | N53: 40001003 | O53: 5 | P53: 45945.708 | Q53: 21
M54: 107971869 | N54: 40001003 | O54: 5 | P54: 45651.422 | Q54: 23
... M109: 108023560 | N109: 40001003 | O109: 5 | P109: 45705.379 | Q109: 21

Sheet Before
A1: Manually Edit These Columns (A -> N). | P1: Don't Edit These Columns (O -> ). Calculations are Automatic.
A2: ="Before Period ("&TEXT('Evaluation Set-up'!$D$9, "mm/dd/yyyy")&" - "&TEXT('Evaluation Set-up'!$E$9, "mm/dd/yyyy")&")" -> Before Period (06/01/2015 - 04/30/2020) | P2: Crash # | Q2: Crash Year | R2: Severity Index | S2: Target-1 Severity Index | T2: Target-1 KABCO | U2: Target-2 Severity Index | V2: Target-2 KABCO
A3: Crash ID | B3: Date | C3: T | D3: C | E3: F | F3: L | G3: S | H3: Final MP | I3: Analyst's Notes Column 1 | J3: Analyst's Notes Column 2 | K3: Analyst's Notes Column 3 | L3: Analyst's Notes Column 4 | M3: Target-1? | N3: Target-2? | Z3: Total | AA3: Target-1 | AB3: Target-2 | AC3: All Targets | AR3: Crash # | AS3: Target Crash? | AT3: Within 250' of an intx?
A4: 104509841 | B4: 42276 | C4: 19 | D4: 2 | E4: 0 | F4: 5 | G4: O | H4: 17.691 | I4: Run through int at SR 1716 | P4: =IF(R4 = "", "", COUNT($R$4:R4)) -> 1 | Q4: =IF(B4="", "", YEAR(B4)) -> 2015 | R4: =IF(A4="", "", IF(G4="",1,IF(G4="O",1,IF(G4="C",8.4,IF(G4="B",8.4,IF(G4="A",76.8,IF(G4="K",76.8,"ERR"))))))) -> 1 | S4: =IF(M4<>"",R4,"") | T4: =IF(IF(M4<>"",G4,"")=0, "O", IF(M4<>"",G4,"")) | U4: =IF(N4<>"",R4,"") | V4: =IF(IF(N4<>"",G4,"")=0, "O", IF(N4<>"",G4,"")) | Y4: K | Z4: =COUNTIF($G$4:$G$1048576,$Y4) -> 0 | AA4: =COUNTIF($T$4:$T$1048576,$Y4) -> 0 | AB4: =COUNTIF($V$4:$V$1048576,$Y4) -> 0 | AC4: =COUNTIF($T:$T, Y4)+COUNTIF($V:$V, Y4)-COUNTIFS($T:$T, Y4, $V:$V, Y4) -> 0 | AR4: =IF(P4>0, P4, "") -> 1 | AS4: =IF(OR(M4="Y",N4="Y"),"Y","") | AT4: =IF(AR4="","",IF(AND(H4>='Intersection Mileposts'!$F$5,H4<='Intersection Mileposts'!$G$5),"Y",IF(AND(H4>='Intersection Mileposts'!$F$6,H4<='Intersection Mileposts'!$G$6),"Y",IF(AND(H4>='Intersection Mileposts'!$F$7,H4<='Intersection Mileposts'!$G$7),"Y",IF(AND(H4>='Intersection Mileposts'!$F$8,H4<='Intersection Mileposts'!$G$8),"Y",IF(AND(H4>='Intersection Mileposts'!$F$9,H4<='Intersection Mileposts'!$G$9),"Y",IF(AND(H4>='Intersection Mileposts'!$F$10,H4<='Intersection Mileposts'!$G$10),"Y",IF(AND(H4>='Intersection Mileposts'!$F$11,H4<='Intersection Mileposts'!$G$11),"Y",IF(AND(H4>='Intersection Mileposts'!$F$12,H4<='Intersection Mileposts'!$G$12),"Y",IF(AND(H4>='Intersection Mileposts'!$F$13,H4<='Intersection Mileposts'!$G$13),"Y",IF(AND(H4>='Intersection Mileposts'!$F$14,H4<='Intersection Mileposts'!$G$14),"Y",IF(AND(H4>='Intersection Mileposts'!$F$15,H4<='Intersection Mileposts'!$G$15),"Y",IF(AND(H4>='Intersection Mileposts'!$F$16,H4<='Intersection Mileposts'!$G$16),"Y",IF(AND(H4>='Intersection Mileposts'!$F$17,H4<='Intersection Mileposts'!$G$17),"Y",IF(AND(H4>='Intersection Mileposts'!$F$18,H4<='Intersection Mileposts'!$G$18),"Y",IF(AND(H4>='Intersection Mileposts'!$F$19,H4<='Intersection Mileposts'!$G$19),"Y",IF(AND(H4>='Intersection Mileposts'!$F$20,H4<='Intersection Mileposts'!$G$20),"Y",IF(AND(H4>='Intersection Mileposts'!$F$21,H4<='Intersection Mileposts'!$G$21),"Y",IF(AND(H4>='Intersection Mileposts'!$F$22,H4<='Intersection Mileposts'!$G$22),"Y",IF(AND(H4>='Intersection Mileposts'!$F$23,H4<='Intersection Mileposts'!$G$23),"Y",IF(AND(H4>='Intersection Mileposts'!$F$24,H4<='Intersection Mileposts'!$G$24),"Y",IF(AND(H4>='Intersection Mileposts'!$F$25,H4<='Intersection Mileposts'!$G$25),"Y",IF(AND(H4>='Intersection Mileposts'!$F$26,H4<='Intersection Mileposts'!$G$26),"Y",IF(AND(H4>='Intersection Mileposts'!$F$27,H4<='Intersection Mileposts'!$G$27),"Y",IF(AND(H4>='Intersection Mileposts'!$F$28,H4<='Intersection Mileposts'!$G$28),"Y",IF(AND(H4>='Intersection Mileposts'!$F$29,H4<='Intersection Mileposts'!$G$29),"Y", IF(AND(H4>='Intersection Mileposts'!$F$30,H4<='Intersection Mileposts'!$G$30),"Y",IF(AND(H4>='Intersection Mileposts'!$F$31,H4<='Intersection Mileposts'!$G$31),"Y",IF(AND(H4>='Intersection Mileposts'!$F$32,H4<='Intersection Mileposts'!$G$32),"Y",IF(AND(H4>='Intersection Mileposts'!$F$33,H4<='Intersection Mileposts'!$G$33),"Y",IF(AND(H4>='Intersection Mileposts'!$F$34,H4<='Intersection Mileposts'!$G$34),"Y",IF(AND(H4>='Intersection Mileposts'!$F$35,H4<='Intersection Mileposts'!$G$35),"Y",IF(AND(H4>='Intersection Mileposts'!$F$36,H4<='Intersection Mileposts'!$G$36),"Y",IF(AND(H4>='Intersection Mileposts'!$F$37,H4<='Intersection Mileposts'!$G$37),"Y",IF(AND(H4>='Intersection Mileposts'!$F$38,H4<='Intersection Mileposts'!$G$38),"Y",IF(AND(H4>='Intersection Mileposts'!$F$39,H4<='Intersection Mileposts'!$G$39),"Y","N")))))))))))))))))))))))))))))))))))) -> Y
A5: 104781542 | B5: 42556 | C5: 19 | D5: 1 | E5: 8 | F5: 5 | H5: 17.691 | I5: Run through int at SR 1716 | P5: =IF(R5 = "", "", COUNT($R$4:R5)) -> 2 | Q5: =IF(B5="", "", YEAR(B5)) -> 2016 | R5: =IF(A5="", "", IF(G5="",1,IF(G5="O",1,IF(G5="C",8.4,IF(G5="B",8.4,IF(G5="A",76.8,IF(G5="K",76.8,"ERR"))))))) -> 1 | S5: =IF(M5<>"",R5,"") | T5: =IF(IF(M5<>"",G5,"")=0, "O", IF(M5<>"",G5,"")) | U5: =IF(N5<>"",R5,"") | V5: =IF(IF(N5<>"",G5,"")=0, "O", IF(N5<>"",G5,"")) | Y5: A | Z5: =COUNTIF($G$4:$G$1048576,$Y5) -> 1 | AA5: =COUNTIF($T$4:$T$1048576,$Y5) -> 1 | AB5: =COUNTIF($V$4:$V$1048576,$Y5) -> 0 | AC5: =COUNTIF($T:$T, Y5)+COUNTIF($V:$V, Y5)-COUNTIFS($T:$T, Y5, $V:$V, Y5) -> 1 | AR5: =IF(P5>0, P5, "") -> 2 | AS5: =IF(OR(M5="Y",N5="Y"),"Y","") | AT5: =IF(AR5="","",IF(AND(H5>='Intersection Mileposts'!$F$5,H5<='Intersection Mileposts'!$G$5),"Y",IF(AND(H5>='Intersection Mileposts'!$F$6,H5<='Intersection Mileposts'!$G$6),"Y",IF(AND(H5>='Intersection Mileposts'!$F$7,H5<='Intersection Mileposts'!$G$7),"Y",IF(AND(H5>='Intersection Mileposts'!$F$8,H5<='Intersection Mileposts'!$G$8),"Y",IF(AND(H5>='Intersection Mileposts'!$F$9,H5<='Intersection Mileposts'!$G$9),"Y",IF(AND(H5>='Intersection Mileposts'!$F$10,H5<='Intersection Mileposts'!$G$10),"Y",IF(AND(H5>='Intersection Mileposts'!$F$11,H5<='Intersection Mileposts'!$G$11),"Y",IF(AND(H5>='Intersection Mileposts'!$F$12,H5<='Intersection Mileposts'!$G$12),"Y",IF(AND(H5>='Intersection Mileposts'!$F$13,H5<='Intersection Mileposts'!$G$13),"Y",IF(AND(H5>='Intersection Mileposts'!$F$14,H5<='Intersection Mileposts'!$G$14),"Y",IF(AND(H5>='Intersection Mileposts'!$F$15,H5<='Intersection Mileposts'!$G$15),"Y",IF(AND(H5>='Intersection Mileposts'!$F$16,H5<='Intersection Mileposts'!$G$16),"Y",IF(AND(H5>='Intersection Mileposts'!$F$17,H5<='Intersection Mileposts'!$G$17),"Y",IF(AND(H5>='Intersection Mileposts'!$F$18,H5<='Intersection Mileposts'!$G$18),"Y",IF(AND(H5>='Intersection Mileposts'!$F$19,H5<='Intersection Mileposts'!$G$19),"Y",IF(AND(H5>='Intersection Mileposts'!$F$20,H5<='Intersection Mileposts'!$G$20),"Y",IF(AND(H5>='Intersection Mileposts'!$F$21,H5<='Intersection Mileposts'!$G$21),"Y",IF(AND(H5>='Intersection Mileposts'!$F$22,H5<='Intersection Mileposts'!$G$22),"Y",IF(AND(H5>='Intersection Mileposts'!$F$23,H5<='Intersection Mileposts'!$G$23),"Y",IF(AND(H5>='Intersection Mileposts'!$F$24,H5<='Intersection Mileposts'!$G$24),"Y",IF(AND(H5>='Intersection Mileposts'!$F$25,H5<='Intersection Mileposts'!$G$25),"Y",IF(AND(H5>='Intersection Mileposts'!$F$26,H5<='Intersection Mileposts'!$G$26),"Y",IF(AND(H5>='Intersection Mileposts'!$F$27,H5<='Intersection Mileposts'!$G$27),"Y",IF(AND(H5>='Intersection Mileposts'!$F$28,H5<='Intersection Mileposts'!$G$28),"Y",IF(AND(H5>='Intersection Mileposts'!$F$29,H5<='Intersection Mileposts'!$G$29),"Y", IF(AND(H5>='Intersection Mileposts'!$F$30,H5<='Intersection Mileposts'!$G$30),"Y",IF(AND(H5>='Intersection Mileposts'!$F$31,H5<='Intersection Mileposts'!$G$31),"Y",IF(AND(H5>='Intersection Mileposts'!$F$32,H5<='Intersection Mileposts'!$G$32),"Y",IF(AND(H5>='Intersection Mileposts'!$F$33,H5<='Intersection Mileposts'!$G$33),"Y",IF(AND(H5>='Intersection Mileposts'!$F$34,H5<='Intersection Mileposts'!$G$34),"Y",IF(AND(H5>='Intersection Mileposts'!$F$35,H5<='Intersection Mileposts'!$G$35),"Y",IF(AND(H5>='Intersection Mileposts'!$F$36,H5<='Intersection Mileposts'!$G$36),"Y",IF(AND(H5>='Intersection Mileposts'!$F$37,H5<='Intersection Mileposts'!$G$37),"Y",IF(AND(H5>='Intersection Mileposts'!$F$38,H5<='Intersection Mileposts'!$G$38),"Y",IF(AND(H5>='Intersection Mileposts'!$F$39,H5<='Intersection Mileposts'!$G$39),"Y","N")))))))))))))))))))))))))))))))))))) -> Y
A6: 105014768 | B6: 42783 | C6: 23 | D6: 1 | E6: 0 | F6: 1 | G6: C | H6: 17.691 | I6: LTSR, SB at fault, struck NB at SR 1716 | M6: Y | P6: =IF(R6 = "", "", COUNT($R$4:R6)) -> 3 | Q6: =IF(B6="", "", YEAR(B6)) -> 2017 | R6: =IF(A6="", "", IF(G6="",1,IF(G6="O",1,IF(G6="C",8.4,IF(G6="B",8.4,IF(G6="A",76.8,IF(G6="K",76.8,"ERR"))))))) -> 8.4 | S6: =IF(M6<>"",R6,"") -> 8.4 | T6: =IF(IF(M6<>"",G6,"")=0, "O", IF(M6<>"",G6,"")) -> C | U6: =IF(N6<>"",R6,"") | V6: =IF(IF(N6<>"",G6,"")=0, "O", IF(N6<>"",G6,"")) | Y6: B | Z6: =COUNTIF($G$4:$G$1048576,$Y6) -> 5 | AA6: =COUNTIF($T$4:$T$1048576,$Y6) -> 3 | AB6: =COUNTIF($V$4:$V$1048576,$Y6) -> 1 | AC6: =COUNTIF($T:$T, Y6)+COUNTIF($V:$V, Y6)-COUNTIFS($T:$T, Y6, $V:$V, Y6) -> 4 | AR6: =IF(P6>0, P6, "") -> 3 | AS6: =IF(OR(M6="Y",N6="Y"),"Y","") -> Y | AT6: =IF(AR6="","",IF(AND(H6>='Intersection Mileposts'!$F$5,H6<='Intersection Mileposts'!$G$5),"Y",IF(AND(H6>='Intersection Mileposts'!$F$6,H6<='Intersection Mileposts'!$G$6),"Y",IF(AND(H6>='Intersection Mileposts'!$F$7,H6<='Intersection Mileposts'!$G$7),"Y",IF(AND(H6>='Intersection Mileposts'!$F$8,H6<='Intersection Mileposts'!$G$8),"Y",IF(AND(H6>='Intersection Mileposts'!$F$9,H6<='Intersection Mileposts'!$G$9),"Y",IF(AND(H6>='Intersection Mileposts'!$F$10,H6<='Intersection Mileposts'!$G$10),"Y",IF(AND(H6>='Intersection Mileposts'!$F$11,H6<='Intersection Mileposts'!$G$11),"Y",IF(AND(H6>='Intersection Mileposts'!$F$12,H6<='Intersection Mileposts'!$G$12),"Y",IF(AND(H6>='Intersection Mileposts'!$F$13,H6<='Intersection Mileposts'!$G$13),"Y",IF(AND(H6>='Intersection Mileposts'!$F$14,H6<='Intersection Mileposts'!$G$14),"Y",IF(AND(H6>='Intersection Mileposts'!$F$15,H6<='Intersection Mileposts'!$G$15),"Y",IF(AND(H6>='Intersection Mileposts'!$F$16,H6<='Intersection Mileposts'!$G$16),"Y",IF(AND(H6>='Intersection Mileposts'!$F$17,H6<='Intersection Mileposts'!$G$17),"Y",IF(AND(H6>='Intersection Mileposts'!$F$18,H6<='Intersection Mileposts'!$G$18),"Y",IF(AND(H6>='Intersection Mileposts'!$F$19,H6<='Intersection Mileposts'!$G$19),"Y",IF(AND(H6>='Intersection Mileposts'!$F$20,H6<='Intersection Mileposts'!$G$20),"Y",IF(AND(H6>='Intersection Mileposts'!$F$21,H6<='Intersection Mileposts'!$G$21),"Y",IF(AND(H6>='Intersection Mileposts'!$F$22,H6<='Intersection Mileposts'!$G$22),"Y",IF(AND(H6>='Intersection Mileposts'!$F$23,H6<='Intersection Mileposts'!$G$23),"Y",IF(AND(H6>='Intersection Mileposts'!$F$24,H6<='Intersection Mileposts'!$G$24),"Y",IF(AND(H6>='Intersection Mileposts'!$F$25,H6<='Intersection Mileposts'!$G$25),"Y",IF(AND(H6>='Intersection Mileposts'!$F$26,H6<='Intersection Mileposts'!$G$26),"Y",IF(AND(H6>='Intersection Mileposts'!$F$27,H6<='Intersection Mileposts'!$G$27),"Y",IF(AND(H6>='Intersection Mileposts'!$F$28,H6<='Intersection Mileposts'!$G$28),"Y",IF(AND(H6>='Intersection Mileposts'!$F$29,H6<='Intersection Mileposts'!$G$29),"Y", IF(AND(H6>='Intersection Mileposts'!$F$30,H6<='Intersection Mileposts'!$G$30),"Y",IF(AND(H6>='Intersection Mileposts'!$F$31,H6<='Intersection Mileposts'!$G$31),"Y",IF(AND(H6>='Intersection Mileposts'!$F$32,H6<='Intersection Mileposts'!$G$32),"Y",IF(AND(H6>='Intersection Mileposts'!$F$33,H6<='Intersection Mileposts'!$G$33),"Y",IF(AND(H6>='Intersection Mileposts'!$F$34,H6<='Intersection Mileposts'!$G$34),"Y",IF(AND(H6>='Intersection Mileposts'!$F$35,H6<='Intersection Mileposts'!$G$35),"Y",IF(AND(H6>='Intersection Mileposts'!$F$36,H6<='Intersection Mileposts'!$G$36),"Y",IF(AND(H6>='Intersection Mileposts'!$F$37,H6<='Intersection Mileposts'!$G$37),"Y",IF(AND(H6>='Intersection Mileposts'!$F$38,H6<='Intersection Mileposts'!$G$38),"Y",IF(AND(H6>='Intersection Mileposts'!$F$39,H6<='Intersection Mileposts'!$G$39),"Y","N")))))))))))))))))))))))))))))))))))) -> Y
