Workbook

Sheet 260722124BA_Fiche
A1: Muni. Code | B1: On Road | C1: Miles | D1: Dir From | E1: From Road | F1: Toward Road | G1: Milepost Road | H1: MP | I1: IS? | J1: MA | K1: Crash ID | L1: Date | M1: T | N1: C | O1: F | P1: L | Q1: S | R1: Type | S1: Dir | T1: Comment | U1: Latitude | V1: Longitude | X1: Unit 1 Dir | Y1: Unit 2 Dir | Z1: Movement
A2: IN STUDY
A3: 74 | B3: NC 179BUS | C3: 0.07 | D3: S | E3: NC 179 | F3: SR 1810 | G3: NC 179BUS | H3: 0.07 | I3: IS | J3: Y | K3: 108569891 | L3: 46225 | M3: 23 | N3: 1 | O3: 4 | P3: 1 | Q3: K | R3: =IFERROR(VLOOKUP(M3,Index!$A$1:$B$26,2,FALSE),"") | S3: =Z3 | T3: in initial study; report: NC 179 BUS, 368 ft S of NC 179 toward SR 1810; lat/long 33.898099, -78.55168; left turn from southbound NC 179B into the PVA of Los Nuevos Charros Mexican Restaurant; inside the section; report MP 0.070 | U3: =IFERROR(INDEX(DetailedFiche!Q:Q,MATCH(K3,DetailedFiche!J:J,0)),"") | V3: =IFERROR(INDEX(DetailedFiche!R:R,MATCH(K3,DetailedFiche!J:J,0)),"") | X3: =IFERROR(IF(AND(INDEX('Initial Study'!K:K, MATCH(K3, 'Initial Study'!B:B, 0)+1)<>0,INDEX('Initial Study'!K:K, MATCH(K3, 'Initial Study'!B:B, 0)+1)<>""),INDEX('Initial Study'!K:K, MATCH(K3, 'Initial Study'!B:B, 0)+1),""),"") | Y3: =IFERROR(IF(AND(INDEX('Initial Study'!K:K, MATCH(K3, 'Initial Study'!B:B, 0)+2)<>0,INDEX('Initial Study'!K:K, MATCH(K3, 'Initial Study'!B:B, 0)+2)<>"",NOT(ISNUMBER(INDEX('Initial Study'!K:K, MATCH(K3, 'Initial Study'!B:B, 0)+2)))),INDEX('Initial Study'!K:K, MATCH(K3, 'Initial Study'!B:B, 0)+2),"-"),"-") | Z3: =IF(R3="RE", X3 & "BT/" & IF(Y3 <> "-", Y3 & "BT", ""), IF(OR(R3="LTDR", R3="LTSR"), X3 & "BL" & IF(Y3 <> "-", "/" & Y3 & "BT", ""), IF(OR(R3="RTDR", R3="RTSR"), X3 & "BR" & IF(Y3 <> "-", "/" & Y3 & "BT", ""), IF(Y3 <> "-", X3 & "BT/" & Y3 & "BT", X3 & "BT"))))
A4: 74 | B4: NC 179BUS | C4: 0.083 | D4: E | E4: NC 179 | F4: SR 1810 | G4: NC 179BUS | H4: 0.083 | I4: IS | J4: Y | K4: 108457510 | L4: 46114 | M4: 23 | N4: 1 | O4: 4 | P4: 1 | Q4: O | R4: =IFERROR(VLOOKUP(M4,Index!$A$1:$B$26,2,FALSE),"") | S4: =Z4 | T4: in initial study; report: NC 179 BUS, 437 ft E of NC 179 toward SR 1810; lat/long 33.898100, -78.55169 (the same coordinates as the fatal); eastbound (southeast-bound) unit 1 turning left into a public drive on the north side; inside the section; report MP 0.083; Coordinates identical to the fatal crash's; the PVA is in all likelihood the same restaurant driveway (437 ft vs 368 ft written by different troopers). | U4: =IFERROR(INDEX(DetailedFiche!Q:Q,MATCH(K4,DetailedFiche!J:J,0)),"") | V4: =IFERROR(INDEX(DetailedFiche!R:R,MATCH(K4,DetailedFiche!J:J,0)),"") | X4: =IFERROR(IF(AND(INDEX('Initial Study'!K:K, MATCH(K4, 'Initial Study'!B:B, 0)+1)<>0,INDEX('Initial Study'!K:K, MATCH(K4, 'Initial Study'!B:B, 0)+1)<>""),INDEX('Initial Study'!K:K, MATCH(K4, 'Initial Study'!B:B, 0)+1),""),"") | Y4: =IFERROR(IF(AND(INDEX('Initial Study'!K:K, MATCH(K4, 'Initial Study'!B:B, 0)+2)<>0,INDEX('Initial Study'!K:K, MATCH(K4, 'Initial Study'!B:B, 0)+2)<>"",NOT(ISNUMBER(INDEX('Initial Study'!K:K, MATCH(K4, 'Initial Study'!B:B, 0)+2)))),INDEX('Initial Study'!K:K, MATCH(K4, 'Initial Study'!B:B, 0)+2),"-"),"-") | Z4: =IF(R4="RE", X4 & "BT/" & IF(Y4 <> "-", Y4 & "BT", ""), IF(OR(R4="LTDR", R4="LTSR"), X4 & "BL" & IF(Y4 <> "-", "/" & Y4 & "BT", ""), IF(OR(R4="RTDR", R4="RTSR"), X4 & "BR" & IF(Y4 <> "-", "/" & Y4 & "BT", ""), IF(Y4 <> "-", X4 & "BT/" & Y4 & "BT", X4 & "BT"))))
A5: 74 | B5: NC 179BUS | C5: 0.1 | D5: S | E5: NC 179 | F5: SR 1246 | G5: NC 179BUS | H5: 0.1 | I5: IS | J5: Y | K5: 107392672 | L5: 45112 | M5: 23 | N5: 1 | O5: 4 | P5: 1 | Q5: O | R5: =IFERROR(VLOOKUP(M5,Index!$A$1:$B$26,2,FALSE),"") | S5: =Z5 | T5: in initial study; report: NC 179 BUS, 0.10 mi S of NC 179 toward SR 1246; no lat/long; southbound unit 1 turning left into the PVA of Central Mamma's Mexican Restaurant (east side) - the same restaurant site as the fatal crash (Los Nuevos Charros), so the true distance is about 370 ft (MP 0.07) rather than the rounded 0.10 mi; inside the section; report MP 0.100 | U5: =IFERROR(INDEX(DetailedFiche!Q:Q,MATCH(K5,DetailedFiche!J:J,0)),"") | V5: =IFERROR(INDEX(DetailedFiche!R:R,MATCH(K5,DetailedFiche!J:J,0)),"") | X5: =IFERROR(IF(AND(INDEX('Initial Study'!K:K, MATCH(K5, 'Initial Study'!B:B, 0)+1)<>0,INDEX('Initial Study'!K:K, MATCH(K5, 'Initial Study'!B:B, 0)+1)<>""),INDEX('Initial Study'!K:K, MATCH(K5, 'Initial Study'!B:B, 0)+1),""),"") | Y5: =IFERROR(IF(AND(INDEX('Initial Study'!K:K, MATCH(K5, 'Initial Study'!B:B, 0)+2)<>0,INDEX('Initial Study'!K:K, MATCH(K5, 'Initial Study'!B:B, 0)+2)<>"",NOT(ISNUMBER(INDEX('Initial Study'!K:K, MATCH(K5, 'Initial Study'!B:B, 0)+2)))),INDEX('Initial Study'!K:K, MATCH(K5, 'Initial Study'!B:B, 0)+2),"-"),"-") | Z5: =IF(R5="RE", X5 & "BT/" & IF(Y5 <> "-", Y5 & "BT", ""), IF(OR(R5="LTDR", R5="LTSR"), X5 & "BL" & IF(Y5 <> "-", "/" & Y5 & "BT", ""), IF(OR(R5="RTDR", R5="RTSR"), X5 & "BR" & IF(Y5 <> "-", "/" & Y5 & "BT", ""), IF(Y5 <> "-", X5 & "BT/" & Y5 & "BT", X5 & "BT"))))
A6: 0 | B6: NC 179BUS | C6: 0.2 | D6: E | E6: NC 179 | F6: SR 1810 | G6: NC 179BUS | H6: 0.2 | I6: IS | J6: Y | K6: 108192988 | L6: 45873 | M6: 26 | N6: 1 | O6: 4 | P6: 1 | Q6: O | R6: =IFERROR(VLOOKUP(M6,Index!$A$1:$B$26,2,FALSE),"") | S6: =Z6 | T6: in initial study; report: NC 179 BUS, written as 0.20 mi E of NC 179 toward SR 1810, 0.90 mi outside Calabash; lat/long 33.897720, -78.55146 (projects to MP 0.105); unit 1 northbound on the PVA of Dollar General turning right onto NC 179B - the Dollar General sits on the west side just past Little Ln (about MP 0.10), which matches the coordinates, not the 0.20 mi written; inside the section; report MP 0.105; TEAAS MP 0.200 comes from the officer's 0.20 mi; the Dollar General PVA and the coordinates put it near MP 0.10. In the section either way. | U6: =IFERROR(INDEX(DetailedFiche!Q:Q,MATCH(K6,DetailedFiche!J:J,0)),"") | V6: =IFERROR(INDEX(DetailedFiche!R:R,MATCH(K6,DetailedFiche!J:J,0)),"") | X6: =IFERROR(IF(AND(INDEX('Initial Study'!K:K, MATCH(K6, 'Initial Study'!B:B, 0)+1)<>0,INDEX('Initial Study'!K:K, MATCH(K6, 'Initial Study'!B:B, 0)+1)<>""),INDEX('Initial Study'!K:K, MATCH(K6, 'Initial Study'!B:B, 0)+1),""),"") | Y6: =IFERROR(IF(AND(INDEX('Initial Study'!K:K, MATCH(K6, 'Initial Study'!B:B, 0)+2)<>0,INDEX('Initial Study'!K:K, MATCH(K6, 'Initial Study'!B:B, 0)+2)<>"",NOT(ISNUMBER(INDEX('Initial Study'!K:K, MATCH(K6, 'Initial Study'!B:B, 0)+2)))),INDEX('Initial Study'!K:K, MATCH(K6, 'Initial Study'!B:B, 0)+2),"-"),"-") | Z6: =IF(R6="RE", X6 & "BT/" & IF(Y6 <> "-", Y6 & "BT", ""), IF(OR(R6="LTDR", R6="LTSR"), X6 & "BL" & IF(Y6 <> "-", "/" & Y6 & "BT", ""), IF(OR(R6="RTDR", R6="RTSR"), X6 & "BR" & IF(Y6 <> "-", "/" & Y6 & "BT", ""), IF(Y6 <> "-", X6 & "BT/" & Y6 & "BT", X6 & "BT"))))
A7: ADDED TO STUDY
A8: 74 | B8: NC 179BUS | C8: 0.057 | D8: W | E8: NC 179 | F8: SR 1810 | G8: NC 179BUS | H8: 0 | I8: ADD | J8: Y | K8: 107422740 | L8: 45149 | M8: 19 | N8: 2 | O8: 4 | P8: 1 | Q8: O | R8: =IFERROR(VLOOKUP(M8,Index!$A$1:$B$26,2,FALSE),"") | S8: =Z8 | T8: report: NC 179 BUS, 300 ft W of NC 179 toward SR 1810, in Calabash; single vehicle westbound (toward the NC 179 intersection) ran off the road to the right into the ditch and culvert; the diagram shows the NAPA Autocenter PVA just ahead of the rest position. 300 ft from NC 179 is MP 0.057, past the NAPA driveway (132 ft) - inside the section; inside the section; report MP 0.057; TEAAS MP 0.000 (the W direction does not run with the route); the report's 300 ft puts it at MP 0.057. | U8: =IFERROR(INDEX(DetailedFiche!Q:Q,MATCH(K8,DetailedFiche!J:J,0)),"") | V8: =IFERROR(INDEX(DetailedFiche!R:R,MATCH(K8,DetailedFiche!J:J,0)),"") | X8: =IFERROR(IF(AND(INDEX('Initial Study'!K:K, MATCH(K8, 'Initial Study'!B:B, 0)+1)<>0,INDEX('Initial Study'!K:K, MATCH(K8, 'Initial Study'!B:B, 0)+1)<>""),INDEX('Initial Study'!K:K, MATCH(K8, 'Initial Study'!B:B, 0)+1),""),"") | Y8: =IFERROR(IF(AND(INDEX('Initial Study'!K:K, MATCH(K8, 'Initial Study'!B:B, 0)+2)<>0,INDEX('Initial Study'!K:K, MATCH(K8, 'Initial Study'!B:B, 0)+2)<>"",NOT(ISNUMBER(INDEX('Initial Study'!K:K, MATCH(K8, 'Initial Study'!B:B, 0)+2)))),INDEX('Initial Study'!K:K, MATCH(K8, 'Initial Study'!B:B, 0)+2),"-"),"-") | Z8: =IF(R8="RE", X8 & "BT/" & IF(Y8 <> "-", Y8 & "BT", ""), IF(OR(R8="LTDR", R8="LTSR"), X8 & "BL" & IF(Y8 <> "-", "/" & Y8 & "BT", ""), IF(OR(R8="RTDR", R8="RTSR"), X8 & "BR" & IF(Y8 <> "-", "/" & Y8 & "BT", ""), IF(Y8 <> "-", X8 & "BT/" & Y8 & "BT", X8 & "BT"))))
A9: 74 | B9: NC 179BUS | C9: 0.019 | D9: S | E9: NC 179 | F9: SR 1246 | G9: NC 179BUS | H9: 0.019 | I9: ADD | J9: Y | K9: 106989320 | L9: 44727 | M9: 23 | N9: 1 | O9: 0 | P9: 1 | Q9: O | R9: =IFERROR(VLOOKUP(M9,Index!$A$1:$B$26,2,FALSE),"") | S9: =Z9 | T9: report: NC 179 BUS, 100 ft S of NC 179 toward SR 1246, in Calabash; southbound unit 1 turning left into the PVA of 1001 Beach Dr SW (east side as drawn, north arrow to the left), struck by northbound unit 2. 1001 Beach Dr SW is the NAPA Auto Parts parcel (OpenStreetMap geocode 33.89915, -78.55171, the lot in the wedge between NC 179 BUS and Old Georgetown Rd) whose driveway is the begin limit; 100 ft is the trooper's round figure; at the begin limit; report MP 0.019; TEAAS MP 0.019 (100 ft), 32 ft before the limit; the driveway is the NAPA lot's (1001 Beach Dr SW). Fourth left-turn-into-NAPA crash with 106921434, 108438531 and 108347203. PE to confirm; proposed ADD. | U9: =IFERROR(INDEX(DetailedFiche!Q:Q,MATCH(K9,DetailedFiche!J:J,0)),"") | V9: =IFERROR(INDEX(DetailedFiche!R:R,MATCH(K9,DetailedFiche!J:J,0)),"") | X9: =IFERROR(IF(AND(INDEX('Initial Study'!K:K, MATCH(K9, 'Initial Study'!B:B, 0)+1)<>0,INDEX('Initial Study'!K:K, MATCH(K9, 'Initial Study'!B:B, 0)+1)<>""),INDEX('Initial Study'!K:K, MATCH(K9, 'Initial Study'!B:B, 0)+1),""),"") | Y9: =IFERROR(IF(AND(INDEX('Initial Study'!K:K, MATCH(K9, 'Initial Study'!B:B, 0)+2)<>0,INDEX('Initial Study'!K:K, MATCH(K9, 'Initial Study'!B:B, 0)+2)<>"",NOT(ISNUMBER(INDEX('Initial Study'!K:K, MATCH(K9, 'Initial Study'!B:B, 0)+2)))),INDEX('Initial Study'!K:K, MATCH(K9, 'Initial Study'!B:B, 0)+2),"-"),"-") | Z9: =IF(R9="RE", X9 & "BT/" & IF(Y9 <> "-", Y9 & "BT", ""), IF(OR(R9="LTDR", R9="LTSR"), X9 & "BL" & IF(Y9 <> "-", "/" & Y9 & "BT", ""), IF(OR(R9="RTDR", R9="RTSR"), X9 & "BR" & IF(Y9 <> "-", "/" & Y9 & "BT", ""), IF(Y9 <> "-", X9 & "BT/" & Y9 & "BT", X9 & "BT"))))
A10: 0 | B10: NC 179BUS | C10: 0.019 | D10: S | E10: SR 1164 | F10: SR 1246 | G10: NC 179BUS | H10: 0.019 | I10: ADD | K10: 107361667 | L10: 45086 | M10: 23 | N10: 1 | O10: 4 | P10: 1 | Q10: O | R10: =IFERROR(VLOOKUP(M10,Index!$A$1:$B$26,2,FALSE),"") | S10: =Z10 | T10: report: NC 179 BUS, written as 100 ft S of SR 1164 toward SR 1246, 0.20 mi N of Calabash outside the town; southbound unit 1 turning left into the PVA of 1021 Beach Dr (east side), struck by northbound unit 2. 1021 Beach Dr SW geocodes (OpenStreetMap) to the east side of NC 179 BUS about 70 ft past Crocker Dr, MP 0.115, between Crocker Dr and Small Way; the written 100 ft is the same round figure this trooper used on 106989320; inside the section; report MP 0.115; TEAAS MP 0.019 from the 100 ft; the 1021 Beach Dr address geocodes to MP 0.115, inside the section. Location rests on the address. | U10: =IFERROR(INDEX(DetailedFiche!Q:Q,MATCH(K10,DetailedFiche!J:J,0)),"") | V10: =IFERROR(INDEX(DetailedFiche!R:R,MATCH(K10,DetailedFiche!J:J,0)),"") | X10: =IFERROR(IF(AND(INDEX('Initial Study'!K:K, MATCH(K10, 'Initial Study'!B:B, 0)+1)<>0,INDEX('Initial Study'!K:K, MATCH(K10, 'Initial Study'!B:B, 0)+1)<>""),INDEX('Initial Study'!K:K, MATCH(K10, 'Initial Study'!B:B, 0)+1),""),"") | Y10: =IFERROR(IF(AND(INDEX('Initial Study'!K:K, MATCH(K10, 'Initial Study'!B:B, 0)+2)<>0,INDEX('Initial Study'!K:K, MATCH(K10, 'Initial Study'!B:B, 0)+2)<>"",NOT(ISNUMBER(INDEX('Initial Study'!K:K, MATCH(K10, 'Initial Study'!B:B, 0)+2)))),INDEX('Initial Study'!K:K, MATCH(K10, 'Initial Study'!B:B, 0)+2),"-"),"-") | Z10: =IF(R10="RE", X10 & "BT/" & IF(Y10 <> "-", Y10 & "BT", ""), IF(OR(R10="LTDR", R10="LTSR"), X10 & "BL" & IF(Y10 <> "-", "/" & Y10 & "BT", ""), IF(OR(R10="RTDR", R10="RTSR"), X10 & "BR" & IF(Y10 <> "-", "/" & Y10 & "BT", ""), IF(Y10 <> "-", X10 & "BT/" & Y10 & "BT", X10 & "BT"))))
A11: 74 | B11: NC 179BUS | C11: 0.023 | D11: E | E11: NC 179 | F11: SR 1810 | G11: NC 179BUS | H11: 0.023 | I11: ADD | J11: Y | K11: 108438531 | L11: 46101 | M11: 23 | N11: 1 | O11: 4 | P11: 1 | Q11: C | R11: =IFERROR(VLOOKUP(M11,Index!$A$1:$B$26,2,FALSE),"") | S11: =Z11 | T11: report: NC 179 BUS, 120 ft E of NC 179 toward SR 1810, in Calabash; lat/long 33.898720, -78.55223 (about 116 ft from the intersection). Eastbound unit 1, stopped for traffic, turned left into the PVA of NAPA Auto Care Center (drawn on the diagram) and was struck by westbound unit 2 - the begin-limit driveway itself; at the begin limit; report MP 0.023; TEAAS MP 0.023 (120 ft) is 11 ft short of the 0.025 limit; the crash is the NAPA driveway left-turn conflict. PE to confirm; proposed ADD. | U11: =IFERROR(INDEX(DetailedFiche!Q:Q,MATCH(K11,DetailedFiche!J:J,0)),"") | V11: =IFERROR(INDEX(DetailedFiche!R:R,MATCH(K11,DetailedFiche!J:J,0)),"") | X11: =IFERROR(IF(AND(INDEX('Initial Study'!K:K, MATCH(K11, 'Initial Study'!B:B, 0)+1)<>0,INDEX('Initial Study'!K:K, MATCH(K11, 'Initial Study'!B:B, 0)+1)<>""),INDEX('Initial Study'!K:K, MATCH(K11, 'Initial Study'!B:B, 0)+1),""),"") | Y11: =IFERROR(IF(AND(INDEX('Initial Study'!K:K, MATCH(K11, 'Initial Study'!B:B, 0)+2)<>0,INDEX('Initial Study'!K:K, MATCH(K11, 'Initial Study'!B:B, 0)+2)<>"",NOT(ISNUMBER(INDEX('Initial Study'!K:K, MATCH(K11, 'Initial Study'!B:B, 0)+2)))),INDEX('Initial Study'!K:K, MATCH(K11, 'Initial Study'!B:B, 0)+2),"-"),"-") | Z11: =IF(R11="RE", X11 & "BT/" & IF(Y11 <> "-", Y11 & "BT", ""), IF(OR(R11="LTDR", R11="LTSR"), X11 & "BL" & IF(Y11 <> "-", "/" & Y11 & "BT", ""), IF(OR(R11="RTDR", R11="RTSR"), X11 & "BR" & IF(Y11 <> "-", "/" & Y11 & "BT", ""), IF(Y11 <> "-", X11 & "BT/" & Y11 & "BT", X11 & "BT"))))
A12: 74 | B12: NC 179BUS | C12: 0.024 | D12: E | E12: NC 179 | F12: SR 1810 | G12: NC 179BUS | H12: 0.024 | I12: ADD | J12: Y | K12: 106921434 | L12: 44663 | M12: 23 | N12: 1 | O12: 4 | P12: 1 | Q12: O | R12: =IFERROR(VLOOKUP(M12,Index!$A$1:$B$26,2,FALSE),"") | S12: =Z12 | T12: report: NC 179 BUS, 126 ft E of NC 179 toward SR 1810, in Calabash; eastbound unit 1 turned left into the NAPA parking lot (NAPA PVA drawn on the diagram, south side as drawn with north down) and collided with westbound unit 2. The NAPA driveway is the begin limit; at the begin limit; report MP 0.024; TEAAS MP 0.024, 5 ft short of the 0.025 limit; the crash is the NAPA driveway left turn. Third left-turn crash at this driveway (with 108438531 and 108347203). PE to confirm; proposed ADD. | U12: =IFERROR(INDEX(DetailedFiche!Q:Q,MATCH(K12,DetailedFiche!J:J,0)),"") | V12: =IFERROR(INDEX(DetailedFiche!R:R,MATCH(K12,DetailedFiche!J:J,0)),"") | X12: =IFERROR(IF(AND(INDEX('Initial Study'!K:K, MATCH(K12, 'Initial Study'!B:B, 0)+1)<>0,INDEX('Initial Study'!K:K, MATCH(K12, 'Initial Study'!B:B, 0)+1)<>""),INDEX('Initial Study'!K:K, MATCH(K12, 'Initial Study'!B:B, 0)+1),""),"") | Y12: =IFERROR(IF(AND(INDEX('Initial Study'!K:K, MATCH(K12, 'Initial Study'!B:B, 0)+2)<>0,INDEX('Initial Study'!K:K, MATCH(K12, 'Initial Study'!B:B, 0)+2)<>"",NOT(ISNUMBER(INDEX('Initial Study'!K:K, MATCH(K12, 'Initial Study'!B:B, 0)+2)))),INDEX('Initial Study'!K:K, MATCH(K12, 'Initial Study'!B:B, 0)+2),"-"),"-") | Z12: =IF(R12="RE", X12 & "BT/" & IF(Y12 <> "-", Y12 & "BT", ""), IF(OR(R12="LTDR", R12="LTSR"), X12 & "BL" & IF(Y12 <> "-", "/" & Y12 & "BT", ""), IF(OR(R12="RTDR", R12="RTSR"), X12 & "BR" & IF(Y12 <> "-", "/" & Y12 & "BT", ""), IF(Y12 <> "-", X12 & "BT/" & Y12 & "BT", X12 & "BT"))))
A13: 0 | B13: NC 179BUS | C13: 0.5 | D13: S | E13: NC 179 | F13: SR 1810 | G13: NC 179BUS | H13: 0.5 | I13: ADD | J13: Y | K13: 108196690 | L13: 45878 | M13: 17 | N13: 1 | O13: 0 | P13: 1 | Q13: O | R13: =IFERROR(VLOOKUP(M13,Index!$A$1:$B$26,2,FALSE),"") | S13: =Z13 | T13: report: NC 179 BUS, written as 0.50 mi S of NC 179 toward SR 1810, 1.00 mi E of Calabash outside the town; lat/long 33.896610, -78.55053, which is on NC 179 BUS 40 ft before Hidden Valley Pl (MP 0.198). The coordinates and the written half mile disagree; the coordinates are the trooper's device reading at the scene and are taken as the location; inside the section; report MP 0.198; TEAAS MP 0.500 follows the written 0.50 mi; the coordinates put the crash inside the section near the end limit. | U13: =IFERROR(INDEX(DetailedFiche!Q:Q,MATCH(K13,DetailedFiche!J:J,0)),"") | V13: =IFERROR(INDEX(DetailedFiche!R:R,MATCH(K13,DetailedFiche!J:J,0)),"") | X13: =IFERROR(IF(AND(INDEX('Initial Study'!K:K, MATCH(K13, 'Initial Study'!B:B, 0)+1)<>0,INDEX('Initial Study'!K:K, MATCH(K13, 'Initial Study'!B:B, 0)+1)<>""),INDEX('Initial Study'!K:K, MATCH(K13, 'Initial Study'!B:B, 0)+1),""),"") | Y13: =IFERROR(IF(AND(INDEX('Initial Study'!K:K, MATCH(K13, 'Initial Study'!B:B, 0)+2)<>0,INDEX('Initial Study'!K:K, MATCH(K13, 'Initial Study'!B:B, 0)+2)<>"",NOT(ISNUMBER(INDEX('Initial Study'!K:K, MATCH(K13, 'Initial Study'!B:B, 0)+2)))),INDEX('Initial Study'!K:K, MATCH(K13, 'Initial Study'!B:B, 0)+2),"-"),"-") | Z13: =IF(R13="RE", X13 & "BT/" & IF(Y13 <> "-", Y13 & "BT", ""), IF(OR(R13="LTDR", R13="LTSR"), X13 & "BL" & IF(Y13 <> "-", "/" & Y13 & "BT", ""), IF(OR(R13="RTDR", R13="RTSR"), X13 & "BR" & IF(Y13 <> "-", "/" & Y13 & "BT", ""), IF(Y13 <> "-", X13 & "BT/" & Y13 & "BT", X13 & "BT"))))
A14: 0 | B14: SR 1164 | C14: 0.2 | D14: S | E14: NC 179 | F14: SR 1810 | G14: SR 1164 | H14: 0.51 | I14: ADD | K14: 107102711 | L14: 44838 | M14: 28 | N14: 1 | O14: 0 | P14: 1 | Q14: O | R14: =IFERROR(VLOOKUP(M14,Index!$A$1:$B$26,2,FALSE),"") | S14: =Z14 | T14: report: Written as SR 1164, 0.20 mi S of NC 179 toward SR 1810, 1.50 mi E of Calabash; unit 2's road is written NC 179 BUS and the diagram is a 24-ft two-lane road with 8-ft shoulders labeled SR1164. SR 1164 (Clariday Rd) runs north from NC 179, so a point 0.2 mi south of NC 179 toward SR 1810 is on NC 179 BUS, about MP 0.20 near Small Way / Hidden Valley Pl, where the road is two lanes; inside the section; report MP 0.200; TEAAS mileposted it on SR 1164 at 0.510 (the NC 179 junction) from the on-road name; the description places it on NC 179 BUS inside the section. Location by description only, no coordinates. | U14: =IFERROR(INDEX(DetailedFiche!Q:Q,MATCH(K14,DetailedFiche!J:J,0)),"") | V14: =IFERROR(INDEX(DetailedFiche!R:R,MATCH(K14,DetailedFiche!J:J,0)),"") | X14: =IFERROR(IF(AND(INDEX('Initial Study'!K:K, MATCH(K14, 'Initial Study'!B:B, 0)+1)<>0,INDEX('Initial Study'!K:K, MATCH(K14, 'Initial Study'!B:B, 0)+1)<>""),INDEX('Initial Study'!K:K, MATCH(K14, 'Initial Study'!B:B, 0)+1),""),"") | Y14: =IFERROR(IF(AND(INDEX('Initial Study'!K:K, MATCH(K14, 'Initial Study'!B:B, 0)+2)<>0,INDEX('Initial Study'!K:K, MATCH(K14, 'Initial Study'!B:B, 0)+2)<>"",NOT(ISNUMBER(INDEX('Initial Study'!K:K, MATCH(K14, 'Initial Study'!B:B, 0)+2)))),INDEX('Initial Study'!K:K, MATCH(K14, 'Initial Study'!B:B, 0)+2),"-"),"-") | Z14: =IF(R14="RE", X14 & "BT/" & IF(Y14 <> "-", Y14 & "BT", ""), IF(OR(R14="LTDR", R14="LTSR"), X14 & "BL" & IF(Y14 <> "-", "/" & Y14 & "BT", ""), IF(OR(R14="RTDR", R14="RTSR"), X14 & "BR" & IF(Y14 <> "-", "/" & Y14 & "BT", ""), IF(Y14 <> "-", X14 & "BT/" & Y14 & "BT", X14 & "BT"))))
A15: 74 | B15: NC 179 | C15: 0.023 | D15: E | E15: SR 1163 | F15: SR 1186 | G15: NC 179 | H15: 5.939 | I15: ADD | K15: 108109880 | L15: 45791 | M15: 19 | N15: 1 | O15: 4 | P15: 1 | Q15: C | R15: =IFERROR(VLOOKUP(M15,Index!$A$1:$B$26,2,FALSE),"") | S15: =Z15 | T15: report: Written as NC 179, 123 ft E of SR 1163 toward SR 1186, in Calabash (the SR numbers are wrong for this spot); lat/long 33.898680, -78.55214, which is on NC 179 BUS about 150 ft southeast of the intersection. Westbound (toward NC 179) unit 1 turned right into a PVA on the north side and dropped into the ditch - at 123 to 150 ft from the intersection on the northeast side that PVA is the Calabash NAPA Auto Care Center driveway, i.e. the begin limit itself; at the begin limit; report MP 0.025; TEAAS coded it on NC 179 at MP 5.939 from the SR 1163 / SR 1186 names; the report and coordinates put it at the NAPA driveway. PE to decide whether a crash turning into the begin-limit driveway counts; proposed ADD. | U15: =IFERROR(INDEX(DetailedFiche!Q:Q,MATCH(K15,DetailedFiche!J:J,0)),"") | V15: =IFERROR(INDEX(DetailedFiche!R:R,MATCH(K15,DetailedFiche!J:J,0)),"") | X15: =IFERROR(IF(AND(INDEX('Initial Study'!K:K, MATCH(K15, 'Initial Study'!B:B, 0)+1)<>0,INDEX('Initial Study'!K:K, MATCH(K15, 'Initial Study'!B:B, 0)+1)<>""),INDEX('Initial Study'!K:K, MATCH(K15, 'Initial Study'!B:B, 0)+1),""),"") | Y15: =IFERROR(IF(AND(INDEX('Initial Study'!K:K, MATCH(K15, 'Initial Study'!B:B, 0)+2)<>0,INDEX('Initial Study'!K:K, MATCH(K15, 'Initial Study'!B:B, 0)+2)<>"",NOT(ISNUMBER(INDEX('Initial Study'!K:K, MATCH(K15, 'Initial Study'!B:B, 0)+2)))),INDEX('Initial Study'!K:K, MATCH(K15, 'Initial Study'!B:B, 0)+2),"-"),"-") | Z15: =IF(R15="RE", X15 & "BT/" & IF(Y15 <> "-", Y15 & "BT", ""), IF(OR(R15="LTDR", R15="LTSR"), X15 & "BL" & IF(Y15 <> "-", "/" & Y15 & "BT", ""), IF(OR(R15="RTDR", R15="RTSR"), X15 & "BR" & IF(Y15 <> "-", "/" & Y15 & "BT", ""), IF(Y15 <> "-", X15 & "BT/" & Y15 & "BT", X15 & "BT"))))
A16: 74 | B16: NC 179 | C16: 0.1 | D16: E | E16: NC 179 | F16: NC 904 | G16: NC 179 | H16: 999.999 | I16: ADD | K16: 108175124 | L16: 45855 | M16: 23 | N16: 1 | O16: 4 | P16: 1 | Q16: O | R16: =IFERROR(VLOOKUP(M16,Index!$A$1:$B$26,2,FALSE),"") | S16: =Z16 | T16: report: Written as NC 179, 0.10 mi E of NC 179 toward NC 904, in Calabash; lat/long 33.898308, -78.55196, which is on NC 179 BUS 290 ft southeast of the intersection (MP 0.055, 5 ft off the centerline), not on the NC 179 leg toward NC 904. The diagram shows a PVA on the north side with eastbound unit 1 turning left into it - the restaurant side of Beach Dr SW. Taken as a left turn into a PVA on NC 179 BUS between the NAPA driveway and the restaurant; inside the section; report MP 0.055; Coded on NC 179 toward NC 904 (MP 999.999) because the trooper wrote NC 179 for both roads; the coordinates put it on NC 179 BUS inside the section. | U16: =IFERROR(INDEX(DetailedFiche!Q:Q,MATCH(K16,DetailedFiche!J:J,0)),"") | V16: =IFERROR(INDEX(DetailedFiche!R:R,MATCH(K16,DetailedFiche!J:J,0)),"") | X16: =IFERROR(IF(AND(INDEX('Initial Study'!K:K, MATCH(K16, 'Initial Study'!B:B, 0)+1)<>0,INDEX('Initial Study'!K:K, MATCH(K16, 'Initial Study'!B:B, 0)+1)<>""),INDEX('Initial Study'!K:K, MATCH(K16, 'Initial Study'!B:B, 0)+1),""),"") | Y16: =IFERROR(IF(AND(INDEX('Initial Study'!K:K, MATCH(K16, 'Initial Study'!B:B, 0)+2)<>0,INDEX('Initial Study'!K:K, MATCH(K16, 'Initial Study'!B:B, 0)+2)<>"",NOT(ISNUMBER(INDEX('Initial Study'!K:K, MATCH(K16, 'Initial Study'!B:B, 0)+2)))),INDEX('Initial Study'!K:K, MATCH(K16, 'Initial Study'!B:B, 0)+2),"-"),"-") | Z16: =IF(R16="RE", X16 & "BT/" & IF(Y16 <> "-", Y16 & "BT", ""), IF(OR(R16="LTDR", R16="LTSR"), X16 & "BL" & IF(Y16 <> "-", "/" & Y16 & "BT", ""), IF(OR(R16="RTDR", R16="RTSR"), X16 & "BR" & IF(Y16 <> "-", "/" & Y16 & "BT", ""), IF(Y16 <> "-", X16 & "BT/" & Y16 & "BT", X16 & "BT"))))
A17: 74 | B17: NC 179BUS | C17: 0.013 | D17: E | E17: NC 179 | F17: SR 1288 | G17: NC 179BUS | H17: 999.999 | I17: ADD | K17: 108347203 | L17: 46010 | M17: 23 | N17: 1 | O17: 4 | P17: 1 | Q17: O | R17: =IFERROR(VLOOKUP(M17,Index!$A$1:$B$26,2,FALSE),"") | S17: =Z17 | T17: report: NC 179 BUS, written as 68 ft E of NC 179 toward SR 1288 (wrong road name), in Calabash; lat/long 33.898700, -78.55222 (about 125 ft from the intersection, the same device position as the other NAPA driveway crashes). Eastbound unit 1 turned left into a PVA on the north side (the NAPA side) and was struck by westbound unit 2. The written 68 ft would put it 64 ft short of the limit; the coordinates and the north-side PVA put it at the NAPA driveway; at the begin limit; report MP 0.024; MP 999.999 from the SR 1288 name; the screening implied MP 0.013 from the 68 ft. Same NAPA-driveway conflict as 108438531; proposed ADD with the limit question flagged for the PE. | U17: =IFERROR(INDEX(DetailedFiche!Q:Q,MATCH(K17,DetailedFiche!J:J,0)),"") | V17: =IFERROR(INDEX(DetailedFiche!R:R,MATCH(K17,DetailedFiche!J:J,0)),"") | X17: =IFERROR(IF(AND(INDEX('Initial Study'!K:K, MATCH(K17, 'Initial Study'!B:B, 0)+1)<>0,INDEX('Initial Study'!K:K, MATCH(K17, 'Initial Study'!B:B, 0)+1)<>""),INDEX('Initial Study'!K:K, MATCH(K17, 'Initial Study'!B:B, 0)+1),""),"") | Y17: =IFERROR(IF(AND(INDEX('Initial Study'!K:K, MATCH(K17, 'Initial Study'!B:B, 0)+2)<>0,INDEX('Initial Study'!K:K, MATCH(K17, 'Initial Study'!B:B, 0)+2)<>"",NOT(ISNUMBER(INDEX('Initial Study'!K:K, MATCH(K17, 'Initial Study'!B:B, 0)+2)))),INDEX('Initial Study'!K:K, MATCH(K17, 'Initial Study'!B:B, 0)+2),"-"),"-") | Z17: =IF(R17="RE", X17 & "BT/" & IF(Y17 <> "-", Y17 & "BT", ""), IF(OR(R17="LTDR", R17="LTSR"), X17 & "BL" & IF(Y17 <> "-", "/" & Y17 & "BT", ""), IF(OR(R17="RTDR", R17="RTSR"), X17 & "BR" & IF(Y17 <> "-", "/" & Y17 & "BT", ""), IF(Y17 <> "-", X17 & "BT/" & Y17 & "BT", X17 & "BT"))))
A18: 0 | B18: BEACH | C18: 0.019 | D18: S | E18: CROCKER | F18: OLD GEORGETOWN | G18: BEACH | H18: 999.999 | I18: ADD | K18: 108481478 | L18: 46141 | M18: 21 | N18: 1 | O18: 0 | P18: 1 | Q18: O | R18: =IFERROR(VLOOKUP(M18,Index!$A$1:$B$26,2,FALSE),"") | S18: =Z18 | T18: report: Beach Dr (NC 179 BUS), written as 100 ft from Crocker Dr toward Old Georgetown Rd with the S box checked (Brunswick County Sheriff report; no lat/long; no business or driveway named). The toward road and the diagram put both vehicles on Beach Dr between Crocker Dr and the NC 179 / Old Georgetown Rd intersection, about 375 ft from NC 179 (MP 0.071); taken literally the S box gives 575 ft (MP 0.109). Inside the section either way; inside the section; report MP 0.071; MP 999.999 because the on road is coded BEACH; the description locates it inside the section. | U18: =IFERROR(INDEX(DetailedFiche!Q:Q,MATCH(K18,DetailedFiche!J:J,0)),"") | V18: =IFERROR(INDEX(DetailedFiche!R:R,MATCH(K18,DetailedFiche!J:J,0)),"") | X18: =IFERROR(IF(AND(INDEX('Initial Study'!K:K, MATCH(K18, 'Initial Study'!B:B, 0)+1)<>0,INDEX('Initial Study'!K:K, MATCH(K18, 'Initial Study'!B:B, 0)+1)<>""),INDEX('Initial Study'!K:K, MATCH(K18, 'Initial Study'!B:B, 0)+1),""),"") | Y18: =IFERROR(IF(AND(INDEX('Initial Study'!K:K, MATCH(K18, 'Initial Study'!B:B, 0)+2)<>0,INDEX('Initial Study'!K:K, MATCH(K18, 'Initial Study'!B:B, 0)+2)<>"",NOT(ISNUMBER(INDEX('Initial Study'!K:K, MATCH(K18, 'Initial Study'!B:B, 0)+2)))),INDEX('Initial Study'!K:K, MATCH(K18, 'Initial Study'!B:B, 0)+2),"-"),"-") | Z18: =IF(R18="RE", X18 & "BT/" & IF(Y18 <> "-", Y18 & "BT", ""), IF(OR(R18="LTDR", R18="LTSR"), X18 & "BL" & IF(Y18 <> "-", "/" & Y18 & "BT", ""), IF(OR(R18="RTDR", R18="RTSR"), X18 & "BR" & IF(Y18 <> "-", "/" & Y18 & "BT", ""), IF(Y18 <> "-", X18 & "BT/" & Y18 & "BT", X18 & "BT"))))
A19: 0 | B19: NC 179BUS | C19: 0.2 | D19: E | E19: SR 1163 | F19: SR 1810 | G19: NC 179BUS | H19: 999.999 | I19: ADD | K19: 108512267 | L19: 46169 | M19: 24 | N19: 1 | O19: 4 | P19: 1 | Q19: C | R19: =IFERROR(VLOOKUP(M19,Index!$A$1:$B$26,2,FALSE),"") | S19: =Z19 | T19: report: NC 179 BUS, written as 0.20 mi E of SR 1163 toward SR 1810 (SR 1163 is a wrong name), 0.20 mi E of Calabash; lat/long 33.896540, -78.55039 is the Hidden Valley Pl junction (MP 0.206). Unit 1 came north out of Hidden Valley Pl (written as a PVA) turning left onto NC 179 BUS; the diagram is labeled PVA Hidden Valley Pl. The junction is the end limit of the section; at the end limit; report MP 0.205; MP 999.999 because of the SR 1163 / SR 1810 names; the coordinates and narrative put it at Hidden Valley Pl, the end limit. A junction crash at the limit: proposed ADD (TEAAS would include a crash mileposted 0.205). | U19: =IFERROR(INDEX(DetailedFiche!Q:Q,MATCH(K19,DetailedFiche!J:J,0)),"") | V19: =IFERROR(INDEX(DetailedFiche!R:R,MATCH(K19,DetailedFiche!J:J,0)),"") | X19: =IFERROR(IF(AND(INDEX('Initial Study'!K:K, MATCH(K19, 'Initial Study'!B:B, 0)+1)<>0,INDEX('Initial Study'!K:K, MATCH(K19, 'Initial Study'!B:B, 0)+1)<>""),INDEX('Initial Study'!K:K, MATCH(K19, 'Initial Study'!B:B, 0)+1),""),"") | Y19: =IFERROR(IF(AND(INDEX('Initial Study'!K:K, MATCH(K19, 'Initial Study'!B:B, 0)+2)<>0,INDEX('Initial Study'!K:K, MATCH(K19, 'Initial Study'!B:B, 0)+2)<>"",NOT(ISNUMBER(INDEX('Initial Study'!K:K, MATCH(K19, 'Initial Study'!B:B, 0)+2)))),INDEX('Initial Study'!K:K, MATCH(K19, 'Initial Study'!B:B, 0)+2),"-"),"-") | Z19: =IF(R19="RE", X19 & "BT/" & IF(Y19 <> "-", Y19 & "BT", ""), IF(OR(R19="LTDR", R19="LTSR"), X19 & "BL" & IF(Y19 <> "-", "/" & Y19 & "BT", ""), IF(OR(R19="RTDR", R19="RTSR"), X19 & "BR" & IF(Y19 <> "-", "/" & Y19 & "BT", ""), IF(Y19 <> "-", X19 & "BT/" & Y19 & "BT", X19 & "BT"))))
A20: 0 | B20: NC 179 | C20: 0.031 | D20: E | E20: SR 1164 | F20: SR 1810 | G20: NC 179 | H20: 999.999 | I20: ADD | K20: 108581555 | L20: 46227 | M20: 24 | N20: 2 | O20: 0 | P20: 1 | Q20: C | R20: =IFERROR(VLOOKUP(M20,Index!$A$1:$B$26,2,FALSE),"") | S20: =Z20 | T20: report: Written as NC 179, 163 ft E of SR 1164 toward SR 1810, 0.10 mi E of Calabash; lat/long 33.898720, -78.55224 is on NC 179 BUS about 116 ft from the intersection. The diagram shows unit 1 leaving the PVA of Minuteman (the food mart on the southwest side, opposite the NAPA driveway) and turning northwest across eastbound unit 2 on a 3-lane 32-ft road. The Minuteman driveway sits opposite the begin-limit driveway, 116 to 163 ft from the intersection; at the begin limit; report MP 0.025; Coded on NC 179 (MP 999.999) from the road names; the report puts it at the Minuteman driveway at the begin limit. PE to confirm; proposed ADD. | U20: =IFERROR(INDEX(DetailedFiche!Q:Q,MATCH(K20,DetailedFiche!J:J,0)),"") | V20: =IFERROR(INDEX(DetailedFiche!R:R,MATCH(K20,DetailedFiche!J:J,0)),"") | X20: =IFERROR(IF(AND(INDEX('Initial Study'!K:K, MATCH(K20, 'Initial Study'!B:B, 0)+1)<>0,INDEX('Initial Study'!K:K, MATCH(K20, 'Initial Study'!B:B, 0)+1)<>""),INDEX('Initial Study'!K:K, MATCH(K20, 'Initial Study'!B:B, 0)+1),""),"") | Y20: =IFERROR(IF(AND(INDEX('Initial Study'!K:K, MATCH(K20, 'Initial Study'!B:B, 0)+2)<>0,INDEX('Initial Study'!K:K, MATCH(K20, 'Initial Study'!B:B, 0)+2)<>"",NOT(ISNUMBER(INDEX('Initial Study'!K:K, MATCH(K20, 'Initial Study'!B:B, 0)+2)))),INDEX('Initial Study'!K:K, MATCH(K20, 'Initial Study'!B:B, 0)+2),"-"),"-") | Z20: =IF(R20="RE", X20 & "BT/" & IF(Y20 <> "-", Y20 & "BT", ""), IF(OR(R20="LTDR", R20="LTSR"), X20 & "BL" & IF(Y20 <> "-", "/" & Y20 & "BT", ""), IF(OR(R20="RTDR", R20="RTSR"), X20 & "BR" & IF(Y20 <> "-", "/" & Y20 & "BT", ""), IF(Y20 <> "-", X20 & "BT/" & Y20 & "BT", X20 & "BT"))))
A21: DELETED FROM STUDY
A22: NOT IN STUDY - REPORT REVIEWED
A23: 0 | B23: NC 179 | C23: 0.006 | D23: W | E23: NC 179 | F23: SR 1167 | G23: NC 179 | H23: 999.999 | I23: NIS | K23: 108175794 | L23: 45855 | M23: 21 | N23: 1 | O23: 12 | P23: 1 | Q23: O | R23: =IFERROR(VLOOKUP(M23,Index!$A$1:$B$26,2,FALSE),"") | S23: =Z23 | T23: report: NC 179, 30 ft W of NC 179 toward SR 1167, near Calabash (0.30 mi E of the town); both vehicles eastbound on NC 179, unit 2 stopped for traffic - a queue on the NC 179 west leg approaching the intersection. The diagram is a two-lane curbed NC 179 (33 ft) with no side street. The lat/long (33.898450, -78.55227) falls about 200 ft southeast of the intersection on Beach Dr SW, which disagrees with the written location; the written location and the stopped-for-traffic narrative are specific and are taken as the crash location; outside the section; Screening flagged it from the coordinates; the report puts it on NC 179 west of the intersection, outside the section. The coordinates were probably taken from where the trooper parked. | U23: =IFERROR(INDEX(DetailedFiche!Q:Q,MATCH(K23,DetailedFiche!J:J,0)),"") | V23: =IFERROR(INDEX(DetailedFiche!R:R,MATCH(K23,DetailedFiche!J:J,0)),"") | X23: =IFERROR(IF(AND(INDEX('Initial Study'!K:K, MATCH(K23, 'Initial Study'!B:B, 0)+1)<>0,INDEX('Initial Study'!K:K, MATCH(K23, 'Initial Study'!B:B, 0)+1)<>""),INDEX('Initial Study'!K:K, MATCH(K23, 'Initial Study'!B:B, 0)+1),""),"") | Y23: =IFERROR(IF(AND(INDEX('Initial Study'!K:K, MATCH(K23, 'Initial Study'!B:B, 0)+2)<>0,INDEX('Initial Study'!K:K, MATCH(K23, 'Initial Study'!B:B, 0)+2)<>"",NOT(ISNUMBER(INDEX('Initial Study'!K:K, MATCH(K23, 'Initial Study'!B:B, 0)+2)))),INDEX('Initial Study'!K:K, MATCH(K23, 'Initial Study'!B:B, 0)+2),"-"),"-") | Z23: =IF(R23="RE", X23 & "BT/" & IF(Y23 <> "-", Y23 & "BT", ""), IF(OR(R23="LTDR", R23="LTSR"), X23 & "BL" & IF(Y23 <> "-", "/" & Y23 & "BT", ""), IF(OR(R23="RTDR", R23="RTSR"), X23 & "BR" & IF(Y23 <> "-", "/" & Y23 & "BT", ""), IF(Y23 <> "-", X23 & "BT/" & Y23 & "BT", X23 & "BT"))))
A24: 74 | B24: NC 179 | C24: 0 | E24: SR 1164 | F24: NC 904 | G24: NC 179 | H24: 999.999 | I24: NIS | K24: 108595754 | L24: 46249 | M24: 26 | N24: 1 | O24: 7 | P24: 1 | Q24: O | R24: =IFERROR(VLOOKUP(M24,Index!$A$1:$B$26,2,FALSE),"") | S24: =Z24 | T24: report: NC 179 at SR 1164 (0 ft, intersection) toward NC 904, in Calabash; lat/long 33.898720, -78.55247 (the intersection); unit 1 northbound on NC 179 turning right onto NC 179B collided in the intersection with unit 2 eastbound on SR 1164; the signal was in flashing red. An intersection crash; outside the section; report MP 0.000; Screening flagged it from the coordinates 55 ft short of the limit; the report puts it in the NC 179 intersection. Not a section crash. Note for the PE: the signal was on flash. | U24: =IFERROR(INDEX(DetailedFiche!Q:Q,MATCH(K24,DetailedFiche!J:J,0)),"") | V24: =IFERROR(INDEX(DetailedFiche!R:R,MATCH(K24,DetailedFiche!J:J,0)),"") | X24: =IFERROR(IF(AND(INDEX('Initial Study'!K:K, MATCH(K24, 'Initial Study'!B:B, 0)+1)<>0,INDEX('Initial Study'!K:K, MATCH(K24, 'Initial Study'!B:B, 0)+1)<>""),INDEX('Initial Study'!K:K, MATCH(K24, 'Initial Study'!B:B, 0)+1),""),"") | Y24: =IFERROR(IF(AND(INDEX('Initial Study'!K:K, MATCH(K24, 'Initial Study'!B:B, 0)+2)<>0,INDEX('Initial Study'!K:K, MATCH(K24, 'Initial Study'!B:B, 0)+2)<>"",NOT(ISNUMBER(INDEX('Initial Study'!K:K, MATCH(K24, 'Initial Study'!B:B, 0)+2)))),INDEX('Initial Study'!K:K, MATCH(K24, 'Initial Study'!B:B, 0)+2),"-"),"-") | Z24: =IF(R24="RE", X24 & "BT/" & IF(Y24 <> "-", Y24 & "BT", ""), IF(OR(R24="LTDR", R24="LTSR"), X24 & "BL" & IF(Y24 <> "-", "/" & Y24 & "BT", ""), IF(OR(R24="RTDR", R24="RTSR"), X24 & "BR" & IF(Y24 <> "-", "/" & Y24 & "BT", ""), IF(Y24 <> "-", X24 & "BT/" & Y24 & "BT", X24 & "BT"))))
A25: 74 | B25: NC 179 | C25: 0.004 | D25: N | E25: SR 1164 | F25: SR 1810 | G25: NC 179 | H25: 999.999 | I25: NIS | K25: 107421425 | L25: 45147 | M25: 25 | N25: 1 | O25: 12 | P25: 1 | Q25: O | R25: =IFERROR(VLOOKUP(M25,Index!$A$1:$B$26,2,FALSE),"") | S25: =Z25 | T25: report: NC 179, 20 ft N of SR 1164 toward SR 1810, in Calabash; the diagram shows the four-leg signalized intersection (SR 1164, Old Georgetown Rd, NC 179, NC 179 south leg): unit 1 turned right from NC 179 into the NC 179 BUS leg, went left of center and struck unit 2 stopped for the red light facing north on that leg, within about 20 ft of the intersection. An intersection crash, 112 ft before the begin limit; outside the section; report MP 0.004; MP 999.999 on NC 179; the crash is in the NC 179 intersection approach, outside the section. | U25: =IFERROR(INDEX(DetailedFiche!Q:Q,MATCH(K25,DetailedFiche!J:J,0)),"") | V25: =IFERROR(INDEX(DetailedFiche!R:R,MATCH(K25,DetailedFiche!J:J,0)),"") | X25: =IFERROR(IF(AND(INDEX('Initial Study'!K:K, MATCH(K25, 'Initial Study'!B:B, 0)+1)<>0,INDEX('Initial Study'!K:K, MATCH(K25, 'Initial Study'!B:B, 0)+1)<>""),INDEX('Initial Study'!K:K, MATCH(K25, 'Initial Study'!B:B, 0)+1),""),"") | Y25: =IFERROR(IF(AND(INDEX('Initial Study'!K:K, MATCH(K25, 'Initial Study'!B:B, 0)+2)<>0,INDEX('Initial Study'!K:K, MATCH(K25, 'Initial Study'!B:B, 0)+2)<>"",NOT(ISNUMBER(INDEX('Initial Study'!K:K, MATCH(K25, 'Initial Study'!B:B, 0)+2)))),INDEX('Initial Study'!K:K, MATCH(K25, 'Initial Study'!B:B, 0)+2),"-"),"-") | Z25: =IF(R25="RE", X25 & "BT/" & IF(Y25 <> "-", Y25 & "BT", ""), IF(OR(R25="LTDR", R25="LTSR"), X25 & "BL" & IF(Y25 <> "-", "/" & Y25 & "BT", ""), IF(OR(R25="RTDR", R25="RTSR"), X25 & "BR" & IF(Y25 <> "-", "/" & Y25 & "BT", ""), IF(Y25 <> "-", X25 & "BT/" & Y25 & "BT", X25 & "BT"))))
A26: 74 | B26: NC 179 | C26: 1 | D26: N | E26: SR 1810 | F26: SR 1164 | G26: NC 179 | H26: 999.999 | I26: NIS | K26: 108280240 | L26: 45950 | M26: 23 | N26: 1 | O26: 4 | P26: 1 | Q26: C | R26: =IFERROR(VLOOKUP(M26,Index!$A$1:$B$26,2,FALSE),"") | S26: =Z26 | T26: report: Written as NC 179, 1.00 mi N of SR 1810 toward SR 1164, in Calabash; lat/long 33.885400, -78.54851; unit 1 northbound turning left into the PVA of Bonaparte Dr (the diagram names it), unit 2 southbound. Bonaparte Dr meets NC 179 BUS at inventory MP 0.955, about 0.75 mi past the end limit, which matches the coordinates (0.8 mi south-southeast of the section); outside the section; report MP 0.955; Coded on NC 179 MP 999.999 from the trooper's road name; it is on NC 179 BUS at about MP 0.95, outside the section. | U26: =IFERROR(INDEX(DetailedFiche!Q:Q,MATCH(K26,DetailedFiche!J:J,0)),"") | V26: =IFERROR(INDEX(DetailedFiche!R:R,MATCH(K26,DetailedFiche!J:J,0)),"") | X26: =IFERROR(IF(AND(INDEX('Initial Study'!K:K, MATCH(K26, 'Initial Study'!B:B, 0)+1)<>0,INDEX('Initial Study'!K:K, MATCH(K26, 'Initial Study'!B:B, 0)+1)<>""),INDEX('Initial Study'!K:K, MATCH(K26, 'Initial Study'!B:B, 0)+1),""),"") | Y26: =IFERROR(IF(AND(INDEX('Initial Study'!K:K, MATCH(K26, 'Initial Study'!B:B, 0)+2)<>0,INDEX('Initial Study'!K:K, MATCH(K26, 'Initial Study'!B:B, 0)+2)<>"",NOT(ISNUMBER(INDEX('Initial Study'!K:K, MATCH(K26, 'Initial Study'!B:B, 0)+2)))),INDEX('Initial Study'!K:K, MATCH(K26, 'Initial Study'!B:B, 0)+2),"-"),"-") | Z26: =IF(R26="RE", X26 & "BT/" & IF(Y26 <> "-", Y26 & "BT", ""), IF(OR(R26="LTDR", R26="LTSR"), X26 & "BL" & IF(Y26 <> "-", "/" & Y26 & "BT", ""), IF(OR(R26="RTDR", R26="RTSR"), X26 & "BR" & IF(Y26 <> "-", "/" & Y26 & "BT", ""), IF(Y26 <> "-", X26 & "BT/" & Y26 & "BT", X26 & "BT"))))
A27: 74 | B27: NC 179BUS | C27: 0 | E27: SR 1164 | F27: SR 1165 | G27: NC 179BUS | H27: 0 | I27: NIS | K27: 108186124 | L27: 45865 | M27: 23 | N27: 1 | O27: 7 | P27: 1 | Q27: B | R27: =IFERROR(VLOOKUP(M27,Index!$A$1:$B$26,2,FALSE),"") | S27: =Z27 | T27: report: NC 179 BUS at SR 1164 (0 ft, intersection) toward SR 1165, in Calabash; lat/long 33.898900, -78.55268 (the intersection); unit 1 westbound on NC 179B turning left into NC 179 was struck in the intersection by unit 2 eastbound on SR 1164. An intersection crash at the signal; outside the section; report MP 0.000; TEAAS MP 0.000 is correct; the crash is in the intersection, outside the section. | U27: =IFERROR(INDEX(DetailedFiche!Q:Q,MATCH(K27,DetailedFiche!J:J,0)),"") | V27: =IFERROR(INDEX(DetailedFiche!R:R,MATCH(K27,DetailedFiche!J:J,0)),"") | X27: =IFERROR(IF(AND(INDEX('Initial Study'!K:K, MATCH(K27, 'Initial Study'!B:B, 0)+1)<>0,INDEX('Initial Study'!K:K, MATCH(K27, 'Initial Study'!B:B, 0)+1)<>""),INDEX('Initial Study'!K:K, MATCH(K27, 'Initial Study'!B:B, 0)+1),""),"") | Y27: =IFERROR(IF(AND(INDEX('Initial Study'!K:K, MATCH(K27, 'Initial Study'!B:B, 0)+2)<>0,INDEX('Initial Study'!K:K, MATCH(K27, 'Initial Study'!B:B, 0)+2)<>"",NOT(ISNUMBER(INDEX('Initial Study'!K:K, MATCH(K27, 'Initial Study'!B:B, 0)+2)))),INDEX('Initial Study'!K:K, MATCH(K27, 'Initial Study'!B:B, 0)+2),"-"),"-") | Z27: =IF(R27="RE", X27 & "BT/" & IF(Y27 <> "-", Y27 & "BT", ""), IF(OR(R27="LTDR", R27="LTSR"), X27 & "BL" & IF(Y27 <> "-", "/" & Y27 & "BT", ""), IF(OR(R27="RTDR", R27="RTSR"), X27 & "BR" & IF(Y27 <> "-", "/" & Y27 & "BT", ""), IF(Y27 <> "-", X27 & "BT/" & Y27 & "BT", X27 & "BT"))))
A28: 74 | B28: NC 179BUS | C28: 0.014 | D28: S | E28: NC 179 | F28: SR 1810 | G28: NC 179BUS | H28: 0.014 | I28: NIS | J28: Y | K28: 107407446 | L28: 45131 | M28: 24 | N28: 1 | O28: 4 | P28: 1 | Q28: O | R28: =IFERROR(VLOOKUP(M28,Index!$A$1:$B$26,2,FALSE),"") | S28: =Z28 | T28: report: NC 179 BUS, 75 ft S of NC 179 toward SR 1810, in Calabash; unit 1 stopped on the PVA of the Minuteman Food Mart (southwest corner lot) turned left onto NC 179B into the path of northbound unit 2; the diagram shows the PVA on the west side with a 36-ft road. 75 ft from the intersection is 57 ft before the begin limit; outside the section; report MP 0.014; Same Minuteman driveway conflict as 108581555 (written 163 ft) but written at 75 ft, before the limit. Proposed NIS; the PE may take both Minuteman crashes together if the begin limit is moved to the intersection. | U28: =IFERROR(INDEX(DetailedFiche!Q:Q,MATCH(K28,DetailedFiche!J:J,0)),"") | V28: =IFERROR(INDEX(DetailedFiche!R:R,MATCH(K28,DetailedFiche!J:J,0)),"") | X28: =IFERROR(IF(AND(INDEX('Initial Study'!K:K, MATCH(K28, 'Initial Study'!B:B, 0)+1)<>0,INDEX('Initial Study'!K:K, MATCH(K28, 'Initial Study'!B:B, 0)+1)<>""),INDEX('Initial Study'!K:K, MATCH(K28, 'Initial Study'!B:B, 0)+1),""),"") | Y28: =IFERROR(IF(AND(INDEX('Initial Study'!K:K, MATCH(K28, 'Initial Study'!B:B, 0)+2)<>0,INDEX('Initial Study'!K:K, MATCH(K28, 'Initial Study'!B:B, 0)+2)<>"",NOT(ISNUMBER(INDEX('Initial Study'!K:K, MATCH(K28, 'Initial Study'!B:B, 0)+2)))),INDEX('Initial Study'!K:K, MATCH(K28, 'Initial Study'!B:B, 0)+2),"-"),"-") | Z28: =IF(R28="RE", X28 & "BT/" & IF(Y28 <> "-", Y28 & "BT", ""), IF(OR(R28="LTDR", R28="LTSR"), X28 & "BL" & IF(Y28 <> "-", "/" & Y28 & "BT", ""), IF(OR(R28="RTDR", R28="RTSR"), X28 & "BR" & IF(Y28 <> "-", "/" & Y28 & "BT", ""), IF(Y28 <> "-", X28 & "BT/" & Y28 & "BT", X28 & "BT"))))
A29: 74 | B29: NC 179BUS | C29: 0.024 | D29: S | E29: NC 179 | F29: SR 1246 | G29: NC 179BUS | H29: 0.024 | I29: NIS | J29: Y | K29: 106894323 | L29: 44638 | M29: 26 | N29: 1 | O29: 4 | P29: 1 | Q29: C | R29: =IFERROR(VLOOKUP(M29,Index!$A$1:$B$26,2,FALSE),"") | S29: =Z29 | T29: report: NC 179 BUS, 126 ft S of NC 179 toward SR 1246, in Calabash; unit 2 came out of the Sunoco PVA on the southwest side (drawn at the right-turn radius) turning right onto NC 179 B and was struck by a southbound tractor-trailer. The Sunoco station is the corner lot on the southwest side at the NC 179 intersection; its driveway at 126 ft is just before the NAPA driveway (132 ft), opposite side; outside the section; report MP 0.024; TEAAS MP 0.024, 5 ft short of the limit. The Sunoco driveway is the corner station's, not a section driveway; proposed NIS. The ITRE_CMV coordinates in the Detailed Fiche (33.941238, -78.411575) are wrong by 8 miles. PE may fold it in if the limits move to the intersection. | U29: =IFERROR(INDEX(DetailedFiche!Q:Q,MATCH(K29,DetailedFiche!J:J,0)),"") | V29: =IFERROR(INDEX(DetailedFiche!R:R,MATCH(K29,DetailedFiche!J:J,0)),"") | X29: =IFERROR(IF(AND(INDEX('Initial Study'!K:K, MATCH(K29, 'Initial Study'!B:B, 0)+1)<>0,INDEX('Initial Study'!K:K, MATCH(K29, 'Initial Study'!B:B, 0)+1)<>""),INDEX('Initial Study'!K:K, MATCH(K29, 'Initial Study'!B:B, 0)+1),""),"") | Y29: =IFERROR(IF(AND(INDEX('Initial Study'!K:K, MATCH(K29, 'Initial Study'!B:B, 0)+2)<>0,INDEX('Initial Study'!K:K, MATCH(K29, 'Initial Study'!B:B, 0)+2)<>"",NOT(ISNUMBER(INDEX('Initial Study'!K:K, MATCH(K29, 'Initial Study'!B:B, 0)+2)))),INDEX('Initial Study'!K:K, MATCH(K29, 'Initial Study'!B:B, 0)+2),"-"),"-") | Z29: =IF(R29="RE", X29 & "BT/" & IF(Y29 <> "-", Y29 & "BT", ""), IF(OR(R29="LTDR", R29="LTSR"), X29 & "BL" & IF(Y29 <> "-", "/" & Y29 & "BT", ""), IF(OR(R29="RTDR", R29="RTSR"), X29 & "BR" & IF(Y29 <> "-", "/" & Y29 & "BT", ""), IF(Y29 <> "-", X29 & "BT/" & Y29 & "BT", X29 & "BT"))))
A30: 0 | B30: NC 179BUS | C30: 0 | E30: NC 179 | F30: *LCL LITTLE LN SW | G30: NC 179BUS | H30: 999.999 | I30: NIS | K30: 107449205 | L30: 45170 | M30: 26 | N30: 1 | O30: 7 | P30: 1 | Q30: O | R30: =IFERROR(VLOOKUP(M30,Index!$A$1:$B$26,2,FALSE),"") | S30: =Z30 | T30: report: NC 179 BUS at NC 179 (0 ft, intersection) toward Little Ln SW, 0.10 mi E of Calabash; the diagram shows the signalized NC 179 / NC 179 B intersection with unit 2 stopped at the light facing north on NC 179 B and eastbound unit 1 turning right onto NC 179 B and striking it in the intersection. An intersection crash, 132 ft before the begin limit; outside the section; report MP 0.000; MP 999.999 because of the Little Ln SW name; the crash is at the NC 179 signal, outside the section. | U30: =IFERROR(INDEX(DetailedFiche!Q:Q,MATCH(K30,DetailedFiche!J:J,0)),"") | V30: =IFERROR(INDEX(DetailedFiche!R:R,MATCH(K30,DetailedFiche!J:J,0)),"") | X30: =IFERROR(IF(AND(INDEX('Initial Study'!K:K, MATCH(K30, 'Initial Study'!B:B, 0)+1)<>0,INDEX('Initial Study'!K:K, MATCH(K30, 'Initial Study'!B:B, 0)+1)<>""),INDEX('Initial Study'!K:K, MATCH(K30, 'Initial Study'!B:B, 0)+1),""),"") | Y30: =IFERROR(IF(AND(INDEX('Initial Study'!K:K, MATCH(K30, 'Initial Study'!B:B, 0)+2)<>0,INDEX('Initial Study'!K:K, MATCH(K30, 'Initial Study'!B:B, 0)+2)<>"",NOT(ISNUMBER(INDEX('Initial Study'!K:K, MATCH(K30, 'Initial Study'!B:B, 0)+2)))),INDEX('Initial Study'!K:K, MATCH(K30, 'Initial Study'!B:B, 0)+2),"-"),"-") | Z30: =IF(R30="RE", X30 & "BT/" & IF(Y30 <> "-", Y30 & "BT", ""), IF(OR(R30="LTDR", R30="LTSR"), X30 & "BL" & IF(Y30 <> "-", "/" & Y30 & "BT", ""), IF(OR(R30="RTDR", R30="RTSR"), X30 & "BR" & IF(Y30 <> "-", "/" & Y30 & "BT", ""), IF(Y30 <> "-", X30 & "BT/" & Y30 & "BT", X30 & "BT"))))
A31: NOT IN STUDY - REPORT NOT REVIEWED
A32: 0 | B32: *LCL ANGEL TRACE RD SW | C32: 0 | E32: NC 179 | F32: NC 904 | H32: 999.999 | I32: NIS | K32: 107342083 | L32: 45064 | M32: 21 | N32: 2 | O32: 8 | P32: 1 | Q32: O | R32: =IFERROR(VLOOKUP(M32,Index!$A$1:$B$26,2,FALSE),"") | S32: =Z32 | U32: =IFERROR(INDEX(DetailedFiche!Q:Q,MATCH(K32,DetailedFiche!J:J,0)),"") | V32: =IFERROR(INDEX(DetailedFiche!R:R,MATCH(K32,DetailedFiche!J:J,0)),"") | X32: =IFERROR(IF(AND(INDEX('Initial Study'!K:K, MATCH(K32, 'Initial Study'!B:B, 0)+1)<>0,INDEX('Initial Study'!K:K, MATCH(K32, 'Initial Study'!B:B, 0)+1)<>""),INDEX('Initial Study'!K:K, MATCH(K32, 'Initial Study'!B:B, 0)+1),""),"") | Y32: =IFERROR(IF(AND(INDEX('Initial Study'!K:K, MATCH(K32, 'Initial Study'!B:B, 0)+2)<>0,INDEX('Initial Study'!K:K, MATCH(K32, 'Initial Study'!B:B, 0)+2)<>"",NOT(ISNUMBER(INDEX('Initial Study'!K:K, MATCH(K32, 'Initial Study'!B:B, 0)+2)))),INDEX('Initial Study'!K:K, MATCH(K32, 'Initial Study'!B:B, 0)+2),"-"),"-") | Z32: =IF(R32="RE", X32 & "BT/" & IF(Y32 <> "-", Y32 & "BT", ""), IF(OR(R32="LTDR", R32="LTSR"), X32 & "BL" & IF(Y32 <> "-", "/" & Y32 & "BT", ""), IF(OR(R32="RTDR", R32="RTSR"), X32 & "BR" & IF(Y32 <> "-", "/" & Y32 & "BT", ""), IF(Y32 <> "-", X32 & "BT/" & Y32 & "BT", X32 & "BT"))))
A33: 631 | B33: BEACH | C33: 0 | E33: *LCL 1904 E BEACH DR | H33: 999.999 | I33: NIS | K33: 108173956 | L33: 45841 | M33: 31 | N33: 1 | O33: 5 | P33: 1 | Q33: O | R33: =IFERROR(VLOOKUP(M33,Index!$A$1:$B$26,2,FALSE),"") | S33: =Z33 | U33: =IFERROR(INDEX(DetailedFiche!Q:Q,MATCH(K33,DetailedFiche!J:J,0)),"") | V33: =IFERROR(INDEX(DetailedFiche!R:R,MATCH(K33,DetailedFiche!J:J,0)),"") | X33: =IFERROR(IF(AND(INDEX('Initial Study'!K:K, MATCH(K33, 'Initial Study'!B:B, 0)+1)<>0,INDEX('Initial Study'!K:K, MATCH(K33, 'Initial Study'!B:B, 0)+1)<>""),INDEX('Initial Study'!K:K, MATCH(K33, 'Initial Study'!B:B, 0)+1),""),"") | Y33: =IFERROR(IF(AND(INDEX('Initial Study'!K:K, MATCH(K33, 'Initial Study'!B:B, 0)+2)<>0,INDEX('Initial Study'!K:K, MATCH(K33, 'Initial Study'!B:B, 0)+2)<>"",NOT(ISNUMBER(INDEX('Initial Study'!K:K, MATCH(K33, 'Initial Study'!B:B, 0)+2)))),INDEX('Initial Study'!K:K, MATCH(K33, 'Initial Study'!B:B, 0)+2),"-"),"-") | Z33: =IF(R33="RE", X33 & "BT/" & IF(Y33 <> "-", Y33 & "BT", ""), IF(OR(R33="LTDR", R33="LTSR"), X33 & "BL" & IF(Y33 <> "-", "/" & Y33 & "BT", ""), IF(OR(R33="RTDR", R33="RTSR"), X33 & "BR" & IF(Y33 <> "-", "/" & Y33 & "BT", ""), IF(Y33 <> "-", X33 & "BT/" & Y33 & "BT", X33 & "BT"))))
A34: 0 | B34: BEACH | C34: 0 | E34: *LCL DUNES BLVD | F34: HALE BEACH | H34: 999.999 | I34: NIS | K34: 108199076 | L34: 45874 | M34: 23 | N34: 1 | O34: 0 | P34: 1 | Q34: O | R34: =IFERROR(VLOOKUP(M34,Index!$A$1:$B$26,2,FALSE),"") | S34: =Z34 | U34: =IFERROR(INDEX(DetailedFiche!Q:Q,MATCH(K34,DetailedFiche!J:J,0)),"") | V34: =IFERROR(INDEX(DetailedFiche!R:R,MATCH(K34,DetailedFiche!J:J,0)),"") | X34: =IFERROR(IF(AND(INDEX('Initial Study'!K:K, MATCH(K34, 'Initial Study'!B:B, 0)+1)<>0,INDEX('Initial Study'!K:K, MATCH(K34, 'Initial Study'!B:B, 0)+1)<>""),INDEX('Initial Study'!K:K, MATCH(K34, 'Initial Study'!B:B, 0)+1),""),"") | Y34: =IFERROR(IF(AND(INDEX('Initial Study'!K:K, MATCH(K34, 'Initial Study'!B:B, 0)+2)<>0,INDEX('Initial Study'!K:K, MATCH(K34, 'Initial Study'!B:B, 0)+2)<>"",NOT(ISNUMBER(INDEX('Initial Study'!K:K, MATCH(K34, 'Initial Study'!B:B, 0)+2)))),INDEX('Initial Study'!K:K, MATCH(K34, 'Initial Study'!B:B, 0)+2),"-"),"-") | Z34: =IF(R34="RE", X34 & "BT/" & IF(Y34 <> "-", Y34 & "BT", ""), IF(OR(R34="LTDR", R34="LTSR"), X34 & "BL" & IF(Y34 <> "-", "/" & Y34 & "BT", ""), IF(OR(R34="RTDR", R34="RTSR"), X34 & "BR" & IF(Y34 <> "-", "/" & Y34 & "BT", ""), IF(Y34 <> "-", X34 & "BT/" & Y34 & "BT", X34 & "BT"))))
A35: 534 | B35: BEACH | C35: 0 | E35: *LCL EVERGREEN LN SW | F35: HOLLY | H35: 999.999 | I35: NIS | K35: 107639269 | L35: 45342 | M35: 17 | N35: 1 | O35: 0 | P35: 5 | Q35: O | R35: =IFERROR(VLOOKUP(M35,Index!$A$1:$B$26,2,FALSE),"") | S35: =Z35 | U35: =IFERROR(INDEX(DetailedFiche!Q:Q,MATCH(K35,DetailedFiche!J:J,0)),"") | V35: =IFERROR(INDEX(DetailedFiche!R:R,MATCH(K35,DetailedFiche!J:J,0)),"") | X35: =IFERROR(IF(AND(INDEX('Initial Study'!K:K, MATCH(K35, 'Initial Study'!B:B, 0)+1)<>0,INDEX('Initial Study'!K:K, MATCH(K35, 'Initial Study'!B:B, 0)+1)<>""),INDEX('Initial Study'!K:K, MATCH(K35, 'Initial Study'!B:B, 0)+1),""),"") | Y35: =IFERROR(IF(AND(INDEX('Initial Study'!K:K, MATCH(K35, 'Initial Study'!B:B, 0)+2)<>0,INDEX('Initial Study'!K:K, MATCH(K35, 'Initial Study'!B:B, 0)+2)<>"",NOT(ISNUMBER(INDEX('Initial Study'!K:K, MATCH(K35, 'Initial Study'!B:B, 0)+2)))),INDEX('Initial Study'!K:K, MATCH(K35, 'Initial Study'!B:B, 0)+2),"-"),"-") | Z35: =IF(R35="RE", X35 & "BT/" & IF(Y35 <> "-", Y35 & "BT", ""), IF(OR(R35="LTDR", R35="LTSR"), X35 & "BL" & IF(Y35 <> "-", "/" & Y35 & "BT", ""), IF(OR(R35="RTDR", R35="RTSR"), X35 & "BR" & IF(Y35 <> "-", "/" & Y35 & "BT", ""), IF(Y35 <> "-", X35 & "BT/" & Y35 & "BT", X35 & "BT"))))
A36: 0 | B36: BEACH | C36: 0.009 | D36: W | E36: *LCL HIDEAWAY RD SW | F36: SEASIDE | H36: 999.999 | I36: NIS | K36: 108532023 | L36: 46187 | M36: 17 | N36: 1 | O36: 0 | P36: 4 | Q36: O | R36: =IFERROR(VLOOKUP(M36,Index!$A$1:$B$26,2,FALSE),"") | S36: =Z36 | U36: =IFERROR(INDEX(DetailedFiche!Q:Q,MATCH(K36,DetailedFiche!J:J,0)),"") | V36: =IFERROR(INDEX(DetailedFiche!R:R,MATCH(K36,DetailedFiche!J:J,0)),"") | X36: =IFERROR(IF(AND(INDEX('Initial Study'!K:K, MATCH(K36, 'Initial Study'!B:B, 0)+1)<>0,INDEX('Initial Study'!K:K, MATCH(K36, 'Initial Study'!B:B, 0)+1)<>""),INDEX('Initial Study'!K:K, MATCH(K36, 'Initial Study'!B:B, 0)+1),""),"") | Y36: =IFERROR(IF(AND(INDEX('Initial Study'!K:K, MATCH(K36, 'Initial Study'!B:B, 0)+2)<>0,INDEX('Initial Study'!K:K, MATCH(K36, 'Initial Study'!B:B, 0)+2)<>"",NOT(ISNUMBER(INDEX('Initial Study'!K:K, MATCH(K36, 'Initial Study'!B:B, 0)+2)))),INDEX('Initial Study'!K:K, MATCH(K36, 'Initial Study'!B:B, 0)+2),"-"),"-") | Z36: =IF(R36="RE", X36 & "BT/" & IF(Y36 <> "-", Y36 & "BT", ""), IF(OR(R36="LTDR", R36="LTSR"), X36 & "BL" & IF(Y36 <> "-", "/" & Y36 & "BT", ""), IF(OR(R36="RTDR", R36="RTSR"), X36 & "BR" & IF(Y36 <> "-", "/" & Y36 & "BT", ""), IF(Y36 <> "-", X36 & "BT/" & Y36 & "BT", X36 & "BT"))))
A37: 631 | B37: BEACH | C37: 0.019 | E37: *LCL SE 46TH STREET | F37: *LCL SE 49TH STREET | H37: 999.999 | I37: NIS | K37: 108419436 | L37: 46083 | M37: 20 | N37: 1 | O37: 0 | P37: 1 | Q37: O | R37: =IFERROR(VLOOKUP(M37,Index!$A$1:$B$26,2,FALSE),"") | S37: =Z37 | U37: =IFERROR(INDEX(DetailedFiche!Q:Q,MATCH(K37,DetailedFiche!J:J,0)),"") | V37: =IFERROR(INDEX(DetailedFiche!R:R,MATCH(K37,DetailedFiche!J:J,0)),"") | X37: =IFERROR(IF(AND(INDEX('Initial Study'!K:K, MATCH(K37, 'Initial Study'!B:B, 0)+1)<>0,INDEX('Initial Study'!K:K, MATCH(K37, 'Initial Study'!B:B, 0)+1)<>""),INDEX('Initial Study'!K:K, MATCH(K37, 'Initial Study'!B:B, 0)+1),""),"") | Y37: =IFERROR(IF(AND(INDEX('Initial Study'!K:K, MATCH(K37, 'Initial Study'!B:B, 0)+2)<>0,INDEX('Initial Study'!K:K, MATCH(K37, 'Initial Study'!B:B, 0)+2)<>"",NOT(ISNUMBER(INDEX('Initial Study'!K:K, MATCH(K37, 'Initial Study'!B:B, 0)+2)))),INDEX('Initial Study'!K:K, MATCH(K37, 'Initial Study'!B:B, 0)+2),"-"),"-") | Z37: =IF(R37="RE", X37 & "BT/" & IF(Y37 <> "-", Y37 & "BT", ""), IF(OR(R37="LTDR", R37="LTSR"), X37 & "BL" & IF(Y37 <> "-", "/" & Y37 & "BT", ""), IF(OR(R37="RTDR", R37="RTSR"), X37 & "BR" & IF(Y37 <> "-", "/" & Y37 & "BT", ""), IF(Y37 <> "-", X37 & "BT/" & Y37 & "BT", X37 & "BT"))))
A38: 401 | B38: BEACH | C38: 0 | E38: *LCL THORPE LANDING RD | H38: 999.999 | I38: NIS | K38: 107765292 | L38: 45457 | M38: 17 | N38: 1 | O38: 0 | P38: 5 | Q38: O | R38: =IFERROR(VLOOKUP(M38,Index!$A$1:$B$26,2,FALSE),"") | S38: =Z38 | U38: =IFERROR(INDEX(DetailedFiche!Q:Q,MATCH(K38,DetailedFiche!J:J,0)),"") | V38: =IFERROR(INDEX(DetailedFiche!R:R,MATCH(K38,DetailedFiche!J:J,0)),"") | X38: =IFERROR(IF(AND(INDEX('Initial Study'!K:K, MATCH(K38, 'Initial Study'!B:B, 0)+1)<>0,INDEX('Initial Study'!K:K, MATCH(K38, 'Initial Study'!B:B, 0)+1)<>""),INDEX('Initial Study'!K:K, MATCH(K38, 'Initial Study'!B:B, 0)+1),""),"") | Y38: =IFERROR(IF(AND(INDEX('Initial Study'!K:K, MATCH(K38, 'Initial Study'!B:B, 0)+2)<>0,INDEX('Initial Study'!K:K, MATCH(K38, 'Initial Study'!B:B, 0)+2)<>"",NOT(ISNUMBER(INDEX('Initial Study'!K:K, MATCH(K38, 'Initial Study'!B:B, 0)+2)))),INDEX('Initial Study'!K:K, MATCH(K38, 'Initial Study'!B:B, 0)+2),"-"),"-") | Z38: =IF(R38="RE", X38 & "BT/" & IF(Y38 <> "-", Y38 & "BT", ""), IF(OR(R38="LTDR", R38="LTSR"), X38 & "BL" & IF(Y38 <> "-", "/" & Y38 & "BT", ""), IF(OR(R38="RTDR", R38="RTSR"), X38 & "BR" & IF(Y38 <> "-", "/" & Y38 & "BT", ""), IF(Y38 <> "-", X38 & "BT/" & Y38 & "BT", X38 & "BT"))))
A39: 401 | B39: BEACH | C39: 1 | D39: W | E39: *LCL WEST KILBART | F39: CAUSEWAY | H39: 999.999 | I39: NIS | K39: 108494151 | L39: 46150 | M39: 13 | N39: 1 | O39: 10 | P39: 1 | Q39: O | R39: =IFERROR(VLOOKUP(M39,Index!$A$1:$B$26,2,FALSE),"") | S39: =Z39 | U39: =IFERROR(INDEX(DetailedFiche!Q:Q,MATCH(K39,DetailedFiche!J:J,0)),"") | V39: =IFERROR(INDEX(DetailedFiche!R:R,MATCH(K39,DetailedFiche!J:J,0)),"") | X39: =IFERROR(IF(AND(INDEX('Initial Study'!K:K, MATCH(K39, 'Initial Study'!B:B, 0)+1)<>0,INDEX('Initial Study'!K:K, MATCH(K39, 'Initial Study'!B:B, 0)+1)<>""),INDEX('Initial Study'!K:K, MATCH(K39, 'Initial Study'!B:B, 0)+1),""),"") | Y39: =IFERROR(IF(AND(INDEX('Initial Study'!K:K, MATCH(K39, 'Initial Study'!B:B, 0)+2)<>0,INDEX('Initial Study'!K:K, MATCH(K39, 'Initial Study'!B:B, 0)+2)<>"",NOT(ISNUMBER(INDEX('Initial Study'!K:K, MATCH(K39, 'Initial Study'!B:B, 0)+2)))),INDEX('Initial Study'!K:K, MATCH(K39, 'Initial Study'!B:B, 0)+2),"-"),"-") | Z39: =IF(R39="RE", X39 & "BT/" & IF(Y39 <> "-", Y39 & "BT", ""), IF(OR(R39="LTDR", R39="LTSR"), X39 & "BL" & IF(Y39 <> "-", "/" & Y39 & "BT", ""), IF(OR(R39="RTDR", R39="RTSR"), X39 & "BR" & IF(Y39 <> "-", "/" & Y39 & "BT", ""), IF(Y39 <> "-", X39 & "BT/" & Y39 & "BT", X39 & "BT"))))
B40: NC 179 | C40: 0.3 | D40: N | E40: *LCL BRENDA LN | F40: NC 130 | H40: 999.999 | I40: NIS | K40: 107620171 | L40: 45330 | M40: 22 | N40: 1 | O40: 0 | P40: 1 | Q40: O | R40: =IFERROR(VLOOKUP(M40,Index!$A$1:$B$26,2,FALSE),"") | S40: =Z40 | U40: =IFERROR(INDEX(DetailedFiche!Q:Q,MATCH(K40,DetailedFiche!J:J,0)),"") | V40: =IFERROR(INDEX(DetailedFiche!R:R,MATCH(K40,DetailedFiche!J:J,0)),"") | X40: =IFERROR(IF(AND(INDEX('Initial Study'!K:K, MATCH(K40, 'Initial Study'!B:B, 0)+1)<>0,INDEX('Initial Study'!K:K, MATCH(K40, 'Initial Study'!B:B, 0)+1)<>""),INDEX('Initial Study'!K:K, MATCH(K40, 'Initial Study'!B:B, 0)+1),""),"") | Y40: =IFERROR(IF(AND(INDEX('Initial Study'!K:K, MATCH(K40, 'Initial Study'!B:B, 0)+2)<>0,INDEX('Initial Study'!K:K, MATCH(K40, 'Initial Study'!B:B, 0)+2)<>"",NOT(ISNUMBER(INDEX('Initial Study'!K:K, MATCH(K40, 'Initial Study'!B:B, 0)+2)))),INDEX('Initial Study'!K:K, MATCH(K40, 'Initial Study'!B:B, 0)+2),"-"),"-") | Z40: =IF(R40="RE", X40 & "BT/" & IF(Y40 <> "-", Y40 & "BT", ""), IF(OR(R40="LTDR", R40="LTSR"), X40 & "BL" & IF(Y40 <> "-", "/" & Y40 & "BT", ""), IF(OR(R40="RTDR", R40="RTSR"), X40 & "BR" & IF(Y40 <> "-", "/" & Y40 & "BT", ""), IF(Y40 <> "-", X40 & "BT/" & Y40 & "BT", X40 & "BT"))))
...

Sheet Review IDs
A1: Crash ID | B1: Flag | C1: Trigger | D1: In Initial Study? | E1: On Road | F1: Miles | G1: Dir | H1: From Road | I1: Toward Road | J1: Milepost Road | K1: MP | L1: Date | M1: T | N1: S | O1: Reason | P1: Decision (ADD / DEL / IS / NIS) | Q1: Report MP | R1: Report location | S1: Report facts | T1: Confidence | U1: Report pages
A2: 108569891 | B2: IS | C2: In study | D2: YES | E2: NC 179BUS | F2: 0.07 | G2: S | H2: NC 179 | I2: SR 1810 | J2: NC 179BUS | K2: 0.07 | L2: 46225 | M2: 23 | N2: K | O2: In initial study - at study MP | P2: IS | Q2: 0.07 | R2: NC 179 BUS, 368 ft S of NC 179 toward SR 1810; lat/long 33.898099, -78.55168; left turn from southbound NC 179B into the PVA of Los Nuevos Charros Mexican Restaurant | S2: 7/22/2026 17:31, daylight, dry. Unit 1 2018 Hyundai SUV southbound 10 mph turning left into the restaurant PVA (maneuver 8); unit 2 2011 Harley-Davidson motorcycle northbound 45 mph (impact 30). Fail to yield. Motorcycle driver (42) killed, passenger B injury, SUV driver B injury. Both motorcycle occupants ejected, wearing DOT helmets. Speed limit 45, 3 lanes (TWLTL), no traffic control (76=0). Charge 175445H misdemeanor death / fail to yield to a motorcycle. Trp H E Todd NCSHP. | T2: high | U2: 1, 2
A3: 108457510 | B3: IS | C3: In study | D3: YES | E3: NC 179BUS | F3: 0.083 | G3: E | H3: NC 179 | I3: SR 1810 | J3: NC 179BUS | K3: 0.083 | L3: 46114 | M3: 23 | N3: O | O3: In initial study - at study MP | P3: IS | Q3: 0.083 | R3: NC 179 BUS, 437 ft E of NC 179 toward SR 1810; lat/long 33.898100, -78.55169 (the same coordinates as the fatal); eastbound (southeast-bound) unit 1 turning left into a public drive on the north side | S3: 4/2/2026 12:52, daylight, dry (surface 3). Unit 1 2015 Toyota pickup eastbound 10 mph turning left into a PVA (maneuver 8); unit 2 2019 Ram pickup westbound 25 mph. Fail to yield; unit 2 ran off road right after impact (17 ft). No injuries (O). Speed limit 45, 3 lanes, road feature 4 (driveway), traffic control 13 (double yellow, no passing). Charge 65604H7 yield. Trp J S Ransom NCSHP. | T3: high | U3: 3, 4
A4: 107392672 | B4: IS | C4: In study | D4: YES | E4: NC 179BUS | F4: 0.1 | G4: S | H4: NC 179 | I4: SR 1246 | J4: NC 179BUS | K4: 0.1 | L4: 45112 | M4: 23 | N4: O | O4: In initial study - at study MP | P4: IS | Q4: 0.1 | R4: NC 179 BUS, 0.10 mi S of NC 179 toward SR 1246; no lat/long; southbound unit 1 turning left into the PVA of Central Mamma's Mexican Restaurant (east side) - the same restaurant site as the fatal crash (Los Nuevos Charros), so the true distance is about 370 ft (MP 0.07) rather than the rounded 0.10 mi | S4: 7/5/2023 10:08, daylight, dry (surface 4?). Unit 1 2011 Chevrolet passenger car southbound 5 mph turning left into the restaurant PVA (maneuver 8); unit 2 2023 Ford pickup northbound 45 mph (25 at impact). Fail to yield. No injuries (O). Speed limit 45, 2 lanes coded, traffic control 13. Charge 4645H06 failure to yield. Trp J H Shaw NCSHP. | T4: high | U4: 5, 6
