Workbook

Sheet 41000076160_Fiche
A1: Muni. Code | B1: On Road | C1: Miles | D1: Dir From | E1: From Road | F1: Toward Road | G1: Milepost Road | H1: MP | I1: IS? | J1: New MP | K1: MA | L1: Crash ID | M1: Date | N1: T | O1: C | P1: F | Q1: L | R1: S | S1: Type | T1: Dir | U1: Comment | V1: Latitude | W1: Longitude
A2: 558 | B2: LOVE MILL | C2: 0.23 | D2: N | E2: *LCL A G R NANCE RD | F2: ZEBULON WILLIAMS | H2: 999.999 | I2: NIS | L2: 108377465 | M2: 46042 | N2: 19 | O2: 1 | P2: 0 | Q2: 1 | R2: O | S2: =IFERROR(VLOOKUP(N2,Index!$A$1:$B$26,2,FALSE),"") | T2: =AA2 | V2: =IFERROR(INDEX(DetailedFiche!Q:Q,MATCH(L2,DetailedFiche!J:J,0)),"") | W2: =IFERROR(INDEX(DetailedFiche!R:R,MATCH(L2,DetailedFiche!J:J,0)),"") | Y2: =IFERROR(IF(AND(INDEX('Initial Study'!K:K, MATCH(L2, 'Initial Study'!B:B, 0)+1)<>0,INDEX('Initial Study'!K:K, MATCH(L2, 'Initial Study'!B:B, 0)+1)<>""),INDEX('Initial Study'!K:K, MATCH(L2, 'Initial Study'!B:B, 0)+1),""),"") | Z2: =IFERROR(IF(AND(INDEX('Initial Study'!K:K, MATCH(L2, 'Initial Study'!B:B, 0)+2)<>0,INDEX('Initial Study'!K:K, MATCH(L2, 'Initial Study'!B:B, 0)+2)<>"",NOT(ISNUMBER(INDEX('Initial Study'!K:K, MATCH(L2, 'Initial Study'!B:B, 0)+2)))),INDEX('Initial Study'!K:K, MATCH(L2, 'Initial Study'!B:B, 0)+2),"-"),"-") | AA2: =IF(S2="RE", Y2 & "BT/" & IF(Z2 <> "-", Z2 & "BT", ""), IF(OR(S2="LTDR", S2="LTSR"), Y2 & "BL" & IF(Z2 <> "-", "/" & Z2 & "BT", ""), IF(OR(S2="RTDR", S2="RTSR"), Y2 & "BR" & IF(Z2 <> "-", "/" & Z2 & "BT", ""), IF(Z2 <> "-", Y2 & "BT/" & Z2 & "BT", Y2 & "BT"))))
A3: 0 | B3: SR 1606 | C3: 0.25 | D3: S | E3: *LCL BIGGERS CEMETERY RD | F3: OLD FERRY | H3: 999.999 | I3: NIS | L3: 105935402 | M3: 43668 | N3: 29 | O3: 1 | P3: 0 | Q3: 1 | R3: O | S3: =IFERROR(VLOOKUP(N3,Index!$A$1:$B$26,2,FALSE),"") | T3: =AA3 | V3: =IFERROR(INDEX(DetailedFiche!Q:Q,MATCH(L3,DetailedFiche!J:J,0)),"") | W3: =IFERROR(INDEX(DetailedFiche!R:R,MATCH(L3,DetailedFiche!J:J,0)),"") | Y3: =IFERROR(IF(AND(INDEX('Initial Study'!K:K, MATCH(L3, 'Initial Study'!B:B, 0)+1)<>0,INDEX('Initial Study'!K:K, MATCH(L3, 'Initial Study'!B:B, 0)+1)<>""),INDEX('Initial Study'!K:K, MATCH(L3, 'Initial Study'!B:B, 0)+1),""),"") | Z3: =IFERROR(IF(AND(INDEX('Initial Study'!K:K, MATCH(L3, 'Initial Study'!B:B, 0)+2)<>0,INDEX('Initial Study'!K:K, MATCH(L3, 'Initial Study'!B:B, 0)+2)<>"",NOT(ISNUMBER(INDEX('Initial Study'!K:K, MATCH(L3, 'Initial Study'!B:B, 0)+2)))),INDEX('Initial Study'!K:K, MATCH(L3, 'Initial Study'!B:B, 0)+2),"-"),"-") | AA3: =IF(S3="RE", Y3 & "BT/" & IF(Z3 <> "-", Z3 & "BT", ""), IF(OR(S3="LTDR", S3="LTSR"), Y3 & "BL" & IF(Z3 <> "-", "/" & Z3 & "BT", ""), IF(OR(S3="RTDR", S3="RTSR"), Y3 & "BR" & IF(Z3 <> "-", "/" & Z3 & "BT", ""), IF(Z3 <> "-", Y3 & "BT/" & Z3 & "BT", Y3 & "BT"))))
A4: 0 | B4: SR 1606 | C4: 0.3 | D4: E | E4: *LCL CAMDEN OAKS LN | F4: SR 1006 | H4: 999.999 | I4: NIS | L4: 106214571 | M4: 43951 | N4: 29 | O4: 1 | P4: 1 | Q4: 1 | R4: O | S4: =IFERROR(VLOOKUP(N4,Index!$A$1:$B$26,2,FALSE),"") | T4: =AA4 | V4: =IFERROR(INDEX(DetailedFiche!Q:Q,MATCH(L4,DetailedFiche!J:J,0)),"") | W4: =IFERROR(INDEX(DetailedFiche!R:R,MATCH(L4,DetailedFiche!J:J,0)),"") | Y4: =IFERROR(IF(AND(INDEX('Initial Study'!K:K, MATCH(L4, 'Initial Study'!B:B, 0)+1)<>0,INDEX('Initial Study'!K:K, MATCH(L4, 'Initial Study'!B:B, 0)+1)<>""),INDEX('Initial Study'!K:K, MATCH(L4, 'Initial Study'!B:B, 0)+1),""),"") | Z4: =IFERROR(IF(AND(INDEX('Initial Study'!K:K, MATCH(L4, 'Initial Study'!B:B, 0)+2)<>0,INDEX('Initial Study'!K:K, MATCH(L4, 'Initial Study'!B:B, 0)+2)<>"",NOT(ISNUMBER(INDEX('Initial Study'!K:K, MATCH(L4, 'Initial Study'!B:B, 0)+2)))),INDEX('Initial Study'!K:K, MATCH(L4, 'Initial Study'!B:B, 0)+2),"-"),"-") | AA4: =IF(S4="RE", Y4 & "BT/" & IF(Z4 <> "-", Z4 & "BT", ""), IF(OR(S4="LTDR", S4="LTSR"), Y4 & "BL" & IF(Z4 <> "-", "/" & Z4 & "BT", ""), IF(OR(S4="RTDR", S4="RTSR"), Y4 & "BR" & IF(Z4 <> "-", "/" & Z4 & "BT", ""), IF(Z4 <> "-", Y4 & "BT/" & Z4 & "BT", Y4 & "BT"))))
A5: 558 | B5: TOM BOYD | C5: 0.024 | D5: SE | E5: *LCL LATHAN WOODS DR | F5: OLD CAMDEN | H5: 999.999 | I5: NIS | L5: 104734401 | M5: 42502 | N5: 21 | O5: 2 | P5: 5 | Q5: 5 | R5: O | S5: =IFERROR(VLOOKUP(N5,Index!$A$1:$B$26,2,FALSE),"") | T5: =AA5 | V5: =IFERROR(INDEX(DetailedFiche!Q:Q,MATCH(L5,DetailedFiche!J:J,0)),"") | W5: =IFERROR(INDEX(DetailedFiche!R:R,MATCH(L5,DetailedFiche!J:J,0)),"") | Y5: =IFERROR(IF(AND(INDEX('Initial Study'!K:K, MATCH(L5, 'Initial Study'!B:B, 0)+1)<>0,INDEX('Initial Study'!K:K, MATCH(L5, 'Initial Study'!B:B, 0)+1)<>""),INDEX('Initial Study'!K:K, MATCH(L5, 'Initial Study'!B:B, 0)+1),""),"") | Z5: =IFERROR(IF(AND(INDEX('Initial Study'!K:K, MATCH(L5, 'Initial Study'!B:B, 0)+2)<>0,INDEX('Initial Study'!K:K, MATCH(L5, 'Initial Study'!B:B, 0)+2)<>"",NOT(ISNUMBER(INDEX('Initial Study'!K:K, MATCH(L5, 'Initial Study'!B:B, 0)+2)))),INDEX('Initial Study'!K:K, MATCH(L5, 'Initial Study'!B:B, 0)+2),"-"),"-") | AA5: =IF(S5="RE", Y5 & "BT/" & IF(Z5 <> "-", Z5 & "BT", ""), IF(OR(S5="LTDR", S5="LTSR"), Y5 & "BL" & IF(Z5 <> "-", "/" & Z5 & "BT", ""), IF(OR(S5="RTDR", S5="RTSR"), Y5 & "BR" & IF(Z5 <> "-", "/" & Z5 & "BT", ""), IF(Z5 <> "-", Y5 & "BT/" & Z5 & "BT", Y5 & "BT"))))
A6: 558 | B6: SR 1001 | C6: 0 | E6: *LCL PEIDMONT SCHOOL RD | F6: SR 1674 | H6: 999.999 | I6: NIS | L6: 108430866 | M6: 46094 | N6: 24 | O6: 1 | P6: 5 | Q6: 1 | R6: C | S6: =IFERROR(VLOOKUP(N6,Index!$A$1:$B$26,2,FALSE),"") | T6: =AA6 | V6: =IFERROR(INDEX(DetailedFiche!Q:Q,MATCH(L6,DetailedFiche!J:J,0)),"") | W6: =IFERROR(INDEX(DetailedFiche!R:R,MATCH(L6,DetailedFiche!J:J,0)),"") | Y6: =IFERROR(IF(AND(INDEX('Initial Study'!K:K, MATCH(L6, 'Initial Study'!B:B, 0)+1)<>0,INDEX('Initial Study'!K:K, MATCH(L6, 'Initial Study'!B:B, 0)+1)<>""),INDEX('Initial Study'!K:K, MATCH(L6, 'Initial Study'!B:B, 0)+1),""),"") | Z6: =IFERROR(IF(AND(INDEX('Initial Study'!K:K, MATCH(L6, 'Initial Study'!B:B, 0)+2)<>0,INDEX('Initial Study'!K:K, MATCH(L6, 'Initial Study'!B:B, 0)+2)<>"",NOT(ISNUMBER(INDEX('Initial Study'!K:K, MATCH(L6, 'Initial Study'!B:B, 0)+2)))),INDEX('Initial Study'!K:K, MATCH(L6, 'Initial Study'!B:B, 0)+2),"-"),"-") | AA6: =IF(S6="RE", Y6 & "BT/" & IF(Z6 <> "-", Z6 & "BT", ""), IF(OR(S6="LTDR", S6="LTSR"), Y6 & "BL" & IF(Z6 <> "-", "/" & Z6 & "BT", ""), IF(OR(S6="RTDR", S6="RTSR"), Y6 & "BR" & IF(Z6 <> "-", "/" & Z6 & "BT", ""), IF(Z6 <> "-", Y6 & "BT/" & Z6 & "BT", Y6 & "BT"))))
A7: 558 | B7: LOVE MILL | C7: 0 | E7: *LCL PIEDMONT SCH DR | F7: SIKES MILL | H7: 999.999 | I7: NIS | L7: 108397947 | M7: 46063 | N7: 26 | O7: 1 | P7: 8 | Q7: 1 | R7: O | S7: =IFERROR(VLOOKUP(N7,Index!$A$1:$B$26,2,FALSE),"") | T7: =AA7 | V7: =IFERROR(INDEX(DetailedFiche!Q:Q,MATCH(L7,DetailedFiche!J:J,0)),"") | W7: =IFERROR(INDEX(DetailedFiche!R:R,MATCH(L7,DetailedFiche!J:J,0)),"") | Y7: =IFERROR(IF(AND(INDEX('Initial Study'!K:K, MATCH(L7, 'Initial Study'!B:B, 0)+1)<>0,INDEX('Initial Study'!K:K, MATCH(L7, 'Initial Study'!B:B, 0)+1)<>""),INDEX('Initial Study'!K:K, MATCH(L7, 'Initial Study'!B:B, 0)+1),""),"") | Z7: =IFERROR(IF(AND(INDEX('Initial Study'!K:K, MATCH(L7, 'Initial Study'!B:B, 0)+2)<>0,INDEX('Initial Study'!K:K, MATCH(L7, 'Initial Study'!B:B, 0)+2)<>"",NOT(ISNUMBER(INDEX('Initial Study'!K:K, MATCH(L7, 'Initial Study'!B:B, 0)+2)))),INDEX('Initial Study'!K:K, MATCH(L7, 'Initial Study'!B:B, 0)+2),"-"),"-") | AA7: =IF(S7="RE", Y7 & "BT/" & IF(Z7 <> "-", Z7 & "BT", ""), IF(OR(S7="LTDR", S7="LTSR"), Y7 & "BL" & IF(Z7 <> "-", "/" & Z7 & "BT", ""), IF(OR(S7="RTDR", S7="RTSR"), Y7 & "BR" & IF(Z7 <> "-", "/" & Z7 & "BT", ""), IF(Z7 <> "-", Y7 & "BT/" & Z7 & "BT", Y7 & "BT"))))
A8: 558 | B8: SIKES MILL | C8: 0.14 | D8: N | E8: *LCL PIEDMONT SCH DR | F8: HAIGLER BAUCOM | H8: 999.999 | I8: NIS | L8: 108319024 | M8: 45986 | N8: 24 | O8: 1 | P8: 4 | Q8: 1 | R8: B | S8: =IFERROR(VLOOKUP(N8,Index!$A$1:$B$26,2,FALSE),"") | T8: =AA8 | V8: =IFERROR(INDEX(DetailedFiche!Q:Q,MATCH(L8,DetailedFiche!J:J,0)),"") | W8: =IFERROR(INDEX(DetailedFiche!R:R,MATCH(L8,DetailedFiche!J:J,0)),"") | Y8: =IFERROR(IF(AND(INDEX('Initial Study'!K:K, MATCH(L8, 'Initial Study'!B:B, 0)+1)<>0,INDEX('Initial Study'!K:K, MATCH(L8, 'Initial Study'!B:B, 0)+1)<>""),INDEX('Initial Study'!K:K, MATCH(L8, 'Initial Study'!B:B, 0)+1),""),"") | Z8: =IFERROR(IF(AND(INDEX('Initial Study'!K:K, MATCH(L8, 'Initial Study'!B:B, 0)+2)<>0,INDEX('Initial Study'!K:K, MATCH(L8, 'Initial Study'!B:B, 0)+2)<>"",NOT(ISNUMBER(INDEX('Initial Study'!K:K, MATCH(L8, 'Initial Study'!B:B, 0)+2)))),INDEX('Initial Study'!K:K, MATCH(L8, 'Initial Study'!B:B, 0)+2),"-"),"-") | AA8: =IF(S8="RE", Y8 & "BT/" & IF(Z8 <> "-", Z8 & "BT", ""), IF(OR(S8="LTDR", S8="LTSR"), Y8 & "BL" & IF(Z8 <> "-", "/" & Z8 & "BT", ""), IF(OR(S8="RTDR", S8="RTSR"), Y8 & "BR" & IF(Z8 <> "-", "/" & Z8 & "BT", ""), IF(Z8 <> "-", Y8 & "BT/" & Z8 & "BT", Y8 & "BT"))))
A9: 558 | B9: SIKES MILL | C9: 0.038 | D9: N | E9: *LCL PIEDMONT SCH RD | F9: HAIGLER BAUCOM | H9: 999.999 | I9: NIS | L9: 107926331 | M9: 45611 | N9: 24 | O9: 1 | P9: 4 | Q9: 1 | R9: O | S9: =IFERROR(VLOOKUP(N9,Index!$A$1:$B$26,2,FALSE),"") | T9: =AA9 | V9: =IFERROR(INDEX(DetailedFiche!Q:Q,MATCH(L9,DetailedFiche!J:J,0)),"") | W9: =IFERROR(INDEX(DetailedFiche!R:R,MATCH(L9,DetailedFiche!J:J,0)),"") | Y9: =IFERROR(IF(AND(INDEX('Initial Study'!K:K, MATCH(L9, 'Initial Study'!B:B, 0)+1)<>0,INDEX('Initial Study'!K:K, MATCH(L9, 'Initial Study'!B:B, 0)+1)<>""),INDEX('Initial Study'!K:K, MATCH(L9, 'Initial Study'!B:B, 0)+1),""),"") | Z9: =IFERROR(IF(AND(INDEX('Initial Study'!K:K, MATCH(L9, 'Initial Study'!B:B, 0)+2)<>0,INDEX('Initial Study'!K:K, MATCH(L9, 'Initial Study'!B:B, 0)+2)<>"",NOT(ISNUMBER(INDEX('Initial Study'!K:K, MATCH(L9, 'Initial Study'!B:B, 0)+2)))),INDEX('Initial Study'!K:K, MATCH(L9, 'Initial Study'!B:B, 0)+2),"-"),"-") | AA9: =IF(S9="RE", Y9 & "BT/" & IF(Z9 <> "-", Z9 & "BT", ""), IF(OR(S9="LTDR", S9="LTSR"), Y9 & "BL" & IF(Z9 <> "-", "/" & Z9 & "BT", ""), IF(OR(S9="RTDR", S9="RTSR"), Y9 & "BR" & IF(Z9 <> "-", "/" & Z9 & "BT", ""), IF(Z9 <> "-", Y9 & "BT/" & Z9 & "BT", Y9 & "BT"))))
A10: 558 | B10: LOVE MILL | C10: 0.072 | D10: N | E10: *LCL PURSER RUSHING RD | F10: HAIGLER BAUCOM | H10: 999.999 | I10: NIS | L10: 107756918 | M10: 45463 | N10: 23 | O10: 1 | P10: 5 | Q10: 3 | R10: O | S10: =IFERROR(VLOOKUP(N10,Index!$A$1:$B$26,2,FALSE),"") | T10: =AA10 | V10: =IFERROR(INDEX(DetailedFiche!Q:Q,MATCH(L10,DetailedFiche!J:J,0)),"") | W10: =IFERROR(INDEX(DetailedFiche!R:R,MATCH(L10,DetailedFiche!J:J,0)),"") | Y10: =IFERROR(IF(AND(INDEX('Initial Study'!K:K, MATCH(L10, 'Initial Study'!B:B, 0)+1)<>0,INDEX('Initial Study'!K:K, MATCH(L10, 'Initial Study'!B:B, 0)+1)<>""),INDEX('Initial Study'!K:K, MATCH(L10, 'Initial Study'!B:B, 0)+1),""),"") | Z10: =IFERROR(IF(AND(INDEX('Initial Study'!K:K, MATCH(L10, 'Initial Study'!B:B, 0)+2)<>0,INDEX('Initial Study'!K:K, MATCH(L10, 'Initial Study'!B:B, 0)+2)<>"",NOT(ISNUMBER(INDEX('Initial Study'!K:K, MATCH(L10, 'Initial Study'!B:B, 0)+2)))),INDEX('Initial Study'!K:K, MATCH(L10, 'Initial Study'!B:B, 0)+2),"-"),"-") | AA10: =IF(S10="RE", Y10 & "BT/" & IF(Z10 <> "-", Z10 & "BT", ""), IF(OR(S10="LTDR", S10="LTSR"), Y10 & "BL" & IF(Z10 <> "-", "/" & Z10 & "BT", ""), IF(OR(S10="RTDR", S10="RTSR"), Y10 & "BR" & IF(Z10 <> "-", "/" & Z10 & "BT", ""), IF(Z10 <> "-", Y10 & "BT/" & Z10 & "BT", Y10 & "BT"))))
A11: 558 | B11: LOVE MILL | C11: 0.25 | D11: N | E11: *LCL PURSER RUSHING RD | F11: HAIGLER BAUCOM | H11: 999.999 | I11: NIS | L11: 108479327 | M11: 46140 | N11: 17 | O11: 1 | P11: 0 | Q11: 5 | R11: O | S11: =IFERROR(VLOOKUP(N11,Index!$A$1:$B$26,2,FALSE),"") | T11: =AA11 | V11: =IFERROR(INDEX(DetailedFiche!Q:Q,MATCH(L11,DetailedFiche!J:J,0)),"") | W11: =IFERROR(INDEX(DetailedFiche!R:R,MATCH(L11,DetailedFiche!J:J,0)),"") | Y11: =IFERROR(IF(AND(INDEX('Initial Study'!K:K, MATCH(L11, 'Initial Study'!B:B, 0)+1)<>0,INDEX('Initial Study'!K:K, MATCH(L11, 'Initial Study'!B:B, 0)+1)<>""),INDEX('Initial Study'!K:K, MATCH(L11, 'Initial Study'!B:B, 0)+1),""),"") | Z11: =IFERROR(IF(AND(INDEX('Initial Study'!K:K, MATCH(L11, 'Initial Study'!B:B, 0)+2)<>0,INDEX('Initial Study'!K:K, MATCH(L11, 'Initial Study'!B:B, 0)+2)<>"",NOT(ISNUMBER(INDEX('Initial Study'!K:K, MATCH(L11, 'Initial Study'!B:B, 0)+2)))),INDEX('Initial Study'!K:K, MATCH(L11, 'Initial Study'!B:B, 0)+2),"-"),"-") | AA11: =IF(S11="RE", Y11 & "BT/" & IF(Z11 <> "-", Z11 & "BT", ""), IF(OR(S11="LTDR", S11="LTSR"), Y11 & "BL" & IF(Z11 <> "-", "/" & Z11 & "BT", ""), IF(OR(S11="RTDR", S11="RTSR"), Y11 & "BR" & IF(Z11 <> "-", "/" & Z11 & "BT", ""), IF(Z11 <> "-", Y11 & "BT/" & Z11 & "BT", Y11 & "BT"))))
A12: 558 | B12: PIEDMONT SCHOOL | C12: 0.019 | D12: N | E12: LOVE MILL | F12: DEAD END | H12: 999.999 | I12: NIS | L12: 107528155 | M12: 45244 | N12: 21 | O12: 1 | P12: 12 | Q12: 1 | R12: O | S12: =IFERROR(VLOOKUP(N12,Index!$A$1:$B$26,2,FALSE),"") | T12: =AA12 | V12: =IFERROR(INDEX(DetailedFiche!Q:Q,MATCH(L12,DetailedFiche!J:J,0)),"") | W12: =IFERROR(INDEX(DetailedFiche!R:R,MATCH(L12,DetailedFiche!J:J,0)),"") | Y12: =IFERROR(IF(AND(INDEX('Initial Study'!K:K, MATCH(L12, 'Initial Study'!B:B, 0)+1)<>0,INDEX('Initial Study'!K:K, MATCH(L12, 'Initial Study'!B:B, 0)+1)<>""),INDEX('Initial Study'!K:K, MATCH(L12, 'Initial Study'!B:B, 0)+1),""),"") | Z12: =IFERROR(IF(AND(INDEX('Initial Study'!K:K, MATCH(L12, 'Initial Study'!B:B, 0)+2)<>0,INDEX('Initial Study'!K:K, MATCH(L12, 'Initial Study'!B:B, 0)+2)<>"",NOT(ISNUMBER(INDEX('Initial Study'!K:K, MATCH(L12, 'Initial Study'!B:B, 0)+2)))),INDEX('Initial Study'!K:K, MATCH(L12, 'Initial Study'!B:B, 0)+2),"-"),"-") | AA12: =IF(S12="RE", Y12 & "BT/" & IF(Z12 <> "-", Z12 & "BT", ""), IF(OR(S12="LTDR", S12="LTSR"), Y12 & "BL" & IF(Z12 <> "-", "/" & Z12 & "BT", ""), IF(OR(S12="RTDR", S12="RTSR"), Y12 & "BR" & IF(Z12 <> "-", "/" & Z12 & "BT", ""), IF(Z12 <> "-", Y12 & "BT/" & Z12 & "BT", Y12 & "BT"))))
A13: 558 | B13: TOM BOYD | C13: 0 | E13: OLD CAMDEN | F13: SIKES MILL | H13: 999.999 | I13: NIS | L13: 105415127 | M13: 43171 | N13: 30 | O13: 2 | P13: 7 | Q13: 1 | R13: C | S13: =IFERROR(VLOOKUP(N13,Index!$A$1:$B$26,2,FALSE),"") | T13: =AA13 | V13: =IFERROR(INDEX(DetailedFiche!Q:Q,MATCH(L13,DetailedFiche!J:J,0)),"") | W13: =IFERROR(INDEX(DetailedFiche!R:R,MATCH(L13,DetailedFiche!J:J,0)),"") | Y13: =IFERROR(IF(AND(INDEX('Initial Study'!K:K, MATCH(L13, 'Initial Study'!B:B, 0)+1)<>0,INDEX('Initial Study'!K:K, MATCH(L13, 'Initial Study'!B:B, 0)+1)<>""),INDEX('Initial Study'!K:K, MATCH(L13, 'Initial Study'!B:B, 0)+1),""),"") | Z13: =IFERROR(IF(AND(INDEX('Initial Study'!K:K, MATCH(L13, 'Initial Study'!B:B, 0)+2)<>0,INDEX('Initial Study'!K:K, MATCH(L13, 'Initial Study'!B:B, 0)+2)<>"",NOT(ISNUMBER(INDEX('Initial Study'!K:K, MATCH(L13, 'Initial Study'!B:B, 0)+2)))),INDEX('Initial Study'!K:K, MATCH(L13, 'Initial Study'!B:B, 0)+2),"-"),"-") | AA13: =IF(S13="RE", Y13 & "BT/" & IF(Z13 <> "-", Z13 & "BT", ""), IF(OR(S13="LTDR", S13="LTSR"), Y13 & "BL" & IF(Z13 <> "-", "/" & Z13 & "BT", ""), IF(OR(S13="RTDR", S13="RTSR"), Y13 & "BR" & IF(Z13 <> "-", "/" & Z13 & "BT", ""), IF(Z13 <> "-", Y13 & "BT/" & Z13 & "BT", Y13 & "BT"))))
A14: 558 | B14: TOM BOYD | C14: 0.16 | D14: NE | E14: OLD CAMDEN | F14: *LCL LATHAM WOODS DR | H14: 999.999 | I14: NIS | L14: 106910957 | M14: 44655 | N14: 17 | O14: 1 | P14: 0 | Q14: 5 | R14: O | S14: =IFERROR(VLOOKUP(N14,Index!$A$1:$B$26,2,FALSE),"") | T14: =AA14 | V14: =IFERROR(INDEX(DetailedFiche!Q:Q,MATCH(L14,DetailedFiche!J:J,0)),"") | W14: =IFERROR(INDEX(DetailedFiche!R:R,MATCH(L14,DetailedFiche!J:J,0)),"") | Y14: =IFERROR(IF(AND(INDEX('Initial Study'!K:K, MATCH(L14, 'Initial Study'!B:B, 0)+1)<>0,INDEX('Initial Study'!K:K, MATCH(L14, 'Initial Study'!B:B, 0)+1)<>""),INDEX('Initial Study'!K:K, MATCH(L14, 'Initial Study'!B:B, 0)+1),""),"") | Z14: =IFERROR(IF(AND(INDEX('Initial Study'!K:K, MATCH(L14, 'Initial Study'!B:B, 0)+2)<>0,INDEX('Initial Study'!K:K, MATCH(L14, 'Initial Study'!B:B, 0)+2)<>"",NOT(ISNUMBER(INDEX('Initial Study'!K:K, MATCH(L14, 'Initial Study'!B:B, 0)+2)))),INDEX('Initial Study'!K:K, MATCH(L14, 'Initial Study'!B:B, 0)+2),"-"),"-") | AA14: =IF(S14="RE", Y14 & "BT/" & IF(Z14 <> "-", Z14 & "BT", ""), IF(OR(S14="LTDR", S14="LTSR"), Y14 & "BL" & IF(Z14 <> "-", "/" & Z14 & "BT", ""), IF(OR(S14="RTDR", S14="RTSR"), Y14 & "BR" & IF(Z14 <> "-", "/" & Z14 & "BT", ""), IF(Z14 <> "-", Y14 & "BT/" & Z14 & "BT", Y14 & "BT"))))
A15: 558 | B15: TOM BOYD | C15: 0.36 | D15: E | E15: OLD CAMDEN | F15: SIKES MILL | H15: 999.999 | I15: NIS | L15: 108277405 | M15: 45954 | N15: 17 | O15: 1 | P15: 0 | Q15: 3 | R15: B | S15: =IFERROR(VLOOKUP(N15,Index!$A$1:$B$26,2,FALSE),"") | T15: =AA15 | V15: =IFERROR(INDEX(DetailedFiche!Q:Q,MATCH(L15,DetailedFiche!J:J,0)),"") | W15: =IFERROR(INDEX(DetailedFiche!R:R,MATCH(L15,DetailedFiche!J:J,0)),"") | Y15: =IFERROR(IF(AND(INDEX('Initial Study'!K:K, MATCH(L15, 'Initial Study'!B:B, 0)+1)<>0,INDEX('Initial Study'!K:K, MATCH(L15, 'Initial Study'!B:B, 0)+1)<>""),INDEX('Initial Study'!K:K, MATCH(L15, 'Initial Study'!B:B, 0)+1),""),"") | Z15: =IFERROR(IF(AND(INDEX('Initial Study'!K:K, MATCH(L15, 'Initial Study'!B:B, 0)+2)<>0,INDEX('Initial Study'!K:K, MATCH(L15, 'Initial Study'!B:B, 0)+2)<>"",NOT(ISNUMBER(INDEX('Initial Study'!K:K, MATCH(L15, 'Initial Study'!B:B, 0)+2)))),INDEX('Initial Study'!K:K, MATCH(L15, 'Initial Study'!B:B, 0)+2),"-"),"-") | AA15: =IF(S15="RE", Y15 & "BT/" & IF(Z15 <> "-", Z15 & "BT", ""), IF(OR(S15="LTDR", S15="LTSR"), Y15 & "BL" & IF(Z15 <> "-", "/" & Z15 & "BT", ""), IF(OR(S15="RTDR", S15="RTSR"), Y15 & "BR" & IF(Z15 <> "-", "/" & Z15 & "BT", ""), IF(Z15 <> "-", Y15 & "BT/" & Z15 & "BT", Y15 & "BT"))))
A16: 558 | B16: HAIGLER BAUCOM | C16: 0.005 | D16: E | E16: SIKES MILL | F16: LOVE MILL | H16: 999.999 | I16: NIS | L16: 107442545 | M16: 45168 | N16: 21 | O16: 2 | P16: 8 | Q16: 1 | R16: O | S16: =IFERROR(VLOOKUP(N16,Index!$A$1:$B$26,2,FALSE),"") | T16: =AA16 | V16: =IFERROR(INDEX(DetailedFiche!Q:Q,MATCH(L16,DetailedFiche!J:J,0)),"") | W16: =IFERROR(INDEX(DetailedFiche!R:R,MATCH(L16,DetailedFiche!J:J,0)),"") | Y16: =IFERROR(IF(AND(INDEX('Initial Study'!K:K, MATCH(L16, 'Initial Study'!B:B, 0)+1)<>0,INDEX('Initial Study'!K:K, MATCH(L16, 'Initial Study'!B:B, 0)+1)<>""),INDEX('Initial Study'!K:K, MATCH(L16, 'Initial Study'!B:B, 0)+1),""),"") | Z16: =IFERROR(IF(AND(INDEX('Initial Study'!K:K, MATCH(L16, 'Initial Study'!B:B, 0)+2)<>0,INDEX('Initial Study'!K:K, MATCH(L16, 'Initial Study'!B:B, 0)+2)<>"",NOT(ISNUMBER(INDEX('Initial Study'!K:K, MATCH(L16, 'Initial Study'!B:B, 0)+2)))),INDEX('Initial Study'!K:K, MATCH(L16, 'Initial Study'!B:B, 0)+2),"-"),"-") | AA16: =IF(S16="RE", Y16 & "BT/" & IF(Z16 <> "-", Z16 & "BT", ""), IF(OR(S16="LTDR", S16="LTSR"), Y16 & "BL" & IF(Z16 <> "-", "/" & Z16 & "BT", ""), IF(OR(S16="RTDR", S16="RTSR"), Y16 & "BR" & IF(Z16 <> "-", "/" & Z16 & "BT", ""), IF(Z16 <> "-", Y16 & "BT/" & Z16 & "BT", Y16 & "BT"))))
A17: 637 | B17: PVA 6609 SIKES MILL RD | C17: 0.028 | D17: W | E17: SIKES MILL | H17: 999.999 | I17: NIS | L17: 106254686 | M17: 44001 | N17: 31 | O17: 1 | P17: 4 | Q17: 1 | R17: O | S17: =IFERROR(VLOOKUP(N17,Index!$A$1:$B$26,2,FALSE),"") | T17: =AA17 | V17: =IFERROR(INDEX(DetailedFiche!Q:Q,MATCH(L17,DetailedFiche!J:J,0)),"") | W17: =IFERROR(INDEX(DetailedFiche!R:R,MATCH(L17,DetailedFiche!J:J,0)),"") | Y17: =IFERROR(IF(AND(INDEX('Initial Study'!K:K, MATCH(L17, 'Initial Study'!B:B, 0)+1)<>0,INDEX('Initial Study'!K:K, MATCH(L17, 'Initial Study'!B:B, 0)+1)<>""),INDEX('Initial Study'!K:K, MATCH(L17, 'Initial Study'!B:B, 0)+1),""),"") | Z17: =IFERROR(IF(AND(INDEX('Initial Study'!K:K, MATCH(L17, 'Initial Study'!B:B, 0)+2)<>0,INDEX('Initial Study'!K:K, MATCH(L17, 'Initial Study'!B:B, 0)+2)<>"",NOT(ISNUMBER(INDEX('Initial Study'!K:K, MATCH(L17, 'Initial Study'!B:B, 0)+2)))),INDEX('Initial Study'!K:K, MATCH(L17, 'Initial Study'!B:B, 0)+2),"-"),"-") | AA17: =IF(S17="RE", Y17 & "BT/" & IF(Z17 <> "-", Z17 & "BT", ""), IF(OR(S17="LTDR", S17="LTSR"), Y17 & "BL" & IF(Z17 <> "-", "/" & Z17 & "BT", ""), IF(OR(S17="RTDR", S17="RTSR"), Y17 & "BR" & IF(Z17 <> "-", "/" & Z17 & "BT", ""), IF(Z17 <> "-", Y17 & "BT/" & Z17 & "BT", Y17 & "BT"))))
A18: 558 | B18: PVA MARATHON | C18: 0.019 | D18: W | E18: SIKES MILL | H18: 999.999 | I18: NIS | L18: 106584227 | M18: 44341 | N18: 31 | O18: 1 | P18: 4 | Q18: 1 | R18: O | S18: =IFERROR(VLOOKUP(N18,Index!$A$1:$B$26,2,FALSE),"") | T18: =AA18 | V18: =IFERROR(INDEX(DetailedFiche!Q:Q,MATCH(L18,DetailedFiche!J:J,0)),"") | W18: =IFERROR(INDEX(DetailedFiche!R:R,MATCH(L18,DetailedFiche!J:J,0)),"") | Y18: =IFERROR(IF(AND(INDEX('Initial Study'!K:K, MATCH(L18, 'Initial Study'!B:B, 0)+1)<>0,INDEX('Initial Study'!K:K, MATCH(L18, 'Initial Study'!B:B, 0)+1)<>""),INDEX('Initial Study'!K:K, MATCH(L18, 'Initial Study'!B:B, 0)+1),""),"") | Z18: =IFERROR(IF(AND(INDEX('Initial Study'!K:K, MATCH(L18, 'Initial Study'!B:B, 0)+2)<>0,INDEX('Initial Study'!K:K, MATCH(L18, 'Initial Study'!B:B, 0)+2)<>"",NOT(ISNUMBER(INDEX('Initial Study'!K:K, MATCH(L18, 'Initial Study'!B:B, 0)+2)))),INDEX('Initial Study'!K:K, MATCH(L18, 'Initial Study'!B:B, 0)+2),"-"),"-") | AA18: =IF(S18="RE", Y18 & "BT/" & IF(Z18 <> "-", Z18 & "BT", ""), IF(OR(S18="LTDR", S18="LTSR"), Y18 & "BL" & IF(Z18 <> "-", "/" & Z18 & "BT", ""), IF(OR(S18="RTDR", S18="RTSR"), Y18 & "BR" & IF(Z18 <> "-", "/" & Z18 & "BT", ""), IF(Z18 <> "-", Y18 & "BT/" & Z18 & "BT", Y18 & "BT"))))
A19: 558 | B19: PVA MARATHON | C19: 0.019 | D19: W | E19: SIKES MILL | H19: 999.999 | I19: NIS | L19: 106303935 | M19: 44055 | N19: 20 | O19: 1 | P19: 4 | Q19: 1 | R19: O | S19: =IFERROR(VLOOKUP(N19,Index!$A$1:$B$26,2,FALSE),"") | T19: =AA19 | V19: =IFERROR(INDEX(DetailedFiche!Q:Q,MATCH(L19,DetailedFiche!J:J,0)),"") | W19: =IFERROR(INDEX(DetailedFiche!R:R,MATCH(L19,DetailedFiche!J:J,0)),"") | Y19: =IFERROR(IF(AND(INDEX('Initial Study'!K:K, MATCH(L19, 'Initial Study'!B:B, 0)+1)<>0,INDEX('Initial Study'!K:K, MATCH(L19, 'Initial Study'!B:B, 0)+1)<>""),INDEX('Initial Study'!K:K, MATCH(L19, 'Initial Study'!B:B, 0)+1),""),"") | Z19: =IFERROR(IF(AND(INDEX('Initial Study'!K:K, MATCH(L19, 'Initial Study'!B:B, 0)+2)<>0,INDEX('Initial Study'!K:K, MATCH(L19, 'Initial Study'!B:B, 0)+2)<>"",NOT(ISNUMBER(INDEX('Initial Study'!K:K, MATCH(L19, 'Initial Study'!B:B, 0)+2)))),INDEX('Initial Study'!K:K, MATCH(L19, 'Initial Study'!B:B, 0)+2),"-"),"-") | AA19: =IF(S19="RE", Y19 & "BT/" & IF(Z19 <> "-", Z19 & "BT", ""), IF(OR(S19="LTDR", S19="LTSR"), Y19 & "BL" & IF(Z19 <> "-", "/" & Z19 & "BT", ""), IF(OR(S19="RTDR", S19="RTSR"), Y19 & "BR" & IF(Z19 <> "-", "/" & Z19 & "BT", ""), IF(Z19 <> "-", Y19 & "BT/" & Z19 & "BT", Y19 & "BT"))))
A20: 558 | B20: PVA PIEDMONT HS | C20: 0.028 | D20: E | E20: SIKES MILL | H20: 999.999 | I20: NIS | L20: 107711938 | M20: 45419 | N20: 23 | O20: 1 | P20: 4 | Q20: 1 | R20: O | S20: =IFERROR(VLOOKUP(N20,Index!$A$1:$B$26,2,FALSE),"") | T20: =AA20 | V20: =IFERROR(INDEX(DetailedFiche!Q:Q,MATCH(L20,DetailedFiche!J:J,0)),"") | W20: =IFERROR(INDEX(DetailedFiche!R:R,MATCH(L20,DetailedFiche!J:J,0)),"") | Y20: =IFERROR(IF(AND(INDEX('Initial Study'!K:K, MATCH(L20, 'Initial Study'!B:B, 0)+1)<>0,INDEX('Initial Study'!K:K, MATCH(L20, 'Initial Study'!B:B, 0)+1)<>""),INDEX('Initial Study'!K:K, MATCH(L20, 'Initial Study'!B:B, 0)+1),""),"") | Z20: =IFERROR(IF(AND(INDEX('Initial Study'!K:K, MATCH(L20, 'Initial Study'!B:B, 0)+2)<>0,INDEX('Initial Study'!K:K, MATCH(L20, 'Initial Study'!B:B, 0)+2)<>"",NOT(ISNUMBER(INDEX('Initial Study'!K:K, MATCH(L20, 'Initial Study'!B:B, 0)+2)))),INDEX('Initial Study'!K:K, MATCH(L20, 'Initial Study'!B:B, 0)+2),"-"),"-") | AA20: =IF(S20="RE", Y20 & "BT/" & IF(Z20 <> "-", Z20 & "BT", ""), IF(OR(S20="LTDR", S20="LTSR"), Y20 & "BL" & IF(Z20 <> "-", "/" & Z20 & "BT", ""), IF(OR(S20="RTDR", S20="RTSR"), Y20 & "BR" & IF(Z20 <> "-", "/" & Z20 & "BT", ""), IF(Z20 <> "-", Y20 & "BT/" & Z20 & "BT", Y20 & "BT"))))
A21: 558 | B21: PVA PIEDMONT MIDDLE SCHOOL | C21: 0.001 | D21: E | E21: SIKES MILL | H21: 999.999 | I21: NIS | L21: 108247372 | M21: 45930 | N21: 21 | O21: 2 | P21: 4 | Q21: 1 | R21: O | S21: =IFERROR(VLOOKUP(N21,Index!$A$1:$B$26,2,FALSE),"") | T21: =AA21 | V21: =IFERROR(INDEX(DetailedFiche!Q:Q,MATCH(L21,DetailedFiche!J:J,0)),"") | W21: =IFERROR(INDEX(DetailedFiche!R:R,MATCH(L21,DetailedFiche!J:J,0)),"") | Y21: =IFERROR(IF(AND(INDEX('Initial Study'!K:K, MATCH(L21, 'Initial Study'!B:B, 0)+1)<>0,INDEX('Initial Study'!K:K, MATCH(L21, 'Initial Study'!B:B, 0)+1)<>""),INDEX('Initial Study'!K:K, MATCH(L21, 'Initial Study'!B:B, 0)+1),""),"") | Z21: =IFERROR(IF(AND(INDEX('Initial Study'!K:K, MATCH(L21, 'Initial Study'!B:B, 0)+2)<>0,INDEX('Initial Study'!K:K, MATCH(L21, 'Initial Study'!B:B, 0)+2)<>"",NOT(ISNUMBER(INDEX('Initial Study'!K:K, MATCH(L21, 'Initial Study'!B:B, 0)+2)))),INDEX('Initial Study'!K:K, MATCH(L21, 'Initial Study'!B:B, 0)+2),"-"),"-") | AA21: =IF(S21="RE", Y21 & "BT/" & IF(Z21 <> "-", Z21 & "BT", ""), IF(OR(S21="LTDR", S21="LTSR"), Y21 & "BL" & IF(Z21 <> "-", "/" & Z21 & "BT", ""), IF(OR(S21="RTDR", S21="RTSR"), Y21 & "BR" & IF(Z21 <> "-", "/" & Z21 & "BT", ""), IF(Z21 <> "-", Y21 & "BT/" & Z21 & "BT", Y21 & "BT"))))
A22: 558 | B22: PVA PIEDMONT MIDDLE SCHOOL | C22: 0.019 | D22: E | E22: SIKES MILL | H22: 999.999 | I22: NIS | L22: 107683218 | M22: 45393 | N22: 31 | O22: 2 | P22: 4 | Q22: 1 | R22: O | S22: =IFERROR(VLOOKUP(N22,Index!$A$1:$B$26,2,FALSE),"") | T22: =AA22 | V22: =IFERROR(INDEX(DetailedFiche!Q:Q,MATCH(L22,DetailedFiche!J:J,0)),"") | W22: =IFERROR(INDEX(DetailedFiche!R:R,MATCH(L22,DetailedFiche!J:J,0)),"") | Y22: =IFERROR(IF(AND(INDEX('Initial Study'!K:K, MATCH(L22, 'Initial Study'!B:B, 0)+1)<>0,INDEX('Initial Study'!K:K, MATCH(L22, 'Initial Study'!B:B, 0)+1)<>""),INDEX('Initial Study'!K:K, MATCH(L22, 'Initial Study'!B:B, 0)+1),""),"") | Z22: =IFERROR(IF(AND(INDEX('Initial Study'!K:K, MATCH(L22, 'Initial Study'!B:B, 0)+2)<>0,INDEX('Initial Study'!K:K, MATCH(L22, 'Initial Study'!B:B, 0)+2)<>"",NOT(ISNUMBER(INDEX('Initial Study'!K:K, MATCH(L22, 'Initial Study'!B:B, 0)+2)))),INDEX('Initial Study'!K:K, MATCH(L22, 'Initial Study'!B:B, 0)+2),"-"),"-") | AA22: =IF(S22="RE", Y22 & "BT/" & IF(Z22 <> "-", Z22 & "BT", ""), IF(OR(S22="LTDR", S22="LTSR"), Y22 & "BL" & IF(Z22 <> "-", "/" & Z22 & "BT", ""), IF(OR(S22="RTDR", S22="RTSR"), Y22 & "BR" & IF(Z22 <> "-", "/" & Z22 & "BT", ""), IF(Z22 <> "-", Y22 & "BT/" & Z22 & "BT", Y22 & "BT"))))
A23: 558 | B23: TOM BOYD | C23: 0.29 | D23: SE | E23: SIKES MILL | F23: OLD CAMDEN | H23: 999.999 | I23: NIS | L23: 107906736 | M23: 45593 | N23: 17 | O23: 1 | P23: 0 | Q23: 5 | R23: O | S23: =IFERROR(VLOOKUP(N23,Index!$A$1:$B$26,2,FALSE),"") | T23: =AA23 | V23: =IFERROR(INDEX(DetailedFiche!Q:Q,MATCH(L23,DetailedFiche!J:J,0)),"") | W23: =IFERROR(INDEX(DetailedFiche!R:R,MATCH(L23,DetailedFiche!J:J,0)),"") | Y23: =IFERROR(IF(AND(INDEX('Initial Study'!K:K, MATCH(L23, 'Initial Study'!B:B, 0)+1)<>0,INDEX('Initial Study'!K:K, MATCH(L23, 'Initial Study'!B:B, 0)+1)<>""),INDEX('Initial Study'!K:K, MATCH(L23, 'Initial Study'!B:B, 0)+1),""),"") | Z23: =IFERROR(IF(AND(INDEX('Initial Study'!K:K, MATCH(L23, 'Initial Study'!B:B, 0)+2)<>0,INDEX('Initial Study'!K:K, MATCH(L23, 'Initial Study'!B:B, 0)+2)<>"",NOT(ISNUMBER(INDEX('Initial Study'!K:K, MATCH(L23, 'Initial Study'!B:B, 0)+2)))),INDEX('Initial Study'!K:K, MATCH(L23, 'Initial Study'!B:B, 0)+2),"-"),"-") | AA23: =IF(S23="RE", Y23 & "BT/" & IF(Z23 <> "-", Z23 & "BT", ""), IF(OR(S23="LTDR", S23="LTSR"), Y23 & "BL" & IF(Z23 <> "-", "/" & Z23 & "BT", ""), IF(OR(S23="RTDR", S23="RTSR"), Y23 & "BR" & IF(Z23 <> "-", "/" & Z23 & "BT", ""), IF(Z23 <> "-", Y23 & "BT/" & Z23 & "BT", Y23 & "BT"))))
A24: 558 | B24: *LCL CAR WASH PVA | C24: 0.001 | D24: E | E24: SR 1001 | F24: DEAD END | H24: 999.999 | I24: NIS | L24: 105722912 | M24: 43452 | N24: 31 | O24: 1 | P24: 0 | Q24: 1 | R24: O | S24: =IFERROR(VLOOKUP(N24,Index!$A$1:$B$26,2,FALSE),"") | T24: =AA24 | V24: =IFERROR(INDEX(DetailedFiche!Q:Q,MATCH(L24,DetailedFiche!J:J,0)),"") | W24: =IFERROR(INDEX(DetailedFiche!R:R,MATCH(L24,DetailedFiche!J:J,0)),"") | Y24: =IFERROR(IF(AND(INDEX('Initial Study'!K:K, MATCH(L24, 'Initial Study'!B:B, 0)+1)<>0,INDEX('Initial Study'!K:K, MATCH(L24, 'Initial Study'!B:B, 0)+1)<>""),INDEX('Initial Study'!K:K, MATCH(L24, 'Initial Study'!B:B, 0)+1),""),"") | Z24: =IFERROR(IF(AND(INDEX('Initial Study'!K:K, MATCH(L24, 'Initial Study'!B:B, 0)+2)<>0,INDEX('Initial Study'!K:K, MATCH(L24, 'Initial Study'!B:B, 0)+2)<>"",NOT(ISNUMBER(INDEX('Initial Study'!K:K, MATCH(L24, 'Initial Study'!B:B, 0)+2)))),INDEX('Initial Study'!K:K, MATCH(L24, 'Initial Study'!B:B, 0)+2),"-"),"-") | AA24: =IF(S24="RE", Y24 & "BT/" & IF(Z24 <> "-", Z24 & "BT", ""), IF(OR(S24="LTDR", S24="LTSR"), Y24 & "BL" & IF(Z24 <> "-", "/" & Z24 & "BT", ""), IF(OR(S24="RTDR", S24="RTSR"), Y24 & "BR" & IF(Z24 <> "-", "/" & Z24 & "BT", ""), IF(Z24 <> "-", Y24 & "BT/" & Z24 & "BT", Y24 & "BT"))))
A25: 558 | B25: PIEDMONT SCHOOL | C25: 0.005 | D25: W | E25: SR 1001 | F25: *LCL - | H25: 999.999 | I25: NIS | L25: 105971602 | M25: 43703 | N25: 24 | O25: 1 | P25: 4 | Q25: 1 | R25: O | S25: =IFERROR(VLOOKUP(N25,Index!$A$1:$B$26,2,FALSE),"") | T25: =AA25 | V25: =IFERROR(INDEX(DetailedFiche!Q:Q,MATCH(L25,DetailedFiche!J:J,0)),"") | W25: =IFERROR(INDEX(DetailedFiche!R:R,MATCH(L25,DetailedFiche!J:J,0)),"") | Y25: =IFERROR(IF(AND(INDEX('Initial Study'!K:K, MATCH(L25, 'Initial Study'!B:B, 0)+1)<>0,INDEX('Initial Study'!K:K, MATCH(L25, 'Initial Study'!B:B, 0)+1)<>""),INDEX('Initial Study'!K:K, MATCH(L25, 'Initial Study'!B:B, 0)+1),""),"") | Z25: =IFERROR(IF(AND(INDEX('Initial Study'!K:K, MATCH(L25, 'Initial Study'!B:B, 0)+2)<>0,INDEX('Initial Study'!K:K, MATCH(L25, 'Initial Study'!B:B, 0)+2)<>"",NOT(ISNUMBER(INDEX('Initial Study'!K:K, MATCH(L25, 'Initial Study'!B:B, 0)+2)))),INDEX('Initial Study'!K:K, MATCH(L25, 'Initial Study'!B:B, 0)+2),"-"),"-") | AA25: =IF(S25="RE", Y25 & "BT/" & IF(Z25 <> "-", Z25 & "BT", ""), IF(OR(S25="LTDR", S25="LTSR"), Y25 & "BL" & IF(Z25 <> "-", "/" & Z25 & "BT", ""), IF(OR(S25="RTDR", S25="RTSR"), Y25 & "BR" & IF(Z25 <> "-", "/" & Z25 & "BT", ""), IF(Z25 <> "-", Y25 & "BT/" & Z25 & "BT", Y25 & "BT"))))
A26: 558 | B26: PVA 2623 SIKES MILL RD | C26: 0.009 | D26: W | E26: SR 1001 | F26: SR 1618 | H26: 999.999 | I26: NIS | L26: 107250998 | M26: 44966 | N26: 20 | O26: 1 | P26: 4 | Q26: 1 | R26: O | S26: =IFERROR(VLOOKUP(N26,Index!$A$1:$B$26,2,FALSE),"") | T26: =AA26 | V26: =IFERROR(INDEX(DetailedFiche!Q:Q,MATCH(L26,DetailedFiche!J:J,0)),"") | W26: =IFERROR(INDEX(DetailedFiche!R:R,MATCH(L26,DetailedFiche!J:J,0)),"") | Y26: =IFERROR(IF(AND(INDEX('Initial Study'!K:K, MATCH(L26, 'Initial Study'!B:B, 0)+1)<>0,INDEX('Initial Study'!K:K, MATCH(L26, 'Initial Study'!B:B, 0)+1)<>""),INDEX('Initial Study'!K:K, MATCH(L26, 'Initial Study'!B:B, 0)+1),""),"") | Z26: =IFERROR(IF(AND(INDEX('Initial Study'!K:K, MATCH(L26, 'Initial Study'!B:B, 0)+2)<>0,INDEX('Initial Study'!K:K, MATCH(L26, 'Initial Study'!B:B, 0)+2)<>"",NOT(ISNUMBER(INDEX('Initial Study'!K:K, MATCH(L26, 'Initial Study'!B:B, 0)+2)))),INDEX('Initial Study'!K:K, MATCH(L26, 'Initial Study'!B:B, 0)+2),"-"),"-") | AA26: =IF(S26="RE", Y26 & "BT/" & IF(Z26 <> "-", Z26 & "BT", ""), IF(OR(S26="LTDR", S26="LTSR"), Y26 & "BL" & IF(Z26 <> "-", "/" & Z26 & "BT", ""), IF(OR(S26="RTDR", S26="RTSR"), Y26 & "BR" & IF(Z26 <> "-", "/" & Z26 & "BT", ""), IF(Z26 <> "-", Y26 & "BT/" & Z26 & "BT", Y26 & "BT"))))
A27: 0 | B27: PVA 3006 SIKES MILL RD | C27: 0.004 | D27: E | E27: SR 1001 | F27: DEAD END | H27: 999.999 | I27: NIS | L27: 105983673 | M27: 43711 | N27: 21 | O27: 1 | P27: 4 | Q27: 1 | R27: O | S27: =IFERROR(VLOOKUP(N27,Index!$A$1:$B$26,2,FALSE),"") | T27: =AA27 | V27: =IFERROR(INDEX(DetailedFiche!Q:Q,MATCH(L27,DetailedFiche!J:J,0)),"") | W27: =IFERROR(INDEX(DetailedFiche!R:R,MATCH(L27,DetailedFiche!J:J,0)),"") | Y27: =IFERROR(IF(AND(INDEX('Initial Study'!K:K, MATCH(L27, 'Initial Study'!B:B, 0)+1)<>0,INDEX('Initial Study'!K:K, MATCH(L27, 'Initial Study'!B:B, 0)+1)<>""),INDEX('Initial Study'!K:K, MATCH(L27, 'Initial Study'!B:B, 0)+1),""),"") | Z27: =IFERROR(IF(AND(INDEX('Initial Study'!K:K, MATCH(L27, 'Initial Study'!B:B, 0)+2)<>0,INDEX('Initial Study'!K:K, MATCH(L27, 'Initial Study'!B:B, 0)+2)<>"",NOT(ISNUMBER(INDEX('Initial Study'!K:K, MATCH(L27, 'Initial Study'!B:B, 0)+2)))),INDEX('Initial Study'!K:K, MATCH(L27, 'Initial Study'!B:B, 0)+2),"-"),"-") | AA27: =IF(S27="RE", Y27 & "BT/" & IF(Z27 <> "-", Z27 & "BT", ""), IF(OR(S27="LTDR", S27="LTSR"), Y27 & "BL" & IF(Z27 <> "-", "/" & Z27 & "BT", ""), IF(OR(S27="RTDR", S27="RTSR"), Y27 & "BR" & IF(Z27 <> "-", "/" & Z27 & "BT", ""), IF(Z27 <> "-", Y27 & "BT/" & Z27 & "BT", Y27 & "BT"))))
A28: 558 | B28: PVA 709 SIKES MILL RD | C28: 0.005 | D28: W | E28: SR 1001 | F28: DEAD END | H28: 999.999 | I28: NIS | L28: 107994713 | M28: 45674 | N28: 20 | O28: 1 | P28: 5 | Q28: 2 | S28: =IFERROR(VLOOKUP(N28,Index!$A$1:$B$26,2,FALSE),"") | T28: =AA28 | V28: =IFERROR(INDEX(DetailedFiche!Q:Q,MATCH(L28,DetailedFiche!J:J,0)),"") | W28: =IFERROR(INDEX(DetailedFiche!R:R,MATCH(L28,DetailedFiche!J:J,0)),"") | Y28: =IFERROR(IF(AND(INDEX('Initial Study'!K:K, MATCH(L28, 'Initial Study'!B:B, 0)+1)<>0,INDEX('Initial Study'!K:K, MATCH(L28, 'Initial Study'!B:B, 0)+1)<>""),INDEX('Initial Study'!K:K, MATCH(L28, 'Initial Study'!B:B, 0)+1),""),"") | Z28: =IFERROR(IF(AND(INDEX('Initial Study'!K:K, MATCH(L28, 'Initial Study'!B:B, 0)+2)<>0,INDEX('Initial Study'!K:K, MATCH(L28, 'Initial Study'!B:B, 0)+2)<>"",NOT(ISNUMBER(INDEX('Initial Study'!K:K, MATCH(L28, 'Initial Study'!B:B, 0)+2)))),INDEX('Initial Study'!K:K, MATCH(L28, 'Initial Study'!B:B, 0)+2),"-"),"-") | AA28: =IF(S28="RE", Y28 & "BT/" & IF(Z28 <> "-", Z28 & "BT", ""), IF(OR(S28="LTDR", S28="LTSR"), Y28 & "BL" & IF(Z28 <> "-", "/" & Z28 & "BT", ""), IF(OR(S28="RTDR", S28="RTSR"), Y28 & "BR" & IF(Z28 <> "-", "/" & Z28 & "BT", ""), IF(Z28 <> "-", Y28 & "BT/" & Z28 & "BT", Y28 & "BT"))))
A29: 558 | B29: PVA MARATHON | C29: 0.009 | D29: W | E29: SR 1001 | F29: SR 1618 | H29: 999.999 | I29: NIS | L29: 108345733 | M29: 46010 | N29: 20 | O29: 1 | P29: 4 | Q29: 1 | R29: O | S29: =IFERROR(VLOOKUP(N29,Index!$A$1:$B$26,2,FALSE),"") | T29: =AA29 | V29: =IFERROR(INDEX(DetailedFiche!Q:Q,MATCH(L29,DetailedFiche!J:J,0)),"") | W29: =IFERROR(INDEX(DetailedFiche!R:R,MATCH(L29,DetailedFiche!J:J,0)),"") | Y29: =IFERROR(IF(AND(INDEX('Initial Study'!K:K, MATCH(L29, 'Initial Study'!B:B, 0)+1)<>0,INDEX('Initial Study'!K:K, MATCH(L29, 'Initial Study'!B:B, 0)+1)<>""),INDEX('Initial Study'!K:K, MATCH(L29, 'Initial Study'!B:B, 0)+1),""),"") | Z29: =IFERROR(IF(AND(INDEX('Initial Study'!K:K, MATCH(L29, 'Initial Study'!B:B, 0)+2)<>0,INDEX('Initial Study'!K:K, MATCH(L29, 'Initial Study'!B:B, 0)+2)<>"",NOT(ISNUMBER(INDEX('Initial Study'!K:K, MATCH(L29, 'Initial Study'!B:B, 0)+2)))),INDEX('Initial Study'!K:K, MATCH(L29, 'Initial Study'!B:B, 0)+2),"-"),"-") | AA29: =IF(S29="RE", Y29 & "BT/" & IF(Z29 <> "-", Z29 & "BT", ""), IF(OR(S29="LTDR", S29="LTSR"), Y29 & "BL" & IF(Z29 <> "-", "/" & Z29 & "BT", ""), IF(OR(S29="RTDR", S29="RTSR"), Y29 & "BR" & IF(Z29 <> "-", "/" & Z29 & "BT", ""), IF(Z29 <> "-", Y29 & "BT/" & Z29 & "BT", Y29 & "BT"))))
A30: 558 | B30: PVA MARATHON GAS | C30: 0.014 | D30: W | E30: SR 1001 | F30: DEAD END | H30: 999.999 | I30: NIS | L30: 105790718 | M30: 43526 | N30: 31 | O30: 1 | P30: 0 | Q30: 1 | R30: O | S30: =IFERROR(VLOOKUP(N30,Index!$A$1:$B$26,2,FALSE),"") | T30: =AA30 | V30: =IFERROR(INDEX(DetailedFiche!Q:Q,MATCH(L30,DetailedFiche!J:J,0)),"") | W30: =IFERROR(INDEX(DetailedFiche!R:R,MATCH(L30,DetailedFiche!J:J,0)),"") | Y30: =IFERROR(IF(AND(INDEX('Initial Study'!K:K, MATCH(L30, 'Initial Study'!B:B, 0)+1)<>0,INDEX('Initial Study'!K:K, MATCH(L30, 'Initial Study'!B:B, 0)+1)<>""),INDEX('Initial Study'!K:K, MATCH(L30, 'Initial Study'!B:B, 0)+1),""),"") | Z30: =IFERROR(IF(AND(INDEX('Initial Study'!K:K, MATCH(L30, 'Initial Study'!B:B, 0)+2)<>0,INDEX('Initial Study'!K:K, MATCH(L30, 'Initial Study'!B:B, 0)+2)<>"",NOT(ISNUMBER(INDEX('Initial Study'!K:K, MATCH(L30, 'Initial Study'!B:B, 0)+2)))),INDEX('Initial Study'!K:K, MATCH(L30, 'Initial Study'!B:B, 0)+2),"-"),"-") | AA30: =IF(S30="RE", Y30 & "BT/" & IF(Z30 <> "-", Z30 & "BT", ""), IF(OR(S30="LTDR", S30="LTSR"), Y30 & "BL" & IF(Z30 <> "-", "/" & Z30 & "BT", ""), IF(OR(S30="RTDR", S30="RTSR"), Y30 & "BR" & IF(Z30 <> "-", "/" & Z30 & "BT", ""), IF(Z30 <> "-", Y30 & "BT/" & Z30 & "BT", Y30 & "BT"))))
A31: 558 | B31: PVA MARATHON GAS | C31: 0.019 | D31: W | E31: SR 1001 | F31: DEAD END | H31: 999.999 | I31: NIS | L31: 106747056 | M31: 44498 | N31: 31 | O31: 1 | P31: 0 | Q31: 1 | R31: O | S31: =IFERROR(VLOOKUP(N31,Index!$A$1:$B$26,2,FALSE),"") | T31: =AA31 | V31: =IFERROR(INDEX(DetailedFiche!Q:Q,MATCH(L31,DetailedFiche!J:J,0)),"") | W31: =IFERROR(INDEX(DetailedFiche!R:R,MATCH(L31,DetailedFiche!J:J,0)),"") | Y31: =IFERROR(IF(AND(INDEX('Initial Study'!K:K, MATCH(L31, 'Initial Study'!B:B, 0)+1)<>0,INDEX('Initial Study'!K:K, MATCH(L31, 'Initial Study'!B:B, 0)+1)<>""),INDEX('Initial Study'!K:K, MATCH(L31, 'Initial Study'!B:B, 0)+1),""),"") | Z31: =IFERROR(IF(AND(INDEX('Initial Study'!K:K, MATCH(L31, 'Initial Study'!B:B, 0)+2)<>0,INDEX('Initial Study'!K:K, MATCH(L31, 'Initial Study'!B:B, 0)+2)<>"",NOT(ISNUMBER(INDEX('Initial Study'!K:K, MATCH(L31, 'Initial Study'!B:B, 0)+2)))),INDEX('Initial Study'!K:K, MATCH(L31, 'Initial Study'!B:B, 0)+2),"-"),"-") | AA31: =IF(S31="RE", Y31 & "BT/" & IF(Z31 <> "-", Z31 & "BT", ""), IF(OR(S31="LTDR", S31="LTSR"), Y31 & "BL" & IF(Z31 <> "-", "/" & Z31 & "BT", ""), IF(OR(S31="RTDR", S31="RTSR"), Y31 & "BR" & IF(Z31 <> "-", "/" & Z31 & "BT", ""), IF(Z31 <> "-", Y31 & "BT/" & Z31 & "BT", Y31 & "BT"))))
A32: 558 | B32: PVA MARATHON GAS STATION | C32: 0.019 | D32: W | E32: SR 1001 | F32: DEAD END | H32: 999.999 | I32: NIS | L32: 107692192 | M32: 45400 | N32: 31 | O32: 1 | P32: 4 | Q32: 1 | R32: O | S32: =IFERROR(VLOOKUP(N32,Index!$A$1:$B$26,2,FALSE),"") | T32: =AA32 | V32: =IFERROR(INDEX(DetailedFiche!Q:Q,MATCH(L32,DetailedFiche!J:J,0)),"") | W32: =IFERROR(INDEX(DetailedFiche!R:R,MATCH(L32,DetailedFiche!J:J,0)),"") | Y32: =IFERROR(IF(AND(INDEX('Initial Study'!K:K, MATCH(L32, 'Initial Study'!B:B, 0)+1)<>0,INDEX('Initial Study'!K:K, MATCH(L32, 'Initial Study'!B:B, 0)+1)<>""),INDEX('Initial Study'!K:K, MATCH(L32, 'Initial Study'!B:B, 0)+1),""),"") | Z32: =IFERROR(IF(AND(INDEX('Initial Study'!K:K, MATCH(L32, 'Initial Study'!B:B, 0)+2)<>0,INDEX('Initial Study'!K:K, MATCH(L32, 'Initial Study'!B:B, 0)+2)<>"",NOT(ISNUMBER(INDEX('Initial Study'!K:K, MATCH(L32, 'Initial Study'!B:B, 0)+2)))),INDEX('Initial Study'!K:K, MATCH(L32, 'Initial Study'!B:B, 0)+2),"-"),"-") | AA32: =IF(S32="RE", Y32 & "BT/" & IF(Z32 <> "-", Z32 & "BT", ""), IF(OR(S32="LTDR", S32="LTSR"), Y32 & "BL" & IF(Z32 <> "-", "/" & Z32 & "BT", ""), IF(OR(S32="RTDR", S32="RTSR"), Y32 & "BR" & IF(Z32 <> "-", "/" & Z32 & "BT", ""), IF(Z32 <> "-", Y32 & "BT/" & Z32 & "BT", Y32 & "BT"))))
A33: 558 | B33: PVA PIEDMONT HIGH SCHOOL | C33: 0.009 | D33: W | E33: SR 1001 | F33: *LCL - | H33: 999.999 | I33: NIS | L33: 104865813 | M33: 42642 | N33: 21 | O33: 2 | P33: 4 | Q33: 1 | R33: C | S33: =IFERROR(VLOOKUP(N33,Index!$A$1:$B$26,2,FALSE),"") | T33: =AA33 | V33: =IFERROR(INDEX(DetailedFiche!Q:Q,MATCH(L33,DetailedFiche!J:J,0)),"") | W33: =IFERROR(INDEX(DetailedFiche!R:R,MATCH(L33,DetailedFiche!J:J,0)),"") | Y33: =IFERROR(IF(AND(INDEX('Initial Study'!K:K, MATCH(L33, 'Initial Study'!B:B, 0)+1)<>0,INDEX('Initial Study'!K:K, MATCH(L33, 'Initial Study'!B:B, 0)+1)<>""),INDEX('Initial Study'!K:K, MATCH(L33, 'Initial Study'!B:B, 0)+1),""),"") | Z33: =IFERROR(IF(AND(INDEX('Initial Study'!K:K, MATCH(L33, 'Initial Study'!B:B, 0)+2)<>0,INDEX('Initial Study'!K:K, MATCH(L33, 'Initial Study'!B:B, 0)+2)<>"",NOT(ISNUMBER(INDEX('Initial Study'!K:K, MATCH(L33, 'Initial Study'!B:B, 0)+2)))),INDEX('Initial Study'!K:K, MATCH(L33, 'Initial Study'!B:B, 0)+2),"-"),"-") | AA33: =IF(S33="RE", Y33 & "BT/" & IF(Z33 <> "-", Z33 & "BT", ""), IF(OR(S33="LTDR", S33="LTSR"), Y33 & "BL" & IF(Z33 <> "-", "/" & Z33 & "BT", ""), IF(OR(S33="RTDR", S33="RTSR"), Y33 & "BR" & IF(Z33 <> "-", "/" & Z33 & "BT", ""), IF(Z33 <> "-", Y33 & "BT/" & Z33 & "BT", Y33 & "BT"))))
A34: 558 | B34: PVA PIEDMONT HIGH SCHOOL | C34: 0.017 | D34: W | E34: SR 1001 | F34: DEAD END | H34: 999.999 | I34: NIS | L34: 104945962 | M34: 42716 | N34: 21 | O34: 1 | P34: 4 | Q34: 1 | R34: O | S34: =IFERROR(VLOOKUP(N34,Index!$A$1:$B$26,2,FALSE),"") | T34: =AA34 | V34: =IFERROR(INDEX(DetailedFiche!Q:Q,MATCH(L34,DetailedFiche!J:J,0)),"") | W34: =IFERROR(INDEX(DetailedFiche!R:R,MATCH(L34,DetailedFiche!J:J,0)),"") | Y34: =IFERROR(IF(AND(INDEX('Initial Study'!K:K, MATCH(L34, 'Initial Study'!B:B, 0)+1)<>0,INDEX('Initial Study'!K:K, MATCH(L34, 'Initial Study'!B:B, 0)+1)<>""),INDEX('Initial Study'!K:K, MATCH(L34, 'Initial Study'!B:B, 0)+1),""),"") | Z34: =IFERROR(IF(AND(INDEX('Initial Study'!K:K, MATCH(L34, 'Initial Study'!B:B, 0)+2)<>0,INDEX('Initial Study'!K:K, MATCH(L34, 'Initial Study'!B:B, 0)+2)<>"",NOT(ISNUMBER(INDEX('Initial Study'!K:K, MATCH(L34, 'Initial Study'!B:B, 0)+2)))),INDEX('Initial Study'!K:K, MATCH(L34, 'Initial Study'!B:B, 0)+2),"-"),"-") | AA34: =IF(S34="RE", Y34 & "BT/" & IF(Z34 <> "-", Z34 & "BT", ""), IF(OR(S34="LTDR", S34="LTSR"), Y34 & "BL" & IF(Z34 <> "-", "/" & Z34 & "BT", ""), IF(OR(S34="RTDR", S34="RTSR"), Y34 & "BR" & IF(Z34 <> "-", "/" & Z34 & "BT", ""), IF(Z34 <> "-", Y34 & "BT/" & Z34 & "BT", Y34 & "BT"))))
A35: 558 | B35: PVA PIEDMONT HIGH SCHOOL | C35: 0.017 | D35: W | E35: SR 1001 | F35: DEAD END | H35: 999.999 | I35: NIS | L35: 104950470 | M35: 42716 | N35: 21 | O35: 1 | P35: 4 | Q35: 1 | R35: O | S35: =IFERROR(VLOOKUP(N35,Index!$A$1:$B$26,2,FALSE),"") | T35: =AA35 | V35: =IFERROR(INDEX(DetailedFiche!Q:Q,MATCH(L35,DetailedFiche!J:J,0)),"") | W35: =IFERROR(INDEX(DetailedFiche!R:R,MATCH(L35,DetailedFiche!J:J,0)),"") | Y35: =IFERROR(IF(AND(INDEX('Initial Study'!K:K, MATCH(L35, 'Initial Study'!B:B, 0)+1)<>0,INDEX('Initial Study'!K:K, MATCH(L35, 'Initial Study'!B:B, 0)+1)<>""),INDEX('Initial Study'!K:K, MATCH(L35, 'Initial Study'!B:B, 0)+1),""),"") | Z35: =IFERROR(IF(AND(INDEX('Initial Study'!K:K, MATCH(L35, 'Initial Study'!B:B, 0)+2)<>0,INDEX('Initial Study'!K:K, MATCH(L35, 'Initial Study'!B:B, 0)+2)<>"",NOT(ISNUMBER(INDEX('Initial Study'!K:K, MATCH(L35, 'Initial Study'!B:B, 0)+2)))),INDEX('Initial Study'!K:K, MATCH(L35, 'Initial Study'!B:B, 0)+2),"-"),"-") | AA35: =IF(S35="RE", Y35 & "BT/" & IF(Z35 <> "-", Z35 & "BT", ""), IF(OR(S35="LTDR", S35="LTSR"), Y35 & "BL" & IF(Z35 <> "-", "/" & Z35 & "BT", ""), IF(OR(S35="RTDR", S35="RTSR"), Y35 & "BR" & IF(Z35 <> "-", "/" & Z35 & "BT", ""), IF(Z35 <> "-", Y35 & "BT/" & Z35 & "BT", Y35 & "BT"))))
A36: 558 | B36: PVA PIEDMONT MIDDLE | C36: 0 | E36: SR 1001 | F36: DEAD END | H36: 999.999 | I36: NIS | L36: 105740561 | M36: 43472 | N36: 21 | O36: 1 | P36: 8 | Q36: 1 | R36: O | S36: =IFERROR(VLOOKUP(N36,Index!$A$1:$B$26,2,FALSE),"") | T36: =AA36 | V36: =IFERROR(INDEX(DetailedFiche!Q:Q,MATCH(L36,DetailedFiche!J:J,0)),"") | W36: =IFERROR(INDEX(DetailedFiche!R:R,MATCH(L36,DetailedFiche!J:J,0)),"") | Y36: =IFERROR(IF(AND(INDEX('Initial Study'!K:K, MATCH(L36, 'Initial Study'!B:B, 0)+1)<>0,INDEX('Initial Study'!K:K, MATCH(L36, 'Initial Study'!B:B, 0)+1)<>""),INDEX('Initial Study'!K:K, MATCH(L36, 'Initial Study'!B:B, 0)+1),""),"") | Z36: =IFERROR(IF(AND(INDEX('Initial Study'!K:K, MATCH(L36, 'Initial Study'!B:B, 0)+2)<>0,INDEX('Initial Study'!K:K, MATCH(L36, 'Initial Study'!B:B, 0)+2)<>"",NOT(ISNUMBER(INDEX('Initial Study'!K:K, MATCH(L36, 'Initial Study'!B:B, 0)+2)))),INDEX('Initial Study'!K:K, MATCH(L36, 'Initial Study'!B:B, 0)+2),"-"),"-") | AA36: =IF(S36="RE", Y36 & "BT/" & IF(Z36 <> "-", Z36 & "BT", ""), IF(OR(S36="LTDR", S36="LTSR"), Y36 & "BL" & IF(Z36 <> "-", "/" & Z36 & "BT", ""), IF(OR(S36="RTDR", S36="RTSR"), Y36 & "BR" & IF(Z36 <> "-", "/" & Z36 & "BT", ""), IF(Z36 <> "-", Y36 & "BT/" & Z36 & "BT", Y36 & "BT"))))
A37: 0 | B37: *PP 2815 OLD CAMDEN RD | C37: 0.019 | D37: W | E37: SR 1606 | F37: DEAD END | H37: 999.999 | I37: NIS | L37: 107479024 | M37: 45203 | N37: 20 | O37: 1 | P37: 5 | Q37: 5 | R37: O | S37: =IFERROR(VLOOKUP(N37,Index!$A$1:$B$26,2,FALSE),"") | T37: =AA37 | V37: =IFERROR(INDEX(DetailedFiche!Q:Q,MATCH(L37,DetailedFiche!J:J,0)),"") | W37: =IFERROR(INDEX(DetailedFiche!R:R,MATCH(L37,DetailedFiche!J:J,0)),"") | Y37: =IFERROR(IF(AND(INDEX('Initial Study'!K:K, MATCH(L37, 'Initial Study'!B:B, 0)+1)<>0,INDEX('Initial Study'!K:K, MATCH(L37, 'Initial Study'!B:B, 0)+1)<>""),INDEX('Initial Study'!K:K, MATCH(L37, 'Initial Study'!B:B, 0)+1),""),"") | Z37: =IFERROR(IF(AND(INDEX('Initial Study'!K:K, MATCH(L37, 'Initial Study'!B:B, 0)+2)<>0,INDEX('Initial Study'!K:K, MATCH(L37, 'Initial Study'!B:B, 0)+2)<>"",NOT(ISNUMBER(INDEX('Initial Study'!K:K, MATCH(L37, 'Initial Study'!B:B, 0)+2)))),INDEX('Initial Study'!K:K, MATCH(L37, 'Initial Study'!B:B, 0)+2),"-"),"-") | AA37: =IF(S37="RE", Y37 & "BT/" & IF(Z37 <> "-", Z37 & "BT", ""), IF(OR(S37="LTDR", S37="LTSR"), Y37 & "BL" & IF(Z37 <> "-", "/" & Z37 & "BT", ""), IF(OR(S37="RTDR", S37="RTSR"), Y37 & "BR" & IF(Z37 <> "-", "/" & Z37 & "BT", ""), IF(Z37 <> "-", Y37 & "BT/" & Z37 & "BT", Y37 & "BT"))))
A38: 558 | B38: PVA 3006 SIKES MILL RD | C38: 0.018 | D38: E | E38: SR 1606 | F38: SR 1001 | H38: 999.999 | I38: NIS | L38: 107844251 | M38: 45540 | N38: 31 | O38: 1 | P38: 0 | Q38: 1 | R38: O | S38: =IFERROR(VLOOKUP(N38,Index!$A$1:$B$26,2,FALSE),"") | T38: =AA38 | V38: =IFERROR(INDEX(DetailedFiche!Q:Q,MATCH(L38,DetailedFiche!J:J,0)),"") | W38: =IFERROR(INDEX(DetailedFiche!R:R,MATCH(L38,DetailedFiche!J:J,0)),"") | Y38: =IFERROR(IF(AND(INDEX('Initial Study'!K:K, MATCH(L38, 'Initial Study'!B:B, 0)+1)<>0,INDEX('Initial Study'!K:K, MATCH(L38, 'Initial Study'!B:B, 0)+1)<>""),INDEX('Initial Study'!K:K, MATCH(L38, 'Initial Study'!B:B, 0)+1),""),"") | Z38: =IFERROR(IF(AND(INDEX('Initial Study'!K:K, MATCH(L38, 'Initial Study'!B:B, 0)+2)<>0,INDEX('Initial Study'!K:K, MATCH(L38, 'Initial Study'!B:B, 0)+2)<>"",NOT(ISNUMBER(INDEX('Initial Study'!K:K, MATCH(L38, 'Initial Study'!B:B, 0)+2)))),INDEX('Initial Study'!K:K, MATCH(L38, 'Initial Study'!B:B, 0)+2),"-"),"-") | AA38: =IF(S38="RE", Y38 & "BT/" & IF(Z38 <> "-", Z38 & "BT", ""), IF(OR(S38="LTDR", S38="LTSR"), Y38 & "BL" & IF(Z38 <> "-", "/" & Z38 & "BT", ""), IF(OR(S38="RTDR", S38="RTSR"), Y38 & "BR" & IF(Z38 <> "-", "/" & Z38 & "BT", ""), IF(Z38 <> "-", Y38 & "BT/" & Z38 & "BT", Y38 & "BT"))))
A39: 558 | B39: PVA MARATHON GAS STATION | C39: 0.014 | D39: W | E39: SR 1606 | F39: SR 1001 | H39: 999.999 | I39: NIS | L39: 105060300 | M39: 42814 | N39: 31 | O39: 1 | P39: 4 | Q39: 1 | R39: O | S39: =IFERROR(VLOOKUP(N39,Index!$A$1:$B$26,2,FALSE),"") | T39: =AA39 | V39: =IFERROR(INDEX(DetailedFiche!Q:Q,MATCH(L39,DetailedFiche!J:J,0)),"") | W39: =IFERROR(INDEX(DetailedFiche!R:R,MATCH(L39,DetailedFiche!J:J,0)),"") | Y39: =IFERROR(IF(AND(INDEX('Initial Study'!K:K, MATCH(L39, 'Initial Study'!B:B, 0)+1)<>0,INDEX('Initial Study'!K:K, MATCH(L39, 'Initial Study'!B:B, 0)+1)<>""),INDEX('Initial Study'!K:K, MATCH(L39, 'Initial Study'!B:B, 0)+1),""),"") | Z39: =IFERROR(IF(AND(INDEX('Initial Study'!K:K, MATCH(L39, 'Initial Study'!B:B, 0)+2)<>0,INDEX('Initial Study'!K:K, MATCH(L39, 'Initial Study'!B:B, 0)+2)<>"",NOT(ISNUMBER(INDEX('Initial Study'!K:K, MATCH(L39, 'Initial Study'!B:B, 0)+2)))),INDEX('Initial Study'!K:K, MATCH(L39, 'Initial Study'!B:B, 0)+2),"-"),"-") | AA39: =IF(S39="RE", Y39 & "BT/" & IF(Z39 <> "-", Z39 & "BT", ""), IF(OR(S39="LTDR", S39="LTSR"), Y39 & "BL" & IF(Z39 <> "-", "/" & Z39 & "BT", ""), IF(OR(S39="RTDR", S39="RTSR"), Y39 & "BR" & IF(Z39 <> "-", "/" & Z39 & "BT", ""), IF(Z39 <> "-", Y39 & "BT/" & Z39 & "BT", Y39 & "BT"))))
A40: 558 | B40: PVA PIEDMONT HIGH SCHOOL | C40: 0.004 | D40: E | E40: SR 1606 | F40: SR 1678 | H40: 999.999 | I40: NIS | L40: 107118944 | M40: 44847 | N40: 31 | O40: 1 | P40: 4 | Q40: 1 | R40: O | S40: =IFERROR(VLOOKUP(N40,Index!$A$1:$B$26,2,FALSE),"") | T40: =AA40 | V40: =IFERROR(INDEX(DetailedFiche!Q:Q,MATCH(L40,DetailedFiche!J:J,0)),"") | W40: =IFERROR(INDEX(DetailedFiche!R:R,MATCH(L40,DetailedFiche!J:J,0)),"") | Y40: =IFERROR(IF(AND(INDEX('Initial Study'!K:K, MATCH(L40, 'Initial Study'!B:B, 0)+1)<>0,INDEX('Initial Study'!K:K, MATCH(L40, 'Initial Study'!B:B, 0)+1)<>""),INDEX('Initial Study'!K:K, MATCH(L40, 'Initial Study'!B:B, 0)+1),""),"") | Z40: =IFERROR(IF(AND(INDEX('Initial Study'!K:K, MATCH(L40, 'Initial Study'!B:B, 0)+2)<>0,INDEX('Initial Study'!K:K, MATCH(L40, 'Initial Study'!B:B, 0)+2)<>"",NOT(ISNUMBER(INDEX('Initial Study'!K:K, MATCH(L40, 'Initial Study'!B:B, 0)+2)))),INDEX('Initial Study'!K:K, MATCH(L40, 'Initial Study'!B:B, 0)+2),"-"),"-") | AA40: =IF(S40="RE", Y40 & "BT/" & IF(Z40 <> "-", Z40 & "BT", ""), IF(OR(S40="LTDR", S40="LTSR"), Y40 & "BL" & IF(Z40 <> "-", "/" & Z40 & "BT", ""), IF(OR(S40="RTDR", S40="RTSR"), Y40 & "BR" & IF(Z40 <> "-", "/" & Z40 & "BT", ""), IF(Z40 <> "-", Y40 & "BT/" & Z40 & "BT", Y40 & "BT"))))
...

Sheet ID
A1: Crash ID | B1: CRASH | C1: IS? | D1: Fiche? | H1: CRASH | I1: ID | J1: ON | K1: RD | L1: CD | M1: SVRTY | N1: DATE | O1: TYPE
A2: 105722912 | B2: 104716467 | D2: YES | H2: 104716467 | I2: 40001617 | J2: 5 | K2: 42487 | L2: 0.81944444 | M2: 30
A3: 104698395 | B3: 104890928 | D3: YES | H3: 104890928 | I3: 40001001 | J3: 4 | K3: 42653 | L3: 0.36805556 | M3: 30
A4: 107479024 | B4: 104901954 | D4: YES | H4: 104901954 | I4: 40001001 | J4: 5 | K4: 42676 | L4: 0.31736111 | M4: 30
A5: 107442545 | B5: 104942804 | D5: YES | H5: 104942804 | I5: 40001001 | J5: 3 | K5: 42712 | L5: 0.67291667 | M5: 30
A6: 108377465 | B6: 104987740 | D6: YES | H6: 104987740 | I6: 40001001 | J6: 3 | K6: 42760 | L6: 0.56944444 | M6: 30
A7: 108397947 | B7: 105210461 | D7: YES | H7: 105210461 | I7: 40001001 | J7: 4 | K7: 42977 | L7: 0.33888889 | M7: 30
A8: 107756918 | B8: 105326435 | D8: YES | H8: 105326435 | I8: 40001001 | J8: 2 | K8: 43085 | L8: 0.48819444 | M8: 30
A9: 108479327 | B9: 105520583 | D9: YES | H9: 105520583 | I9: 40001001 | J9: 5 | K9: 43271 | L9: 0.8125 | M9: 19
A10: 107528155 | B10: 105535858 | D10: YES | H10: 105535858 | I10: 40001001 | J10: 3 | K10: 43290 | L10: 0.35347222 | M10: 30
A11: 105971602 | B11: 105553349 | D11: YES | H11: 105553349 | I11: 40001001 | J11: 5 | K11: 43304 | L11: 0.80486111 | M11: 18
A12: 107250998 | B12: 105885258 | D12: YES | H12: 105885258 | I12: 40001617 | J12: 5 | K12: 43620 | L12: 0.32013889 | M12: 29
A13: 105983673 | B13: 106126767 | D13: YES | H13: 106126767 | I13: 40001001 | J13: 5 | K13: 43843 | L13: 0.55069444 | M13: 21
... A23: 105060300 | B23: 108279485 | D23: YES | H23: 108279485 | I23: 40001001 | J23: 4 | K23: 45953 | L23: 0.53680556 | M23: 30
A24: 104865813
A25: 104945962
A26: 104950470
A27: 107118944
A28: 107711938
A29: 105740561
A30: 108247372
A31: 107683218
A32: 105226618
A33: 108319024
A34: 107926331
A35: 108430866
... A588: 105387411

Sheet Index
A1: 0 | B1: unknown
A2: 1 | B2: ROR-R
A3: 2 | B3: ROR-L
A4: 3 | B4: ROR-T
A5: 4 | B5: jackknife
A6: 5 | B6: overturn
A7: 13 | B7: other
A8: 14 | B8: pedestrian
A9: 15 | B9: cyclist
A10: 16 | B10: RR
A11: 17 | B11: animal
A12: 18 | B12: MO
... A26: 32 | B26: other

Sheet Initial Study
B1: North Carolina Department of Transportation Traffic Engineering Accident Analysis System Intersection Analysis Report
A2: Study Criteria Summary
A3: County: | B3: UNION | C3: City: | D3: All and Rural
A4: Date: | B4: 42461 | C4: to | D4: 46203 | E4: Study: | F4: 41000076160
A5: Location: | B5: SR 1001 (Sikes Mill Road) at SR 1617 (Tom Boyd Road)
A6: Report Details
A7: Acc No | B7: Crash ID | C7: Date | D7: Accident Type | E7: Total Damage | F7: Injuries | G7: F | H7: A | I7: B | J7: C | K7: R | L7: Condition | M7: L | N7: W | O7: Road | P7: Ch | Q7: Ci | R7: Dv | S7: Trfc Ctl | T7: Op
A8: 1 | B8: 104716467 | C8: 42487.819 | D8: ANGLE | E8: $ | F8: 15000 | G8: 0 | H8: 0 | I8: 0 | J8: 0 | K8: 1 | L8: 1 | M8: 1 | N8: 1 | O8: 0 | P8: 1 | Q8: 1
A9: Unit | B9: 1 | C9: : | D9: 4 | E9: Alchl/Drgs: | F9: 0 | G9: Speed: | H9: 0 | I9: MPH | J9: Dir: | K9: E | L9: Veh Mnvr / Ped Actn: | M9: 4 | N9: Obj Strk:
A10: Unit | B10: 2 | C10: : | D10: 5 | E10: Alchl/Drgs: | F10: 0 | G10: Speed: | H10: 45 | I10: MPH | J10: Dir: | K10: S | L10: Veh Mnvr / Ped Actn: | M10: 4 | N10: Obj Strk:
A11: 2 | B11: 104890928 | C11: 42653.368 | D11: ANGLE | E11: $ | F11: 2660 | G11: 0 | H11: 0 | I11: 0 | J11: 3 | K11: 1 | L11: 1 | M11: 1 | N11: 3 | O11: 0 | P11: 1 | Q11: 1
A12: Unit | B12: 1 | C12: : | D12: 1 | E12: Alchl/Drgs: | F12: 0 | G12: Speed: | H12: 55 | I12: MPH | J12: Dir: | K12: SW | L12: Veh Mnvr / Ped Actn: | M12: 4 | N12: Obj Strk:
A13: Unit | B13: 2 | C13: : | D13: 2 | E13: Alchl/Drgs: | F13: 0 | G13: Speed: | H13: 5 | I13: MPH | J13: Dir: | K13: NW | L13: Veh Mnvr / Ped Actn: | M13: 4 | N13: Obj Strk:
A14: 3 | B14: 104901954 | C14: 42676.317 | D14: ANGLE | E14: $ | F14: 11500 | G14: 0 | H14: 0 | I14: 0 | J14: 0 | K14: 1 | L14: 1 | M14: 1 | N14: 2 | O14: 0 | P14: 1 | Q14: 1
A15: Unit | B15: 1 | C15: : | D15: 2 | E15: Alchl/Drgs: | F15: 0 | G15: Speed: | H15: 0 | I15: MPH | J15: Dir: | K15: W | L15: Veh Mnvr / Ped Actn: | M15: 4 | N15: Obj Strk:
A16: Unit | B16: 2 | C16: : | D16: 1 | E16: Alchl/Drgs: | F16: 0 | G16: Speed: | H16: 45 | I16: MPH | J16: Dir: | K16: S | L16: Veh Mnvr / Ped Actn: | M16: 4 | N16: Obj Strk:
A17: Unit | B17: 3 | C17: : | D17: 4 | E17: Alchl/Drgs: | F17: 0 | G17: Speed: | H17: 45 | I17: MPH | J17: Dir: | K17: E | L17: Veh Mnvr / Ped Actn: | M17: 1 | N17: Obj Strk:
A18: 4 | B18: 104942804 | C18: 42712.673 | D18: ANGLE | E18: $ | F18: 7000 | G18: 0 | H18: 0 | I18: 1 | J18: 0 | K18: 1 | L18: 1 | M18: 2 | N18: 3 | O18: 0 | P18: 1 | Q18: 1
A19: Unit | B19: 1 | C19: : | D19: 1 | E19: Alchl/Drgs: | F19: 0 | G19: Speed: | H19: 10 | I19: MPH | J19: Dir: | K19: W | L19: Veh Mnvr / Ped Actn: | M19: 4 | N19: Obj Strk:
A20: Unit | B20: 2 | C20: : | D20: 1 | E20: Alchl/Drgs: | F20: 0 | G20: Speed: | H20: 60 | I20: MPH | J20: Dir: | K20: S | L20: Veh Mnvr / Ped Actn: | M20: 4 | N20: Obj Strk:
A21: 5 | B21: 104987740 | C21: 42760.569 | D21: ANGLE | E21: $ | F21: 10575 | G21: 0 | H21: 0 | I21: 3 | J21: 3 | K21: 1 | L21: 1 | M21: 1 | N21: 3 | O21: 0 | P21: 1 | Q21: 1
A22: Unit | B22: 1 | C22: : | D22: 1 | E22: Alchl/Drgs: | F22: 0 | G22: Speed: | H22: 45 | I22: MPH | J22: Dir: | K22: W | L22: Veh Mnvr / Ped Actn: | M22: 4 | N22: Obj Strk:
A23: Unit | B23: 2 | C23: : | D23: 4 | E23: Alchl/Drgs: | F23: 0 | G23: Speed: | H23: 50 | I23: MPH | J23: Dir: | K23: S | L23: Veh Mnvr / Ped Actn: | M23: 4 | N23: Obj Strk: | O23: 60
A24: 6 | B24: 105210461 | C24: 42977.339 | D24: ANGLE | E24: $ | F24: 4500 | G24: 0 | H24: 0 | I24: 0 | J24: 2 | K24: 1 | L24: 1 | M24: 1 | N24: 3 | O24: 0 | P24: 1 | Q24: 1
A25: Unit | B25: 1 | C25: : | D25: 4 | E25: Alchl/Drgs: | F25: 0 | G25: Speed: | H25: 0 | I25: MPH | J25: Dir: | K25: E | L25: Veh Mnvr / Ped Actn: | M25: 4 | N25: Obj Strk:
A26: Unit | B26: 2 | C26: : | D26: 7 | E26: Alchl/Drgs: | F26: 0 | G26: Speed: | H26: 45 | I26: MPH | J26: Dir: | K26: N | L26: Veh Mnvr / Ped Actn: | M26: 4 | N26: Obj Strk:
A27: 7 | B27: 105326435 | C27: 43085.488 | D27: ANGLE | E27: $ | F27: 20000 | G27: 0 | H27: 1 | I27: 1 | J27: 0 | K27: 1 | L27: 1 | M27: 1 | N27: 1 | O27: 0 | P27: 1 | Q27: 1
A28: Unit | B28: 1 | C28: : | D28: 14 | E28: Alchl/Drgs: | F28: 0 | G28: Speed: | H28: 45 | I28: MPH | J28: Dir: | K28: S | L28: Veh Mnvr / Ped Actn: | M28: 4 | N28: Obj Strk: | O28: 58
A29: Unit | B29: 2 | C29: : | D29: 1 | E29: Alchl/Drgs: | F29: 0 | G29: Speed: | H29: 55 | I29: MPH | J29: Dir: | K29: E | L29: Veh Mnvr / Ped Actn: | M29: 4 | N29: Obj Strk:
B30: 46254 | C30: All data presented in this report comes explicitly from the Traffic Engineering Accident Analysis System based upon various input criteria provided by the report's creator. The onus is strictly upon the user of this report to exercise due diligence in interpreting and further representing this data. | D30: -1-
B31: North Carolina Department of Transportation Traffic Engineering Accident Analysis System Intersection Analysis Report
A32: Acc No | B32: Crash ID | C32: Date | D32: Accident Type | E32: Total Damage | F32: Injuries | G32: F | H32: A | I32: B | J32: C | K32: R | L32: Condition | M32: L | N32: W | O32: Road | P32: Ch | Q32: Ci | R32: Dv | S32: Trfc Ctl | T32: Op
A33: 8 | B33: 105520583 | C33: 43271.812 | D33: FIXED OBJECT | E33: $ | F33: 1000 | G33: 0 | H33: 0 | I33: 0 | J33: 0 | K33: 2 | L33: 1 | M33: 3 | N33: 5 | O33: 0 | P33: 13 | Q33: 1
A34: Unit | B34: 1 | C34: : | D34: 1 | E34: Alchl/Drgs: | F34: 0 | G34: Speed: | H34: 35 | I34: MPH | J34: Dir: | K34: N | L34: Veh Mnvr / Ped Actn: | M34: 4 | N34: Obj Strk: | O34: 58
A35: 9 | B35: 105535858 | C35: 43290.353 | D35: ANGLE | E35: $ | F35: 28650 | G35: 0 | H35: 0 | I35: 2 | J35: 0 | K35: 1 | L35: 1 | M35: 1 | N35: 1 | O35: 0 | P35: 1 | Q35: 1
A36: Unit | B36: 1 | C36: : | D36: 1 | E36: Alchl/Drgs: | F36: 0 | G36: Speed: | H36: 50 | I36: MPH | J36: Dir: | K36: SE | L36: Veh Mnvr / Ped Actn: | M36: 4 | N36: Obj Strk: | O36: 64
A37: Unit | B37: 2 | C37: : | D37: 4 | E37: Alchl/Drgs: | F37: 0 | G37: Speed: | H37: 45 | I37: MPH | J37: Dir: | K37: SW | L37: Veh Mnvr / Ped Actn: | M37: 4 | N37: Obj Strk:
A38: Unit | B38: 3 | C38: : | D38: 2 | E38: Alchl/Drgs: | F38: 7 | G38: Speed: | H38: 0 | I38: MPH | J38: Dir: | K38: W | L38: Veh Mnvr / Ped Actn: | M38: 2 | N38: Obj Strk:
A39: 10 | B39: 105553349 | C39: 43304.805 | D39: MOVABLE OBJECT | E39: $ | F39: 500 | G39: 0 | H39: 0 | I39: 0 | J39: 0 | K39: 2 | L39: 1 | M39: 3 | N39: 7 | O39: 0 | P39: 13 | Q39: 1
A40: Unit | B40: 1 | C40: : | D40: 1 | E40: Alchl/Drgs: | F40: 0 | G40: Speed: | H40: 65 | I40: MPH | J40: Dir: | K40: N | L40: Veh Mnvr / Ped Actn: | M40: 4 | N40: Obj Strk: | O40: 18
...

Sheet DetailedFiche
A1: Municipality | B1: On Road | C1: Miles | D1: Dir From | E1: From Road | F1: Toward Road | G1: Milepost Road | H1: MP | I1: MA | J1: Crash ID | K1: Date | L1: T | M1: C | N1: F | O1: L | P1: S | Q1: Latitude | R1: Longitude | S1: Source
A2: NEW SALEM | B2: LOVE MILL | C2: 0.026 | D2: S | E2: GREEN | F2: SANTA CLAUS | G2: SR 1001 | H2: 8.623 | J2: 106457925 | K2: 44203 | L2: 5 | M2: 1 | N2: 0 | O2: 1 | P2: C
A3: UNIONVILLE | B3: SR 1619 | C3: 0 | E3: SR 1681 | G3: SR 1619 | H3: 0.573 | J3: 107533157 | K3: 45249 | L3: 19 | M3: 1 | N3: 8 | O3: 1 | P3: O | Q3: 35.07597 | R3: -80.49265 | S3: DMV349CLEANED
A4: UNIONVILLE | B4: SIKES MILL | C4: 0.17 | D4: S | E4: HAIGLER BAUCOM | F4: PIEDMONT SCHOOL | G4: SIKES MILL | H4: 999.999 | J4: 106479132 | K4: 44230 | L4: 19 | M4: 1 | N4: 0 | O4: 1 | P4: C
A5: UNIONVILLE | B5: SIKES MILL | C5: 0 | E5: TOM BOYD | F5: LAWYERS | G5: SR 1001 | H5: 3.461 | J5: 106133705 | K5: 43853 | L5: 30 | M5: 1 | N5: 7 | O5: 1 | P5: O
A6: UNIONVILLE | B6: SIKES MILL | C6: 0.26 | D6: S | E6: BAUCOM | F6: US 601 | G6: SR 1001 | H6: 1.092 | J6: 105898128 | K6: 43629 | L6: 17 | M6: 1 | N6: 0 | O6: 5 | P6: O
A7: UNIONVILLE | B7: SIKES MILL | C7: 0 | E7: TOM HELMS | F7: PIEDMONT SCHOOL | G7: SR 1001 | H7: 4.094 | J7: 107101493 | K7: 44840 | L7: 28 | M7: 1 | N7: 10 | O7: 1 | P7: O
A8: UNIONVILLE | B8: SR 1001 | C8: 0.5 | D8: E | E8: US 601 | F8: SPRING LAKE | G8: SR 1001 | H8: 0.5 | J8: 108339974 | K8: 45993 | L8: 17 | M8: 2 | N8: 0 | O8: 1 | P8: O | Q8: 35.03374 | R8: -80.53659 | S8: DMV349CLEANED
A9: RURAL | B9: SIKES MILL | C9: 0.002 | D9: S | E9: SPRING LAKE | F9: US 601 | G9: SR 1001 | H9: 0.883 | J9: 106059402 | K9: 43777 | L9: 19 | M9: 2 | N9: 0 | O9: 4 | P9: B
A10: RURAL | B10: SIKES MILL | C10: 0 | E10: NC 218 | F10: *LCL OLD FISH RD | G10: SIKES MILL | H10: 999.999 | J10: 106882446 | K10: 44619 | L10: 21 | M10: 2 | N10: 7 | O10: 1 | P10: O
A11: UNIONVILLE | B11: SR 1619 | C11: 0.095 | D11: E | E11: SR 1001 | F11: SR 1606 | G11: SR 1619 | H11: 0.095 | J11: 107771302 | K11: 45468 | L11: 17 | M11: 1 | N11: 0 | O11: 5 | P11: O | Q11: 35.0802 | R11: -80.49869 | S11: DMV349CLEANED
A12: UNIONVILLE | B12: SIKES MILL | C12: 0.009 | D12: N | E12: BAUCOM | F12: CHANEY | G12: SR 1001 | H12: 1.361 | J12: 104780506 | K12: 42553 | L12: 21 | M12: 1 | N12: 8 | O12: 1 | P12: O
A13: UNIONVILLE | B13: US 601 | C13: 0 | E13: SIKES MILL | F13: BAUCOM DEESE | G13: US 601 | H13: 18.007 | J13: 107221390 | K13: 44946 | L13: 24 | M13: 1 | N13: 8 | O13: 1 | P13: O
