Workbook

Sheet Step-by-Step Instructions

Sheet Typical Target Crash Types
B2: Target Crash Type Guidance - Intersection Treatments
C4: Countermeasure | D4: Target-1 | E4: Target-2 | F4: Target-1 Crash | G4: Target-2 Crash | H4: Notes
C5: Advance Activated Warning Sign (a.k.a. Be Prepared to Stop Signs) | D5: Y | E5: Y | F5: Frontal Impact Crashes where Vehicle on Treated Approach Ran Red Light | G5: Rear End Crashes Approaching Intersection on Treated Approaches | H5: Treated Approaches are likely both Mainline Approaches
C6: All Way Stop | D6: Y | F6: Frontal Impact Crashes in Intersection
C7: Reduced Conflict Intersection (RCI) | D7: Y | F7: Frontal Impact Crashes involving vehicle making a movement that is restricted in the after period | H7: If the treatment included the construction of U-turn bulbouts, the entire constructed section may need to be included in the treatment analysis. If the treatment was ONLY the RCI, analyze downstream U-turn crashes in a separate table.
C8: Flashing Traffic Signal (i.e. Overhead Non-Actuated Flasher) | D8: Y | F8: Frontal Impact Crashes in Intersection
C9: Grade Separation | D9: Y | F9: Frontal Impact Crashes in Intersection
C10: Increase Conspicuity of Stop Condition (i.e. Double Indicated Stop Sign, Transverse Rumble Strips, Double Arrow Sign) | D10: Y | F10: Frontal Impact Crashes where Vehicle on Treated Approach Ran the Stop Sign | H10: Include Ran Off Road - Straight Crashes for T Intersections
C11: Increase Conspicuity of Traffic Signal (i.e. Double Indicated Red, Backplates) | D11: Y | F11: Frontal Impact Crashes where Vehicle on Treated Approach Ran Red Light | H11: Include Rear End crashes from the treated approaches within the Additional Information Table.
C12: Intersection Realignment | D12: Y | E12: Y | F12: Frontal Impact Crashes in Intersection | G12: Varies by Treatment - Other Targets may be necessary depending on the situation (i.e. Rear End Crashes or Lane Departure Crashes) | H12: Y-Lines may need to be extended. Analyze Entire Area impacted by realignment
C13: Left Turn Lane - New Installation | D13: Y | E13: Y | F13: Rear End Crashes Approaching Intersection on Treated Approaches | G13: Left Turn Same Roadway Crashes on Treated Approaches | H13: If a multilane facility, rear ends may need to be specific to the inner lanes
C14: Left Turn Lane - Offset Existing Lane | D14: Y | F14: Left Turn Same Roadway Crashes on Treated Approaches
C15: Median Channelization on an Intersection Approach (i.e. Assess Management for Driveways) | D15: Y | E15: Y | F15: Frontal Impact Crashes involving vehicle making a movement that is restricted in the after period | G15: Varies by Treatment - Other Targets may be necessary depending on the situation (i.e. rear end crashes alleviated due to a movement restriction) | H15: Analyze a Potential Area of Influence / Downstream U-Turn Crashes in the additional information table and/or the discussion
C16: New Traffic Signal | D16: Y | F16: Frontal Impact Crashes in Intersection
C17: Pedestrian/Bicycle Treatments | D17: Y | F17: Pedestrian and Bicycle Crashes | H17: For a Pedestrian signal, rear end crashes may also need to be analyzed
C18: Remove Access/Intersection | D18: Y | E18: Y | F18: Frontal Impact Crashes in Intersection* | G18: Varies by Treatment - Other Targets may be necessary depending on the situation (i.e. Rear End Crashes) | H18: *Target crashes can vary depending on the specifics of what was removed
C19: Right Turn Lane at Intersection | D19: Y | E19: Y | F19: Rear End Crashes Approaching Intersection on Treated Approaches | G19: Sideswipe Crashes Approaching Intersection on Treated Approaches | H19: If a multilane facility, rear ends and sideswipes may need to be specific to the outer lanes
C20: Roundabout | D20: Y | F20: Frontal Impact Crashes in Intersection | H20: Particularly for rural roundabouts, note whether there is lighting present within the discussion and detail any patterns regarding nighttime crashes or nighttime lane departures within the additional information table and/or discussion
C21: Sight Distance Improvements at Intersection | D21: Y | F21: Frontal Impact Crashes in Intersection | H21: May need to only include Frontal Impact Crashes involving vehicles making maneuvers directly affected by sight distance improvements (i.e. if one quadrant was cleared)
C22: Traffic Signal Revisions - Flashing Yellow Arrow | D22: Y | F22: Left Turn Same Roadway Crashes on Treated Approaches
C23: Traffic Signal Revisions - Left Turn Phasing Revisions | D23: Y | F23: Left Turn Same Roadway Crashes on Treated Approaches
C24: Vehicle Entering When Flashing | D24: Y | F24: Frontal Impact Crashes involving Vehicles from Treated Approaches | H24: Look at the sign and loop placement to determine what are the treated approaches. If the signs are only on one approach, then only include crashes involving vehicles from that approach. Crashes involving vehicles from the same roadway (Left Turn Same Roadway, Right Turn Same Roadway and Head On Crashes) are typically excluded because the flashers are not displayed to vehicles traveling on the same roadway.
B26: Comments/Instructions for Typical Target Crashes:
B27: ● | C27: Frontal impacts crash types: left-turn same roadway, left-turn different roadway, right-turn same roadway, right-turn different roadway, head-on, and angle crashes

Sheet Evaluation Set-up
B2: Date Range Calculator | J2: AADT Calculator
C4: Most recent TEAAS date | D4: 46203 | F4: Color Key | L4: Representative Years Selection: | P4: Representative Volumes: | T4: Instructions for AADT Calculator:
C5: Construction Period Length (Give Value in Months) | D5: 3 | F5: Cells that need to be edited | L5: Select Before Period Year: | N5: 2019 | P5: Before Period Volume: | R5: =IFERROR(ROUND(VLOOKUP($N$5, $K$11:$R$35, 8, FALSE), -2), "Select Year") -> 5100 | T5: ● | U5: In cells N5 and N6, select the last year within each period that has available volume data (i.e. actual collected volume data, not estimated/interpolated data) | AF5: cells needed for calcs:
F6: Auto-calculated cells | L6: Select After Period Year: | N6: 2022 | P6: After Period Volume: | R6: =IFERROR(ROUND(VLOOKUP($N$6, $K$11:$R$35, 8, FALSE), -2), "Select Year") -> 4200
AH7: Total # of months in between
C8: Time Period | D8: Start Date | E8: End Date | F8: # of Years | G8: # of Months | K8: AADTs for every year within the study period | T8: ● | U8: When inputting volume data into this tool, use Black font color for values taken directly from the available volume data | AF8: =YEAR(E9) -> 2021 | AG8: =MONTH(E9) -> 3 | AH8: =(YEAR(D10)-YEAR(D9))*12+MONTH(D10)-MONTH(D9) -> 60
C9: Before Period | D9: =DATE(AF8-F11,AG8-G11+1,1) -> 42461 | E9: =D10-1 -> 44286 | F9: =ROUNDDOWN(AH8/12,0) -> 5 | G9: =AH8-12*F9 -> 0 | K9: Year | L9: Major Road - Leg #1 | M9: Major Road - Leg #2 | N9: Major Road - Average AADT | O9: Minor Rd - Leg #3 | P9: Minor Rd - Leg #4 | Q9: Minor Road - Average AADT | R9: Intersection AADT | AF9: =YEAR(E10) -> 2021 | AG9: =MONTH(E10) -> 6 | AH9: =(YEAR(D11)-YEAR(D10))*12+MONTH(D11)-MONTH(D10) -> 3
C10: Construction Period | D10: =DATE(AF9,AG9-(D5-1),1) -> 44287 | E10: 44377 | F10: =ROUNDDOWN(AH9/12,0) -> 0 | G10: =AH9-12*F10 -> 3 | T10: ● | U10: When inputting volume data into this tool, use Red font color for values that need to be calculated, interpolated, or assumed | AG10: =E11+1 -> 46204 | AH10: =(YEAR(AG10)-YEAR(D11))*12+MONTH(AG10)-MONTH(D11) -> 60
C11: After Period | D11: =E10+1 -> 44378 | E11: =D4 -> 46203 | F11: =ROUNDDOWN(AH10/12,0) -> 5 | G11: =AH10-12*F11 -> 0 | K11: 2006 | N11: =IF(COUNT(L11:M11) = 0, "",L11/2+M11/2) | Q11: =IF(COUNT(O11:P11) = 0, "",O11/2+P11/2) | R11: =IF(COUNT(L11:M11) = 0, "",N11+Q11)
K12: 2007 | N12: =IF(COUNT(L12:M12) = 0, "",L12/2+M12/2) | Q12: =IF(COUNT(O12:P12) = 0, "",O12/2+P12/2) | R12: =IF(COUNT(L12:M12) = 0, "",N12+Q12) | T12: ● | U12: Input AADTs for every year that appears in the study range (Before and After Period). You do not need to input volumes for the years outside of the study time periods
B13: Comments/Instruction on Date Range Calculator: | K13: 2008 | N13: =IF(COUNT(L13:M13) = 0, "",L13/2+M13/2) | Q13: =IF(COUNT(O13:P13) = 0, "",O13/2+P13/2) | R13: =IF(COUNT(L13:M13) = 0, "",N13+Q13)
B14: ● | C14: Use a typical 3-month Construction Period unless you have specific information to the contrary (ex. construction dates were provided, info from satellite views, etc.). | K14: 2009 | N14: =IF(COUNT(L14:M14) = 0, "",L14/2+M14/2) | Q14: =IF(COUNT(O14:P14) = 0, "",O14/2+P14/2) | R14: =IF(COUNT(L14:M14) = 0, "",N14+Q14)
K15: 2010 | N15: =IF(COUNT(L15:M15) = 0, "",L15/2+M15/2) | Q15: =IF(COUNT(O15:P15) = 0, "",O15/2+P15/2) | R15: =IF(COUNT(L15:M15) = 0, "",N15+Q15) | T15: ● | U15: Volumes should be entered in for each leg of the intersection, even if no count data is available. Legs without available volume counts will need to have their volumes estimated.
B16: ● | C16: You CAN input the construction start date directly into cell D10 or simply just enter in the construction period length into cells D5/D6. | K16: 2011 | N16: =IF(COUNT(L16:M16) = 0, "",L16/2+M16/2) | Q16: =IF(COUNT(O16:P16) = 0, "",O16/2+P16/2) | R16: =IF(COUNT(L16:M16) = 0, "",N16+Q16)
K17: 2012 | N17: =IF(COUNT(L17:M17) = 0, "",L17/2+M17/2) | Q17: =IF(COUNT(O17:P17) = 0, "",O17/2+P17/2) | R17: =IF(COUNT(L17:M17) = 0, "",N17+Q17)
B18: ● | C18: This tool only works in WHOLE MONTHS. Construction start dates should be rounded up to the first of the month and construction end dates should be rounded down to the end the month. | K18: 2013 | N18: =IF(COUNT(L18:M18) = 0, "",L18/2+M18/2) | Q18: =IF(COUNT(O18:P18) = 0, "",O18/2+P18/2) | R18: =IF(COUNT(L18:M18) = 0, "",N18+Q18) | T18: ● | U18: In the case of a T-intersection, leave leg #4 blank (Column Q)
K19: 2014 | N19: =IF(COUNT(L19:M19) = 0, "",L19/2+M19/2) | Q19: =IF(COUNT(O19:P19) = 0, "",O19/2+P19/2) | R19: =IF(COUNT(L19:M19) = 0, "",N19+Q19) | T19: ● | U19: Intersections with 5 or more legs should just have the yearly volumes for the WHOLE intersection calcuated manually and entered into column R.
K20: 2015 | N20: =IF(COUNT(L20:M20) = 0, "",L20/2+M20/2) | Q20: =IF(COUNT(O20:P20) = 0, "",O20/2+P20/2) | R20: =IF(COUNT(L20:M20) = 0, "",N20+Q20)
K21: 2016 | L21: 4100 | M21: 2200 | N21: =IF(COUNT(L21:M21) = 0, "",L21/2+M21/2) -> 3150 | O21: 1400 | P21: 1400 | Q21: =IF(COUNT(O21:P21) = 0, "",O21/2+P21/2) -> 1400 | R21: =IF(COUNT(L21:M21) = 0, "",N21+Q21) -> 4550
K22: 2017 | L22: 4100 | M22: 2650 | N22: =IF(COUNT(L22:M22) = 0, "",L22/2+M22/2) -> 3375 | O22: 1400 | P22: 1400 | Q22: =IF(COUNT(O22:P22) = 0, "",O22/2+P22/2) -> 1400 | R22: =IF(COUNT(L22:M22) = 0, "",N22+Q22) -> 4775 | T22: ● | U22: Please note that this tool will not correctly calculate the AADT of an intersection that involves a one-way road. Should the major or minor road involve one-way traffic, the total entering volume into the intersection by that road should be directly entered into Column O (if the major road is one-way) or column R (if the minor road is one-way)
K23: 2018 | L23: 4300 | M23: 3100 | N23: =IF(COUNT(L23:M23) = 0, "",L23/2+M23/2) -> 3700 | O23: 1400 | P23: 1400 | Q23: =IF(COUNT(O23:P23) = 0, "",O23/2+P23/2) -> 1400 | R23: =IF(COUNT(L23:M23) = 0, "",N23+Q23) -> 5100
K24: 2019 | L24: 4500 | M24: 2850 | N24: =IF(COUNT(L24:M24) = 0, "",L24/2+M24/2) -> 3675 | O24: 1400 | P24: 1400 | Q24: =IF(COUNT(O24:P24) = 0, "",O24/2+P24/2) -> 1400 | R24: =IF(COUNT(L24:M24) = 0, "",N24+Q24) -> 5075
K25: 2020 | L25: 4000 | M25: 2600 | N25: =IF(COUNT(L25:M25) = 0, "",L25/2+M25/2) -> 3300 | O25: 1400 | P25: 1400 | Q25: =IF(COUNT(O25:P25) = 0, "",O25/2+P25/2) -> 1400 | R25: =IF(COUNT(L25:M25) = 0, "",N25+Q25) -> 4700
K26: 2021 | L26: 3500 | M26: 2350 | N26: =IF(COUNT(L26:M26) = 0, "",L26/2+M26/2) -> 2925 | O26: 1400 | P26: 1400 | Q26: =IF(COUNT(O26:P26) = 0, "",O26/2+P26/2) -> 1400 | R26: =IF(COUNT(L26:M26) = 0, "",N26+Q26) -> 4325
K27: 2022 | L27: 3500 | M27: 2100 | N27: =IF(COUNT(L27:M27) = 0, "",L27/2+M27/2) -> 2800 | O27: 1400 | P27: 1400 | Q27: =IF(COUNT(O27:P27) = 0, "",O27/2+P27/2) -> 1400 | R27: =IF(COUNT(L27:M27) = 0, "",N27+Q27) -> 4200
K28: 2023 | L28: 3500 | M28: 2100 | N28: =IF(COUNT(L28:M28) = 0, "",L28/2+M28/2) -> 2800 | O28: 1400 | P28: 1400 | Q28: =IF(COUNT(O28:P28) = 0, "",O28/2+P28/2) -> 1400 | R28: =IF(COUNT(L28:M28) = 0, "",N28+Q28) -> 4200 | T28: ● | U28: Do not select 2020 as a representative year for a particular time period, due to the effects of the COVID-19 pandemic, even if it is the last year with available AADT data within said time period.
K29: 2024 | L29: 3500 | M29: 2100 | N29: =IF(COUNT(L29:M29) = 0, "",L29/2+M29/2) -> 2800 | O29: 1400 | P29: 1400 | Q29: =IF(COUNT(O29:P29) = 0, "",O29/2+P29/2) -> 1400 | R29: =IF(COUNT(L29:M29) = 0, "",N29+Q29) -> 4200
K30: 2025 | L30: 3500 | M30: 2100 | N30: =IF(COUNT(L30:M30) = 0, "",L30/2+M30/2) -> 2800 | O30: 1400 | P30: 1400 | Q30: =IF(COUNT(O30:P30) = 0, "",O30/2+P30/2) -> 1400 | R30: =IF(COUNT(L30:M30) = 0, "",N30+Q30) -> 4200
K31: 2026 | L31: 3500 | M31: 2100 | N31: =IF(COUNT(L31:M31) = 0, "",L31/2+M31/2) -> 2800 | O31: 1400 | P31: 1400 | Q31: =IF(COUNT(O31:P31) = 0, "",O31/2+P31/2) -> 1400 | R31: =IF(COUNT(L31:M31) = 0, "",N31+Q31) -> 4200
K32: 2027 | N32: =IF(COUNT(L32:M32) = 0, "",L32/2+M32/2) | Q32: =IF(COUNT(O32:P32) = 0, "",O32/2+P32/2) | R32: =IF(COUNT(L32:M32) = 0, "",N32+Q32)
K33: 2028 | N33: =IF(COUNT(L33:M33) = 0, "",L33/2+M33/2) | Q33: =IF(COUNT(O33:P33) = 0, "",O33/2+P33/2) | R33: =IF(COUNT(L33:M33) = 0, "",N33+Q33)
K34: 2029 | N34: =IF(COUNT(L34:M34) = 0, "",L34/2+M34/2) | Q34: =IF(COUNT(O34:P34) = 0, "",O34/2+P34/2) | R34: =IF(COUNT(L34:M34) = 0, "",N34+Q34)
K35: 2030 | N35: =IF(COUNT(L35:M35) = 0, "",L35/2+M35/2) | Q35: =IF(COUNT(O35:P35) = 0, "",O35/2+P35/2) | R35: =IF(COUNT(L35:M35) = 0, "",N35+Q35)

Sheet Original Fiche
A1: Muni. Code | B1: On Road | C1: Miles | D1: Dir From | E1: From Road | F1: Toward Road | G1: Milepost Road | H1: MP | I1: MA | J1: Crash ID | K1: Date | L1: T | M1: C | N1: F | O1: L | P1: S | Q1: Latitude | R1: Longitude | S1: Source
A2: 558 | B2: *LCL CAR WASH PVA | C2: 0.001 | D2: E | E2: SR 1001 | F2: DEAD END | H2: 999.999 | J2: 105722912 | K2: 12/18/2018 | L2: 31 | M2: 1 | N2: 0 | O2: 1 | P2: O
A3: 558 | B3: *PP 1518 TOM BOYD RD | C3: 0.014 | D3: W | E3: SR 1619 | F3: *LCL - | H3: 999.999 | J3: 104698395 | K3: 4/9/2016 | L3: 31 | M3: 1 | N3: 5 | O3: 5 | P3: O
A4: 0 | B4: *PP 2815 OLD CAMDEN RD | C4: 0.019 | D4: W | E4: SR 1606 | F4: DEAD END | H4: 999.999 | J4: 107479024 | K4: 10/4/2023 | L4: 20 | M4: 1 | N4: 5 | O4: 5 | P4: O
A5: 558 | B5: HAIGLER BAUCOM | C5: 0.005 | D5: E | E5: SIKES MILL | F5: LOVE MILL | H5: 999.999 | J5: 107442545 | K5: 8/30/2023 | L5: 21 | M5: 2 | N5: 8 | O5: 1 | P5: O
A6: 558 | B6: LOVE MILL | C6: 0.23 | D6: N | E6: *LCL A G R NANCE RD | F6: ZEBULON WILLIAMS | H6: 999.999 | J6: 108377465 | K6: 1/20/2026 | L6: 19 | M6: 1 | N6: 0 | O6: 1 | P6: O
A7: 558 | B7: LOVE MILL | C7: 0 | E7: *LCL PIEDMONT SCH DR | F7: SIKES MILL | H7: 999.999 | J7: 108397947 | K7: 2/10/2026 | L7: 26 | M7: 1 | N7: 8 | O7: 1 | P7: O
A8: 558 | B8: LOVE MILL | C8: 0.072 | D8: N | E8: *LCL PURSER RUSHING RD | F8: HAIGLER BAUCOM | H8: 999.999 | J8: 107756918 | K8: 6/20/2024 | L8: 23 | M8: 1 | N8: 5 | O8: 3 | P8: O
A9: 558 | B9: LOVE MILL | C9: 0.25 | D9: N | E9: *LCL PURSER RUSHING RD | F9: HAIGLER BAUCOM | H9: 999.999 | J9: 108479327 | K9: 4/28/2026 | L9: 17 | M9: 1 | N9: 0 | O9: 5 | P9: O
A10: 558 | B10: PIEDMONT SCHOOL | C10: 0.019 | D10: N | E10: LOVE MILL | F10: DEAD END | H10: 999.999 | J10: 107528155 | K10: 11/14/2023 | L10: 21 | M10: 1 | N10: 12 | O10: 1 | P10: O
A11: 558 | B11: PIEDMONT SCHOOL | C11: 0.005 | D11: W | E11: SR 1001 | F11: *LCL - | H11: 999.999 | J11: 105971602 | K11: 8/26/2019 | L11: 24 | M11: 1 | N11: 4 | O11: 1 | P11: O
A12: 558 | B12: PVA 2623 SIKES MILL RD | C12: 0.009 | D12: W | E12: SR 1001 | F12: SR 1618 | H12: 999.999 | J12: 107250998 | K12: 2/9/2023 | L12: 20 | M12: 1 | N12: 4 | O12: 1 | P12: O
A13: 0 | B13: PVA 3006 SIKES MILL RD | C13: 0.004 | D13: E | E13: SR 1001 | F13: DEAD END | H13: 999.999 | J13: 105983673 | K13: 9/3/2019 | L13: 21 | M13: 1 | N13: 4 | O13: 1 | P13: O
A14: 558 | B14: PVA 3006 SIKES MILL RD | C14: 0.018 | D14: E | E14: SR 1606 | F14: SR 1001 | H14: 999.999 | J14: 107844251 | K14: 9/5/2024 | L14: 31 | M14: 1 | N14: 0 | O14: 1 | P14: O | Q14: 35.09455 | R14: -80.4927 | S14: DMV349
A15: 637 | B15: PVA 6609 SIKES MILL RD | C15: 0.028 | D15: W | E15: SIKES MILL | H15: 999.999 | J15: 106254686 | K15: 6/19/2020 | L15: 31 | M15: 1 | N15: 4 | O15: 1 | P15: O
A16: 558 | B16: PVA 709 SIKES MILL RD | C16: 0.005 | D16: W | E16: SR 1001 | F16: DEAD END | H16: 999.999 | J16: 107994713 | K16: 1/17/2025 | L16: 20 | M16: 1 | N16: 5 | O16: 2
A17: 558 | B17: PVA MARATHON | C17: 0.019 | D17: W | E17: SIKES MILL | H17: 999.999 | J17: 106584227 | K17: 5/25/2021 | L17: 31 | M17: 1 | N17: 4 | O17: 1 | P17: O
A18: 558 | B18: PVA MARATHON | C18: 0.019 | D18: W | E18: SIKES MILL | H18: 999.999 | J18: 106303935 | K18: 8/12/2020 | L18: 20 | M18: 1 | N18: 4 | O18: 1 | P18: O
A19: 558 | B19: PVA MARATHON | C19: 0.009 | D19: W | E19: SR 1001 | F19: SR 1618 | H19: 999.999 | J19: 108345733 | K19: 12/19/2025 | L19: 20 | M19: 1 | N19: 4 | O19: 1 | P19: O | Q19: 35.08 | R19: -80.49 | S19: DMV349
A20: 558 | B20: PVA MARATHON GAS | C20: 0.014 | D20: W | E20: SR 1001 | F20: DEAD END | H20: 999.999 | J20: 105790718 | K20: 3/2/2019 | L20: 31 | M20: 1 | N20: 0 | O20: 1 | P20: O
A21: 558 | B21: PVA MARATHON GAS | C21: 0.019 | D21: W | E21: SR 1001 | F21: DEAD END | H21: 999.999 | J21: 106747056 | K21: 10/29/2021 | L21: 31 | M21: 1 | N21: 0 | O21: 1 | P21: O
A22: 558 | B22: PVA MARATHON GAS STATION | C22: 0.019 | D22: W | E22: SR 1001 | F22: DEAD END | H22: 999.999 | J22: 107692192 | K22: 4/18/2024 | L22: 31 | M22: 1 | N22: 4 | O22: 1 | P22: O | Q22: 35.0886 | R22: -80.49449 | S22: DMV349
A23: 558 | B23: PVA MARATHON GAS STATION | C23: 0.014 | D23: W | E23: SR 1606 | F23: SR 1001 | H23: 999.999 | J23: 105060300 | K23: 3/20/2017 | L23: 31 | M23: 1 | N23: 4 | O23: 1 | P23: O
A24: 558 | B24: PVA PIEDMONT HIGH SCHOOL | C24: 0.009 | D24: W | E24: SR 1001 | F24: *LCL - | H24: 999.999 | J24: 104865813 | K24: 9/29/2016 | L24: 21 | M24: 2 | N24: 4 | O24: 1 | P24: C
A25: 558 | B25: PVA PIEDMONT HIGH SCHOOL | C25: 0.017 | D25: W | E25: SR 1001 | F25: DEAD END | H25: 999.999 | J25: 104945962 | K25: 12/12/2016 | L25: 21 | M25: 1 | N25: 4 | O25: 1 | P25: O
A26: 558 | B26: PVA PIEDMONT HIGH SCHOOL | C26: 0.017 | D26: W | E26: SR 1001 | F26: DEAD END | H26: 999.999 | J26: 104950470 | K26: 12/12/2016 | L26: 21 | M26: 1 | N26: 4 | O26: 1 | P26: O
A27: 558 | B27: PVA PIEDMONT HIGH SCHOOL | C27: 0.004 | D27: E | E27: SR 1606 | F27: SR 1678 | H27: 999.999 | J27: 107118944 | K27: 10/13/2022 | L27: 31 | M27: 1 | N27: 4 | O27: 1 | P27: O
A28: 558 | B28: PVA PIEDMONT HS | C28: 0.028 | D28: E | E28: SIKES MILL | H28: 999.999 | J28: 107711938 | K28: 5/7/2024 | L28: 23 | M28: 1 | N28: 4 | O28: 1 | P28: O
A29: 558 | B29: PVA PIEDMONT MIDDLE | C29: 0 | E29: SR 1001 | F29: DEAD END | H29: 999.999 | J29: 105740561 | K29: 1/7/2019 | L29: 21 | M29: 1 | N29: 8 | O29: 1 | P29: O
A30: 558 | B30: PVA PIEDMONT MIDDLE SCHOOL | C30: 0.001 | D30: E | E30: SIKES MILL | H30: 999.999 | J30: 108247372 | K30: 9/30/2025 | L30: 21 | M30: 2 | N30: 4 | O30: 1 | P30: O
A31: 558 | B31: PVA PIEDMONT MIDDLE SCHOOL | C31: 0.019 | D31: E | E31: SIKES MILL | H31: 999.999 | J31: 107683218 | K31: 4/11/2024 | L31: 31 | M31: 2 | N31: 4 | O31: 1 | P31: O
A32: 558 | B32: PVA PIEDMONT MIDDLE SCHOOL | C32: 0.019 | D32: E | E32: SR 1606 | F32: DEAD END | H32: 999.999 | J32: 105226618 | K32: 9/20/2017 | L32: 21 | M32: 1 | N32: 8 | O32: 1 | P32: O
A33: 558 | B33: SIKES MILL | C33: 0.14 | D33: N | E33: *LCL PIEDMONT SCH DR | F33: HAIGLER BAUCOM | H33: 999.999 | J33: 108319024 | K33: 11/25/2025 | L33: 24 | M33: 1 | N33: 4 | O33: 1 | P33: B
A34: 558 | B34: SIKES MILL | C34: 0.038 | D34: N | E34: *LCL PIEDMONT SCH RD | F34: HAIGLER BAUCOM | H34: 999.999 | J34: 107926331 | K34: 11/15/2024 | L34: 24 | M34: 1 | N34: 4 | O34: 1 | P34: O
A35: 558 | B35: SR 1001 | C35: 0 | E35: *LCL PEIDMONT SCHOOL RD | F35: SR 1674 | H35: 999.999 | J35: 108430866 | K35: 3/13/2026 | L35: 24 | M35: 1 | N35: 5 | O35: 1 | P35: C | Q35: 35.093641 | R35: -80.4873 | S35: DMV349CLEANED
A36: 0 | B36: SR 1606 | C36: 0.25 | D36: S | E36: *LCL BIGGERS CEMETERY RD | F36: OLD FERRY | H36: 999.999 | J36: 105935402 | K36: 7/22/2019 | L36: 29 | M36: 1 | N36: 0 | O36: 1 | P36: O
A37: 0 | B37: SR 1606 | C37: 0.3 | D37: E | E37: *LCL CAMDEN OAKS LN | F37: SR 1006 | H37: 999.999 | J37: 106214571 | K37: 4/30/2020 | L37: 29 | M37: 1 | N37: 1 | O37: 1 | P37: O
A38: 558 | B38: TOM BOYD | C38: 0.024 | D38: SE | E38: *LCL LATHAN WOODS DR | F38: OLD CAMDEN | H38: 999.999 | J38: 104734401 | K38: 5/12/2016 | L38: 21 | M38: 2 | N38: 5 | O38: 5 | P38: O
A39: 558 | B39: TOM BOYD | C39: 0 | E39: OLD CAMDEN | F39: SIKES MILL | H39: 999.999 | J39: 105415127 | K39: 3/12/2018 | L39: 30 | M39: 2 | N39: 7 | O39: 1 | P39: C
A40: 558 | B40: TOM BOYD | C40: 0.16 | D40: NE | E40: OLD CAMDEN | F40: *LCL LATHAM WOODS DR | H40: 999.999 | J40: 106910957 | K40: 4/4/2022 | L40: 17 | M40: 1 | N40: 0 | O40: 5 | P40: O
...

Sheet Filtered Fiche
A1: Muni. Code | B1: On Road | C1: Miles | D1: Dir From | E1: From Road | F1: Toward Road | G1: Milepost Road | H1: MP | I1: IS | J1: New MP | K1: MA | L1: Crash ID | M1: Date | N1: T | O1: C | P1: F | Q1: L | R1: S | S1: Comments
A2: IN STUDY
A3: 558 | B3: SR 1001 | C3: 0.019 | D3: S | E3: SR 1617 | G3: SR 1001 | H3: 3.442 | I3: IS | L3: 105520583 | M3: 6/20/2018 | N3: 19 | O3: 2 | P3: 0 | Q3: 1 | R3: O | S3: SR 1001 MP 3.442, 100 ft south; NB ran off right into the ditch, charged safe speed; not intersection related
A4: 558 | B4: SR 1001 | C4: 0.014 | D4: S | E4: TOM BOYD | F4: SR 1606 | G4: SR 1001 | H4: 3.447 | I4: IS | L4: 105553349 | M4: 7/23/2018 | N4: 18 | O4: 2 | P4: 0 | Q4: 1 | R4: O | S4: SR 1001 MP 3.447, 74 ft south; NB at 65 crossed the centerline into the ditch; not intersection related
A5: 558 | B5: SIKES MILL | C5: 0 | E5: TOM BOYD | F5: UNIONVILLE | G5: SR 1001 | H5: 3.461 | I5: IS | L5: 107601791 | M5: 1/23/2024 | N5: 30 | O5: 2 | P5: 7 | Q5: 1 | R5: O | S5: coded at the junction, 0.000 from the study pair; EB Tom Boyd failed to yield from the stop; both at 10 mph
A6: 558 | B6: SIKES MILL | C6: 0 | E6: TOM BOYD | F6: UNIONVILLE | G6: SR 1001 | H6: 3.461 | I6: IS | L6: 106772984 | M6: 11/19/2021 | N6: 30 | O6: 1 | P6: 7 | Q6: 1 | R6: O | S6: coded at the junction, 0.000 from the study pair; both at 10 to 15 mph; officer could not determine which failed to yield
A7: 558 | B7: SIKES MILL | C7: 0 | E7: TOM BOYD | F7: LOVE MILL | G7: SR 1001 | H7: 3.461 | I7: IS | L7: 107870118 | M7: 10/3/2024 | N7: 30 | O7: 1 | P7: 7 | Q7: 1 | R7: O | S7: coded at the junction, 0.000 from the study pair; NB SR 1001 failed to stop at the new all way stop at 25
A8: 558 | B8: SIKES MILL | C8: 0 | E8: TOM BOYD | F8: LAWYERS | G8: SR 1001 | H8: 3.461 | I8: IS | L8: 106133705 | M8: 1/23/2020 | N8: 30 | O8: 1 | P8: 7 | Q8: 1 | R8: O | S8: coded at the junction, 0.000 from the study pair; EB west leg failed to yield at 15 against the NB through
A9: 558 | B9: SR 1001 | C9: 0 | E9: SR 1617 | F9: SR 1618 | G9: SR 1001 | H9: 3.461 | I9: IS | L9: 108250468 | M9: 10/1/2025 | N9: 30 | O9: 1 | P9: 7 | Q9: 5 | R9: O | S9: at the junction; DMV349 coords 0 ft; both departed their stops at 5 mph; no fault determined
A10: 558 | B10: SR 1001 | C10: 0 | E10: SR 1617 | F10: SR 1606 | G10: SR 1001 | H10: 3.461 | I10: IS | L10: 108279485 | M10: 10/23/2025 | N10: 30 | O10: 1 | P10: 7 | Q10: 1 | R10: C | S10: at the junction; DMV349 coords 12 ft; WB SR 1001 failed to stop at the four way at 45, charged failed to stop; the after period target C injury
A11: 558 | B11: SR 1001 | C11: 0 | E11: SR 1617 | F11: SR 1681 | G11: SR 1001 | H11: 3.461 | I11: IS | L11: 107902086 | M11: 10/28/2024 | N11: 30 | O11: 1 | P11: 7 | Q11: 1 | R11: O | S11: at the junction; DMV349 coords 10 ft; NB SR 1001 failed to yield from the stop sign; both from stops at 5 mph
A12: 0 | B12: SR 1001 | C12: 0 | E12: SR 1617 | G12: SR 1001 | H12: 3.461 | I12: IS | L12: 106743409 | M12: 10/25/2021 | N12: 30 | O12: 1 | P12: 7 | Q12: 5 | R12: O | S12: coded at the junction, 0.000 from the study pair; NB SR 1001 pulled from the new stop into a crossing vehicle nearly clear; failed to yield, charged; 5 to 10 mph
A13: 558 | B13: SR 1001 | C13: 0 | E13: SR 1617 | F13: SR 1615 | G13: SR 1001 | H13: 3.461 | I13: IS | L13: 106286453 | M13: 7/25/2020 | N13: 30 | O13: 1 | P13: 7 | Q13: 1 | R13: C | S13: coded at the junction, 0.000 from the study pair; EB west leg crossed at 10 against the NB through; charged failure to yield
A14: 0 | B14: SR 1001 | C14: 0 | E14: SR 1617 | F14: SR 1615 | G14: SR 1001 | H14: 3.461 | I14: IS | L14: 105535858 | M14: 7/9/2018 | N14: 30 | O14: 1 | P14: 7 | Q14: 1 | R14: B | S14: coded at the junction, 0.000 from the study pair; SE west leg ran the stop sign at 50, struck broadside; ran on to sideswipe the house at 2220 Sikes Mill Rd; charged stop sign violation
A15: 558 | B15: SR 1001 | C15: 0 | E15: SR 1617 | F15: SR 1681 | G15: SR 1001 | H15: 3.461 | I15: IS | L15: 105326435 | M15: 12/16/2017 | N15: 30 | O15: 1 | P15: 7 | Q15: 1 | R15: A | S15: coded at the junction, 0.000 from the study pair; EB west leg ran the stop sign, struck a SB truck trailer's saddle fuel tank; the A injury; charged stop sign violation
A16: 558 | B16: SR 1001 | C16: 0 | E16: SR 1617 | F16: SR 1615 | G16: SR 1001 | H16: 3.461 | I16: IS | L16: 105210461 | M16: 8/30/2017 | N16: 30 | O16: 1 | P16: 7 | Q16: 1 | R16: C | S16: coded at the junction, 0.000 from the study pair; EB west leg stopped, then entered against the NB through; failed to yield, charged
A17: 558 | B17: SR 1001 | C17: 0 | E17: SR 1617 | F17: SR 1615 | G17: SR 1001 | H17: 3.461 | I17: IS | L17: 104890928 | M17: 10/10/2016 | N17: 30 | O17: 1 | P17: 7 | Q17: 1 | R17: C | S17: coded at the junction, 0.000 from the study pair; WB east leg stopped at the sign, pulled into the SB through; failed to yield, charged
A18: 558 | B18: SR 1001 | C18: 0 | E18: SR 1617 | F18: SR 1618 | G18: SR 1001 | H18: 3.461 | I18: IS | L18: 104901954 | M18: 11/2/2016 | N18: 30 | O18: 1 | P18: 7 | Q18: 1 | R18: O | S18: coded at the junction, 0.000 from the study pair; WB east leg pulled from the stop into the SB through, then struck the opposite waiting vehicle; failed to yield, charged unsafe movement
A19: 558 | B19: SR 1001 | C19: 0 | E19: SR 1617 | F19: SR 1615 | G19: SR 1001 | H19: 3.461 | I19: IS | L19: 104987740 | M19: 1/25/2017 | N19: 30 | O19: 1 | P19: 7 | Q19: 1 | R19: B | S19: coded at the junction, 0.000 from the study pair; WB east leg ran the stop sign at 45; charged stop sign violation
A20: 0 | B20: SR 1001 | C20: 0 | E20: SR 1617 | F20: SR 1615 | G20: SR 1001 | H20: 3.461 | I20: IS | L20: 104942804 | M20: 12/8/2016 | N20: 30 | O20: 1 | P20: 7 | Q20: 1 | R20: B | S20: coded at the junction, 0.000 from the study pair; WB east leg stopped, then entered against the SB through; failed to yield
A21: 558 | B21: SIKES MILL | C21: 0.005 | D21: N | E21: TOM BOYD | F21: LOVE MILL | G21: SR 1001 | H21: 3.466 | I21: IS | L21: 107945637 | M21: 12/4/2024 | N21: 21 | O21: 1 | P21: 7 | Q21: 1 | R21: C | S21: SR 1001 MP 3.466, 26 ft north; rear end into a vehicle stopped at the all way stop, failed to reduce speed; the after period C injury
A22: 558 | B22: SR 1001 | C22: 0.005 | D22: N | E22: SR 1617 | F22: SR 1637 | G22: SR 1001 | H22: 3.466 | I22: IS | L22: 106126767 | M22: 1/13/2020 | N22: 21 | O22: 2 | P22: 7 | Q22: 1 | R22: O | S22: SR 1001 MP 3.466, 26 ft north; SB queue rear end, vehicles stopped for traffic flow ahead; charged failure to reduce speed
A23: 558 | B23: SR 1617 | C23: 0.028 | D23: W | E23: SR 1001 | F23: SR 1615 | G23: SR 1617 | H23: 0.512 | I23: IS | L23: 105885258 | M23: 6/4/2019 | N23: 29 | O23: 1 | P23: 0 | Q23: 1 | R23: O | S23: SR 1617 MP 0.512, 148 ft west, right at the y-line; opposite direction mirror strike on Tom Boyd, unit 1 fled; not control related
A24: 558 | B24: SR 1617 | C24: 0 | E24: SR 1001 | G24: SR 1617 | H24: 0.54 | I24: IS | L24: 104716467 | M24: 4/27/2016 | N24: 30 | O24: 1 | P24: 7 | Q24: 1 | R24: O | S24: at the junction, SR 1617 MP 0.540; EB west leg stopped, then failed to yield crossing; charged failure to yield
A25: ADDED TO STUDY
A26: 558 | B26: SR 1001 | C26: 0 | E26: SR 1619 | F26: SR 1618 | G26: SR 1001 | H26: 3.461 | I26: ADD | L26: 105363964 | M26: 1/26/2018 | N26: 30 | O26: 1 | P26: 7 | Q26: 5 | R26: C | S26: confirmed at the study intersection (report 0 ft, at SR 1619): WB east leg stopped, then failed to yield into the SB SR 1001 vehicle; charged fail to yield at stop sign; angle, target type, before period
A27: NOT IN STUDY - REPORT REVIEWED
A28: 558 | B28: *PP 1518 TOM BOYD RD | C28: 0.014 | D28: W | E28: SR 1619 | F28: *LCL - | H28: 999.999 | I28: NIS | L28: 104698395 | M28: 4/9/2016 | N28: 31 | O28: 1 | P28: 5 | Q28: 5 | R28: O | S28: confirmed off roadway: backed into a parked vehicle on the private drive at 1518 Tom Boyd Rd, 75 ft off the road
A29: 558 | B29: SR 1001 | C29: 0.1 | D29: N | E29: SR 1615 | F29: SR 1617 | G29: SR 1001 | H29: 2.971 | I29: NIS | L29: 108184887 | M29: 7/27/2025 | N29: 19 | O29: 1 | P29: 0 | Q29: 1 | R29: A | S29: confirmed elsewhere: ran off left mid block and struck a tree; the report's coded reference and its own coordinates disagree but both fall outside the y-line
A30: 558 | B30: SR 1001 | C30: 0.038 | D30: S | E30: SR 1617 | F30: US 601 | G30: SR 1001 | H30: 3.423 | I30: NIS | L30: 105964079 | M30: 8/15/2019 | N30: 19 | O30: 2 | P30: 0 | Q30: 5 | R30: O | S30: confirmed elsewhere: too fast on a wet curve, slid off right, struck the ditch and overturned; no intersection involvement
A31: 558 | B31: SR 1001 | C31: 0.03 | D31: S | E31: SR 1617 | F31: SR 1615 | G31: SR 1001 | H31: 3.431 | I31: NIS | L31: 105208918 | M31: 9/1/2017 | N31: 27 | O31: 3 | P31: 0 | Q31: 1 | R31: C | S31: confirmed elsewhere: ran off right on the curve, overcorrected across the centerline, head on in the southbound lane 156 ft south; lane departure, no intersection involvement
A32: NOT IN STUDY - REPORT NOT REVIEWED
A33: 558 | B33: *LCL CAR WASH PVA | C33: 0.001 | D33: E | E33: SR 1001 | F33: DEAD END | H33: 999.999 | L33: 105722912 | M33: 12/18/2018 | N33: 31 | O33: 1 | P33: 0 | Q33: 1 | R33: O
A34: 0 | B34: *PP 2815 OLD CAMDEN RD | C34: 0.019 | D34: W | E34: SR 1606 | F34: DEAD END | H34: 999.999 | L34: 107479024 | M34: 10/4/2023 | N34: 20 | O34: 1 | P34: 5 | Q34: 5 | R34: O
A35: 558 | B35: HAIGLER BAUCOM | C35: 0.005 | D35: E | E35: SIKES MILL | F35: LOVE MILL | H35: 999.999 | L35: 107442545 | M35: 8/30/2023 | N35: 21 | O35: 2 | P35: 8 | Q35: 1 | R35: O
A36: 558 | B36: LOVE MILL | C36: 0.23 | D36: N | E36: *LCL A G R NANCE RD | F36: ZEBULON WILLIAMS | H36: 999.999 | L36: 108377465 | M36: 1/20/2026 | N36: 19 | O36: 1 | P36: 0 | Q36: 1 | R36: O
A37: 558 | B37: LOVE MILL | C37: 0 | E37: *LCL PIEDMONT SCH DR | F37: SIKES MILL | H37: 999.999 | L37: 108397947 | M37: 2/10/2026 | N37: 26 | O37: 1 | P37: 8 | Q37: 1 | R37: O
A38: 558 | B38: LOVE MILL | C38: 0.072 | D38: N | E38: *LCL PURSER RUSHING RD | F38: HAIGLER BAUCOM | H38: 999.999 | L38: 107756918 | M38: 6/20/2024 | N38: 23 | O38: 1 | P38: 5 | Q38: 3 | R38: O
A39: 558 | B39: LOVE MILL | C39: 0.25 | D39: N | E39: *LCL PURSER RUSHING RD | F39: HAIGLER BAUCOM | H39: 999.999 | L39: 108479327 | M39: 4/28/2026 | N39: 17 | O39: 1 | P39: 0 | Q39: 5 | R39: O
A40: 558 | B40: PIEDMONT SCHOOL | C40: 0.019 | D40: N | E40: LOVE MILL | F40: DEAD END | H40: 999.999 | L40: 107528155 | M40: 11/14/2023 | N40: 21 | O40: 1 | P40: 12 | Q40: 1 | R40: O
...

Sheet Binned Crashes

Sheet Before
A1: Manually Edit These Columns (A -> M) | O1: Don't Edit These Columns (N -> ). Calculations are Automatic.
A2: ="Before Period ("&TEXT('Evaluation Set-up'!D9, "mm/dd/yy")&" - "&TEXT('Evaluation Set-up'!E9, "mm/dd/yy")&")" -> Before Period (04/01/16 - 03/31/21) | O2: Crash # | P2: Crash Year | Q2: Severity Index | R2: Target-1 Severity Index | S2: Target-1 KABCO | T2: Target-2 Severity Index | U2: Target-2 KABCO
A3: Crash ID | B3: Date | C3: T | D3: C | E3: F | F3: L | G3: S | H3: Analyst's Notes Column 1 | I3: Analyst's Notes Column 2 | J3: Analyst's Notes Column 3 | K3: Analyst's Notes Column 4 | L3: Target-1? | M3: Target-2? | Y3: Total | Z3: Target-1 | AA3: Target-2 | AB3: All Targets | AR3: Crash # | AS3: Target Crash?
A4: 104716467 | B4: 42487 | C4: 30 | D4: 1 | E4: 7 | F4: 1 | G4: O | L4: Y | O4: =IF(Q4 = "", "", COUNT(Q$4:$Q4)) -> 1 | P4: =IF(C4 > 0, YEAR(B4), "") -> 2016 | Q4: =IF(A4="", "", IF(G4="",1,IF(G4="O",1,IF(G4="C",8.4,IF(G4="B",8.4,IF(G4="A",76.8,IF(G4="K",76.8,"ERR"))))))) -> 1 | R4: =IF(L4<>"",Q4,"") -> 1 | S4: =IF(IF(L4<>"",G4,"")=0, "O", IF(L4<>"",G4,"")) -> O | T4: =IF(M4<>"",Q4,"") | U4: =IF(IF(M4<>"",G4,"")=0, "O", IF(M4<>"",G4,"")) | X4: K | Y4: =COUNTIF($G$4:$G$1048576,$X4) -> 0 | Z4: =COUNTIF($S$4:$S$1048576,$X4) -> 0 | AA4: =COUNTIF($U$4:$U$1048576,$X4) -> 0 | AB4: =COUNTIF($S:$S, X4)+COUNTIF($U:$U, X4)-COUNTIFS($S:$S, X4, $U:$U, X4) -> 0 | AR4: =IF(O4>0, O4, "") -> 1 | AS4: =IF(OR(L4="Y",M4="Y"),"Y","") -> Y
A5: 104890928 | B5: 42653 | C5: 30 | D5: 1 | E5: 7 | F5: 1 | G5: C | L5: Y | O5: =IF(Q5 = "", "", COUNT(Q$4:$Q5)) -> 2 | P5: =IF(C5 > 0, YEAR(B5), "") -> 2016 | Q5: =IF(A5="", "", IF(G5="",1,IF(G5="O",1,IF(G5="C",8.4,IF(G5="B",8.4,IF(G5="A",76.8,IF(G5="K",76.8,"ERR"))))))) -> 8.4 | R5: =IF(L5<>"",Q5,"") -> 8.4 | S5: =IF(IF(L5<>"",G5,"")=0, "O", IF(L5<>"",G5,"")) -> C | T5: =IF(M5<>"",Q5,"") | U5: =IF(IF(M5<>"",G5,"")=0, "O", IF(M5<>"",G5,"")) | X5: A | Y5: =COUNTIF($G$4:$G$1048576,$X5) -> 1 | Z5: =COUNTIF($S$4:$S$1048576,$X5) -> 1 | AA5: =COUNTIF($U$4:$U$1048576,$X5) -> 0 | AB5: =COUNTIF($S:$S, X5)+COUNTIF($U:$U, X5)-COUNTIFS($S:$S, X5, $U:$U, X5) -> 1 | AR5: =IF(O5>0, O5, "") -> 2 | AS5: =IF(OR(L5="Y",M5="Y"),"Y","") -> Y
A6: 104901954 | B6: 42676 | C6: 30 | D6: 1 | E6: 7 | F6: 1 | G6: O | L6: Y | O6: =IF(Q6 = "", "", COUNT(Q$4:$Q6)) -> 3 | P6: =IF(C6 > 0, YEAR(B6), "") -> 2016 | Q6: =IF(A6="", "", IF(G6="",1,IF(G6="O",1,IF(G6="C",8.4,IF(G6="B",8.4,IF(G6="A",76.8,IF(G6="K",76.8,"ERR"))))))) -> 1 | R6: =IF(L6<>"",Q6,"") -> 1 | S6: =IF(IF(L6<>"",G6,"")=0, "O", IF(L6<>"",G6,"")) -> O | T6: =IF(M6<>"",Q6,"") | U6: =IF(IF(M6<>"",G6,"")=0, "O", IF(M6<>"",G6,"")) | X6: B | Y6: =COUNTIF($G$4:$G$1048576,$X6) -> 3 | Z6: =COUNTIF($S$4:$S$1048576,$X6) -> 3 | AA6: =COUNTIF($U$4:$U$1048576,$X6) -> 0 | AB6: =COUNTIF($S:$S, X6)+COUNTIF($U:$U, X6)-COUNTIFS($S:$S, X6, $U:$U, X6) -> 3 | AR6: =IF(O6>0, O6, "") -> 3 | AS6: =IF(OR(L6="Y",M6="Y"),"Y","") -> Y
A7: 104942804 | B7: 42712 | C7: 30 | D7: 1 | E7: 7 | F7: 1 | G7: B | L7: Y | O7: =IF(Q7 = "", "", COUNT(Q$4:$Q7)) -> 4 | P7: =IF(C7 > 0, YEAR(B7), "") -> 2016 | Q7: =IF(A7="", "", IF(G7="",1,IF(G7="O",1,IF(G7="C",8.4,IF(G7="B",8.4,IF(G7="A",76.8,IF(G7="K",76.8,"ERR"))))))) -> 8.4 | R7: =IF(L7<>"",Q7,"") -> 8.4 | S7: =IF(IF(L7<>"",G7,"")=0, "O", IF(L7<>"",G7,"")) -> B | T7: =IF(M7<>"",Q7,"") | U7: =IF(IF(M7<>"",G7,"")=0, "O", IF(M7<>"",G7,"")) | X7: C | Y7: =COUNTIF($G$4:$G$1048576,$X7) -> 4 | Z7: =COUNTIF($S$4:$S$1048576,$X7) -> 4 | AA7: =COUNTIF($U$4:$U$1048576,$X7) -> 0 | AB7: =COUNTIF($S:$S, X7)+COUNTIF($U:$U, X7)-COUNTIFS($S:$S, X7, $U:$U, X7) -> 4 | AR7: =IF(O7>0, O7, "") -> 4 | AS7: =IF(OR(L7="Y",M7="Y"),"Y","") -> Y
A8: 104987740 | B8: 42760 | C8: 30 | D8: 1 | E8: 7 | F8: 1 | G8: B | L8: Y | O8: =IF(Q8 = "", "", COUNT(Q$4:$Q8)) -> 5 | P8: =IF(C8 > 0, YEAR(B8), "") -> 2017 | Q8: =IF(A8="", "", IF(G8="",1,IF(G8="O",1,IF(G8="C",8.4,IF(G8="B",8.4,IF(G8="A",76.8,IF(G8="K",76.8,"ERR"))))))) -> 8.4 | R8: =IF(L8<>"",Q8,"") -> 8.4 | S8: =IF(IF(L8<>"",G8,"")=0, "O", IF(L8<>"",G8,"")) -> B | T8: =IF(M8<>"",Q8,"") | U8: =IF(IF(M8<>"",G8,"")=0, "O", IF(M8<>"",G8,"")) | X8: O | Y8: =COUNTIF($G$4:$G$1048576,$X8)+COUNTIFS($G$4:$G$1048576, "", $O$4:$O$1048576, ">0") -> 7 | Z8: =COUNTIF($S$4:$S$1048576,$X8) -> 3 | AA8: =COUNTIF($U$4:$U$1048576,$X8) -> 0 | AB8: =COUNTIF($S:$S, X8)+COUNTIF($U:$U, X8)-COUNTIFS($S:$S, X8, $U:$U, X8) -> 3 | AR8: =IF(O8>0, O8, "") -> 5 | AS8: =IF(OR(L8="Y",M8="Y"),"Y","") -> Y
A9: 105210461 | B9: 42977 | C9: 30 | D9: 1 | E9: 7 | F9: 1 | G9: C | L9: Y | O9: =IF(Q9 = "", "", COUNT(Q$4:$Q9)) -> 6 | P9: =IF(C9 > 0, YEAR(B9), "") -> 2017 | Q9: =IF(A9="", "", IF(G9="",1,IF(G9="O",1,IF(G9="C",8.4,IF(G9="B",8.4,IF(G9="A",76.8,IF(G9="K",76.8,"ERR"))))))) -> 8.4 | R9: =IF(L9<>"",Q9,"") -> 8.4 | S9: =IF(IF(L9<>"",G9,"")=0, "O", IF(L9<>"",G9,"")) -> C | T9: =IF(M9<>"",Q9,"") | U9: =IF(IF(M9<>"",G9,"")=0, "O", IF(M9<>"",G9,"")) | X9: Total | Y9: =COUNTIF(O4:O1048576, ">0") -> 15 | Z9: =COUNT(R4:R1048576) -> 11 | AA9: =COUNT(T4:T1048576) -> 0 | AB9: =SUM(AB4:AB8) -> 11 | AR9: =IF(O9>0, O9, "") -> 6 | AS9: =IF(OR(L9="Y",M9="Y"),"Y","") -> Y
A10: 105326435 | B10: 43085 | C10: 30 | D10: 1 | E10: 7 | F10: 1 | G10: A | L10: Y | O10: =IF(Q10 = "", "", COUNT(Q$4:$Q10)) -> 7 | P10: =IF(C10 > 0, YEAR(B10), "") -> 2017 | Q10: =IF(A10="", "", IF(G10="",1,IF(G10="O",1,IF(G10="C",8.4,IF(G10="B",8.4,IF(G10="A",76.8,IF(G10="K",76.8,"ERR"))))))) -> 76.8 | R10: =IF(L10<>"",Q10,"") -> 76.8 | S10: =IF(IF(L10<>"",G10,"")=0, "O", IF(L10<>"",G10,"")) -> A | T10: =IF(M10<>"",Q10,"") | U10: =IF(IF(M10<>"",G10,"")=0, "O", IF(M10<>"",G10,"")) | X10: SI | Y10: =IFERROR(AVERAGE(Q4:Q1048576), 0) -> 9.5066667 | Z10: =IFERROR(AVERAGE(R4:R1048576),0) -> 12.6 | AA10: =IFERROR(AVERAGE(T4:T1048576),0) -> 0 | AB10: =IFERROR(AVERAGEIF($AS$4:$AS$1048576,"Y", Q4:Q1048576 ),0) -> 12.6 | AR10: =IF(O10>0, O10, "") -> 7 | AS10: =IF(OR(L10="Y",M10="Y"),"Y","") -> Y
A11: 105363964 | B11: 43126 | C11: 30 | D11: 1 | E11: 7 | F11: 5 | G11: C | L11: Y | O11: =IF(Q11 = "", "", COUNT(Q$4:$Q11)) -> 8 | P11: =IF(C11 > 0, YEAR(B11), "") -> 2018 | Q11: =IF(A11="", "", IF(G11="",1,IF(G11="O",1,IF(G11="C",8.4,IF(G11="B",8.4,IF(G11="A",76.8,IF(G11="K",76.8,"ERR"))))))) -> 8.4 | R11: =IF(L11<>"",Q11,"") -> 8.4 | S11: =IF(IF(L11<>"",G11,"")=0, "O", IF(L11<>"",G11,"")) -> C | T11: =IF(M11<>"",Q11,"") | U11: =IF(IF(M11<>"",G11,"")=0, "O", IF(M11<>"",G11,"")) | AR11: =IF(O11>0, O11, "") -> 8 | AS11: =IF(OR(L11="Y",M11="Y"),"Y","") -> Y
A12: 105520583 | B12: 43271 | C12: 19 | D12: 2 | E12: 0 | F12: 1 | G12: O | O12: =IF(Q12 = "", "", COUNT(Q$4:$Q12)) -> 9 | P12: =IF(C12 > 0, YEAR(B12), "") -> 2018 | Q12: =IF(A12="", "", IF(G12="",1,IF(G12="O",1,IF(G12="C",8.4,IF(G12="B",8.4,IF(G12="A",76.8,IF(G12="K",76.8,"ERR"))))))) -> 1 | R12: =IF(L12<>"",Q12,"") | S12: =IF(IF(L12<>"",G12,"")=0, "O", IF(L12<>"",G12,"")) | T12: =IF(M12<>"",Q12,"") | U12: =IF(IF(M12<>"",G12,"")=0, "O", IF(M12<>"",G12,"")) | AR12: =IF(O12>0, O12, "") -> 9 | AS12: =IF(OR(L12="Y",M12="Y"),"Y","")
A13: 105535858 | B13: 43290 | C13: 30 | D13: 1 | E13: 7 | F13: 1 | G13: B | L13: Y | O13: =IF(Q13 = "", "", COUNT(Q$4:$Q13)) -> 10 | P13: =IF(C13 > 0, YEAR(B13), "") -> 2018 | Q13: =IF(A13="", "", IF(G13="",1,IF(G13="O",1,IF(G13="C",8.4,IF(G13="B",8.4,IF(G13="A",76.8,IF(G13="K",76.8,"ERR"))))))) -> 8.4 | R13: =IF(L13<>"",Q13,"") -> 8.4 | S13: =IF(IF(L13<>"",G13,"")=0, "O", IF(L13<>"",G13,"")) -> B | T13: =IF(M13<>"",Q13,"") | U13: =IF(IF(M13<>"",G13,"")=0, "O", IF(M13<>"",G13,"")) | AR13: =IF(O13>0, O13, "") -> 10 | AS13: =IF(OR(L13="Y",M13="Y"),"Y","") -> Y
A14: 105553349 | B14: 43304 | C14: 18 | D14: 2 | E14: 0 | F14: 1 | G14: O | O14: =IF(Q14 = "", "", COUNT(Q$4:$Q14)) -> 11 | P14: =IF(C14 > 0, YEAR(B14), "") -> 2018 | Q14: =IF(A14="", "", IF(G14="",1,IF(G14="O",1,IF(G14="C",8.4,IF(G14="B",8.4,IF(G14="A",76.8,IF(G14="K",76.8,"ERR"))))))) -> 1 | R14: =IF(L14<>"",Q14,"") | S14: =IF(IF(L14<>"",G14,"")=0, "O", IF(L14<>"",G14,"")) | T14: =IF(M14<>"",Q14,"") | U14: =IF(IF(M14<>"",G14,"")=0, "O", IF(M14<>"",G14,"")) | W14: Steps | AR14: =IF(O14>0, O14, "") -> 11 | AS14: =IF(OR(L14="Y",M14="Y"),"Y","")
A15: 105885258 | B15: 43620 | C15: 29 | D15: 1 | E15: 0 | F15: 1 | G15: O | O15: =IF(Q15 = "", "", COUNT(Q$4:$Q15)) -> 12 | P15: =IF(C15 > 0, YEAR(B15), "") -> 2019 | Q15: =IF(A15="", "", IF(G15="",1,IF(G15="O",1,IF(G15="C",8.4,IF(G15="B",8.4,IF(G15="A",76.8,IF(G15="K",76.8,"ERR"))))))) -> 1 | R15: =IF(L15<>"",Q15,"") | S15: =IF(IF(L15<>"",G15,"")=0, "O", IF(L15<>"",G15,"")) | T15: =IF(M15<>"",Q15,"") | U15: =IF(IF(M15<>"",G15,"")=0, "O", IF(M15<>"",G15,"")) | W15: 1 | X15: For the crashes you have determined to be within your study area and in the BEFORE period, copy and paste the Crash ID, Date, T, C, F, L, and S columns from your filtered fiche into this tab's Columns A -> G. | AR15: =IF(O15>0, O15, "") -> 12 | AS15: =IF(OR(L15="Y",M15="Y"),"Y","")
A16: 106126767 | B16: 43843 | C16: 21 | D16: 2 | E16: 7 | F16: 1 | G16: O | O16: =IF(Q16 = "", "", COUNT(Q$4:$Q16)) -> 13 | P16: =IF(C16 > 0, YEAR(B16), "") -> 2020 | Q16: =IF(A16="", "", IF(G16="",1,IF(G16="O",1,IF(G16="C",8.4,IF(G16="B",8.4,IF(G16="A",76.8,IF(G16="K",76.8,"ERR"))))))) -> 1 | R16: =IF(L16<>"",Q16,"") | S16: =IF(IF(L16<>"",G16,"")=0, "O", IF(L16<>"",G16,"")) | T16: =IF(M16<>"",Q16,"") | U16: =IF(IF(M16<>"",G16,"")=0, "O", IF(M16<>"",G16,"")) | AR16: =IF(O16>0, O16, "") -> 13 | AS16: =IF(OR(L16="Y",M16="Y"),"Y","")
A17: 106133705 | B17: 43853 | C17: 30 | D17: 1 | E17: 7 | F17: 1 | G17: O | L17: Y | O17: =IF(Q17 = "", "", COUNT(Q$4:$Q17)) -> 14 | P17: =IF(C17 > 0, YEAR(B17), "") -> 2020 | Q17: =IF(A17="", "", IF(G17="",1,IF(G17="O",1,IF(G17="C",8.4,IF(G17="B",8.4,IF(G17="A",76.8,IF(G17="K",76.8,"ERR"))))))) -> 1 | R17: =IF(L17<>"",Q17,"") -> 1 | S17: =IF(IF(L17<>"",G17,"")=0, "O", IF(L17<>"",G17,"")) -> O | T17: =IF(M17<>"",Q17,"") | U17: =IF(IF(M17<>"",G17,"")=0, "O", IF(M17<>"",G17,"")) | AR17: =IF(O17>0, O17, "") -> 14 | AS17: =IF(OR(L17="Y",M17="Y"),"Y","") -> Y
A18: 106286453 | B18: 44037 | C18: 30 | D18: 1 | E18: 7 | F18: 1 | G18: C | L18: Y | O18: =IF(Q18 = "", "", COUNT(Q$4:$Q18)) -> 15 | P18: =IF(C18 > 0, YEAR(B18), "") -> 2020 | Q18: =IF(A18="", "", IF(G18="",1,IF(G18="O",1,IF(G18="C",8.4,IF(G18="B",8.4,IF(G18="A",76.8,IF(G18="K",76.8,"ERR"))))))) -> 8.4 | R18: =IF(L18<>"",Q18,"") -> 8.4 | S18: =IF(IF(L18<>"",G18,"")=0, "O", IF(L18<>"",G18,"")) -> C | T18: =IF(M18<>"",Q18,"") | U18: =IF(IF(M18<>"",G18,"")=0, "O", IF(M18<>"",G18,"")) | X18: ● | Y18: It is ESSENTIAL that the data you are pasting into these columns corresponds to their above headers. | AR18: =IF(O18>0, O18, "") -> 15 | AS18: =IF(OR(L18="Y",M18="Y"),"Y","") -> Y
O19: =IF(Q19 = "", "", COUNT(Q$4:$Q19)) | P19: =IF(C19 > 0, YEAR(B19), "") | Q19: =IF(A19="", "", IF(G19="",1,IF(G19="O",1,IF(G19="C",8.4,IF(G19="B",8.4,IF(G19="A",76.8,IF(G19="K",76.8,"ERR"))))))) | R19: =IF(L19<>"",Q19,"") | S19: =IF(IF(L19<>"",G19,"")=0, "O", IF(L19<>"",G19,"")) | T19: =IF(M19<>"",Q19,"") | U19: =IF(IF(M19<>"",G19,"")=0, "O", IF(M19<>"",G19,"")) | AR19: =IF(O19>0, O19, "") | AS19: =IF(OR(L19="Y",M19="Y"),"Y","")
O20: =IF(Q20 = "", "", COUNT(Q$4:$Q20)) | P20: =IF(C20 > 0, YEAR(B20), "") | Q20: =IF(A20="", "", IF(G20="",1,IF(G20="O",1,IF(G20="C",8.4,IF(G20="B",8.4,IF(G20="A",76.8,IF(G20="K",76.8,"ERR"))))))) | R20: =IF(L20<>"",Q20,"") | S20: =IF(IF(L20<>"",G20,"")=0, "O", IF(L20<>"",G20,"")) | T20: =IF(M20<>"",Q20,"") | U20: =IF(IF(M20<>"",G20,"")=0, "O", IF(M20<>"",G20,"")) | X20: ● | Y20: It is recommended that the user of this workbook enters in the crash data in the same order of the TEAAS study’s crash #s. This allows for consistency between this workbook’s crash #s with the TEAAS study’s crash #s and the collision diagram’s crash #s. Reviewers would find this consistency helpful. | AR20: =IF(O20>0, O20, "") | AS20: =IF(OR(L20="Y",M20="Y"),"Y","")
O21: =IF(Q21 = "", "", COUNT(Q$4:$Q21)) | P21: =IF(C21 > 0, YEAR(B21), "") | Q21: =IF(A21="", "", IF(G21="",1,IF(G21="O",1,IF(G21="C",8.4,IF(G21="B",8.4,IF(G21="A",76.8,IF(G21="K",76.8,"ERR"))))))) | R21: =IF(L21<>"",Q21,"") | S21: =IF(IF(L21<>"",G21,"")=0, "O", IF(L21<>"",G21,"")) | T21: =IF(M21<>"",Q21,"") | U21: =IF(IF(M21<>"",G21,"")=0, "O", IF(M21<>"",G21,"")) | AR21: =IF(O21>0, O21, "") | AS21: =IF(OR(L21="Y",M21="Y"),"Y","")
O22: =IF(Q22 = "", "", COUNT(Q$4:$Q22)) | P22: =IF(C22 > 0, YEAR(B22), "") | Q22: =IF(A22="", "", IF(G22="",1,IF(G22="O",1,IF(G22="C",8.4,IF(G22="B",8.4,IF(G22="A",76.8,IF(G22="K",76.8,"ERR"))))))) | R22: =IF(L22<>"",Q22,"") | S22: =IF(IF(L22<>"",G22,"")=0, "O", IF(L22<>"",G22,"")) | T22: =IF(M22<>"",Q22,"") | U22: =IF(IF(M22<>"",G22,"")=0, "O", IF(M22<>"",G22,"")) | AR22: =IF(O22>0, O22, "") | AS22: =IF(OR(L22="Y",M22="Y"),"Y","")
O23: =IF(Q23 = "", "", COUNT(Q$4:$Q23)) | P23: =IF(C23 > 0, YEAR(B23), "") | Q23: =IF(A23="", "", IF(G23="",1,IF(G23="O",1,IF(G23="C",8.4,IF(G23="B",8.4,IF(G23="A",76.8,IF(G23="K",76.8,"ERR"))))))) | R23: =IF(L23<>"",Q23,"") | S23: =IF(IF(L23<>"",G23,"")=0, "O", IF(L23<>"",G23,"")) | T23: =IF(M23<>"",Q23,"") | U23: =IF(IF(M23<>"",G23,"")=0, "O", IF(M23<>"",G23,"")) | AR23: =IF(O23>0, O23, "") | AS23: =IF(OR(L23="Y",M23="Y"),"Y","")
O24: =IF(Q24 = "", "", COUNT(Q$4:$Q24)) | P24: =IF(C24 > 0, YEAR(B24), "") | Q24: =IF(A24="", "", IF(G24="",1,IF(G24="O",1,IF(G24="C",8.4,IF(G24="B",8.4,IF(G24="A",76.8,IF(G24="K",76.8,"ERR"))))))) | R24: =IF(L24<>"",Q24,"") | S24: =IF(IF(L24<>"",G24,"")=0, "O", IF(L24<>"",G24,"")) | T24: =IF(M24<>"",Q24,"") | U24: =IF(IF(M24<>"",G24,"")=0, "O", IF(M24<>"",G24,"")) | AR24: =IF(O24>0, O24, "") | AS24: =IF(OR(L24="Y",M24="Y"),"Y","")
O25: =IF(Q25 = "", "", COUNT(Q$4:$Q25)) | P25: =IF(C25 > 0, YEAR(B25), "") | Q25: =IF(A25="", "", IF(G25="",1,IF(G25="O",1,IF(G25="C",8.4,IF(G25="B",8.4,IF(G25="A",76.8,IF(G25="K",76.8,"ERR"))))))) | R25: =IF(L25<>"",Q25,"") | S25: =IF(IF(L25<>"",G25,"")=0, "O", IF(L25<>"",G25,"")) | T25: =IF(M25<>"",Q25,"") | U25: =IF(IF(M25<>"",G25,"")=0, "O", IF(M25<>"",G25,"")) | X25: ● | Y25: Make sure that rows are not skipped when pasting the fiche's in-study crash data. Skipping rows will break some of the background formulas | AR25: =IF(O25>0, O25, "") | AS25: =IF(OR(L25="Y",M25="Y"),"Y","")
O26: =IF(Q26 = "", "", COUNT(Q$4:$Q26)) | P26: =IF(C26 > 0, YEAR(B26), "") | Q26: =IF(A26="", "", IF(G26="",1,IF(G26="O",1,IF(G26="C",8.4,IF(G26="B",8.4,IF(G26="A",76.8,IF(G26="K",76.8,"ERR"))))))) | R26: =IF(L26<>"",Q26,"") | S26: =IF(IF(L26<>"",G26,"")=0, "O", IF(L26<>"",G26,"")) | T26: =IF(M26<>"",Q26,"") | U26: =IF(IF(M26<>"",G26,"")=0, "O", IF(M26<>"",G26,"")) | AR26: =IF(O26>0, O26, "") | AS26: =IF(OR(L26="Y",M26="Y"),"Y","")
O27: =IF(Q27 = "", "", COUNT(Q$4:$Q27)) | P27: =IF(C27 > 0, YEAR(B27), "") | Q27: =IF(A27="", "", IF(G27="",1,IF(G27="O",1,IF(G27="C",8.4,IF(G27="B",8.4,IF(G27="A",76.8,IF(G27="K",76.8,"ERR"))))))) | R27: =IF(L27<>"",Q27,"") | S27: =IF(IF(L27<>"",G27,"")=0, "O", IF(L27<>"",G27,"")) | T27: =IF(M27<>"",Q27,"") | U27: =IF(IF(M27<>"",G27,"")=0, "O", IF(M27<>"",G27,"")) | X27: ● | Y27: The determination of the crashes in the study should be finalized/set-in-stone before pasting into this tab. Deleting and adjusting cells in the tab may break the formulas used in the calculations. | AR27: =IF(O27>0, O27, "") | AS27: =IF(OR(L27="Y",M27="Y"),"Y","")
O28: =IF(Q28 = "", "", COUNT(Q$4:$Q28)) | P28: =IF(C28 > 0, YEAR(B28), "") | Q28: =IF(A28="", "", IF(G28="",1,IF(G28="O",1,IF(G28="C",8.4,IF(G28="B",8.4,IF(G28="A",76.8,IF(G28="K",76.8,"ERR"))))))) | R28: =IF(L28<>"",Q28,"") | S28: =IF(IF(L28<>"",G28,"")=0, "O", IF(L28<>"",G28,"")) | T28: =IF(M28<>"",Q28,"") | U28: =IF(IF(M28<>"",G28,"")=0, "O", IF(M28<>"",G28,"")) | AR28: =IF(O28>0, O28, "") | AS28: =IF(OR(L28="Y",M28="Y"),"Y","")
O29: =IF(Q29 = "", "", COUNT(Q$4:$Q29)) | P29: =IF(C29 > 0, YEAR(B29), "") | Q29: =IF(A29="", "", IF(G29="",1,IF(G29="O",1,IF(G29="C",8.4,IF(G29="B",8.4,IF(G29="A",76.8,IF(G29="K",76.8,"ERR"))))))) | R29: =IF(L29<>"",Q29,"") | S29: =IF(IF(L29<>"",G29,"")=0, "O", IF(L29<>"",G29,"")) | T29: =IF(M29<>"",Q29,"") | U29: =IF(IF(M29<>"",G29,"")=0, "O", IF(M29<>"",G29,"")) | AR29: =IF(O29>0, O29, "") | AS29: =IF(OR(L29="Y",M29="Y"),"Y","")
O30: =IF(Q30 = "", "", COUNT(Q$4:$Q30)) | P30: =IF(C30 > 0, YEAR(B30), "") | Q30: =IF(A30="", "", IF(G30="",1,IF(G30="O",1,IF(G30="C",8.4,IF(G30="B",8.4,IF(G30="A",76.8,IF(G30="K",76.8,"ERR"))))))) | R30: =IF(L30<>"",Q30,"") | S30: =IF(IF(L30<>"",G30,"")=0, "O", IF(L30<>"",G30,"")) | T30: =IF(M30<>"",Q30,"") | U30: =IF(IF(M30<>"",G30,"")=0, "O", IF(M30<>"",G30,"")) | W30: 2 | X30: Different analysts like using different columns for their notes when filtering the Fiche and labeling crashes. Columns H -> K are your prerogative, feel free to copy in whatever notes you used in the analysis. | AR30: =IF(O30>0, O30, "") | AS30: =IF(OR(L30="Y",M30="Y"),"Y","")
O31: =IF(Q31 = "", "", COUNT(Q$4:$Q31)) | P31: =IF(C31 > 0, YEAR(B31), "") | Q31: =IF(A31="", "", IF(G31="",1,IF(G31="O",1,IF(G31="C",8.4,IF(G31="B",8.4,IF(G31="A",76.8,IF(G31="K",76.8,"ERR"))))))) | R31: =IF(L31<>"",Q31,"") | S31: =IF(IF(L31<>"",G31,"")=0, "O", IF(L31<>"",G31,"")) | T31: =IF(M31<>"",Q31,"") | U31: =IF(IF(M31<>"",G31,"")=0, "O", IF(M31<>"",G31,"")) | AR31: =IF(O31>0, O31, "") | AS31: =IF(OR(L31="Y",M31="Y"),"Y","")
O32: =IF(Q32 = "", "", COUNT(Q$4:$Q32)) | P32: =IF(C32 > 0, YEAR(B32), "") | Q32: =IF(A32="", "", IF(G32="",1,IF(G32="O",1,IF(G32="C",8.4,IF(G32="B",8.4,IF(G32="A",76.8,IF(G32="K",76.8,"ERR"))))))) | R32: =IF(L32<>"",Q32,"") | S32: =IF(IF(L32<>"",G32,"")=0, "O", IF(L32<>"",G32,"")) | T32: =IF(M32<>"",Q32,"") | U32: =IF(IF(M32<>"",G32,"")=0, "O", IF(M32<>"",G32,"")) | AR32: =IF(O32>0, O32, "") | AS32: =IF(OR(L32="Y",M32="Y"),"Y","")
O33: =IF(Q33 = "", "", COUNT(Q$4:$Q33)) | P33: =IF(C33 > 0, YEAR(B33), "") | Q33: =IF(A33="", "", IF(G33="",1,IF(G33="O",1,IF(G33="C",8.4,IF(G33="B",8.4,IF(G33="A",76.8,IF(G33="K",76.8,"ERR"))))))) | R33: =IF(L33<>"",Q33,"") | S33: =IF(IF(L33<>"",G33,"")=0, "O", IF(L33<>"",G33,"")) | T33: =IF(M33<>"",Q33,"") | U33: =IF(IF(M33<>"",G33,"")=0, "O", IF(M33<>"",G33,"")) | W33: 3 | X33: Columns L and M require manual input to identify Target Crashes | AR33: =IF(O33>0, O33, "") | AS33: =IF(OR(L33="Y",M33="Y"),"Y","")
O34: =IF(Q34 = "", "", COUNT(Q$4:$Q34)) | P34: =IF(C34 > 0, YEAR(B34), "") | Q34: =IF(A34="", "", IF(G34="",1,IF(G34="O",1,IF(G34="C",8.4,IF(G34="B",8.4,IF(G34="A",76.8,IF(G34="K",76.8,"ERR"))))))) | R34: =IF(L34<>"",Q34,"") | S34: =IF(IF(L34<>"",G34,"")=0, "O", IF(L34<>"",G34,"")) | T34: =IF(M34<>"",Q34,"") | U34: =IF(IF(M34<>"",G34,"")=0, "O", IF(M34<>"",G34,"")) | X34: ● | Y34: Type Y in Column L if Target-1 Crash. | AR34: =IF(O34>0, O34, "") | AS34: =IF(OR(L34="Y",M34="Y"),"Y","")
O35: =IF(Q35 = "", "", COUNT(Q$4:$Q35)) | P35: =IF(C35 > 0, YEAR(B35), "") | Q35: =IF(A35="", "", IF(G35="",1,IF(G35="O",1,IF(G35="C",8.4,IF(G35="B",8.4,IF(G35="A",76.8,IF(G35="K",76.8,"ERR"))))))) | R35: =IF(L35<>"",Q35,"") | S35: =IF(IF(L35<>"",G35,"")=0, "O", IF(L35<>"",G35,"")) | T35: =IF(M35<>"",Q35,"") | U35: =IF(IF(M35<>"",G35,"")=0, "O", IF(M35<>"",G35,"")) | X35: ● | Y35: Type Y in Column M if Target-2 Crash. | AR35: =IF(O35>0, O35, "") | AS35: =IF(OR(L35="Y",M35="Y"),"Y","")
O36: =IF(Q36 = "", "", COUNT(Q$4:$Q36)) | P36: =IF(C36 > 0, YEAR(B36), "") | Q36: =IF(A36="", "", IF(G36="",1,IF(G36="O",1,IF(G36="C",8.4,IF(G36="B",8.4,IF(G36="A",76.8,IF(G36="K",76.8,"ERR"))))))) | R36: =IF(L36<>"",Q36,"") | S36: =IF(IF(L36<>"",G36,"")=0, "O", IF(L36<>"",G36,"")) | T36: =IF(M36<>"",Q36,"") | U36: =IF(IF(M36<>"",G36,"")=0, "O", IF(M36<>"",G36,"")) | X36: ● | Y36: Leave these columns blank if not a Target Crash. | AR36: =IF(O36>0, O36, "") | AS36: =IF(OR(L36="Y",M36="Y"),"Y","")
O37: =IF(Q37 = "", "", COUNT(Q$4:$Q37)) | P37: =IF(C37 > 0, YEAR(B37), "") | Q37: =IF(A37="", "", IF(G37="",1,IF(G37="O",1,IF(G37="C",8.4,IF(G37="B",8.4,IF(G37="A",76.8,IF(G37="K",76.8,"ERR"))))))) | R37: =IF(L37<>"",Q37,"") | S37: =IF(IF(L37<>"",G37,"")=0, "O", IF(L37<>"",G37,"")) | T37: =IF(M37<>"",Q37,"") | U37: =IF(IF(M37<>"",G37,"")=0, "O", IF(M37<>"",G37,"")) | X37: ● | Y37: NOTE: If a crash could potentially fall in more than one target group, discuss with SEG Staff on how to prioritize the target placement. Each target crash should only fall in one target group. There should not be overlap. | AR37: =IF(O37>0, O37, "") | AS37: =IF(OR(L37="Y",M37="Y"),"Y","")
O38: =IF(Q38 = "", "", COUNT(Q$4:$Q38)) | P38: =IF(C38 > 0, YEAR(B38), "") | Q38: =IF(A38="", "", IF(G38="",1,IF(G38="O",1,IF(G38="C",8.4,IF(G38="B",8.4,IF(G38="A",76.8,IF(G38="K",76.8,"ERR"))))))) | R38: =IF(L38<>"",Q38,"") | S38: =IF(IF(L38<>"",G38,"")=0, "O", IF(L38<>"",G38,"")) | T38: =IF(M38<>"",Q38,"") | U38: =IF(IF(M38<>"",G38,"")=0, "O", IF(M38<>"",G38,"")) | AR38: =IF(O38>0, O38, "") | AS38: =IF(OR(L38="Y",M38="Y"),"Y","")
O39: =IF(Q39 = "", "", COUNT(Q$4:$Q39)) | P39: =IF(C39 > 0, YEAR(B39), "") | Q39: =IF(A39="", "", IF(G39="",1,IF(G39="O",1,IF(G39="C",8.4,IF(G39="B",8.4,IF(G39="A",76.8,IF(G39="K",76.8,"ERR"))))))) | R39: =IF(L39<>"",Q39,"") | S39: =IF(IF(L39<>"",G39,"")=0, "O", IF(L39<>"",G39,"")) | T39: =IF(M39<>"",Q39,"") | U39: =IF(IF(M39<>"",G39,"")=0, "O", IF(M39<>"",G39,"")) | AR39: =IF(O39>0, O39, "") | AS39: =IF(OR(L39="Y",M39="Y"),"Y","")
O40: =IF(Q40 = "", "", COUNT(Q$4:$Q40)) | P40: =IF(C40 > 0, YEAR(B40), "") | Q40: =IF(A40="", "", IF(G40="",1,IF(G40="O",1,IF(G40="C",8.4,IF(G40="B",8.4,IF(G40="A",76.8,IF(G40="K",76.8,"ERR"))))))) | R40: =IF(L40<>"",Q40,"") | S40: =IF(IF(L40<>"",G40,"")=0, "O", IF(L40<>"",G40,"")) | T40: =IF(M40<>"",Q40,"") | U40: =IF(IF(M40<>"",G40,"")=0, "O", IF(M40<>"",G40,"")) | AR40: =IF(O40>0, O40, "") | AS40: =IF(OR(L40="Y",M40="Y"),"Y","")
...

Sheet After
A1: Manually Edit These Columns (A -> M) | O1: Don't Edit These Columns (N -> ). Calculations are Automatic.
A2: ="After Period ("&TEXT('Evaluation Set-up'!D11, "mm/dd/yy")&" - "&TEXT('Evaluation Set-up'!E11, "mm/dd/yy")&")" -> After Period (07/01/21 - 06/30/26) | O2: Crash # | P2: Crash Year | Q2: Severity Index | R2: Target-1 Severity Index | S2: Target-1 KABCO | T2: Target-2 Severity Index | U2: Target-2 KABCO
A3: Crash ID | B3: Date | C3: T | D3: C | E3: F | F3: L | G3: S | H3: Analyst's Notes Column 1 | I3: Analyst's Notes Column 2 | J3: Analyst's Notes Column 3 | K3: Analyst's Notes Column 4 | L3: Target-1? | M3: Target-2? | Y3: Total | Z3: Target-1 | AA3: Target-2 | AB3: All Targets | AR3: Crash # | AS3: Target Crash?
A4: 106743409 | B4: 44494 | C4: 30 | D4: 1 | E4: 7 | F4: 5 | G4: O | L4: Y | O4: =IF(Q4 = "", "", COUNT(Q$4:$Q4)) -> 1 | P4: =IF(C4 > 0, YEAR(B4), "") -> 2021 | Q4: =IF(A4="", "", IF(G4="",1,IF(G4="O",1,IF(G4="C",8.4,IF(G4="B",8.4,IF(G4="A",76.8,IF(G4="K",76.8,"ERR"))))))) -> 1 | R4: =IF(L4<>"",Q4,"") -> 1 | S4: =IF(IF(L4<>"",G4,"")=0, "O", IF(L4<>"",G4,"")) -> O | T4: =IF(M4<>"",Q4,"") | U4: =IF(IF(M4<>"",G4,"")=0, "O", IF(M4<>"",G4,"")) | X4: K | Y4: =COUNTIF($G$4:$G$1048576,$X4) -> 0 | Z4: =COUNTIF($S$4:$S$1048576,$X4) -> 0 | AA4: =COUNTIF($U$4:$U$1048576,$X4) -> 0 | AB4: =COUNTIF($S:$S, X4)+COUNTIF($U:$U, X4)-COUNTIFS($S:$S, X4, $U:$U, X4) -> 0 | AR4: =IF(O4>0, O4, "") -> 1 | AS4: =IF(OR(L4="Y",M4="Y"),"Y","") -> Y
A5: 106772984 | B5: 44519 | C5: 30 | D5: 1 | E5: 7 | F5: 1 | G5: O | L5: Y | O5: =IF(Q5 = "", "", COUNT(Q$4:$Q5)) -> 2 | P5: =IF(C5 > 0, YEAR(B5), "") -> 2021 | Q5: =IF(A5="", "", IF(G5="",1,IF(G5="O",1,IF(G5="C",8.4,IF(G5="B",8.4,IF(G5="A",76.8,IF(G5="K",76.8,"ERR"))))))) -> 1 | R5: =IF(L5<>"",Q5,"") -> 1 | S5: =IF(IF(L5<>"",G5,"")=0, "O", IF(L5<>"",G5,"")) -> O | T5: =IF(M5<>"",Q5,"") | U5: =IF(IF(M5<>"",G5,"")=0, "O", IF(M5<>"",G5,"")) | X5: A | Y5: =COUNTIF($G$4:$G$1048576,$X5) -> 0 | Z5: =COUNTIF($S$4:$S$1048576,$X5) -> 0 | AA5: =COUNTIF($U$4:$U$1048576,$X5) -> 0 | AB5: =COUNTIF($S:$S, X5)+COUNTIF($U:$U, X5)-COUNTIFS($S:$S, X5, $U:$U, X5) -> 0 | AR5: =IF(O5>0, O5, "") -> 2 | AS5: =IF(OR(L5="Y",M5="Y"),"Y","") -> Y
A6: 107601791 | B6: 45314 | C6: 30 | D6: 2 | E6: 7 | F6: 1 | G6: O | L6: Y | O6: =IF(Q6 = "", "", COUNT(Q$4:$Q6)) -> 3 | P6: =IF(C6 > 0, YEAR(B6), "") -> 2024 | Q6: =IF(A6="", "", IF(G6="",1,IF(G6="O",1,IF(G6="C",8.4,IF(G6="B",8.4,IF(G6="A",76.8,IF(G6="K",76.8,"ERR"))))))) -> 1 | R6: =IF(L6<>"",Q6,"") -> 1 | S6: =IF(IF(L6<>"",G6,"")=0, "O", IF(L6<>"",G6,"")) -> O | T6: =IF(M6<>"",Q6,"") | U6: =IF(IF(M6<>"",G6,"")=0, "O", IF(M6<>"",G6,"")) | X6: B | Y6: =COUNTIF($G$4:$G$1048576,$X6) -> 0 | Z6: =COUNTIF($S$4:$S$1048576,$X6) -> 0 | AA6: =COUNTIF($U$4:$U$1048576,$X6) -> 0 | AB6: =COUNTIF($S:$S, X6)+COUNTIF($U:$U, X6)-COUNTIFS($S:$S, X6, $U:$U, X6) -> 0 | AR6: =IF(O6>0, O6, "") -> 3 | AS6: =IF(OR(L6="Y",M6="Y"),"Y","") -> Y
A7: 107870118 | B7: 45568 | C7: 30 | D7: 1 | E7: 7 | F7: 1 | G7: O | L7: Y | O7: =IF(Q7 = "", "", COUNT(Q$4:$Q7)) -> 4 | P7: =IF(C7 > 0, YEAR(B7), "") -> 2024 | Q7: =IF(A7="", "", IF(G7="",1,IF(G7="O",1,IF(G7="C",8.4,IF(G7="B",8.4,IF(G7="A",76.8,IF(G7="K",76.8,"ERR"))))))) -> 1 | R7: =IF(L7<>"",Q7,"") -> 1 | S7: =IF(IF(L7<>"",G7,"")=0, "O", IF(L7<>"",G7,"")) -> O | T7: =IF(M7<>"",Q7,"") | U7: =IF(IF(M7<>"",G7,"")=0, "O", IF(M7<>"",G7,"")) | X7: C | Y7: =COUNTIF($G$4:$G$1048576,$X7) -> 2 | Z7: =COUNTIF($S$4:$S$1048576,$X7) -> 1 | AA7: =COUNTIF($U$4:$U$1048576,$X7) -> 0 | AB7: =COUNTIF($S:$S, X7)+COUNTIF($U:$U, X7)-COUNTIFS($S:$S, X7, $U:$U, X7) -> 1 | AR7: =IF(O7>0, O7, "") -> 4 | AS7: =IF(OR(L7="Y",M7="Y"),"Y","") -> Y
A8: 107902086 | B8: 45593 | C8: 30 | D8: 1 | E8: 7 | F8: 1 | G8: O | L8: Y | O8: =IF(Q8 = "", "", COUNT(Q$4:$Q8)) -> 5 | P8: =IF(C8 > 0, YEAR(B8), "") -> 2024 | Q8: =IF(A8="", "", IF(G8="",1,IF(G8="O",1,IF(G8="C",8.4,IF(G8="B",8.4,IF(G8="A",76.8,IF(G8="K",76.8,"ERR"))))))) -> 1 | R8: =IF(L8<>"",Q8,"") -> 1 | S8: =IF(IF(L8<>"",G8,"")=0, "O", IF(L8<>"",G8,"")) -> O | T8: =IF(M8<>"",Q8,"") | U8: =IF(IF(M8<>"",G8,"")=0, "O", IF(M8<>"",G8,"")) | X8: O | Y8: =COUNTIF($G$4:$G$1048576,$X8)+COUNTIFS($G$4:$G$1048576, "", $O$4:$O$1048576, ">0") -> 6 | Z8: =COUNTIF($S$4:$S$1048576,$X8) -> 6 | AA8: =COUNTIF($U$4:$U$1048576,$X8) -> 0 | AB8: =COUNTIF($S:$S, X8)+COUNTIF($U:$U, X8)-COUNTIFS($S:$S, X8, $U:$U, X8) -> 6 | AR8: =IF(O8>0, O8, "") -> 5 | AS8: =IF(OR(L8="Y",M8="Y"),"Y","") -> Y
A9: 107945637 | B9: 45630 | C9: 21 | D9: 1 | E9: 7 | F9: 1 | G9: C | O9: =IF(Q9 = "", "", COUNT(Q$4:$Q9)) -> 6 | P9: =IF(C9 > 0, YEAR(B9), "") -> 2024 | Q9: =IF(A9="", "", IF(G9="",1,IF(G9="O",1,IF(G9="C",8.4,IF(G9="B",8.4,IF(G9="A",76.8,IF(G9="K",76.8,"ERR"))))))) -> 8.4 | R9: =IF(L9<>"",Q9,"") | S9: =IF(IF(L9<>"",G9,"")=0, "O", IF(L9<>"",G9,"")) | T9: =IF(M9<>"",Q9,"") | U9: =IF(IF(M9<>"",G9,"")=0, "O", IF(M9<>"",G9,"")) | X9: Total | Y9: =COUNTIF(O4:O1048576, ">0") -> 8 | Z9: =COUNT(R4:R1048576) -> 7 | AA9: =COUNT(T4:T1048576) -> 0 | AB9: =SUM(AB4:AB8) -> 7 | AR9: =IF(O9>0, O9, "") -> 6 | AS9: =IF(OR(L9="Y",M9="Y"),"Y","")
A10: 108250468 | B10: 45931 | C10: 30 | D10: 1 | E10: 7 | F10: 5 | G10: O | L10: Y | O10: =IF(Q10 = "", "", COUNT(Q$4:$Q10)) -> 7 | P10: =IF(C10 > 0, YEAR(B10), "") -> 2025 | Q10: =IF(A10="", "", IF(G10="",1,IF(G10="O",1,IF(G10="C",8.4,IF(G10="B",8.4,IF(G10="A",76.8,IF(G10="K",76.8,"ERR"))))))) -> 1 | R10: =IF(L10<>"",Q10,"") -> 1 | S10: =IF(IF(L10<>"",G10,"")=0, "O", IF(L10<>"",G10,"")) -> O | T10: =IF(M10<>"",Q10,"") | U10: =IF(IF(M10<>"",G10,"")=0, "O", IF(M10<>"",G10,"")) | X10: SI | Y10: =IFERROR(AVERAGE(Q4:Q1048576), 0) -> 2.85 | Z10: =IFERROR(AVERAGE(R4:R1048576),0) -> 2.0571429 | AA10: =IFERROR(AVERAGE(T4:T1048576),0) -> 0 | AB10: =IFERROR(AVERAGEIF($AS$4:$AS$1048576,"Y", Q4:Q1048576 ),0) -> 2.0571429 | AR10: =IF(O10>0, O10, "") -> 7 | AS10: =IF(OR(L10="Y",M10="Y"),"Y","") -> Y
A11: 108279485 | B11: 45953 | C11: 30 | D11: 1 | E11: 7 | F11: 1 | G11: C | L11: Y | O11: =IF(Q11 = "", "", COUNT(Q$4:$Q11)) -> 8 | P11: =IF(C11 > 0, YEAR(B11), "") -> 2025 | Q11: =IF(A11="", "", IF(G11="",1,IF(G11="O",1,IF(G11="C",8.4,IF(G11="B",8.4,IF(G11="A",76.8,IF(G11="K",76.8,"ERR"))))))) -> 8.4 | R11: =IF(L11<>"",Q11,"") -> 8.4 | S11: =IF(IF(L11<>"",G11,"")=0, "O", IF(L11<>"",G11,"")) -> C | T11: =IF(M11<>"",Q11,"") | U11: =IF(IF(M11<>"",G11,"")=0, "O", IF(M11<>"",G11,"")) | AR11: =IF(O11>0, O11, "") -> 8 | AS11: =IF(OR(L11="Y",M11="Y"),"Y","") -> Y
