Workbook

Sheet Step-by-Step Instructions

Sheet Typical Target Crash Types
B2: Target Crash Type Guidance - Intersection Treatments
C4: Countermeasure | D4: Target-1 | E4: Target-2 | F4: Target-1 Crash | G4: Target-2 Crash | H4: Notes
C5: Advance Activated Warning Sign (a.k.a. Be Prepared to Stop Signs) | D5: Y | E5: Y | F5: Frontal Impact Crashes where Vehicle on Treated Approach Ran Red Light | G5: Rear End Crashes Approaching Intersection on Treated Approaches | H5: Treated Approaches are likely both Mainline Approaches
C6: All Way Stop | D6: Y | F6: Frontal Impact Crashes in Intersection
C7: Reduced Conflict Intersection (RCI) | D7: Y | F7: Frontal Impact Crashes involving vehicle making a movement that is restricted in the after period | H7: If the treatment included the construction of U-turn bulbouts, the entire constructed section may need to be included in the treatment analysis. If the treatment was ONLY the RCI, analyze downstream U-turn crashes in a separate table.
C8: Flashing Traffic Signal (i.e. Overhead Non-Actuated Flasher) | D8: Y | F8: Frontal Impact Crashes in Intersection
C9: Grade Separation | D9: Y | F9: Frontal Impact Crashes in Intersection
C10: Increase Conspicuity of Stop Condition (i.e. Double Indicated Stop Sign, Transverse Rumble Strips, Double Arrow Sign) | D10: Y | F10: Frontal Impact Crashes where Vehicle on Treated Approach Ran the Stop Sign | H10: Include Ran Off Road - Straight Crashes for T Intersections
C11: Increase Conspicuity of Traffic Signal (i.e. Double Indicated Red, Backplates) | D11: Y | F11: Frontal Impact Crashes where Vehicle on Treated Approach Ran Red Light | H11: Include Rear End crashes from the treated approaches within the Additional Information Table.
C12: Intersection Realignment | D12: Y | E12: Y | F12: Frontal Impact Crashes in Intersection | G12: Varies by Treatment - Other Targets may be necessary depending on the situation (i.e. Rear End Crashes or Lane Departure Crashes) | H12: Y-Lines may need to be extended. Analyze Entire Area impacted by realignment
C13: Left Turn Lane - New Installation | D13: Y | E13: Y | F13: Rear End Crashes Approaching Intersection on Treated Approaches | G13: Left Turn Same Roadway Crashes on Treated Approaches | H13: If a multilane facility, rear ends may need to be specific to the inner lanes
C14: Left Turn Lane - Offset Existing Lane | D14: Y | F14: Left Turn Same Roadway Crashes on Treated Approaches
C15: Median Channelization on an Intersection Approach (i.e. Assess Management for Driveways) | D15: Y | E15: Y | F15: Frontal Impact Crashes involving vehicle making a movement that is restricted in the after period | G15: Varies by Treatment - Other Targets may be necessary depending on the situation (i.e. rear end crashes alleviated due to a movement restriction) | H15: Analyze a Potential Area of Influence / Downstream U-Turn Crashes in the additional information table and/or the discussion
C16: New Traffic Signal | D16: Y | F16: Frontal Impact Crashes in Intersection
C17: Pedestrian/Bicycle Treatments | D17: Y | F17: Pedestrian and Bicycle Crashes | H17: For a Pedestrian signal, rear end crashes may also need to be analyzed
C18: Remove Access/Intersection | D18: Y | E18: Y | F18: Frontal Impact Crashes in Intersection* | G18: Varies by Treatment - Other Targets may be necessary depending on the situation (i.e. Rear End Crashes) | H18: *Target crashes can vary depending on the specifics of what was removed
C19: Right Turn Lane at Intersection | D19: Y | E19: Y | F19: Rear End Crashes Approaching Intersection on Treated Approaches | G19: Sideswipe Crashes Approaching Intersection on Treated Approaches | H19: If a multilane facility, rear ends and sideswipes may need to be specific to the outer lanes
C20: Roundabout | D20: Y | F20: Frontal Impact Crashes in Intersection | H20: Particularly for rural roundabouts, note whether there is lighting present within the discussion and detail any patterns regarding nighttime crashes or nighttime lane departures within the additional information table and/or discussion
C21: Sight Distance Improvements at Intersection | D21: Y | F21: Frontal Impact Crashes in Intersection | H21: May need to only include Frontal Impact Crashes involving vehicles making maneuvers directly affected by sight distance improvements (i.e. if one quadrant was cleared)
C22: Traffic Signal Revisions - Flashing Yellow Arrow | D22: Y | F22: Left Turn Same Roadway Crashes on Treated Approaches
C23: Traffic Signal Revisions - Left Turn Phasing Revisions | D23: Y | F23: Left Turn Same Roadway Crashes on Treated Approaches
C24: Vehicle Entering When Flashing | D24: Y | F24: Frontal Impact Crashes involving Vehicles from Treated Approaches | H24: Look at the sign and loop placement to determine what are the treated approaches. If the signs are only on one approach, then only include crashes involving vehicles from that approach. Crashes involving vehicles from the same roadway (Left Turn Same Roadway, Right Turn Same Roadway and Head On Crashes) are typically excluded because the flashers are not displayed to vehicles traveling on the same roadway.
B26: Comments/Instructions for Typical Target Crashes:
B27: ● | C27: Frontal impacts crash types: left-turn same roadway, left-turn different roadway, right-turn same roadway, right-turn different roadway, head-on, and angle crashes

Sheet Evaluation Set-up
B2: Date Range Calculator | J2: AADT Calculator
C4: Most recent TEAAS date | D4: 46112 | F4: Color Key | L4: Representative Years Selection: | P4: Representative Volumes: | T4: Instructions for AADT Calculator:
C5: Construction Period Length (Give Value in Months) | D5: 5 | F5: Cells that need to be edited | L5: Select Before Period Year: | N5: 2021 | P5: Before Period Volume: | R5: =IFERROR(ROUND(VLOOKUP($N$5, $K$11:$R$35, 8, FALSE()), -2), "Select Year") -> 1500 | T5: ● | U5: In cells N5 and N6, select the last year within each period that has available volume data (i.e. actual collected volume data, not estimated/interpolated data) | AF5: cells needed for calcs:
F6: Auto-calculated cells | L6: Select After Period Year: | N6: 2024 | P6: After Period Volume: | R6: =IFERROR(ROUND(VLOOKUP($N$6, $K$11:$R$35, 8, FALSE()), -2), "Select Year") -> 1800
AH7: Total # of months in between
C8: Time Period | D8: Start Date | E8: End Date | F8: # of Years | G8: # of Months | K8: AADTs for every year within the study period | T8: ● | U8: When inputting volume data into this tool, use Black font color for values taken directly from the available volume data | AF8: =YEAR(E9) -> 2021 | AG8: =MONTH(E9) -> 10 | AH8: =(YEAR(D10)-YEAR(D9))*12+MONTH(D10)-MONTH(D9) -> 48
C9: Before Period | D9: 43040 | E9: 44500 | F9: =ROUNDDOWN(AH8/12,0) -> 4 | G9: =AH8-12*F9 -> 0 | K9: Year | L9: Major Road - Leg #1 | M9: Major Road - Leg #2 | N9: Major Road - Average AADT | O9: Minor Rd - Leg #3 | P9: Minor Rd - Leg #4 | Q9: Minor Road - Average AADT | R9: Intersection AADT | AF9: =YEAR(E10) -> 2022 | AG9: =MONTH(E10) -> 3 | AH9: =(YEAR(D11)-YEAR(D10))*12+MONTH(D11)-MONTH(D10) -> 5
C10: Construction Period | D10: 44501 | E10: 44651 | F10: =ROUNDDOWN(AH9/12,0) -> 0 | G10: =AH9-12*F10 -> 5 | T10: ● | U10: When inputting volume data into this tool, use Red font color for values that need to be calculated, interpolated, or assumed | AG10: =E11+1 -> 46113 | AH10: =(YEAR(AG10)-YEAR(D11))*12+MONTH(AG10)-MONTH(D11) -> 48
C11: After Period | D11: 44652 | E11: 46112 | F11: =ROUNDDOWN(AH10/12,0) -> 4 | G11: =AH10-12*F11 -> 0 | K11: 2006 | N11: =IF(COUNT(L11:M11) = 0, "",L11/2+M11/2) | Q11: =IF(COUNT(O11:P11) = 0, "",O11/2+P11/2) | R11: =IF(COUNT(L11:M11) = 0, "",N11+Q11)
K12: 2007 | N12: =IF(COUNT(L12:M12) = 0, "",L12/2+M12/2) | Q12: =IF(COUNT(O12:P12) = 0, "",O12/2+P12/2) | R12: =IF(COUNT(L12:M12) = 0, "",N12+Q12) | T12: ● | U12: Input AADTs for every year that appears in the study range (Before and After Period). You do not need to input volumes for the years outside of the study time periods
B13: Comments/Instruction on Date Range Calculator: | K13: 2008 | N13: =IF(COUNT(L13:M13) = 0, "",L13/2+M13/2) | Q13: =IF(COUNT(O13:P13) = 0, "",O13/2+P13/2) | R13: =IF(COUNT(L13:M13) = 0, "",N13+Q13)
B14: ● | C14: Use a typical 3-month Construction Period unless you have specific information to the contrary (ex. construction dates were provided, info from satellite views, etc.). | K14: 2009 | N14: =IF(COUNT(L14:M14) = 0, "",L14/2+M14/2) | Q14: =IF(COUNT(O14:P14) = 0, "",O14/2+P14/2) | R14: =IF(COUNT(L14:M14) = 0, "",N14+Q14)
K15: 2010 | N15: =IF(COUNT(L15:M15) = 0, "",L15/2+M15/2) | Q15: =IF(COUNT(O15:P15) = 0, "",O15/2+P15/2) | R15: =IF(COUNT(L15:M15) = 0, "",N15+Q15) | T15: ● | U15: Volumes should be entered in for each leg of the intersection, even if no count data is available. Legs without available volume counts will need to have their volumes estimated.
B16: ● | C16: You CAN input the construction start date directly into cell D10 or simply just enter in the construction period length into cells D5/D6. | K16: 2011 | N16: =IF(COUNT(L16:M16) = 0, "",L16/2+M16/2) | Q16: =IF(COUNT(O16:P16) = 0, "",O16/2+P16/2) | R16: =IF(COUNT(L16:M16) = 0, "",N16+Q16)
K17: 2012 | N17: =IF(COUNT(L17:M17) = 0, "",L17/2+M17/2) | Q17: =IF(COUNT(O17:P17) = 0, "",O17/2+P17/2) | R17: =IF(COUNT(L17:M17) = 0, "",N17+Q17)
B18: ● | C18: This tool only works in WHOLE MONTHS. Construction start dates should be rounded up to the first of the month and construction end dates should be rounded down to the end the month. | K18: 2013 | N18: =IF(COUNT(L18:M18) = 0, "",L18/2+M18/2) | Q18: =IF(COUNT(O18:P18) = 0, "",O18/2+P18/2) | R18: =IF(COUNT(L18:M18) = 0, "",N18+Q18) | T18: ● | U18: In the case of a T-intersection, leave leg #4 blank (Column Q)
K19: 2014 | N19: =IF(COUNT(L19:M19) = 0, "",L19/2+M19/2) | Q19: =IF(COUNT(O19:P19) = 0, "",O19/2+P19/2) | R19: =IF(COUNT(L19:M19) = 0, "",N19+Q19) | T19: ● | U19: Intersections with 5 or more legs should just have the yearly volumes for the WHOLE intersection calcuated manually and entered into column R.
K20: 2015 | N20: =IF(COUNT(L20:M20) = 0, "",L20/2+M20/2) | Q20: =IF(COUNT(O20:P20) = 0, "",O20/2+P20/2) | R20: =IF(COUNT(L20:M20) = 0, "",N20+Q20)
K21: 2016 | N21: =IF(COUNT(L21:M21) = 0, "",L21/2+M21/2) | Q21: =IF(COUNT(O21:P21) = 0, "",O21/2+P21/2) | R21: =IF(COUNT(L21:M21) = 0, "",N21+Q21)
K22: 2017 | L22: =L57 -> 1100 | M22: =M57 -> 1200 | N22: =IF(COUNT(L22:M22) = 0, "",L22/2+M22/2) -> 1150 | O22: =O57 -> 650 | P22: =P57 -> 610 | Q22: =IF(COUNT(O22:P22) = 0, "",O22/2+P22/2) -> 630 | R22: =IF(COUNT(L22:M22) = 0, "",N22+Q22) -> 1780 | T22: ● | U22: Please note that this tool will not correctly calculate the AADT of an intersection that involves a one-way road. Should the major or minor road involve one-way traffic, the total entering volume into the intersection by that road should be directly entered into Column O (if the major road is one-way) or column R (if the minor road is one-way)
K23: 2018 | L23: =L58 -> 1100 | M23: =M58 -> 1300 | N23: =IF(COUNT(L23:M23) = 0, "",L23/2+M23/2) -> 1200 | O23: =ROUND(AVERAGE(O22,O24),-1) -> 650 | P23: =ROUND(AVERAGE(P22,P24),-1) -> 560 | Q23: =IF(COUNT(O23:P23) = 0, "",O23/2+P23/2) -> 605 | R23: =IF(COUNT(L23:M23) = 0, "",N23+Q23) -> 1805
K24: 2019 | L24: =L59 -> 950 | M24: =ROUND(M23/L23*L24,-2) -> 1100 | N24: =IF(COUNT(L24:M24) = 0, "",L24/2+M24/2) -> 1025 | O24: =O59 -> 650 | P24: =P59 -> 500 | Q24: =IF(COUNT(O24:P24) = 0, "",O24/2+P24/2) -> 575 | R24: =IF(COUNT(L24:M24) = 0, "",N24+Q24) -> 1600
K25: 2020 | L25: =L60 -> 900 | M25: =ROUND(M24/L24*L25,-2) -> 1000 | N25: =IF(COUNT(L25:M25) = 0, "",L25/2+M25/2) -> 950 | O25: =O26 -> 450 | P25: =P26 -> 400 | Q25: =IF(COUNT(O25:P25) = 0, "",O25/2+P25/2) -> 425 | R25: =IF(COUNT(L25:M25) = 0, "",N25+Q25) -> 1375
K26: 2021 | L26: =L61 -> 950 | M26: =M61 -> 1100 | N26: =IF(COUNT(L26:M26) = 0, "",L26/2+M26/2) -> 1025 | O26: =O61 -> 450 | P26: =P61 -> 400 | Q26: =IF(COUNT(O26:P26) = 0, "",O26/2+P26/2) -> 425 | R26: =IF(COUNT(L26:M26) = 0, "",N26+Q26) -> 1450
K27: 2022 | L27: =L62 -> 900 | M27: =M62 -> 1000 | N27: =IF(COUNT(L27:M27) = 0, "",L27/2+M27/2) -> 950 | O27: =ROUND(AVERAGE(O26,O28),-1) -> 550 | P27: =ROUND(AVERAGE(P26,P28),-1) -> 500 | Q27: =IF(COUNT(O27:P27) = 0, "",O27/2+P27/2) -> 525 | R27: =IF(COUNT(L27:M27) = 0, "",N27+Q27) -> 1475
K28: 2023 | L28: =L63 -> 1100 | M28: =M63 -> 1300 | N28: =IF(COUNT(L28:M28) = 0, "",L28/2+M28/2) -> 1200 | O28: =O63 -> 650 | P28: =P63 -> 600 | Q28: =IF(COUNT(O28:P28) = 0, "",O28/2+P28/2) -> 625 | R28: =IF(COUNT(L28:M28) = 0, "",N28+Q28) -> 1825 | T28: ● | U28: Do not select 2020 as a representative year for a particular time period, due to the effects of the COVID-19 pandemic, even if it is the last year with available AADT data within said time period.
K29: 2024 | L29: =L64 -> 950 | M29: =M64 -> 1200 | N29: =IF(COUNT(L29:M29) = 0, "",L29/2+M29/2) -> 1075 | O29: =O64 -> 700 | P29: =P64 -> 650 | Q29: =IF(COUNT(O29:P29) = 0, "",O29/2+P29/2) -> 675 | R29: =IF(COUNT(L29:M29) = 0, "",N29+Q29) -> 1750
K30: 2025 | L30: =L29 -> 950 | M30: =M29 -> 1200 | N30: =IF(COUNT(L30:M30) = 0, "",L30/2+M30/2) -> 1075 | O30: =O29 -> 700 | P30: =P29 -> 650 | Q30: =IF(COUNT(O30:P30) = 0, "",O30/2+P30/2) -> 675 | R30: =IF(COUNT(L30:M30) = 0, "",N30+Q30) -> 1750
K31: 2026 | L31: =L30 -> 950 | M31: =M30 -> 1200 | N31: =IF(COUNT(L31:M31) = 0, "",L31/2+M31/2) -> 1075 | O31: =O30 -> 700 | P31: =P30 -> 650 | Q31: =IF(COUNT(O31:P31) = 0, "",O31/2+P31/2) -> 675 | R31: =IF(COUNT(L31:M31) = 0, "",N31+Q31) -> 1750
K32: 2027 | N32: =IF(COUNT(L32:M32) = 0, "",L32/2+M32/2) | Q32: =IF(COUNT(O32:P32) = 0, "",O32/2+P32/2) | R32: =IF(COUNT(L32:M32) = 0, "",N32+Q32)
K33: 2028 | N33: =IF(COUNT(L33:M33) = 0, "",L33/2+M33/2) | Q33: =IF(COUNT(O33:P33) = 0, "",O33/2+P33/2) | R33: =IF(COUNT(L33:M33) = 0, "",N33+Q33)
K34: 2029 | N34: =IF(COUNT(L34:M34) = 0, "",L34/2+M34/2) | Q34: =IF(COUNT(O34:P34) = 0, "",O34/2+P34/2) | R34: =IF(COUNT(L34:M34) = 0, "",N34+Q34)
K35: 2030 | N35: =IF(COUNT(L35:M35) = 0, "",L35/2+M35/2) | Q35: =IF(COUNT(O35:P35) = 0, "",O35/2+P35/2) | R35: =IF(COUNT(L35:M35) = 0, "",N35+Q35)
G37: LocationID | H37: 400000005 | L37: 400000087 | M37: 400000004 | O37: 400000021 | P37: 400000005
G38: COUNTY | H38: GREENE | L38: GREENE | M38: GREENE | O38: GREENE | P38: GREENE
G39: RTE_CLS | H39: Secondary Routes | L39: NC Hwys | M39: NC Hwys | O39: Secondary Routes | P39: Secondary Routes
G40: ROUTE | H40: SR 1303 (Fieldsboro Rd) | L40: NC 91 | M40: NC 91 | O40: SR 1225 (Speights Bridge Rd) | P40: SR 1303 (Fieldsboro Rd)
G41: LOCATION | H41: EAST OF NC 91 | L41: SOUTH OF SR 1313 Gay Rd | M41: SOUTH OF SR 1304 E Railroad St | O41: EAST OF SR 1249 Howell Swamp Church Rd | P41: EAST OF NC 91
G42: AADT_2002 | M42: 1200
G43: AADT_2003 | H43: 530 | L43: 1000 | M43: 1200 | O43: 580 | P43: 530
...

Sheet Original Fiche
A1: North Carolina Department of Transportation Traffic Engineering Accident Analysis System Fiche Report
A2: County | B2: County Code | C2: Division | D2: Municipality | E2: Municipality Code | F2: Begin Date | G2: End Date | H2: Years | I2: Y-Line Feet
B3: GREENE | C3: 40 | D3: 2 | E3: All and Rural | G3: 43040 | H3: 46112 | I3: 8.41 | J3: 150
A4: Road Name | B4: Road Code
A5: SR 1303 | B5: 40001303
A6: NC 91 | B6: 30000091
A7: SPEIGHTS BRIDGE | B7: 50028745
A8: WILSON | B8: 50033187
A9: SR 1225 | B9: 40001225
A10: FIFTH | B10: 50010479
A11: FIELDSBORO | B11: 50049016
A12: 46171 | B12: Page 1 of 12
A13: Muni. Code | B13: On Road | C13: Miles / Dir From | D13: From Road | E13: Toward Road | F13: Milepost Road | G13: MP | H13: MA | I13: Crash ID | J13: Date | K13: T | L13: C | M13: F | N13: L | O13: S
A14: 0 | B14: NC 91 | C14: 0.004 | D14: N | E14: *LCL AUTUMN FLAME RD | F14: SR 1228 | H14: 999.999 | J14: 108153048 | K14: 45821 | L14: 19 | M14: 2 | N14: 5 | O14: 1 | P14: B
A15: 576 | B15: NC 91 | C15: 1.6 | D15: S | E15: *LCL US264A | F15: SR 1303 | H15: 999.999 | J15: 107765099 | K15: 45469 | L15: 17 | M15: 1 | N15: 0 | O15: 2 | P15: O
A16: 0 | B16: I 587 | C16: 0.019 | D16: W | E16: NC 91 | F16: *MILE 41 | G16: I 587 | H16: 3.046 | J16: 108280159 | K16: 45954 | L16: 17 | M16: 1 | N16: 16 | O16: 5 | P16: O
A17: 0 | B17: US 264 | C17: 0 | E17: NC 91 | F17: *MILE 59 | G17: I 587 | H17: 3.066 | I17: Y | J17: 106760348 | K17: 44505 | L17: 28 | M17: 1 | N17: 0 | O17: 5 | P17: O
A18: 0 | B18: NC 58 | C18: 0 | E18: SR 1225 | F18: SR 1253 | G18: NC 58 | H18: 17.354 | J18: 107899906 | K18: 45591 | L18: 30 | M18: 1 | N18: 7 | O18: 1 | P18: B
A19: 0 | B19: NC 58 | C19: 0 | E19: SR 1225 | F19: SR 1253 | G19: NC 58 | H19: 17.354 | J19: 108430264 | K19: 46092 | L19: 30 | M19: 1 | N19: 7 | O19: 1 | P19: C
A20: 0 | B20: NC 58 | C20: 0 | E20: SR 1225 | F20: SR 1253 | G20: NC 58 | H20: 17.354 | J20: 108202953 | K20: 45884 | L20: 30 | M20: 1 | N20: 7 | O20: 1 | P20: B
A21: 0 | B21: NC 58 | C21: 0 | E21: SR 1225 | F21: SR 1217 | G21: NC 58 | H21: 17.354 | J21: 108160977 | K21: 45840 | L21: 30 | M21: 1 | N21: 7 | O21: 1 | P21: O
A22: 0 | B22: NC 91 | C22: 0 | E22: US 258 | F22: SR 1247 | G22: NC 91 | H22: 0 | J22: 107467120 | K22: 45192 | L22: 30 | M22: 2 | N22: 7 | O22: 1 | P22: O
A23: 0 | B23: NC 91 | C23: 0 | E23: US 258 | F23: SR 1400 | G23: NC 91 | H23: 0 | J23: 106589495 | K23: 44344 | L23: 30 | M23: 1 | N23: 7 | O23: 1 | P23: O
A24: 0 | B24: NC 91 | C24: 0.095 | D24: S | E24: US 258 | F24: SECOND | G24: NC 91 | H24: 0 | J24: 107214302 | K24: 44939 | L24: 19 | M24: 2 | N24: 0 | O24: 4 | P24: O
A25: 0 | B25: NC 91 | C25: 0.009 | D25: N | E25: US 258 | F25: SR 1247 | G25: NC 91 | H25: 0.009 | J25: 106362782 | K25: 44113 | L25: 19 | M25: 1 | N25: 7 | O25: 5 | P25: O
A26: 0 | B26: NC 91 | C26: 0.1 | D26: S | E26: SR 1247 | F26: US 13 | G26: NC 91 | H26: 0.025 | J26: 107835963 | K26: 45521 | L26: 21 | M26: 1 | N26: 12 | O26: 1 | P26: O
A27: 0 | B27: NC 91 | C27: 0.1 | D27: N | E27: US 258 | F27: SR 1247 | G27: NC 91 | H27: 0.1 | J27: 105523576 | K27: 43267 | L27: 13 | M27: 1 | N27: 0 | O27: 5 | P27: O
A28: 0 | B28: NC 91 | C28: 0 | E28: SR 1364 | F28: SR 1330 | G28: NC 91 | H28: 0.125 | J28: 105588011 | K28: 43340 | L28: 25 | M28: 1 | N28: 7 | O28: 1 | P28: O
A29: 0 | B29: NC 91 | C29: 0 | E29: SR 1364 | F29: SR 1330 | G29: NC 91 | H29: 0.125 | J29: 105802310 | K29: 43536 | L29: 25 | M29: 1 | N29: 7 | O29: 1 | P29: O
A30: 0 | B30: NC 91 | C30: 0.2 | D30: N | E30: US 258 | F30: US 13 | G30: NC 91 | H30: 0.2 | J30: 106387930 | K30: 44132 | L30: 17 | M30: 1 | N30: 0 | O30: 1 | P30: O
A31: 0 | B31: NC 91 | C31: 0.3 | D31: N | E31: SR 1247 | F31: SR 1330 | G31: NC 91 | H31: 0.425 | J31: 107704191 | K31: 45413 | L31: 19 | M31: 1 | N31: 0 | O31: 5 | P31: O
A32: 0 | B32: NC 91 | C32: 0.3 | D32: N | E32: SR 1247 | F32: SR 1358 | G32: NC 91 | H32: 0.425 | J32: 107806612 | K32: 45506 | L32: 17 | M32: 1 | N32: 0 | O32: 5 | P32: O
A33: 0 | B33: NC 91 | C33: 0.5 | D33: N | E33: US 13 | F33: SR 1357 | G33: NC 91 | H33: 0.5 | J33: 106423037 | K33: 44166 | L33: 21 | M33: 1 | N33: 0 | O33: 1 | P33: O
A34: 0 | B34: NC 91 | C34: 0.5 | D34: N | E34: US 258 | F34: SR 1226 | G34: NC 91 | H34: 0.5 | J34: 106831693 | K34: 44572 | L34: 19 | M34: 1 | N34: 8 | O34: 1 | P34: O
A35: 0 | B35: NC 91 | C35: 0.5 | D35: N | E35: US 258 | F35: SR 1330 | G35: NC 91 | H35: 0.5 | J35: 106536246 | K35: 44292 | L35: 17 | M35: 1 | N35: 0 | O35: 1 | P35: O
A36: 0 | B36: NC 91 | C36: 0.4 | D36: N | E36: SR 1247 | F36: SR 1330 | G36: NC 91 | H36: 0.525 | J36: 106136954 | K36: 43855 | L36: 21 | M36: 2 | N36: 5 | O36: 1 | P36: C
A37: 0 | B37: NC 91 | C37: 0.6 | D37: N | E37: US 258 | F37: SR 1330 | G37: NC 91 | H37: 0.6 | J37: 106360965 | K37: 44111 | L37: 17 | M37: 1 | N37: 0 | O37: 5 | P37: O
A38: 0 | B38: NC 91 | C38: 0.5 | D38: N | E38: SR 1247 | F38: SR 1358 | G38: NC 91 | H38: 0.625 | J38: 107133428 | K38: 44867 | L38: 21 | M38: 1 | N38: 5 | O38: 1 | P38: C
A39: 0 | B39: NC 91 | C39: 0.5 | D39: S | E39: SR 1358 | F39: US 258 | G39: NC 91 | H39: 0.673 | J39: 106732615 | K39: 44483 | L39: 28 | M39: 1 | N39: 0 | O39: 1 | P39: O
A40: 0 | B40: NC 91 | C40: 0.7 | D40: N | E40: SR 1247 | F40: SR 1358 | G40: NC 91 | H40: 0.825 | J40: 106764606 | K40: 44511 | L40: 17 | M40: 1 | N40: 0 | O40: 5 | P40: O
...

Sheet Filtered Fiche
A1: Muni. Code | B1: On Road | C1: Miles | D1: Dir From | E1: From Road | F1: Toward Road | G1: Milepost Road | H1: MP | I1: IS? | J1: MA | K1: Crash ID | L1: Date | M1: T | N1: C | O1: F | P1: L | Q1: S | R1: Type | S1: Dir | T1: Comment
A2: IN STUDY
A3: 0 | B3: NC 91 | C3: 0 | E3: SR 1225 | F3: SR 1249 | G3: NC 91 | H3: 9.032 | I3: IS | K3: 106812116 | L3: 44547 | M3: 24 | N3: 1 | O3: 7 | P3: 1 | Q3: O | R3: =VLOOKUP(M3,Index!$A$1:$B$26, 2, FALSE) -> LTDR | S3: =X3 -> EBL/NBT | T3: failed to yield | V3: {=IF(AND(INDEX('Initial Study'!K:K, MATCH(K3, 'Initial Study'!B:B, 0) + 1) <> 0, INDEX('Initial Study'!K:K, MATCH(K3, 'Initial Study'!B:B, 0) + 1) <> ""), INDEX('Initial Study'!K:K, MATCH(K3, 'Initial Study'!B:B, 0) + 1), "")} -> E | W3: {=IF(AND(INDEX('Initial Study'!K:K, MATCH(K3, 'Initial Study'!B:B, 0) + 2) <> 0, INDEX('Initial Study'!K:K, MATCH(K3, 'Initial Study'!B:B, 0) + 2) <> "", NOT(ISNUMBER(INDEX('Initial Study'!K:K, MATCH(K3, 'Initial Study'!B:B, 0) + 2)))), INDEX('Initial Study'!K:K, MATCH(K3, 'Initial Study'!B:B, 0) + 2), "-")} -> N | X3: =IF(R3="RE", V3 & "BT/" & IF(W3 <> "-", W3 & "BT", ""), IF(OR(R3="LTDR", R3="LTSR"), V3 & "BL" & IF(W3 <> "-", "/" & W3 & "BT", ""), IF(OR(R3="RTDR", R3="RTSR"), V3 & "BR" & IF(W3 <> "-", "/" & W3 & "BT", ""), IF(W3 <> "-", V3 & "BT/" & W3 & "BT", V3 & "BT")))) -> EBL/NBT
A4: 0 | B4: NC 91 | C4: 0 | E4: SR 1225 | F4: SR 1249 | G4: NC 91 | H4: 9.032 | I4: IS | K4: 106226479 | L4: 43966 | M4: 30 | N4: 1 | O4: 7 | P4: 1 | Q4: O | R4: =VLOOKUP(M4,Index!$A$1:$B$26, 2, FALSE) -> angle | S4: WBT/SBT | T4: failed to yield | V4: {=IF(AND(INDEX('Initial Study'!K:K, MATCH(K4, 'Initial Study'!B:B, 0) + 1) <> 0, INDEX('Initial Study'!K:K, MATCH(K4, 'Initial Study'!B:B, 0) + 1) <> ""), INDEX('Initial Study'!K:K, MATCH(K4, 'Initial Study'!B:B, 0) + 1), "")} -> W | W4: {=IF(AND(INDEX('Initial Study'!K:K, MATCH(K4, 'Initial Study'!B:B, 0) + 2) <> 0, INDEX('Initial Study'!K:K, MATCH(K4, 'Initial Study'!B:B, 0) + 2) <> "", NOT(ISNUMBER(INDEX('Initial Study'!K:K, MATCH(K4, 'Initial Study'!B:B, 0) + 2)))), INDEX('Initial Study'!K:K, MATCH(K4, 'Initial Study'!B:B, 0) + 2), "-")} -> - | X4: =IF(R4="RE", V4 & "BT/" & IF(W4 <> "-", W4 & "BT", ""), IF(OR(R4="LTDR", R4="LTSR"), V4 & "BL" & IF(W4 <> "-", "/" & W4 & "BT", ""), IF(OR(R4="RTDR", R4="RTSR"), V4 & "BR" & IF(W4 <> "-", "/" & W4 & "BT", ""), IF(W4 <> "-", V4 & "BT/" & W4 & "BT", V4 & "BT")))) -> WBT
A5: 0 | B5: NC 91 | C5: 0 | E5: SR 1225 | F5: SR 1249 | G5: NC 91 | H5: 9.032 | I5: IS | K5: 106014182 | L5: 43742 | M5: 30 | N5: 1 | O5: 7 | P5: 1 | Q5: C | R5: =VLOOKUP(M5,Index!$A$1:$B$26, 2, FALSE) -> angle | S5: =X5 -> EBT/NBT | T5: failed to yield | V5: {=IF(AND(INDEX('Initial Study'!K:K, MATCH(K5, 'Initial Study'!B:B, 0) + 1) <> 0, INDEX('Initial Study'!K:K, MATCH(K5, 'Initial Study'!B:B, 0) + 1) <> ""), INDEX('Initial Study'!K:K, MATCH(K5, 'Initial Study'!B:B, 0) + 1), "")} -> E | W5: {=IF(AND(INDEX('Initial Study'!K:K, MATCH(K5, 'Initial Study'!B:B, 0) + 2) <> 0, INDEX('Initial Study'!K:K, MATCH(K5, 'Initial Study'!B:B, 0) + 2) <> "", NOT(ISNUMBER(INDEX('Initial Study'!K:K, MATCH(K5, 'Initial Study'!B:B, 0) + 2)))), INDEX('Initial Study'!K:K, MATCH(K5, 'Initial Study'!B:B, 0) + 2), "-")} -> N | X5: =IF(R5="RE", V5 & "BT/" & IF(W5 <> "-", W5 & "BT", ""), IF(OR(R5="LTDR", R5="LTSR"), V5 & "BL" & IF(W5 <> "-", "/" & W5 & "BT", ""), IF(OR(R5="RTDR", R5="RTSR"), V5 & "BR" & IF(W5 <> "-", "/" & W5 & "BT", ""), IF(W5 <> "-", V5 & "BT/" & W5 & "BT", V5 & "BT")))) -> EBT/NBT
A6: 0 | B6: NC 91 | C6: 0 | E6: SR 1225 | F6: SR 1249 | G6: NC 91 | H6: 9.032 | I6: IS | K6: 105843862 | L6: 43571 | M6: 30 | N6: 1 | O6: 7 | P6: 1 | Q6: C | R6: =VLOOKUP(M6,Index!$A$1:$B$26, 2, FALSE) -> angle | S6: =X6 -> EBT/NBT | T6: failed to yield | V6: {=IF(AND(INDEX('Initial Study'!K:K, MATCH(K6, 'Initial Study'!B:B, 0) + 1) <> 0, INDEX('Initial Study'!K:K, MATCH(K6, 'Initial Study'!B:B, 0) + 1) <> ""), INDEX('Initial Study'!K:K, MATCH(K6, 'Initial Study'!B:B, 0) + 1), "")} -> E | W6: {=IF(AND(INDEX('Initial Study'!K:K, MATCH(K6, 'Initial Study'!B:B, 0) + 2) <> 0, INDEX('Initial Study'!K:K, MATCH(K6, 'Initial Study'!B:B, 0) + 2) <> "", NOT(ISNUMBER(INDEX('Initial Study'!K:K, MATCH(K6, 'Initial Study'!B:B, 0) + 2)))), INDEX('Initial Study'!K:K, MATCH(K6, 'Initial Study'!B:B, 0) + 2), "-")} -> N | X6: =IF(R6="RE", V6 & "BT/" & IF(W6 <> "-", W6 & "BT", ""), IF(OR(R6="LTDR", R6="LTSR"), V6 & "BL" & IF(W6 <> "-", "/" & W6 & "BT", ""), IF(OR(R6="RTDR", R6="RTSR"), V6 & "BR" & IF(W6 <> "-", "/" & W6 & "BT", ""), IF(W6 <> "-", V6 & "BT/" & W6 & "BT", V6 & "BT")))) -> EBT/NBT
A7: 0 | B7: NC 91 | C7: 0 | E7: SR 1225 | F7: SR 1249 | G7: NC 91 | H7: 9.032 | I7: IS | K7: 105685815 | L7: 43422 | M7: 30 | N7: 1 | O7: 7 | P7: 1 | Q7: O | R7: =VLOOKUP(M7,Index!$A$1:$B$26, 2, FALSE) -> angle | S7: EBT/NBT | T7: failed to yield | V7: {=IF(AND(INDEX('Initial Study'!K:K, MATCH(K7, 'Initial Study'!B:B, 0) + 1) <> 0, INDEX('Initial Study'!K:K, MATCH(K7, 'Initial Study'!B:B, 0) + 1) <> ""), INDEX('Initial Study'!K:K, MATCH(K7, 'Initial Study'!B:B, 0) + 1), "")} -> NE | W7: {=IF(AND(INDEX('Initial Study'!K:K, MATCH(K7, 'Initial Study'!B:B, 0) + 2) <> 0, INDEX('Initial Study'!K:K, MATCH(K7, 'Initial Study'!B:B, 0) + 2) <> "", NOT(ISNUMBER(INDEX('Initial Study'!K:K, MATCH(K7, 'Initial Study'!B:B, 0) + 2)))), INDEX('Initial Study'!K:K, MATCH(K7, 'Initial Study'!B:B, 0) + 2), "-")} -> N | X7: =IF(R7="RE", V7 & "BT/" & IF(W7 <> "-", W7 & "BT", ""), IF(OR(R7="LTDR", R7="LTSR"), V7 & "BL" & IF(W7 <> "-", "/" & W7 & "BT", ""), IF(OR(R7="RTDR", R7="RTSR"), V7 & "BR" & IF(W7 <> "-", "/" & W7 & "BT", ""), IF(W7 <> "-", V7 & "BT/" & W7 & "BT", V7 & "BT")))) -> NEBT/NBT
A8: 0 | B8: NC 91 | C8: 0 | E8: SR 1225 | F8: SR 1226 | G8: NC 91 | H8: 9.032 | I8: IS | K8: 105366208 | L8: 43122 | M8: 30 | N8: 1 | O8: 7 | P8: 1 | Q8: O | R8: =VLOOKUP(M8,Index!$A$1:$B$26, 2, FALSE) -> angle | S8: EBT/NBT | T8: failed to yield | V8: {=IF(AND(INDEX('Initial Study'!K:K, MATCH(K8, 'Initial Study'!B:B, 0) + 1) <> 0, INDEX('Initial Study'!K:K, MATCH(K8, 'Initial Study'!B:B, 0) + 1) <> ""), INDEX('Initial Study'!K:K, MATCH(K8, 'Initial Study'!B:B, 0) + 1), "")} -> NE | W8: {=IF(AND(INDEX('Initial Study'!K:K, MATCH(K8, 'Initial Study'!B:B, 0) + 2) <> 0, INDEX('Initial Study'!K:K, MATCH(K8, 'Initial Study'!B:B, 0) + 2) <> "", NOT(ISNUMBER(INDEX('Initial Study'!K:K, MATCH(K8, 'Initial Study'!B:B, 0) + 2)))), INDEX('Initial Study'!K:K, MATCH(K8, 'Initial Study'!B:B, 0) + 2), "-")} -> N | X8: =IF(R8="RE", V8 & "BT/" & IF(W8 <> "-", W8 & "BT", ""), IF(OR(R8="LTDR", R8="LTSR"), V8 & "BL" & IF(W8 <> "-", "/" & W8 & "BT", ""), IF(OR(R8="RTDR", R8="RTSR"), V8 & "BR" & IF(W8 <> "-", "/" & W8 & "BT", ""), IF(W8 <> "-", V8 & "BT/" & W8 & "BT", V8 & "BT")))) -> NEBT/NBT
A9: 0 | B9: NC 91 | C9: 0 | E9: SR 1225 | F9: SR 1226 | G9: NC 91 | H9: 9.032 | I9: IS | K9: 106038472 | L9: 43745 | M9: 24 | N9: 1 | O9: 7 | P9: 1 | Q9: C | R9: =VLOOKUP(M9,Index!$A$1:$B$26, 2, FALSE) -> LTDR | S9: =X9 -> EBL/NBT | T9: failed to yield | V9: {=IF(AND(INDEX('Initial Study'!K:K, MATCH(K9, 'Initial Study'!B:B, 0) + 1) <> 0, INDEX('Initial Study'!K:K, MATCH(K9, 'Initial Study'!B:B, 0) + 1) <> ""), INDEX('Initial Study'!K:K, MATCH(K9, 'Initial Study'!B:B, 0) + 1), "")} -> E | W9: {=IF(AND(INDEX('Initial Study'!K:K, MATCH(K9, 'Initial Study'!B:B, 0) + 2) <> 0, INDEX('Initial Study'!K:K, MATCH(K9, 'Initial Study'!B:B, 0) + 2) <> "", NOT(ISNUMBER(INDEX('Initial Study'!K:K, MATCH(K9, 'Initial Study'!B:B, 0) + 2)))), INDEX('Initial Study'!K:K, MATCH(K9, 'Initial Study'!B:B, 0) + 2), "-")} -> N | X9: =IF(R9="RE", V9 & "BT/" & IF(W9 <> "-", W9 & "BT", ""), IF(OR(R9="LTDR", R9="LTSR"), V9 & "BL" & IF(W9 <> "-", "/" & W9 & "BT", ""), IF(OR(R9="RTDR", R9="RTSR"), V9 & "BR" & IF(W9 <> "-", "/" & W9 & "BT", ""), IF(W9 <> "-", V9 & "BT/" & W9 & "BT", V9 & "BT")))) -> EBL/NBT
A10: 0 | B10: NC 91 | C10: 0 | E10: SR 1225 | F10: SR 1249 | G10: NC 91 | H10: 9.032 | I10: IS | K10: 107856191 | L10: 45554 | M10: 30 | N10: 1 | O10: 7 | P10: 1 | Q10: O | R10: =VLOOKUP(M10,Index!$A$1:$B$26, 2, FALSE) -> angle | S10: NBT/EBT | T10: ran stop sign | V10: {=IF(AND(INDEX('Initial Study'!K:K, MATCH(K10, 'Initial Study'!B:B, 0) + 1) <> 0, INDEX('Initial Study'!K:K, MATCH(K10, 'Initial Study'!B:B, 0) + 1) <> ""), INDEX('Initial Study'!K:K, MATCH(K10, 'Initial Study'!B:B, 0) + 1), "")} -> N | W10: {=IF(AND(INDEX('Initial Study'!K:K, MATCH(K10, 'Initial Study'!B:B, 0) + 2) <> 0, INDEX('Initial Study'!K:K, MATCH(K10, 'Initial Study'!B:B, 0) + 2) <> "", NOT(ISNUMBER(INDEX('Initial Study'!K:K, MATCH(K10, 'Initial Study'!B:B, 0) + 2)))), INDEX('Initial Study'!K:K, MATCH(K10, 'Initial Study'!B:B, 0) + 2), "-")} -> SE | X10: =IF(R10="RE", V10 & "BT/" & IF(W10 <> "-", W10 & "BT", ""), IF(OR(R10="LTDR", R10="LTSR"), V10 & "BL" & IF(W10 <> "-", "/" & W10 & "BT", ""), IF(OR(R10="RTDR", R10="RTSR"), V10 & "BR" & IF(W10 <> "-", "/" & W10 & "BT", ""), IF(W10 <> "-", V10 & "BT/" & W10 & "BT", V10 & "BT")))) -> NBT/SEBT
A11: 0 | B11: NC 91 | C11: 0 | E11: SR 1303 | F11: SR 1249 | G11: NC 91 | H11: 9.032 | I11: IS | K11: 105880887 | L11: 43614 | M11: 30 | N11: 1 | O11: 7 | P11: 1 | Q11: C | R11: =VLOOKUP(M11,Index!$A$1:$B$26, 2, FALSE) -> angle | S11: =X11 -> WBT/SBT | T11: failed to yield | V11: {=IF(AND(INDEX('Initial Study'!K:K, MATCH(K11, 'Initial Study'!B:B, 0) + 1) <> 0, INDEX('Initial Study'!K:K, MATCH(K11, 'Initial Study'!B:B, 0) + 1) <> ""), INDEX('Initial Study'!K:K, MATCH(K11, 'Initial Study'!B:B, 0) + 1), "")} -> W | W11: {=IF(AND(INDEX('Initial Study'!K:K, MATCH(K11, 'Initial Study'!B:B, 0) + 2) <> 0, INDEX('Initial Study'!K:K, MATCH(K11, 'Initial Study'!B:B, 0) + 2) <> "", NOT(ISNUMBER(INDEX('Initial Study'!K:K, MATCH(K11, 'Initial Study'!B:B, 0) + 2)))), INDEX('Initial Study'!K:K, MATCH(K11, 'Initial Study'!B:B, 0) + 2), "-")} -> S | X11: =IF(R11="RE", V11 & "BT/" & IF(W11 <> "-", W11 & "BT", ""), IF(OR(R11="LTDR", R11="LTSR"), V11 & "BL" & IF(W11 <> "-", "/" & W11 & "BT", ""), IF(OR(R11="RTDR", R11="RTSR"), V11 & "BR" & IF(W11 <> "-", "/" & W11 & "BT", ""), IF(W11 <> "-", V11 & "BT/" & W11 & "BT", V11 & "BT")))) -> WBT/SBT
A12: 0 | B12: NC 91 | C12: 0 | E12: SR 1303 | F12: SR 1313 | G12: NC 91 | H12: 9.032 | I12: IS | K12: 105543910 | L12: 43297 | M12: 24 | N12: 1 | O12: 7 | P12: 1 | Q12: O | R12: =VLOOKUP(M12,Index!$A$1:$B$26, 2, FALSE) -> LTDR | S12: WBL/SBT | T12: failed to yield | V12: {=IF(AND(INDEX('Initial Study'!K:K, MATCH(K12, 'Initial Study'!B:B, 0) + 1) <> 0, INDEX('Initial Study'!K:K, MATCH(K12, 'Initial Study'!B:B, 0) + 1) <> ""), INDEX('Initial Study'!K:K, MATCH(K12, 'Initial Study'!B:B, 0) + 1), "")} -> S | W12: {=IF(AND(INDEX('Initial Study'!K:K, MATCH(K12, 'Initial Study'!B:B, 0) + 2) <> 0, INDEX('Initial Study'!K:K, MATCH(K12, 'Initial Study'!B:B, 0) + 2) <> "", NOT(ISNUMBER(INDEX('Initial Study'!K:K, MATCH(K12, 'Initial Study'!B:B, 0) + 2)))), INDEX('Initial Study'!K:K, MATCH(K12, 'Initial Study'!B:B, 0) + 2), "-")} -> S | X12: =IF(R12="RE", V12 & "BT/" & IF(W12 <> "-", W12 & "BT", ""), IF(OR(R12="LTDR", R12="LTSR"), V12 & "BL" & IF(W12 <> "-", "/" & W12 & "BT", ""), IF(OR(R12="RTDR", R12="RTSR"), V12 & "BR" & IF(W12 <> "-", "/" & W12 & "BT", ""), IF(W12 <> "-", V12 & "BT/" & W12 & "BT", V12 & "BT")))) -> SBL/SBT
A14: NOT IN STUDY - REPORT REVIEWED
A15: 0 | B15: NC 91 | C15: 0.1 | D15: N | E15: SR 1300 | F15: SR 1225 | G15: NC 91 | H15: 3.46 | I15: NIS | K15: 106445553 | L15: 44188 | M15: 17 | N15: 1 | O15: 0 | P15: 5 | Q15: O | R15: =VLOOKUP(M15,Index!$A$1:$B$26, 2, FALSE) -> animal
A16: 0 | B16: NC 91 | C16: 0.5 | D16: N | E16: SR 1239 | F16: SR 1225 | G16: NC 91 | H16: 7.33 | I16: NIS | K16: 106945246 | L16: 44685 | M16: 17 | N16: 1 | O16: 0 | P16: 5 | Q16: O | R16: =VLOOKUP(M16,Index!$A$1:$B$26, 2, FALSE) -> animal
A17: 0 | B17: NC 91 | C17: 0.2 | D17: E | E17: SR 1313 | F17: SR 1225 | G17: NC 91 | H17: 8 | I17: NIS | K17: 105746262 | L17: 43480 | M17: 17 | N17: 1 | O17: 0 | P17: 5 | Q17: O | R17: =VLOOKUP(M17,Index!$A$1:$B$26, 2, FALSE) -> animal
A18: 0 | B18: NC 91 | C18: 0.1 | D18: N | E18: SR 1249 | F18: SR 1225 | G18: NC 91 | H18: 8.51 | I18: NIS | K18: 105276544 | L18: 43040 | M18: 22 | N18: 1 | O18: 0 | P18: 5 | Q18: O | R18: =VLOOKUP(M18,Index!$A$1:$B$26, 2, FALSE) -> RE-T | T18: not at an intersection
A19: 0 | B19: NC 91 | C19: 0.3 | D19: N | E19: SR 1249 | F19: SR 1303 | G19: NC 91 | H19: 8.71 | I19: NIS | K19: 107364880 | L19: 45085 | M19: 17 | N19: 1 | O19: 0 | P19: 5 | Q19: O | R19: =VLOOKUP(M19,Index!$A$1:$B$26, 2, FALSE) -> animal
A20: 0 | B20: NC 91 | C20: 0.3 | D20: S | E20: SR 1225 | F20: SR 1249 | G20: NC 91 | H20: 8.732 | I20: NIS | K20: 105332237 | L20: 43092 | M20: 17 | N20: 1 | O20: 0 | P20: 1 | Q20: O | R20: =VLOOKUP(M20,Index!$A$1:$B$26, 2, FALSE) -> animal
A21: 0 | B21: NC 91 | C21: 0.1 | D21: S | E21: SR 1225 | F21: SR 1303 | G21: NC 91 | H21: 8.932 | I21: NIS | K21: 105981611 | L21: 43713 | M21: 19 | N21: 2 | O21: 0 | P21: 1 | Q21: O | R21: =VLOOKUP(M21,Index!$A$1:$B$26, 2, FALSE) -> FO | T21: not at an intersection
A22: 0 | B22: NC 91 | C22: 0.076 | D22: N | E22: SR 1303 | F22: MAIN | G22: NC 91 | H22: 9.108 | I22: NIS | K22: 107782765 | L22: 45485 | M22: 21 | N22: 2 | O22: 0 | P22: 1 | Q22: O | R22: =VLOOKUP(M22,Index!$A$1:$B$26, 2, FALSE) -> RE | T22: not at an intersection
A23: 0 | B23: NC 91 | C23: 0.1 | D23: N | E23: SR 1225 | F23: WHITLEY | G23: NC 91 | H23: 9.132 | I23: NIS | K23: 106905526 | L23: 44646 | M23: 17 | N23: 1 | O23: 0 | P23: 1 | Q23: O | R23: =VLOOKUP(M23,Index!$A$1:$B$26, 2, FALSE) -> animal
A24: 0 | B24: NC 91 | C24: 0.1 | D24: N | E24: SR 1303 | F24: MAIN | G24: NC 91 | H24: 9.132 | I24: NIS | K24: 108117743 | L24: 45797 | M24: 17 | N24: 1 | O24: 0 | P24: 1 | Q24: O | R24: =VLOOKUP(M24,Index!$A$1:$B$26, 2, FALSE) -> animal
A25: 0 | B25: NC 91 | C25: 0.2 | D25: N | E25: SR 1225 | F25: MAIN | G25: NC 91 | H25: 9.232 | I25: NIS | K25: 106249150 | L25: 43992 | M25: 17 | N25: 1 | O25: 0 | P25: 5 | Q25: O | R25: =VLOOKUP(M25,Index!$A$1:$B$26, 2, FALSE) -> animal
A26: 0 | B26: NC 91 | C26: 0.2 | D26: N | E26: SR 1303 | F26: SR 1226 | G26: NC 91 | H26: 9.232 | I26: NIS | K26: 106492243 | L26: 44243 | M26: 19 | N26: 1 | O26: 5 | P26: 5 | Q26: C | R26: =VLOOKUP(M26,Index!$A$1:$B$26, 2, FALSE) -> FO | T26: not at an intersection
A27: 0 | B27: NC 91 | C27: 0.3 | D27: N | E27: SR 1225 | F27: SR 1226 | G27: NC 91 | H27: 9.332 | I27: NIS | K27: 105414696 | L27: 43174 | M27: 17 | N27: 1 | O27: 5 | P27: 1 | Q27: O | R27: =VLOOKUP(M27,Index!$A$1:$B$26, 2, FALSE) -> animal
A28: 576 | B28: NC 91 | C28: 0.7 | D28: N | E28: SR 1303 | F28: SR 1226 | G28: NC 91 | H28: 9.732 | I28: NIS | K28: 107245537 | L28: 44972 | M28: 17 | N28: 1 | O28: 0 | P28: 5 | Q28: O | R28: =VLOOKUP(M28,Index!$A$1:$B$26, 2, FALSE) -> animal
A29: 576 | B29: NC 91 | C29: 0.076 | D29: S | E29: SR 1226 | F29: SR 1303 | G29: NC 91 | H29: 9.903 | I29: NIS | K29: 108422243 | L29: 46079 | M29: 19 | N29: 2 | O29: 0 | P29: 1 | Q29: O | R29: =VLOOKUP(M29,Index!$A$1:$B$26, 2, FALSE) -> FO | T29: not at an intersection
A30: 576 | B30: NC 91 | C30: 0.1 | D30: S | E30: NC 91 | F30: SR 1226 | G30: NC 91 | H30: 999.999 | I30: NIS | K30: 106335461 | L30: 44082 | M30: 19 | N30: 2 | O30: 0 | P30: 1 | Q30: C | R30: =VLOOKUP(M30,Index!$A$1:$B$26, 2, FALSE) -> FO | T30: not at an intersection
A31: 0 | B31: NC 91 | C31: 0.6 | D31: S | E31: SR 1302 | F31: NC 91 | G31: NC 91 | H31: 999.999 | I31: NIS | K31: 107808878 | L31: 45491 | M31: 19 | N31: 1 | O31: 0 | P31: 1 | Q31: O | R31: =VLOOKUP(M31,Index!$A$1:$B$26, 2, FALSE) -> FO | T31: not at an intersection
A32: 0 | B32: SR 1225 | C32: 0.2 | D32: E | E32: SR 1249 | F32: NC 91 | G32: SR 1225 | H32: 7.57 | K32: 106957216 | L32: 44695 | M32: 19 | N32: 1 | O32: 0 | P32: 1 | Q32: A | R32: =VLOOKUP(M32,Index!$A$1:$B$26, 2, FALSE) -> FO | T32: not at an intersection
A33: 0 | B33: SR 1225 | C33: 0.5 | D33: N | E33: SR 1249 | F33: NC 91 | G33: SR 1225 | H33: 7.87 | K33: 106871677 | L33: 44613 | M33: 17 | N33: 1 | O33: 0 | P33: 5 | Q33: O | R33: =VLOOKUP(M33,Index!$A$1:$B$26, 2, FALSE) -> animal
A34: 0 | B34: SR 1225 | C34: 1.75 | D34: N | E34: NC 91 | F34: SR 1227 | G34: SR 1225 | H34: 8.091 | K34: 106637614 | L34: 44394 | M34: 17 | N34: 1 | O34: 0 | P34: 5 | Q34: O | R34: =VLOOKUP(M34,Index!$A$1:$B$26, 2, FALSE) -> animal
A35: 576 | B35: SR 1228 | C35: 0 | E35: NC 91 | F35: SR 1226 | G35: SR 1228 | H35: 0 | K35: 107064237 | L35: 44802 | M35: 19 | N35: 1 | O35: 8 | P35: 1 | Q35: O | R35: =VLOOKUP(M35,Index!$A$1:$B$26, 2, FALSE) -> FO | T35: not at an intersection
A36: 0 | B36: SR 1230 | C36: 0.015 | D36: S | E36: NC 91 | F36: SR 1237 | G36: SR 1230 | H36: 999.999 | K36: 105386275 | L36: 43148 | M36: 31 | N36: 1 | O36: 0 | P36: 1 | Q36: O | R36: =VLOOKUP(M36,Index!$A$1:$B$26, 2, FALSE) -> backing | T36: not at an intersection
A37: 0 | B37: SR 1237 | C37: 0 | E37: NC 91 | F37: PRIVATE PROPERTY | G37: SR 1237 | H37: 2.049 | K37: 106206609 | L37: 43938 | M37: 19 | N37: 1 | O37: 8 | P37: 5 | R37: =VLOOKUP(M37,Index!$A$1:$B$26, 2, FALSE) -> FO | T37: not at an intersection
A38: 0 | B38: SR 1303 | C38: 0.1 | D38: S | E38: SR 1302 | F38: NC 91 | G38: SR 1303 | H38: 0.681 | K38: 107204732 | L38: 44931 | M38: 19 | N38: 1 | O38: 0 | P38: 1 | Q38: O | R38: =VLOOKUP(M38,Index!$A$1:$B$26, 2, FALSE) -> FO | T38: not at an intersection
A39: 0 | B39: SR 1303 | C39: 0.3 | D39: E | E39: NC 91 | F39: SR 1302 | G39: SR 1303 | H39: 0.3 | K39: 108348926 | L39: 46006 | M39: 17 | N39: 1 | O39: 0 | P39: 5 | Q39: O | R39: =VLOOKUP(M39,Index!$A$1:$B$26, 2, FALSE) -> animal
A41: NOT IN STUDY - REPORT NOT REVIEWED
A42: 0 | B42: I 587 | C42: 0.019 | D42: W | E42: NC 91 | F42: *MILE 41 | G42: I 587 | H42: 3.046 | I42: NIS | K42: 108280159 | L42: 45954 | M42: 17 | N42: 1 | O42: 16 | P42: 5 | Q42: O
...

Sheet ID
A1: Crash ID | B1: CRASH | C1: IS? | D1: Fiche? | H1: CRASH | I1: ID | J1: ON | K1: RD | L1: CD | M1: SVRTY | N1: DATE | O1: TYPE
A2: 108280159 | B2: 105366208 | C2: =IF(ISNUMBER(MATCH(A2,B:B,0)),"IS","") | D2: =IF(COUNTIF(A:A,B2),"YES","NO") -> YES | H2: 105366208 | I2: 30000091 | J2: 5 | K2: 43122 | L2: 0.36805556 | M2: 30
A3: 106760348 | B3: 105543910 | C3: =IF(ISNUMBER(MATCH(A3,B:B,0)),"IS","") | D3: =IF(COUNTIF(A:A,B3),"YES","NO") -> YES | H3: 105543910 | I3: 30000091 | J3: 5 | K3: 43297 | L3: 0.75486111 | M3: 24
A4: 107899906 | B4: 105685815 | C4: =IF(ISNUMBER(MATCH(A4,B:B,0)),"IS","") | D4: =IF(COUNTIF(A:A,B4),"YES","NO") -> YES | H4: 105685815 | I4: 30000091 | J4: 5 | K4: 43422 | L4: 0.6 | M4: 30
A5: 108430264 | B5: 105843862 | C5: =IF(ISNUMBER(MATCH(A5,B:B,0)),"IS","") | D5: =IF(COUNTIF(A:A,B5),"YES","NO") -> YES | H5: 105843862 | I5: 30000091 | J5: 4 | K5: 43571 | L5: 0.45555556 | M5: 30
A6: 108202953 | B6: 105880887 | C6: =IF(ISNUMBER(MATCH(A6,B:B,0)),"IS","") | D6: =IF(COUNTIF(A:A,B6),"YES","NO") -> YES | H6: 105880887 | I6: 30000091 | J6: 4 | K6: 43614 | L6: 0.71319444 | M6: 30
A7: 108160977 | B7: 106014182 | C7: =IF(ISNUMBER(MATCH(A7,B:B,0)),"IS","") | D7: =IF(COUNTIF(A:A,B7),"YES","NO") -> YES | H7: 106014182 | I7: 30000091 | J7: 4 | K7: 43742 | L7: 0.77430556 | M7: 30
A8: 107467120 | B8: 106038472 | C8: =IF(ISNUMBER(MATCH(A8,B:B,0)),"IS","") | D8: =IF(COUNTIF(A:A,B8),"YES","NO") -> YES | H8: 106038472 | I8: 30000091 | J8: 4 | K8: 43745 | L8: 0.63402778 | M8: 24
A9: 106589495 | B9: 106226479 | C9: =IF(ISNUMBER(MATCH(A9,B:B,0)),"IS","") | D9: =IF(COUNTIF(A:A,B9),"YES","NO") -> YES | H9: 106226479 | I9: 30000091 | J9: 5 | K9: 43966 | L9: 0.64722222 | M9: 30
A10: 107214302 | B10: 106812116 | C10: =IF(ISNUMBER(MATCH(A10,B:B,0)),"IS","") | D10: =IF(COUNTIF(A:A,B10),"YES","NO") -> YES | H10: 106812116 | I10: 30000091 | J10: 5 | K10: 44547 | L10: 0.54027778 | M10: 24
A11: 106362782 | B11: 107856191 | C11: =IF(ISNUMBER(MATCH(A11,B:B,0)),"IS","") | D11: =IF(COUNTIF(A:A,B11),"YES","NO") -> YES | H11: 107856191 | I11: 30000091 | J11: 5 | K11: 45554 | L11: 0.31597222 | M11: 30
A12: 107835963 | C12: =IF(ISNUMBER(MATCH(A12,B:B,0)),"IS","")
A13: 105523576 | C13: =IF(ISNUMBER(MATCH(A13,B:B,0)),"IS","")
A14: 105588011 | C14: =IF(ISNUMBER(MATCH(A14,B:B,0)),"IS","")
A15: 105802310 | C15: =IF(ISNUMBER(MATCH(A15,B:B,0)),"IS","")
A16: 106387930 | C16: =IF(ISNUMBER(MATCH(A16,B:B,0)),"IS","")
A17: 107704191 | C17: =IF(ISNUMBER(MATCH(A17,B:B,0)),"IS","")
A18: 107806612 | C18: =IF(ISNUMBER(MATCH(A18,B:B,0)),"IS","")
A19: 106423037 | C19: =IF(ISNUMBER(MATCH(A19,B:B,0)),"IS","")
A20: 106831693 | C20: =IF(ISNUMBER(MATCH(A20,B:B,0)),"IS","")
A21: 106536246 | C21: =IF(ISNUMBER(MATCH(A21,B:B,0)),"IS","")
A22: 106136954 | C22: =IF(ISNUMBER(MATCH(A22,B:B,0)),"IS","")
A23: 106360965 | C23: =IF(ISNUMBER(MATCH(A23,B:B,0)),"IS","")
... A321: 107765099 | C321: =IF(ISNUMBER(MATCH(A321,B:B,0)),"IS","")
C322: =IF(ISNUMBER(MATCH(A322,B:B,0)),"IS","")
C323: =IF(ISNUMBER(MATCH(A323,B:B,0)),"IS","")
C324: =IF(ISNUMBER(MATCH(A324,B:B,0)),"IS","")
C325: =IF(ISNUMBER(MATCH(A325,B:B,0)),"IS","")
C326: =IF(ISNUMBER(MATCH(A326,B:B,0)),"IS","")
C327: =IF(ISNUMBER(MATCH(A327,B:B,0)),"IS","")
C328: =IF(ISNUMBER(MATCH(A328,B:B,0)),"IS","")
C329: =IF(ISNUMBER(MATCH(A329,B:B,0)),"IS","")
C330: =IF(ISNUMBER(MATCH(A330,B:B,0)),"IS","")
C331: =IF(ISNUMBER(MATCH(A331,B:B,0)),"IS","")
C332: =IF(ISNUMBER(MATCH(A332,B:B,0)),"IS","")
C333: =IF(ISNUMBER(MATCH(A333,B:B,0)),"IS","")
... C2806: =IF(ISNUMBER(MATCH(A2806,B:B,0)),"IS","")

Sheet Index
A1: 0 | B1: unknown
A2: 1 | B2: ROR-R
A3: 2 | B3: ROR-L
A4: 3 | B4: ROR-T
A5: 4 | B5: jackknife
A6: 5 | B6: overturn
A7: 13 | B7: other
A8: 14 | B8: pedestrian
A9: 15 | B9: cyclist
A10: 16 | B10: RR
A11: 17 | B11: animal
A12: 18 | B12: MO
... A26: 32 | B26: other

Sheet Initial Study
B1: North Carolina Department of Transportation Traffic Engineering Accident Analysis System Intersection Analysis Report
A2: Study Criteria Summary
A3: County: | B3: GREENE | C3: City: | D3: All and Rural
A4: Date: | B4: 43040 | C4: to | D4: 46112 | E4: Study: | F4: 410000780441
A5: Location: | B5: NC 91 at SR 1225 (Speights Bridge Road)/SR 1303 (Fieldsboro Road)
A6: Report Details
A7: Acc No | B7: Crash ID | C7: Date | D7: Accident Type | E7: Total Damage | F7: Injuries | G7: F | H7: A | I7: B | J7: C | K7: R | L7: Condition | M7: L | N7: W | O7: Road | P7: Ch | Q7: Ci | R7: Dv | S7: Trfc Ctl | T7: Op
A8: 1 | B8: 105366208 | C8: 43122.368 | D8: ANGLE | E8: $ | F8: 1100 | G8: 0 | H8: 0 | I8: 0 | J8: 0 | K8: 1 | L8: 1 | M8: 2 | N8: 1 | O8: 0 | P8: 1 | Q8: 1
A9: Unit | B9: 1 | C9: : | D9: 1 | E9: Alchl/Drgs: | F9: 0 | G9: Speed: | H9: 15 | I9: MPH | J9: Dir: | K9: NE | L9: Veh Mnvr / Ped Actn: | M9: 4 | N9: Obj Strk:
A10: Unit | B10: 2 | C10: : | D10: 1 | E10: Alchl/Drgs: | F10: 0 | G10: Speed: | H10: 55 | I10: MPH | J10: Dir: | K10: N | L10: Veh Mnvr / Ped Actn: | M10: 4 | N10: Obj Strk: | O10: 58
A11: 2 | B11: 105543910 | C11: 43297.755 | D11: LEFT TURN, DIFFERENT ROADWAYS | E11: $ | F11: 5000 | G11: 0 | H11: 0 | I11: 0 | J11: 0 | K11: 1 | L11: 1 | M11: 2 | N11: 1 | O11: 0 | P11: 1 | Q11: 1
A12: Unit | B12: 1 | C12: : | D12: 2 | E12: Alchl/Drgs: | F12: 0 | G12: Speed: | H12: 15 | I12: MPH | J12: Dir: | K12: S | L12: Veh Mnvr / Ped Actn: | M12: 8 | N12: Obj Strk:
A13: Unit | B13: 2 | C13: : | D13: 10 | E13: Alchl/Drgs: | F13: 0 | G13: Speed: | H13: 55 | I13: MPH | J13: Dir: | K13: S | L13: Veh Mnvr / Ped Actn: | M13: 4 | N13: Obj Strk:
A14: 3 | B14: 105685815 | C14: 43422.6 | D14: ANGLE | E14: $ | F14: 9500 | G14: 0 | H14: 0 | I14: 0 | J14: 0 | K14: 1 | L14: 1 | M14: 1 | N14: 1 | O14: 0 | P14: 1 | Q14: 1
A15: Unit | B15: 1 | C15: : | D15: 4 | E15: Alchl/Drgs: | F15: 0 | G15: Speed: | H15: 0 | I15: MPH | J15: Dir: | K15: NE | L15: Veh Mnvr / Ped Actn: | M15: 4 | N15: Obj Strk:
A16: Unit | B16: 2 | C16: : | D16: 2 | E16: Alchl/Drgs: | F16: 0 | G16: Speed: | H16: 55 | I16: MPH | J16: Dir: | K16: N | L16: Veh Mnvr / Ped Actn: | M16: 4 | N16: Obj Strk:
A17: 4 | B17: 105843862 | C17: 43571.456 | D17: ANGLE | E17: $ | F17: 18500 | G17: 0 | H17: 0 | I17: 0 | J17: 3 | K17: 1 | L17: 1 | M17: 1 | N17: 1 | O17: 0 | P17: 1 | Q17: 1
A18: Unit | B18: 1 | C18: : | D18: 4 | E18: Alchl/Drgs: | F18: 0 | G18: Speed: | H18: 55 | I18: MPH | J18: Dir: | K18: E | L18: Veh Mnvr / Ped Actn: | M18: 4 | N18: Obj Strk:
A19: Unit | B19: 2 | C19: : | D19: 2 | E19: Alchl/Drgs: | F19: 0 | G19: Speed: | H19: 55 | I19: MPH | J19: Dir: | K19: N | L19: Veh Mnvr / Ped Actn: | M19: 4 | N19: Obj Strk: | O19: 58
A20: 5 | B20: 105880887 | C20: 43614.713 | D20: ANGLE | E20: $ | F20: 11000 | G20: 0 | H20: 0 | I20: 0 | J20: 1 | K20: 1 | L20: 1 | M20: 1 | N20: 1 | O20: 0 | P20: 1 | Q20: 1
A21: Unit | B21: 1 | C21: : | D21: 1 | E21: Alchl/Drgs: | F21: 0 | G21: Speed: | H21: 20 | I21: MPH | J21: Dir: | K21: W | L21: Veh Mnvr / Ped Actn: | M21: 4 | N21: Obj Strk:
A22: Unit | B22: 2 | C22: : | D22: 1 | E22: Alchl/Drgs: | F22: 0 | G22: Speed: | H22: 55 | I22: MPH | J22: Dir: | K22: S | L22: Veh Mnvr / Ped Actn: | M22: 4 | N22: Obj Strk: | O22: 58
A23: 6 | B23: 106014182 | C23: 43742.774 | D23: ANGLE | E23: $ | F23: 7500 | G23: 0 | H23: 0 | I23: 0 | J23: 3 | K23: 1 | L23: 1 | M23: 1 | N23: 1 | O23: 0 | P23: 1 | Q23: 1
A24: Unit | B24: 1 | C24: : | D24: 1 | E24: Alchl/Drgs: | F24: 0 | G24: Speed: | H24: 55 | I24: MPH | J24: Dir: | K24: E | L24: Veh Mnvr / Ped Actn: | M24: 4 | N24: Obj Strk:
A25: Unit | B25: 2 | C25: : | D25: 1 | E25: Alchl/Drgs: | F25: 0 | G25: Speed: | H25: 45 | I25: MPH | J25: Dir: | K25: N | L25: Veh Mnvr / Ped Actn: | M25: 4 | N25: Obj Strk:
A26: 7 | B26: 106038472 | C26: 43745.634 | D26: LEFT TURN, DIFFERENT ROADWAYS | E26: $ | F26: 13000 | G26: 0 | H26: 0 | I26: 0 | J26: 1 | K26: 1 | L26: 1 | M26: 1 | N26: 1 | O26: 0 | P26: 1 | Q26: 1
A27: Unit | B27: 1 | C27: : | D27: 2 | E27: Alchl/Drgs: | F27: 0 | G27: Speed: | H27: 25 | I27: MPH | J27: Dir: | K27: E | L27: Veh Mnvr / Ped Actn: | M27: 8 | N27: Obj Strk:
A28: Unit | B28: 2 | C28: : | D28: 2 | E28: Alchl/Drgs: | F28: 0 | G28: Speed: | H28: 55 | I28: MPH | J28: Dir: | K28: N | L28: Veh Mnvr / Ped Actn: | M28: 4 | N28: Obj Strk:
A29: 8 | B29: 106226479 | C29: 43966.647 | D29: ANGLE | E29: $ | F29: 6300 | G29: 0 | H29: 0 | I29: 0 | J29: 0 | K29: 1 | L29: 1 | M29: 1 | N29: 1 | O29: 0 | P29: 13 | Q29: 1
A30: Unit | B30: 1 | C30: : | D30: 4 | E30: Alchl/Drgs: | F30: 0 | G30: Speed: | H30: 55 | I30: MPH | J30: Dir: | K30: W | L30: Veh Mnvr / Ped Actn: | M30: 4 | N30: Obj Strk:
B31: 46171 | C31: All data presented in this report comes explicitly from the Traffic Engineering Accident Analysis System based upon various input criteria provided by the report's creator. The onus is strictly upon the user of this report to exercise due diligence in interpreting and further representing this data. | D31: -1-
B32: North Carolina Department of Transportation Traffic Engineering Accident Analysis System Intersection Analysis Report
A33: Acc No | B33: Crash ID | C33: Date | D33: Accident Type | E33: Total Damage | F33: Injuries | G33: F | H33: A | I33: B | J33: C | K33: R | L33: Condition | M33: L | N33: W | O33: Road | P33: Ch | Q33: Ci | R33: Dv | S33: Trfc Ctl | T33: Op
A34: Unit | B34: 2 | C34: : | D34: 2 | E34: Alchl/Drgs: | F34: 0 | G34: Speed: | H34: 55 | I34: MPH | J34: Dir: | K34: S | L34: Veh Mnvr / Ped Actn: | M34: 4 | N34: Obj Strk:
A35: 9 | B35: 106812116 | C35: 44547.54 | D35: LEFT TURN, DIFFERENT ROADWAYS | E35: $ | F35: 11000 | G35: 0 | H35: 0 | I35: 0 | J35: 0 | K35: 1 | L35: 1 | M35: 1 | N35: 1 | O35: 0 | P35: 1 | Q35: 1
A36: Unit | B36: 1 | C36: : | D36: 1 | E36: Alchl/Drgs: | F36: 0 | G36: Speed: | H36: 10 | I36: MPH | J36: Dir: | K36: E | L36: Veh Mnvr / Ped Actn: | M36: 8 | N36: Obj Strk:
A37: Unit | B37: 2 | C37: : | D37: 10 | E37: Alchl/Drgs: | F37: 0 | G37: Speed: | H37: 50 | I37: MPH | J37: Dir: | K37: N | L37: Veh Mnvr / Ped Actn: | M37: 4 | N37: Obj Strk:
A38: 10 | B38: 107856191 | C38: 45554.316 | D38: ANGLE | E38: $ | F38: 18250 | G38: 0 | H38: 0 | I38: 0 | J38: 0 | K38: 1 | L38: 1 | M38: 2 | N38: 1 | O38: 0 | P38: 1 | Q38: 1
A39: Unit | B39: 1 | C39: : | D39: 2 | E39: Alchl/Drgs: | F39: 0 | G39: Speed: | H39: 55 | I39: MPH | J39: Dir: | K39: N | L39: Veh Mnvr / Ped Actn: | M39: 4 | N39: Obj Strk: | O39: 37
A40: Unit | B40: 2 | C40: : | D40: 1 | E40: Alchl/Drgs: | F40: 0 | G40: Speed: | H40: 5 | I40: MPH | J40: Dir: | K40: SE | L40: Veh Mnvr / Ped Actn: | M40: 12 | N40: Obj Strk:
...

Sheet Binned Crashes
A1: Muni. Code | B1: On Road | C1: Miles | D1: Dir From | E1: From Road | F1: Toward Road | G1: Milepost Road | H1: MP | I1: IS? | J1: MA | K1: Crash ID | L1: Date | M1: T | N1: C | O1: F | P1: L | Q1: S | R1: Type | S1: Dir | T1: Comment
A2: =Before!A2 -> Before Period (11/01/17 - 10/31/21)
A3: 0 | B3: NC 91 | C3: 0 | E3: SR 1225 | F3: SR 1226 | G3: NC 91 | H3: 9.032 | I3: IS | K3: 105366208 | L3: 43122 | M3: 30 | N3: 1 | O3: 7 | P3: 1 | Q3: O | R3: =VLOOKUP(M3,Index!$A$1:$B$26, 2, FALSE) -> angle | S3: EBT/NBT | T3: failed to yield | V3: {=IF(AND(INDEX('Initial Study'!K:K, MATCH(K3, 'Initial Study'!B:B, 0) + 1) <> 0, INDEX('Initial Study'!K:K, MATCH(K3, 'Initial Study'!B:B, 0) + 1) <> ""), INDEX('Initial Study'!K:K, MATCH(K3, 'Initial Study'!B:B, 0) + 1), "")} -> NE | W3: {=IF(AND(INDEX('Initial Study'!K:K, MATCH(K3, 'Initial Study'!B:B, 0) + 2) <> 0, INDEX('Initial Study'!K:K, MATCH(K3, 'Initial Study'!B:B, 0) + 2) <> "", NOT(ISNUMBER(INDEX('Initial Study'!K:K, MATCH(K3, 'Initial Study'!B:B, 0) + 2)))), INDEX('Initial Study'!K:K, MATCH(K3, 'Initial Study'!B:B, 0) + 2), "-")} -> N | X3: =IF(R3="RE", V3 & "BT/" & IF(W3 <> "-", W3 & "BT", ""), IF(OR(R3="LTDR", R3="LTSR"), V3 & "BL" & IF(W3 <> "-", "/" & W3 & "BT", ""), IF(OR(R3="RTDR", R3="RTSR"), V3 & "BR" & IF(W3 <> "-", "/" & W3 & "BT", ""), IF(W3 <> "-", V3 & "BT/" & W3 & "BT", V3 & "BT")))) -> NEBT/NBT
A4: 0 | B4: NC 91 | C4: 0 | E4: SR 1303 | F4: SR 1313 | G4: NC 91 | H4: 9.032 | I4: IS | K4: 105543910 | L4: 43297 | M4: 24 | N4: 1 | O4: 7 | P4: 1 | Q4: O | R4: =VLOOKUP(M4,Index!$A$1:$B$26, 2, FALSE) -> LTDR | S4: WBL/SBT | T4: failed to yield | V4: {=IF(AND(INDEX('Initial Study'!K:K, MATCH(K4, 'Initial Study'!B:B, 0) + 1) <> 0, INDEX('Initial Study'!K:K, MATCH(K4, 'Initial Study'!B:B, 0) + 1) <> ""), INDEX('Initial Study'!K:K, MATCH(K4, 'Initial Study'!B:B, 0) + 1), "")} -> S | W4: {=IF(AND(INDEX('Initial Study'!K:K, MATCH(K4, 'Initial Study'!B:B, 0) + 2) <> 0, INDEX('Initial Study'!K:K, MATCH(K4, 'Initial Study'!B:B, 0) + 2) <> "", NOT(ISNUMBER(INDEX('Initial Study'!K:K, MATCH(K4, 'Initial Study'!B:B, 0) + 2)))), INDEX('Initial Study'!K:K, MATCH(K4, 'Initial Study'!B:B, 0) + 2), "-")} -> S | X4: =IF(R4="RE", V4 & "BT/" & IF(W4 <> "-", W4 & "BT", ""), IF(OR(R4="LTDR", R4="LTSR"), V4 & "BL" & IF(W4 <> "-", "/" & W4 & "BT", ""), IF(OR(R4="RTDR", R4="RTSR"), V4 & "BR" & IF(W4 <> "-", "/" & W4 & "BT", ""), IF(W4 <> "-", V4 & "BT/" & W4 & "BT", V4 & "BT")))) -> SBL/SBT
A5: 0 | B5: NC 91 | C5: 0 | E5: SR 1225 | F5: SR 1249 | G5: NC 91 | H5: 9.032 | I5: IS | K5: 105685815 | L5: 43422 | M5: 30 | N5: 1 | O5: 7 | P5: 1 | Q5: O | R5: =VLOOKUP(M5,Index!$A$1:$B$26, 2, FALSE) -> angle | S5: EBT/NBT | T5: failed to yield | V5: {=IF(AND(INDEX('Initial Study'!K:K, MATCH(K5, 'Initial Study'!B:B, 0) + 1) <> 0, INDEX('Initial Study'!K:K, MATCH(K5, 'Initial Study'!B:B, 0) + 1) <> ""), INDEX('Initial Study'!K:K, MATCH(K5, 'Initial Study'!B:B, 0) + 1), "")} -> NE | W5: {=IF(AND(INDEX('Initial Study'!K:K, MATCH(K5, 'Initial Study'!B:B, 0) + 2) <> 0, INDEX('Initial Study'!K:K, MATCH(K5, 'Initial Study'!B:B, 0) + 2) <> "", NOT(ISNUMBER(INDEX('Initial Study'!K:K, MATCH(K5, 'Initial Study'!B:B, 0) + 2)))), INDEX('Initial Study'!K:K, MATCH(K5, 'Initial Study'!B:B, 0) + 2), "-")} -> N | X5: =IF(R5="RE", V5 & "BT/" & IF(W5 <> "-", W5 & "BT", ""), IF(OR(R5="LTDR", R5="LTSR"), V5 & "BL" & IF(W5 <> "-", "/" & W5 & "BT", ""), IF(OR(R5="RTDR", R5="RTSR"), V5 & "BR" & IF(W5 <> "-", "/" & W5 & "BT", ""), IF(W5 <> "-", V5 & "BT/" & W5 & "BT", V5 & "BT")))) -> NEBT/NBT
A6: 0 | B6: NC 91 | C6: 0 | E6: SR 1225 | F6: SR 1249 | G6: NC 91 | H6: 9.032 | I6: IS | K6: 105843862 | L6: 43571 | M6: 30 | N6: 1 | O6: 7 | P6: 1 | Q6: C | R6: =VLOOKUP(M6,Index!$A$1:$B$26, 2, FALSE) -> angle | S6: =X6 -> EBT/NBT | T6: failed to yield | V6: {=IF(AND(INDEX('Initial Study'!K:K, MATCH(K6, 'Initial Study'!B:B, 0) + 1) <> 0, INDEX('Initial Study'!K:K, MATCH(K6, 'Initial Study'!B:B, 0) + 1) <> ""), INDEX('Initial Study'!K:K, MATCH(K6, 'Initial Study'!B:B, 0) + 1), "")} -> E | W6: {=IF(AND(INDEX('Initial Study'!K:K, MATCH(K6, 'Initial Study'!B:B, 0) + 2) <> 0, INDEX('Initial Study'!K:K, MATCH(K6, 'Initial Study'!B:B, 0) + 2) <> "", NOT(ISNUMBER(INDEX('Initial Study'!K:K, MATCH(K6, 'Initial Study'!B:B, 0) + 2)))), INDEX('Initial Study'!K:K, MATCH(K6, 'Initial Study'!B:B, 0) + 2), "-")} -> N | X6: =IF(R6="RE", V6 & "BT/" & IF(W6 <> "-", W6 & "BT", ""), IF(OR(R6="LTDR", R6="LTSR"), V6 & "BL" & IF(W6 <> "-", "/" & W6 & "BT", ""), IF(OR(R6="RTDR", R6="RTSR"), V6 & "BR" & IF(W6 <> "-", "/" & W6 & "BT", ""), IF(W6 <> "-", V6 & "BT/" & W6 & "BT", V6 & "BT")))) -> EBT/NBT
A7: 0 | B7: NC 91 | C7: 0 | E7: SR 1303 | F7: SR 1249 | G7: NC 91 | H7: 9.032 | I7: IS | K7: 105880887 | L7: 43614 | M7: 30 | N7: 1 | O7: 7 | P7: 1 | Q7: C | R7: =VLOOKUP(M7,Index!$A$1:$B$26, 2, FALSE) -> angle | S7: =X7 -> WBT/SBT | T7: failed to yield | V7: {=IF(AND(INDEX('Initial Study'!K:K, MATCH(K7, 'Initial Study'!B:B, 0) + 1) <> 0, INDEX('Initial Study'!K:K, MATCH(K7, 'Initial Study'!B:B, 0) + 1) <> ""), INDEX('Initial Study'!K:K, MATCH(K7, 'Initial Study'!B:B, 0) + 1), "")} -> W | W7: {=IF(AND(INDEX('Initial Study'!K:K, MATCH(K7, 'Initial Study'!B:B, 0) + 2) <> 0, INDEX('Initial Study'!K:K, MATCH(K7, 'Initial Study'!B:B, 0) + 2) <> "", NOT(ISNUMBER(INDEX('Initial Study'!K:K, MATCH(K7, 'Initial Study'!B:B, 0) + 2)))), INDEX('Initial Study'!K:K, MATCH(K7, 'Initial Study'!B:B, 0) + 2), "-")} -> S | X7: =IF(R7="RE", V7 & "BT/" & IF(W7 <> "-", W7 & "BT", ""), IF(OR(R7="LTDR", R7="LTSR"), V7 & "BL" & IF(W7 <> "-", "/" & W7 & "BT", ""), IF(OR(R7="RTDR", R7="RTSR"), V7 & "BR" & IF(W7 <> "-", "/" & W7 & "BT", ""), IF(W7 <> "-", V7 & "BT/" & W7 & "BT", V7 & "BT")))) -> WBT/SBT
A8: 0 | B8: NC 91 | C8: 0 | E8: SR 1225 | F8: SR 1249 | G8: NC 91 | H8: 9.032 | I8: IS | K8: 106014182 | L8: 43742 | M8: 30 | N8: 1 | O8: 7 | P8: 1 | Q8: C | R8: =VLOOKUP(M8,Index!$A$1:$B$26, 2, FALSE) -> angle | S8: =X8 -> EBT/NBT | T8: failed to yield | V8: {=IF(AND(INDEX('Initial Study'!K:K, MATCH(K8, 'Initial Study'!B:B, 0) + 1) <> 0, INDEX('Initial Study'!K:K, MATCH(K8, 'Initial Study'!B:B, 0) + 1) <> ""), INDEX('Initial Study'!K:K, MATCH(K8, 'Initial Study'!B:B, 0) + 1), "")} -> E | W8: {=IF(AND(INDEX('Initial Study'!K:K, MATCH(K8, 'Initial Study'!B:B, 0) + 2) <> 0, INDEX('Initial Study'!K:K, MATCH(K8, 'Initial Study'!B:B, 0) + 2) <> "", NOT(ISNUMBER(INDEX('Initial Study'!K:K, MATCH(K8, 'Initial Study'!B:B, 0) + 2)))), INDEX('Initial Study'!K:K, MATCH(K8, 'Initial Study'!B:B, 0) + 2), "-")} -> N | X8: =IF(R8="RE", V8 & "BT/" & IF(W8 <> "-", W8 & "BT", ""), IF(OR(R8="LTDR", R8="LTSR"), V8 & "BL" & IF(W8 <> "-", "/" & W8 & "BT", ""), IF(OR(R8="RTDR", R8="RTSR"), V8 & "BR" & IF(W8 <> "-", "/" & W8 & "BT", ""), IF(W8 <> "-", V8 & "BT/" & W8 & "BT", V8 & "BT")))) -> EBT/NBT
A9: 0 | B9: NC 91 | C9: 0 | E9: SR 1225 | F9: SR 1226 | G9: NC 91 | H9: 9.032 | I9: IS | K9: 106038472 | L9: 43745 | M9: 24 | N9: 1 | O9: 7 | P9: 1 | Q9: C | R9: =VLOOKUP(M9,Index!$A$1:$B$26, 2, FALSE) -> LTDR | S9: =X9 -> EBL/NBT | T9: failed to yield | V9: {=IF(AND(INDEX('Initial Study'!K:K, MATCH(K9, 'Initial Study'!B:B, 0) + 1) <> 0, INDEX('Initial Study'!K:K, MATCH(K9, 'Initial Study'!B:B, 0) + 1) <> ""), INDEX('Initial Study'!K:K, MATCH(K9, 'Initial Study'!B:B, 0) + 1), "")} -> E | W9: {=IF(AND(INDEX('Initial Study'!K:K, MATCH(K9, 'Initial Study'!B:B, 0) + 2) <> 0, INDEX('Initial Study'!K:K, MATCH(K9, 'Initial Study'!B:B, 0) + 2) <> "", NOT(ISNUMBER(INDEX('Initial Study'!K:K, MATCH(K9, 'Initial Study'!B:B, 0) + 2)))), INDEX('Initial Study'!K:K, MATCH(K9, 'Initial Study'!B:B, 0) + 2), "-")} -> N | X9: =IF(R9="RE", V9 & "BT/" & IF(W9 <> "-", W9 & "BT", ""), IF(OR(R9="LTDR", R9="LTSR"), V9 & "BL" & IF(W9 <> "-", "/" & W9 & "BT", ""), IF(OR(R9="RTDR", R9="RTSR"), V9 & "BR" & IF(W9 <> "-", "/" & W9 & "BT", ""), IF(W9 <> "-", V9 & "BT/" & W9 & "BT", V9 & "BT")))) -> EBL/NBT
A10: 0 | B10: NC 91 | C10: 0 | E10: SR 1225 | F10: SR 1249 | G10: NC 91 | H10: 9.032 | I10: IS | K10: 106226479 | L10: 43966 | M10: 30 | N10: 1 | O10: 7 | P10: 1 | Q10: O | R10: =VLOOKUP(M10,Index!$A$1:$B$26, 2, FALSE) -> angle | S10: WBT/SBT | T10: failed to yield | V10: {=IF(AND(INDEX('Initial Study'!K:K, MATCH(K10, 'Initial Study'!B:B, 0) + 1) <> 0, INDEX('Initial Study'!K:K, MATCH(K10, 'Initial Study'!B:B, 0) + 1) <> ""), INDEX('Initial Study'!K:K, MATCH(K10, 'Initial Study'!B:B, 0) + 1), "")} -> W | W10: {=IF(AND(INDEX('Initial Study'!K:K, MATCH(K10, 'Initial Study'!B:B, 0) + 2) <> 0, INDEX('Initial Study'!K:K, MATCH(K10, 'Initial Study'!B:B, 0) + 2) <> "", NOT(ISNUMBER(INDEX('Initial Study'!K:K, MATCH(K10, 'Initial Study'!B:B, 0) + 2)))), INDEX('Initial Study'!K:K, MATCH(K10, 'Initial Study'!B:B, 0) + 2), "-")} -> - | X10: =IF(R10="RE", V10 & "BT/" & IF(W10 <> "-", W10 & "BT", ""), IF(OR(R10="LTDR", R10="LTSR"), V10 & "BL" & IF(W10 <> "-", "/" & W10 & "BT", ""), IF(OR(R10="RTDR", R10="RTSR"), V10 & "BR" & IF(W10 <> "-", "/" & W10 & "BT", ""), IF(W10 <> "-", V10 & "BT/" & W10 & "BT", V10 & "BT")))) -> WBT
A11: ="Construction Period (" & TEXT('Evaluation Set-up'!D10,"mm/dd/yy") & " - " & TEXT('Evaluation Set-up'!E10,"mm/dd/yy") & ")" -> Construction Period (11/01/21 - 03/31/22)
A12: 0 | B12: NC 91 | C12: 0 | E12: SR 1225 | F12: SR 1249 | G12: NC 91 | H12: 9.032 | I12: IS | K12: 106812116 | L12: 44547 | M12: 24 | N12: 1 | O12: 7 | P12: 1 | Q12: O | R12: =VLOOKUP(M12,Index!$A$1:$B$26, 2, FALSE) -> LTDR | S12: =X12 -> EBL/NBT | T12: failed to yield | V12: {=IF(AND(INDEX('Initial Study'!K:K, MATCH(K12, 'Initial Study'!B:B, 0) + 1) <> 0, INDEX('Initial Study'!K:K, MATCH(K12, 'Initial Study'!B:B, 0) + 1) <> ""), INDEX('Initial Study'!K:K, MATCH(K12, 'Initial Study'!B:B, 0) + 1), "")} -> E | W12: {=IF(AND(INDEX('Initial Study'!K:K, MATCH(K12, 'Initial Study'!B:B, 0) + 2) <> 0, INDEX('Initial Study'!K:K, MATCH(K12, 'Initial Study'!B:B, 0) + 2) <> "", NOT(ISNUMBER(INDEX('Initial Study'!K:K, MATCH(K12, 'Initial Study'!B:B, 0) + 2)))), INDEX('Initial Study'!K:K, MATCH(K12, 'Initial Study'!B:B, 0) + 2), "-")} -> N | X12: =IF(R12="RE", V12 & "BT/" & IF(W12 <> "-", W12 & "BT", ""), IF(OR(R12="LTDR", R12="LTSR"), V12 & "BL" & IF(W12 <> "-", "/" & W12 & "BT", ""), IF(OR(R12="RTDR", R12="RTSR"), V12 & "BR" & IF(W12 <> "-", "/" & W12 & "BT", ""), IF(W12 <> "-", V12 & "BT/" & W12 & "BT", V12 & "BT")))) -> EBL/NBT
A14: =After!A2 -> After Period (04/01/22 - 03/31/26)
