Workbook

Sheet Step-by-Step Instructions

Sheet Typical Target Crashes
B2: Target Crash Type Guidance - Section Treatments
C4: Countermeasure | D4: Target-1 | E4: Target-2 | F4: Target Subset | G4: Other | H4: Target-1 Crash* | I4: Target-2 Crash | J4: Notes
C5: Clear Zone Improvements | D5: Y | H5: Lane Departure Crashes (Type 1 or 2)
C6: Closed Loop Signal System | D6: Y | E6: Y | H6: Frontal Impact Crashes in the treated intersections | I6: Rear End Crashes on the treated corridor
C7: Congestion Detection System | D7: Y | H7: Rear End Crashes
C8: Curve Wedging and Resurfacing / Curve Superelevation Improvements | D8: Y | H8: Lane Departure Crashes (Type 1 or 2)
C9: Drainage Improvements | D9: Y | F9: Y | H9: Wet Crashes (Road Codes 2-6) (precipitation data analysis also needed) | J9: Wet L.D. Crashes (Road Codes 2-6) should also be included within the additional information table.
C10: Guardrail - (Shoulder, Culvert or Bridge Approach) | D10: Y | G10: Y | H10: Lane Departure Crashes (Type 1 or 2) | J10: Guardrail Hit Crashes should also be included within the additional information table.
C11: Horizontal Alignment Improvements | D11: Y | H11: Lane Departure Crashes (Type 1 or 2)
C12: Lighting | D12: Y | F12: ? | H12: Night Crashes (Light Codes 4-6) | J12: Night L.D. Crashes (Light Codes 4-6) may also need to be included within the additional information table depending on the countermeasure
C13: Median Guardrail | D13: Y | F13: Y | G13: Y | H13: Lane Departure Crashes (Type 2) involving vehicle Running Off Road toward the median side of roadway | J13: Cross Median Crashes (this is a subset of L.D. crashes) and Median Guardrail Hit Crashes should be included within the additional information table
C14: Pavement Markings (i.e. Wider Lane Lines) | D14: Y | F14: Y | H14: Lane Departure Crashes (Type 1 or 2) | J14: Night L.D. Crashes (Light Codes 4-6) should also be included within the additional information table
C15: Resurfacing | D15: Y | F15: Y | H15: Wet Crashes (Road Codes 2-6) (precipitation data analysis also needed) | J15: Wet L.D. Crashes (Road Codes 2-6) should also be included within the additional information table. Examples of this countermeasure: Open Graded Friction Course, High Friction Surface Treatment, Nova Chip, etc.
C16: Road Diet (i.e. 4-Lane to 3-Lane) | D16: Y | E16: Y | H16: Rear End Crashes | I16: Left Turn Same Roadway Crashes | J16: If 4-Lane Cross-Section before, may need to break out Rear End Crashes in Inner Lanes for Target-1
C17: Rumble Strips - Centerline | D17: Y | F17: Y | H17: Lane Departure Crashes (Type 1 or 2) | J17: Correctable L.D. Crashes need to be included within the additional information table. Lane Departure Crashes are considered correctable if: the first event involved at least one vehicle crossing the centerline; it was not caused by a vehicle swerving to avoid a vehicle, person, animal, or other object in the roadway; it was not caused by mechanical problems, blown tires, or a medical problem with the driver; it was not caused by the weather, such as hydroplaning or sliding on ice; and it was not clear from the crash diagram/narrative that the driver lost control prior to crossing the roadway centerline.
C18: Rumble Strips - Shoulder | D18: Y | F18: Y | H18: Lane Departure Crashes (Type 1 or 2) | J18: Correctable L.D. Crashes need to be included within the additional information table. Lane Departure Crashes are considered correctable if: the first event involved at least one vehicle crossing the edgeline; it was not caused by a vehicle swerving to avoid a vehicle, person, animal, or other object in the roadway; it was not caused by mechanical problems, blown tires, or a medical problem with the driver; it was not caused by the weather, such as hydroplaning or sliding on ice; and it was not clear from the crash diagram/narrative that the driver lost control prior to crossing the roadway edgeline.
C19: Truck countermeasures | D19: Y | H19: Truck Crashes | J19: Truck codes may vary by project but typical Truck codes are 10-16. "Heavy" truck codes are 12-16. Use the assumptions email to confirm which Truck definition is most appropriate for the project.
C20: Widening for Paved Shoulders | D20: Y | F20: ? | H20: Lane Departure Crashes (Type 1 or 2) | J20: Wet L.D. Crashes (Road Codes 2-6) may need to be included within the additional information table if resurfacing was part of project
C21: Widening for Two-Way Center Turn Lane (i.e. 2-Lane to 3-Lane) | D21: Y | E21: Y | H21: Rear End Crashes | I21: Left Turn Same Roadway Crashes | J21: If 4-Lane Cross-Section before, may need to break out Rear End Crashes in Inner Lanes for Target-1
B23: Comments on Typical Target Crashes
B24: ● | C24: *Lane Departure Crashes (Type 1 - Use for Two Lane Facilities) = Ran Off Road (Left, Right or Straight), Overturn/Rollover, Fixed Object, Head On, Sideswipe Opposite Direction. Side street run through crashes are not considered targets.
B25: ● | C25: *Lane Departure Crashes (Type 2 - Use for Multilane Facilities) = Ran Off Road (Left, Right or Straight), Overturn/Rollover, Fixed Object, Head On, Sideswipe Same Direction, Sideswipe Opposite Direction. Side street run through crashes are not considered targets.
B27: ● | C27: The selection of target crashes should be confirmed in the assumptions email prior to starting the analysis. Additionally, any other crash types or other information that need be mentioned in the additional information table should also be noted in the assumptions email.

Sheet Evaluation Set-up
B2: Split Time Periods - Date Range Input | J2: Section AADT Calculator - Weighted Average by Sub-Section
C4: Split Time Period | D4: Split After Period | J4: Comments/Instructions on AADT Calculator Use: | AK4: =C7 -> Before Period | AL4: =C9 -> After Period #1 | AM4: =C11 -> After Period #2
J5: ● | K5: In cells AI7 -> AK7, select the last year within each period that has available volume data (i.e. actual collected volume data, not estimated/interpolated data)
C6: Time Period | D6: start date | E6: end date | F6: # of years | G6: # of months | J6: ● | K6: When inputting volume data into this tool, use Black font color for values taken directly from the available volume data | AR6: cells needed for calcs:
C7: =IF($D$4="Split After Period", "Before Period", "Before Period #1") -> Before Period | D7: 41275 | E7: 43131 | F7: =ROUNDDOWN(AR7/12,0) -> 5 | G7: =AR7-12*F7 -> 1 | J7: ● | K7: When inputting volume data into this tool, use Red font color for values that need to be calculated, interpolated, or assumed | AG7: Representative Years Selection: | AK7: 2016 | AL7: 2018 | AM7: 2022 | AR7: =(YEAR(D8)-YEAR(D7))*12+MONTH(D8)-MONTH(D7) -> 61
C8: Construction Period #1 | D8: 43132 | E8: 43220 | F8: =ROUNDDOWN(AR8/12,0) -> 0 | G8: =AR8-12*F8 -> 3 | J8: ● | K8: Input AADTs for each calendar year within the study period. You do not need to input volumes for years outside the study date range | AG8: Representative Volumes | AK8: =ROUND(HLOOKUP(AK7, $O$16:$AM$42, 27, 0), -2) -> 12900 | AL8: =ROUND(HLOOKUP(AL7, $O$16:$AM$42, 27, 0), -2) -> 13500 | AM8: =ROUND(HLOOKUP(AM7, $O$16:$AM$42, 27, 0), -2) -> 12900 | AR8: =(YEAR(D9)-YEAR(D8))*12+MONTH(D9)-MONTH(D8) -> 3
C9: =IF($D$4="Split After Period", "After Period #1", "Before Period #2") -> After Period #1 | D9: 43221 | E9: 44377 | F9: =ROUNDDOWN(AR9/12,0) -> 3 | G9: =AR9-12*F9 -> 2 | J9: ● | K9: Make sure you enter in the beginning and ending MP for each sub-section | AR9: =(YEAR(D10)-YEAR(D9))*12+MONTH(D10)-MONTH(D9) -> 38
C10: Construction Period #2 | D10: 44378 | E10: 44469 | F10: =ROUNDDOWN(AR10/12,0) -> 0 | G10: =AR10-12*F10 -> 3 | J10: ● | K10: If more than one volume count is available within the study section, give each count location a coresponing sub-section and a mile post range that it is responsible for | AR10: =(YEAR(D11)-YEAR(D10))*12+MONTH(D11)-MONTH(D10) -> 3
C11: =IF($D$4="Split After Period", "After Period #2", "After Period") -> After Period #2 | D11: 44470 | E11: 45169 | F11: =ROUNDDOWN(AR11/12,0) -> 1 | G11: =AR11-12*F11 -> 11 | J11: ● | K11: If only one volume count is available for a section, just use the 1st row of this calculator and leave the other rows blank. | AR11: =(YEAR(E11+1)-YEAR(D11))*12+MONTH(E11+1)-MONTH(D11) -> 23
J12: ● | K12: Do not select 2020 as a representative year for a particular time period, due to the effects of the COVID-19 pandemic, even if it is the last year with available AADT data within said time period.
B13: Comments/Instruction on Date Range Calculator:
B14: ● | C14: Select whether the evaluation has split before or after period in cells D4 + E4 | K14: Sub-Section Information | O14: AADTs for every year within the study period
B15: ● | C15: Enter in the Starting and Ending Dates for each of the time periods in cells D7 -> E11
B16: ● | C16: This tool only works in WHOLE MONTHS. Construction start dates should be rounded up to the first of the month and construction end dates should be rounded down to the end the month | K16: # | L16: Begin MP | M16: End MP | N16: Length | O16: 2006 | P16: 2007 | Q16: 2008 | R16: 2009 | S16: 2010 | T16: 2011 | U16: 2012 | V16: 2013 | W16: 2014 | X16: 2015 | Y16: 2016 | Z16: 2017 | AA16: 2018 | AB16: 2019 | AC16: 2020 | AD16: 2021 | AE16: 2022 | AF16: 2023 | AG16: 2024 | AH16: 2025 | AI16: 2026 | AJ16: 2027 | AK16: 2028 | AL16: 2029 | AM16: 2030
K17: 1 | L17: 0.558 | M17: 1.32 | N17: =ABS(M17-L17) -> 0.762 | V17: =MROUND(11000*1.03^(2013-2012),100) -> 11300 | W17: =MROUND(11000*1.03^(2014-2012),100) -> 11700 | X17: =MROUND(11000*1.03^(2015-2012),100) -> 12000 | Y17: 12000 | Z17: =AVERAGE(Y17,AA17) -> 12500 | AA17: 13000 | AB17: =MROUND($AA$17*1.03^(AB16-$AA$16),100) -> 13400 | AC17: =MROUND($AA$17*1.03^(AC16-$AA$16),100) -> 13800 | AD17: =MROUND($AA$17*1.03^(AD16-$AA$16),100) -> 14200 | AE17: 12000 | AF17: =MROUND(AE17*1.03^(AF16-AE16),100) -> 12400
K18: 2 | L18: 1.32 | M18: 2.04 | N18: =IF(ABS(M18-L18) = 0, "", ABS(M18-L18)) -> 0.72 | V18: =AVERAGE(11000,W18) -> 11000 | W18: 11000 | X18: =AVERAGE(W18,Y18) -> 11500 | Y18: 12000 | Z18: =AVERAGE(Y18,AA18) -> 12500 | AA18: 13000 | AB18: =MROUND($AA$18*1.03^(AB16-$AA$16),100) -> 13400 | AC18: =MROUND($AA$18*1.03^(AC16-$AA$16),100) -> 13800 | AD18: =MROUND($AA$18*1.03^(AD16-$AA$16),100) -> 14200 | AE18: 12500 | AF18: =MROUND(AE18*1.03^(AF16-AE16),100) -> 12900
K19: 3 | L19: 2.04 | M19: 2.46 | N19: =IF(ABS(M19-L19) = 0, "", ABS(M19-L19)) -> 0.42 | V19: =AVERAGE(12000,W19) -> 12500 | W19: 13000 | X19: =AVERAGE(W19,Y19) -> 13500 | Y19: 14000 | Z19: =MROUND(AVERAGE(Y19,AA19),100) -> 14300 | AA19: 14500 | AB19: =MROUND($AA$19*1.03^(AB16-$AA$16),100) -> 14900 | AC19: 13000 | AD19: =MROUND($AA$19*1.03^(AD16-$AA$16),100) -> 15800 | AE19: 14000 | AF19: =MROUND(AE19*1.03^(AF16-AE16),100) -> 14400
K20: 4 | L20: 2.46 | M20: 2.896 | N20: =IF(ABS(M20-L20) = 0, "", ABS(M20-L20)) -> 0.436 | V20: =AVERAGE(12000,W20) -> 12500 | W20: 13000 | X20: =AVERAGE(W20,Y20) -> 14000 | Y20: 15000 | Z20: =MROUND(AVERAGE(Y20,AA20),100) -> 14800 | AA20: 14500 | AB20: =MROUND($AA$20*1.03^(AB16-$AA$16),100) -> 14900 | AC20: =MROUND($AA$20*1.03^(AC16-$AA$16),100) -> 15400 | AD20: =MROUND($AA$20*1.03^(AD16-$AA$16),100) -> 15800 | AE20: 14000 | AF20: =MROUND(AE20*1.03^(AF16-AE16),100) -> 14400
B21: Color Key | K21: 5 | N21: =IF(ABS(M21-L21) = 0, "", ABS(M21-L21))
B22: Cells that need to be edited | K22: 6 | N22: =IF(ABS(M22-L22) = 0, "", ABS(M22-L22))
B23: Auto-calculated cells | K23: 7 | N23: =IF(ABS(M23-L23) = 0, "", ABS(M23-L23))
K24: 8 | N24: =IF(ABS(M24-L24) = 0, "", ABS(M24-L24))
K25: 9 | N25: =IF(ABS(M25-L25) = 0, "", ABS(M25-L25))
K26: 10 | N26: =IF(ABS(M26-L26) = 0, "", ABS(M26-L26))
K27: 11 | N27: =IF(ABS(M27-L27) = 0, "", ABS(M27-L27))
K28: 12 | N28: =IF(ABS(M28-L28) = 0, "", ABS(M28-L28))
K29: 13 | N29: =IF(ABS(M29-L29) = 0, "", ABS(M29-L29))
K30: 14 | N30: =IF(ABS(M30-L30) = 0, "", ABS(M30-L30))
K31: 15 | N31: =IF(ABS(M31-L31) = 0, "", ABS(M31-L31))
K32: 16 | N32: =IF(ABS(M32-L32) = 0, "", ABS(M32-L32))
K33: 17 | N33: =IF(ABS(M33-L33) = 0, "", ABS(M33-L33))
K34: 18 | N34: =IF(ABS(M34-L34) = 0, "", ABS(M34-L34))
K35: 19 | N35: =IF(ABS(M35-L35) = 0, "", ABS(M35-L35))
... K41: 25 | N41: =IF(ABS(M41-L41) = 0, "", ABS(M41-L41))
K42: Sum | L42: -- | M42: -- | N42: =SUM(N17:N41) -> 2.338 | O42: =IF(O17="", "", O75) | P42: =IF(P17="", "", P75) | Q42: =IF(Q17="", "", Q75) | R42: =IF(R17="", "", R75) | S42: =IF(S17="", "", S75) | T42: =IF(T17="", "", T75) | U42: =IF(U17="", "", U75) | V42: =IF(V17="", "", V75) -> 11646.963 | ... AM42: =IF(AM17="", "", AM75)
M48: Year-by-Year AADTs - For multi-project tracking by Safety Evaluation Group
M49: Section | N49: weight | O49: 2006 | P49: 2007 | Q49: 2008 | R49: 2009 | S49: 2010 | T49: 2011 | U49: 2012 | V49: 2013 | W49: 2014 | X49: 2015 | Y49: 2016 | Z49: 2017 | AA49: 2018 | AB49: 2019 | AC49: 2020 | AD49: 2021 | AE49: 2022 | AF49: 2023 | AG49: 2024 | AH49: 2025 | AI49: 2026 | AJ49: 2027 | AK49: 2028 | AL49: 2029 | AM49: 2030
M50: 1 | N50: =IFERROR(N17/$N$42, "") -> 0.32591959 | O50: =IF(O17="", "", O17*$N50) | P50: =IF(P17="", "", P17*$N50) | Q50: =IF(Q17="", "", Q17*$N50) | R50: =IF(R17="", "", R17*$N50) | S50: =IF(S17="", "", S17*$N50) | T50: =IF(T17="", "", T17*$N50) | U50: =IF(U17="", "", U17*$N50) | V50: =IF(V17="", "", V17*$N50) -> 3682.8914 | ... AM50: =IF(AM17="", "", AM17*$N50)
M51: 2 | N51: =IFERROR(N18/$N$42, "") -> 0.30795552 | O51: =IF(O18="", "", O18*$N51) | P51: =IF(P18="", "", P18*$N51) | Q51: =IF(Q18="", "", Q18*$N51) | R51: =IF(R18="", "", R18*$N51) | S51: =IF(S18="", "", S18*$N51) | T51: =IF(T18="", "", T18*$N51) | U51: =IF(U18="", "", U18*$N51) | V51: =IF(V18="", "", V18*$N51) -> 3387.5107 | ... AM51: =IF(AM18="", "", AM18*$N51)
M52: 3 | N52: =IFERROR(N19/$N$42, "") -> 0.17964072 | O52: =IF(O19="", "", O19*$N52) | P52: =IF(P19="", "", P19*$N52) | Q52: =IF(Q19="", "", Q19*$N52) | R52: =IF(R19="", "", R19*$N52) | S52: =IF(S19="", "", S19*$N52) | T52: =IF(T19="", "", T19*$N52) | U52: =IF(U19="", "", U19*$N52) | V52: =IF(V19="", "", V19*$N52) -> 2245.509 | ... AM52: =IF(AM19="", "", AM19*$N52)
...

Sheet Intersection Mileposts
B2: Intersection Milepost Table (Used for Multi-Project Tracking)
C4: # | D4: Intersecting Road Name | E4: Milepost of Intersection | F4: -250' | G4: +250' | I4: Comments/Instructions on Intersection Milepost Table:
C5: #1 | D5: OLD AIRPORT/UNION | E5: 0.558 | F5: =IF(D5="", "", E5-250/5280) -> 0.51065152 | G5: =IF(D5="", "", E5+250/5280) -> 0.60534848 | I5: ● | J5: Please enter in the intersections within your study's Milepost Limits on the Features reports
C6: #2 | D6: LAWNDALE/CRESTSIDE | E6: 2.04 | F6: =IF(D6="", "", E6-250/5280) -> 1.9926515 | G6: =IF(D6="", "", E6+250/5280) -> 2.0873485 | I6: ● | J6: Don't enter in the names/mileposts for non-intersections (etc. bridges, structures, etc.)
C7: #3 | D7: NC 73 (CORBAN) | E7: 2.896 | F7: =IF(D7="", "", E7-250/5280) -> 2.8486515 | G7: =IF(D7="", "", E7+250/5280) -> 2.9433485 | I7: ● | J7: Enter in the name of the road into the cells in column D
C8: #4 | F8: =IF(D8="", "", E8-250/5280) | G8: =IF(D8="", "", E8+250/5280) | I8: ● | J8: Enter in the Milepost from the features report into the cells in column E
C9: #5 | F9: =IF(D9="", "", E9-250/5280) | G9: =IF(D9="", "", E9+250/5280) | I9: ● | J9: If you adjusted a milepost of an intersection during your review, enter that value instead of the milepost from the features report
C10: #6 | F10: =IF(D10="", "", E10-250/5280) | G10: =IF(D10="", "", E10+250/5280)
C11: #7 | F11: =IF(D11="", "", E11-250/5280) | G11: =IF(D11="", "", E11+250/5280) | I11: ● | J11: Each row within the table to the left should correspond to one intersection along the study section. There should only be one milepost per intersection. You do not need to use multiple rows for intersections with crossing routes with multiple names
C12: #8 | F12: =IF(D12="", "", E12-250/5280) | G12: =IF(D12="", "", E12+250/5280)
C13: #9 | F13: =IF(D13="", "", E13-250/5280) | G13: =IF(D13="", "", E13+250/5280)
C14: #10 | F14: =IF(D14="", "", E14-250/5280) | G14: =IF(D14="", "", E14+250/5280) | I14: ● | J14: If the number of intersections exceeds 35, before entering data into this tab, contact SEG staff to determine whether this step needs to be completed
C15: #11 | F15: =IF(D15="", "", E15-250/5280) | G15: =IF(D15="", "", E15+250/5280)
C16: #12 | F16: =IF(D16="", "", E16-250/5280) | G16: =IF(D16="", "", E16+250/5280) | I16: ● | J16: DO NOT DRAG/SHIFT/MOVE CELLS in this table. Formulas within the Tracking tab at the end of this workbook (tracking tab is for internal NCDOT staff) use the information in this table for annual crash counting calculations. Any dragging or deleting of cells will break these formulas and cause errors.
C17: #13 | F17: =IF(D17="", "", E17-250/5280) | G17: =IF(D17="", "", E17+250/5280)
C18: #14 | F18: =IF(D18="", "", E18-250/5280) | G18: =IF(D18="", "", E18+250/5280)
C19: #15 | F19: =IF(D19="", "", E19-250/5280) | G19: =IF(D19="", "", E19+250/5280)
C20: #16 | F20: =IF(D20="", "", E20-250/5280) | G20: =IF(D20="", "", E20+250/5280)
C21: #17 | F21: =IF(D21="", "", E21-250/5280) | G21: =IF(D21="", "", E21+250/5280)
C22: #18 | F22: =IF(D22="", "", E22-250/5280) | G22: =IF(D22="", "", E22+250/5280)
C23: #19 | F23: =IF(D23="", "", E23-250/5280) | G23: =IF(D23="", "", E23+250/5280)
C24: #20 | F24: =IF(D24="", "", E24-250/5280) | G24: =IF(D24="", "", E24+250/5280)
C25: #21 | F25: =IF(D25="", "", E25-250/5280) | G25: =IF(D25="", "", E25+250/5280)
C26: #22 | F26: =IF(D26="", "", E26-250/5280) | G26: =IF(D26="", "", E26+250/5280)
C27: #23 | F27: =IF(D27="", "", E27-250/5280) | G27: =IF(D27="", "", E27+250/5280)
C28: #24 | F28: =IF(D28="", "", E28-250/5280) | G28: =IF(D28="", "", E28+250/5280)
... C39: #35 | F39: =IF(D39="", "", E39-250/5280) | G39: =IF(D39="", "", E39+250/5280)

Sheet Original fiche

Sheet Filtered Fiche

Sheet Binned Crashes

Sheet 1st Time Period
A1: Manually Edit These Columns (A -> N). | P1: Don't Edit These Columns (P -> ). Calculations are Automatic.
A2: ='Evaluation Set-up'!$C$7&" ("&TEXT('Evaluation Set-up'!$D$7, "mm/dd/yyyy")&" - "&TEXT('Evaluation Set-up'!$E$7, "mm/dd/yyyy")&")" -> Before Period (01/01/2013 - 01/31/2018) | P2: Crash # | Q2: Crash Year | R2: Severity Index | S2: Target-1 Severity Index | T2: Target-1 KABCO | U2: Target-2 Severity Index | V2: Target-2 KABCO
A3: Crash ID | B3: Date | C3: T | D3: C | E3: F | F3: L | G3: S | H3: Final MP | I3: Analyst's Notes Column 1 | J3: Analyst's Notes Column 2 | K3: Analyst's Notes Column 3 | L3: Analyst's Notes Column 4 | M3: Target-1? | N3: Target-2? | Z3: Total | AA3: Target-1 | AB3: Target-2 | AC3: All Targets | AR3: Crash # | AS3: Target Crash? | AT3: Within 250' of an intx?
A4: Example | B4: 41482 | C4: 30 | D4: 1 | E4: 7 | F4: 1 | G4: B | H4: 0.558 | P4: =IF(R4 = "", "", COUNT($R$4:R4)) -> 1 | Q4: =IF(B4="", "", YEAR(B4)) -> 2013 | R4: =IF(A4="", "", IF(G4="",1,IF(G4="O",1,IF(G4="C",8.4,IF(G4="B",8.4,IF(G4="A",76.8,IF(G4="K",76.8,"ERR"))))))) -> 8.4 | S4: =IF(M4="Y",R4,"") | T4: =IF(IF(M4="Y",G4,"")=0, "O", IF(M4="Y",G4,"")) | U4: =IF(N4="Y",R4,"") | V4: =IF(IF(N4="Y",G4,"")=0, "O", IF(N4="Y",G4,"")) | Y4: K | Z4: =COUNTIF($G$4:$G$1048576,$Y4) -> 2 | AA4: =COUNTIF($T$4:$T$1048576,$Y4) -> 2 | AB4: =COUNTIF($V$4:$V$1048576,$Y4) -> 0 | AC4: =COUNTIF($T:$T, Y4)+COUNTIF($V:$V, Y4)-COUNTIFS($T:$T, Y4, $V:$V, Y4) -> 2 | AR4: =IF(P4>0, P4, "") -> 1 | AS4: =IF(OR(M4="Y",N4="Y"),"Y","") | AT4: =IF(AR4="","",IF(AND(H4>='Intersection Mileposts'!$F$5,H4<='Intersection Mileposts'!$G$5),"Y",IF(AND(H4>='Intersection Mileposts'!$F$6,H4<='Intersection Mileposts'!$G$6),"Y",IF(AND(H4>='Intersection Mileposts'!$F$7,H4<='Intersection Mileposts'!$G$7),"Y",IF(AND(H4>='Intersection Mileposts'!$F$8,H4<='Intersection Mileposts'!$G$8),"Y",IF(AND(H4>='Intersection Mileposts'!$F$9,H4<='Intersection Mileposts'!$G$9),"Y",IF(AND(H4>='Intersection Mileposts'!$F$10,H4<='Intersection Mileposts'!$G$10),"Y",IF(AND(H4>='Intersection Mileposts'!$F$11,H4<='Intersection Mileposts'!$G$11),"Y",IF(AND(H4>='Intersection Mileposts'!$F$12,H4<='Intersection Mileposts'!$G$12),"Y",IF(AND(H4>='Intersection Mileposts'!$F$13,H4<='Intersection Mileposts'!$G$13),"Y",IF(AND(H4>='Intersection Mileposts'!$F$14,H4<='Intersection Mileposts'!$G$14),"Y",IF(AND(H4>='Intersection Mileposts'!$F$15,H4<='Intersection Mileposts'!$G$15),"Y",IF(AND(H4>='Intersection Mileposts'!$F$16,H4<='Intersection Mileposts'!$G$16),"Y",IF(AND(H4>='Intersection Mileposts'!$F$17,H4<='Intersection Mileposts'!$G$17),"Y",IF(AND(H4>='Intersection Mileposts'!$F$18,H4<='Intersection Mileposts'!$G$18),"Y",IF(AND(H4>='Intersection Mileposts'!$F$19,H4<='Intersection Mileposts'!$G$19),"Y",IF(AND(H4>='Intersection Mileposts'!$F$20,H4<='Intersection Mileposts'!$G$20),"Y",IF(AND(H4>='Intersection Mileposts'!$F$21,H4<='Intersection Mileposts'!$G$21),"Y",IF(AND(H4>='Intersection Mileposts'!$F$22,H4<='Intersection Mileposts'!$G$22),"Y",IF(AND(H4>='Intersection Mileposts'!$F$23,H4<='Intersection Mileposts'!$G$23),"Y",IF(AND(H4>='Intersection Mileposts'!$F$24,H4<='Intersection Mileposts'!$G$24),"Y",IF(AND(H4>='Intersection Mileposts'!$F$25,H4<='Intersection Mileposts'!$G$25),"Y",IF(AND(H4>='Intersection Mileposts'!$F$26,H4<='Intersection Mileposts'!$G$26),"Y",IF(AND(H4>='Intersection Mileposts'!$F$27,H4<='Intersection Mileposts'!$G$27),"Y",IF(AND(H4>='Intersection Mileposts'!$F$28,H4<='Intersection Mileposts'!$G$28),"Y",IF(AND(H4>='Intersection Mileposts'!$F$29,H4<='Intersection Mileposts'!$G$29),"Y", IF(AND(H4>='Intersection Mileposts'!$F$30,H4<='Intersection Mileposts'!$G$30),"Y",IF(AND(H4>='Intersection Mileposts'!$F$31,H4<='Intersection Mileposts'!$G$31),"Y",IF(AND(H4>='Intersection Mileposts'!$F$32,H4<='Intersection Mileposts'!$G$32),"Y",IF(AND(H4>='Intersection Mileposts'!$F$33,H4<='Intersection Mileposts'!$G$33),"Y",IF(AND(H4>='Intersection Mileposts'!$F$34,H4<='Intersection Mileposts'!$G$34),"Y",IF(AND(H4>='Intersection Mileposts'!$F$35,H4<='Intersection Mileposts'!$G$35),"Y",IF(AND(H4>='Intersection Mileposts'!$F$36,H4<='Intersection Mileposts'!$G$36),"Y",IF(AND(H4>='Intersection Mileposts'!$F$37,H4<='Intersection Mileposts'!$G$37),"Y",IF(AND(H4>='Intersection Mileposts'!$F$38,H4<='Intersection Mileposts'!$G$38),"Y",IF(AND(H4>='Intersection Mileposts'!$F$39,H4<='Intersection Mileposts'!$G$39),"Y","N")))))))))))))))))))))))))))))))))))) -> Y
A5: Example | B5: 41651 | C5: 24 | D5: 1 | E5: 7 | F5: 1 | G5: O | H5: 0.558 | P5: =IF(R5 = "", "", COUNT($R$4:R5)) -> 2 | Q5: =IF(B5="", "", YEAR(B5)) -> 2014 | R5: =IF(A5="", "", IF(G5="",1,IF(G5="O",1,IF(G5="C",8.4,IF(G5="B",8.4,IF(G5="A",76.8,IF(G5="K",76.8,"ERR"))))))) -> 1 | S5: =IF(M5="Y",R5,"") | T5: =IF(IF(M5="Y",G5,"")=0, "O", IF(M5="Y",G5,"")) | U5: =IF(N5="Y",R5,"") | V5: =IF(IF(N5="Y",G5,"")=0, "O", IF(N5="Y",G5,"")) | Y5: A | Z5: =COUNTIF($G$4:$G$1048576,$Y5) -> 1 | AA5: =COUNTIF($T$4:$T$1048576,$Y5) -> 1 | AB5: =COUNTIF($V$4:$V$1048576,$Y5) -> 0 | AC5: =COUNTIF($T:$T, Y5)+COUNTIF($V:$V, Y5)-COUNTIFS($T:$T, Y5, $V:$V, Y5) -> 1 | AR5: =IF(P5>0, P5, "") -> 2 | AS5: =IF(OR(M5="Y",N5="Y"),"Y","") | AT5: =IF(AR5="","",IF(AND(H5>='Intersection Mileposts'!$F$5,H5<='Intersection Mileposts'!$G$5),"Y",IF(AND(H5>='Intersection Mileposts'!$F$6,H5<='Intersection Mileposts'!$G$6),"Y",IF(AND(H5>='Intersection Mileposts'!$F$7,H5<='Intersection Mileposts'!$G$7),"Y",IF(AND(H5>='Intersection Mileposts'!$F$8,H5<='Intersection Mileposts'!$G$8),"Y",IF(AND(H5>='Intersection Mileposts'!$F$9,H5<='Intersection Mileposts'!$G$9),"Y",IF(AND(H5>='Intersection Mileposts'!$F$10,H5<='Intersection Mileposts'!$G$10),"Y",IF(AND(H5>='Intersection Mileposts'!$F$11,H5<='Intersection Mileposts'!$G$11),"Y",IF(AND(H5>='Intersection Mileposts'!$F$12,H5<='Intersection Mileposts'!$G$12),"Y",IF(AND(H5>='Intersection Mileposts'!$F$13,H5<='Intersection Mileposts'!$G$13),"Y",IF(AND(H5>='Intersection Mileposts'!$F$14,H5<='Intersection Mileposts'!$G$14),"Y",IF(AND(H5>='Intersection Mileposts'!$F$15,H5<='Intersection Mileposts'!$G$15),"Y",IF(AND(H5>='Intersection Mileposts'!$F$16,H5<='Intersection Mileposts'!$G$16),"Y",IF(AND(H5>='Intersection Mileposts'!$F$17,H5<='Intersection Mileposts'!$G$17),"Y",IF(AND(H5>='Intersection Mileposts'!$F$18,H5<='Intersection Mileposts'!$G$18),"Y",IF(AND(H5>='Intersection Mileposts'!$F$19,H5<='Intersection Mileposts'!$G$19),"Y",IF(AND(H5>='Intersection Mileposts'!$F$20,H5<='Intersection Mileposts'!$G$20),"Y",IF(AND(H5>='Intersection Mileposts'!$F$21,H5<='Intersection Mileposts'!$G$21),"Y",IF(AND(H5>='Intersection Mileposts'!$F$22,H5<='Intersection Mileposts'!$G$22),"Y",IF(AND(H5>='Intersection Mileposts'!$F$23,H5<='Intersection Mileposts'!$G$23),"Y",IF(AND(H5>='Intersection Mileposts'!$F$24,H5<='Intersection Mileposts'!$G$24),"Y",IF(AND(H5>='Intersection Mileposts'!$F$25,H5<='Intersection Mileposts'!$G$25),"Y",IF(AND(H5>='Intersection Mileposts'!$F$26,H5<='Intersection Mileposts'!$G$26),"Y",IF(AND(H5>='Intersection Mileposts'!$F$27,H5<='Intersection Mileposts'!$G$27),"Y",IF(AND(H5>='Intersection Mileposts'!$F$28,H5<='Intersection Mileposts'!$G$28),"Y",IF(AND(H5>='Intersection Mileposts'!$F$29,H5<='Intersection Mileposts'!$G$29),"Y", IF(AND(H5>='Intersection Mileposts'!$F$30,H5<='Intersection Mileposts'!$G$30),"Y",IF(AND(H5>='Intersection Mileposts'!$F$31,H5<='Intersection Mileposts'!$G$31),"Y",IF(AND(H5>='Intersection Mileposts'!$F$32,H5<='Intersection Mileposts'!$G$32),"Y",IF(AND(H5>='Intersection Mileposts'!$F$33,H5<='Intersection Mileposts'!$G$33),"Y",IF(AND(H5>='Intersection Mileposts'!$F$34,H5<='Intersection Mileposts'!$G$34),"Y",IF(AND(H5>='Intersection Mileposts'!$F$35,H5<='Intersection Mileposts'!$G$35),"Y",IF(AND(H5>='Intersection Mileposts'!$F$36,H5<='Intersection Mileposts'!$G$36),"Y",IF(AND(H5>='Intersection Mileposts'!$F$37,H5<='Intersection Mileposts'!$G$37),"Y",IF(AND(H5>='Intersection Mileposts'!$F$38,H5<='Intersection Mileposts'!$G$38),"Y",IF(AND(H5>='Intersection Mileposts'!$F$39,H5<='Intersection Mileposts'!$G$39),"Y","N")))))))))))))))))))))))))))))))))))) -> Y
A6: Example | B6: 42212 | C6: 28 | D6: 2 | E6: 7 | F6: 4 | G6: O | H6: 0.558 | P6: =IF(R6 = "", "", COUNT($R$4:R6)) -> 3 | Q6: =IF(B6="", "", YEAR(B6)) -> 2015 | R6: =IF(A6="", "", IF(G6="",1,IF(G6="O",1,IF(G6="C",8.4,IF(G6="B",8.4,IF(G6="A",76.8,IF(G6="K",76.8,"ERR"))))))) -> 1 | S6: =IF(M6="Y",R6,"") | T6: =IF(IF(M6="Y",G6,"")=0, "O", IF(M6="Y",G6,"")) | U6: =IF(N6="Y",R6,"") | V6: =IF(IF(N6="Y",G6,"")=0, "O", IF(N6="Y",G6,"")) | Y6: B | Z6: =COUNTIF($G$4:$G$1048576,$Y6) -> 6 | AA6: =COUNTIF($T$4:$T$1048576,$Y6) -> 1 | AB6: =COUNTIF($V$4:$V$1048576,$Y6) -> 0 | AC6: =COUNTIF($T:$T, Y6)+COUNTIF($V:$V, Y6)-COUNTIFS($T:$T, Y6, $V:$V, Y6) -> 1 | AR6: =IF(P6>0, P6, "") -> 3 | AS6: =IF(OR(M6="Y",N6="Y"),"Y","") | AT6: =IF(AR6="","",IF(AND(H6>='Intersection Mileposts'!$F$5,H6<='Intersection Mileposts'!$G$5),"Y",IF(AND(H6>='Intersection Mileposts'!$F$6,H6<='Intersection Mileposts'!$G$6),"Y",IF(AND(H6>='Intersection Mileposts'!$F$7,H6<='Intersection Mileposts'!$G$7),"Y",IF(AND(H6>='Intersection Mileposts'!$F$8,H6<='Intersection Mileposts'!$G$8),"Y",IF(AND(H6>='Intersection Mileposts'!$F$9,H6<='Intersection Mileposts'!$G$9),"Y",IF(AND(H6>='Intersection Mileposts'!$F$10,H6<='Intersection Mileposts'!$G$10),"Y",IF(AND(H6>='Intersection Mileposts'!$F$11,H6<='Intersection Mileposts'!$G$11),"Y",IF(AND(H6>='Intersection Mileposts'!$F$12,H6<='Intersection Mileposts'!$G$12),"Y",IF(AND(H6>='Intersection Mileposts'!$F$13,H6<='Intersection Mileposts'!$G$13),"Y",IF(AND(H6>='Intersection Mileposts'!$F$14,H6<='Intersection Mileposts'!$G$14),"Y",IF(AND(H6>='Intersection Mileposts'!$F$15,H6<='Intersection Mileposts'!$G$15),"Y",IF(AND(H6>='Intersection Mileposts'!$F$16,H6<='Intersection Mileposts'!$G$16),"Y",IF(AND(H6>='Intersection Mileposts'!$F$17,H6<='Intersection Mileposts'!$G$17),"Y",IF(AND(H6>='Intersection Mileposts'!$F$18,H6<='Intersection Mileposts'!$G$18),"Y",IF(AND(H6>='Intersection Mileposts'!$F$19,H6<='Intersection Mileposts'!$G$19),"Y",IF(AND(H6>='Intersection Mileposts'!$F$20,H6<='Intersection Mileposts'!$G$20),"Y",IF(AND(H6>='Intersection Mileposts'!$F$21,H6<='Intersection Mileposts'!$G$21),"Y",IF(AND(H6>='Intersection Mileposts'!$F$22,H6<='Intersection Mileposts'!$G$22),"Y",IF(AND(H6>='Intersection Mileposts'!$F$23,H6<='Intersection Mileposts'!$G$23),"Y",IF(AND(H6>='Intersection Mileposts'!$F$24,H6<='Intersection Mileposts'!$G$24),"Y",IF(AND(H6>='Intersection Mileposts'!$F$25,H6<='Intersection Mileposts'!$G$25),"Y",IF(AND(H6>='Intersection Mileposts'!$F$26,H6<='Intersection Mileposts'!$G$26),"Y",IF(AND(H6>='Intersection Mileposts'!$F$27,H6<='Intersection Mileposts'!$G$27),"Y",IF(AND(H6>='Intersection Mileposts'!$F$28,H6<='Intersection Mileposts'!$G$28),"Y",IF(AND(H6>='Intersection Mileposts'!$F$29,H6<='Intersection Mileposts'!$G$29),"Y", IF(AND(H6>='Intersection Mileposts'!$F$30,H6<='Intersection Mileposts'!$G$30),"Y",IF(AND(H6>='Intersection Mileposts'!$F$31,H6<='Intersection Mileposts'!$G$31),"Y",IF(AND(H6>='Intersection Mileposts'!$F$32,H6<='Intersection Mileposts'!$G$32),"Y",IF(AND(H6>='Intersection Mileposts'!$F$33,H6<='Intersection Mileposts'!$G$33),"Y",IF(AND(H6>='Intersection Mileposts'!$F$34,H6<='Intersection Mileposts'!$G$34),"Y",IF(AND(H6>='Intersection Mileposts'!$F$35,H6<='Intersection Mileposts'!$G$35),"Y",IF(AND(H6>='Intersection Mileposts'!$F$36,H6<='Intersection Mileposts'!$G$36),"Y",IF(AND(H6>='Intersection Mileposts'!$F$37,H6<='Intersection Mileposts'!$G$37),"Y",IF(AND(H6>='Intersection Mileposts'!$F$38,H6<='Intersection Mileposts'!$G$38),"Y",IF(AND(H6>='Intersection Mileposts'!$F$39,H6<='Intersection Mileposts'!$G$39),"Y","N")))))))))))))))))))))))))))))))))))) -> Y
A7: Example | B7: 42220 | C7: 30 | D7: 1 | E7: 12 | F7: 1 | G7: B | H7: 0.558 | P7: =IF(R7 = "", "", COUNT($R$4:R7)) -> 4 | Q7: =IF(B7="", "", YEAR(B7)) -> 2015 | R7: =IF(A7="", "", IF(G7="",1,IF(G7="O",1,IF(G7="C",8.4,IF(G7="B",8.4,IF(G7="A",76.8,IF(G7="K",76.8,"ERR"))))))) -> 8.4 | S7: =IF(M7="Y",R7,"") | T7: =IF(IF(M7="Y",G7,"")=0, "O", IF(M7="Y",G7,"")) | U7: =IF(N7="Y",R7,"") | V7: =IF(IF(N7="Y",G7,"")=0, "O", IF(N7="Y",G7,"")) | Y7: C | Z7: =COUNTIF($G$4:$G$1048576,$Y7) -> 12 | AA7: =COUNTIF($T$4:$T$1048576,$Y7) -> 2 | AB7: =COUNTIF($V$4:$V$1048576,$Y7) -> 0 | AC7: =COUNTIF($T:$T, Y7)+COUNTIF($V:$V, Y7)-COUNTIFS($T:$T, Y7, $V:$V, Y7) -> 2 | AR7: =IF(P7>0, P7, "") -> 4 | AS7: =IF(OR(M7="Y",N7="Y"),"Y","") | AT7: =IF(AR7="","",IF(AND(H7>='Intersection Mileposts'!$F$5,H7<='Intersection Mileposts'!$G$5),"Y",IF(AND(H7>='Intersection Mileposts'!$F$6,H7<='Intersection Mileposts'!$G$6),"Y",IF(AND(H7>='Intersection Mileposts'!$F$7,H7<='Intersection Mileposts'!$G$7),"Y",IF(AND(H7>='Intersection Mileposts'!$F$8,H7<='Intersection Mileposts'!$G$8),"Y",IF(AND(H7>='Intersection Mileposts'!$F$9,H7<='Intersection Mileposts'!$G$9),"Y",IF(AND(H7>='Intersection Mileposts'!$F$10,H7<='Intersection Mileposts'!$G$10),"Y",IF(AND(H7>='Intersection Mileposts'!$F$11,H7<='Intersection Mileposts'!$G$11),"Y",IF(AND(H7>='Intersection Mileposts'!$F$12,H7<='Intersection Mileposts'!$G$12),"Y",IF(AND(H7>='Intersection Mileposts'!$F$13,H7<='Intersection Mileposts'!$G$13),"Y",IF(AND(H7>='Intersection Mileposts'!$F$14,H7<='Intersection Mileposts'!$G$14),"Y",IF(AND(H7>='Intersection Mileposts'!$F$15,H7<='Intersection Mileposts'!$G$15),"Y",IF(AND(H7>='Intersection Mileposts'!$F$16,H7<='Intersection Mileposts'!$G$16),"Y",IF(AND(H7>='Intersection Mileposts'!$F$17,H7<='Intersection Mileposts'!$G$17),"Y",IF(AND(H7>='Intersection Mileposts'!$F$18,H7<='Intersection Mileposts'!$G$18),"Y",IF(AND(H7>='Intersection Mileposts'!$F$19,H7<='Intersection Mileposts'!$G$19),"Y",IF(AND(H7>='Intersection Mileposts'!$F$20,H7<='Intersection Mileposts'!$G$20),"Y",IF(AND(H7>='Intersection Mileposts'!$F$21,H7<='Intersection Mileposts'!$G$21),"Y",IF(AND(H7>='Intersection Mileposts'!$F$22,H7<='Intersection Mileposts'!$G$22),"Y",IF(AND(H7>='Intersection Mileposts'!$F$23,H7<='Intersection Mileposts'!$G$23),"Y",IF(AND(H7>='Intersection Mileposts'!$F$24,H7<='Intersection Mileposts'!$G$24),"Y",IF(AND(H7>='Intersection Mileposts'!$F$25,H7<='Intersection Mileposts'!$G$25),"Y",IF(AND(H7>='Intersection Mileposts'!$F$26,H7<='Intersection Mileposts'!$G$26),"Y",IF(AND(H7>='Intersection Mileposts'!$F$27,H7<='Intersection Mileposts'!$G$27),"Y",IF(AND(H7>='Intersection Mileposts'!$F$28,H7<='Intersection Mileposts'!$G$28),"Y",IF(AND(H7>='Intersection Mileposts'!$F$29,H7<='Intersection Mileposts'!$G$29),"Y", IF(AND(H7>='Intersection Mileposts'!$F$30,H7<='Intersection Mileposts'!$G$30),"Y",IF(AND(H7>='Intersection Mileposts'!$F$31,H7<='Intersection Mileposts'!$G$31),"Y",IF(AND(H7>='Intersection Mileposts'!$F$32,H7<='Intersection Mileposts'!$G$32),"Y",IF(AND(H7>='Intersection Mileposts'!$F$33,H7<='Intersection Mileposts'!$G$33),"Y",IF(AND(H7>='Intersection Mileposts'!$F$34,H7<='Intersection Mileposts'!$G$34),"Y",IF(AND(H7>='Intersection Mileposts'!$F$35,H7<='Intersection Mileposts'!$G$35),"Y",IF(AND(H7>='Intersection Mileposts'!$F$36,H7<='Intersection Mileposts'!$G$36),"Y",IF(AND(H7>='Intersection Mileposts'!$F$37,H7<='Intersection Mileposts'!$G$37),"Y",IF(AND(H7>='Intersection Mileposts'!$F$38,H7<='Intersection Mileposts'!$G$38),"Y",IF(AND(H7>='Intersection Mileposts'!$F$39,H7<='Intersection Mileposts'!$G$39),"Y","N")))))))))))))))))))))))))))))))))))) -> Y
A8: Example | B8: 42515 | C8: 24 | D8: 1 | E8: 7 | F8: 1 | G8: O | H8: 0.558 | P8: =IF(R8 = "", "", COUNT($R$4:R8)) -> 5 | Q8: =IF(B8="", "", YEAR(B8)) -> 2016 | R8: =IF(A8="", "", IF(G8="",1,IF(G8="O",1,IF(G8="C",8.4,IF(G8="B",8.4,IF(G8="A",76.8,IF(G8="K",76.8,"ERR"))))))) -> 1 | S8: =IF(M8="Y",R8,"") | T8: =IF(IF(M8="Y",G8,"")=0, "O", IF(M8="Y",G8,"")) | U8: =IF(N8="Y",R8,"") | V8: =IF(IF(N8="Y",G8,"")=0, "O", IF(N8="Y",G8,"")) | Y8: O | Z8: =COUNTIF($G$4:$G$1048576,$Y8)+COUNTIFS($G$4:$G$1048576, "", $P$4:$P$1048576, ">0") -> 47 | AA8: =COUNTIF($T$4:$T$1048576,$Y8) -> 6 | AB8: =COUNTIF($V$4:$V$1048576,$Y8) -> 0 | AC8: =COUNTIF($T:$T, Y8)+COUNTIF($V:$V, Y8)-COUNTIFS($T:$T, Y8, $V:$V, Y8) -> 6 | AR8: =IF(P8>0, P8, "") -> 5 | AS8: =IF(OR(M8="Y",N8="Y"),"Y","") | AT8: =IF(AR8="","",IF(AND(H8>='Intersection Mileposts'!$F$5,H8<='Intersection Mileposts'!$G$5),"Y",IF(AND(H8>='Intersection Mileposts'!$F$6,H8<='Intersection Mileposts'!$G$6),"Y",IF(AND(H8>='Intersection Mileposts'!$F$7,H8<='Intersection Mileposts'!$G$7),"Y",IF(AND(H8>='Intersection Mileposts'!$F$8,H8<='Intersection Mileposts'!$G$8),"Y",IF(AND(H8>='Intersection Mileposts'!$F$9,H8<='Intersection Mileposts'!$G$9),"Y",IF(AND(H8>='Intersection Mileposts'!$F$10,H8<='Intersection Mileposts'!$G$10),"Y",IF(AND(H8>='Intersection Mileposts'!$F$11,H8<='Intersection Mileposts'!$G$11),"Y",IF(AND(H8>='Intersection Mileposts'!$F$12,H8<='Intersection Mileposts'!$G$12),"Y",IF(AND(H8>='Intersection Mileposts'!$F$13,H8<='Intersection Mileposts'!$G$13),"Y",IF(AND(H8>='Intersection Mileposts'!$F$14,H8<='Intersection Mileposts'!$G$14),"Y",IF(AND(H8>='Intersection Mileposts'!$F$15,H8<='Intersection Mileposts'!$G$15),"Y",IF(AND(H8>='Intersection Mileposts'!$F$16,H8<='Intersection Mileposts'!$G$16),"Y",IF(AND(H8>='Intersection Mileposts'!$F$17,H8<='Intersection Mileposts'!$G$17),"Y",IF(AND(H8>='Intersection Mileposts'!$F$18,H8<='Intersection Mileposts'!$G$18),"Y",IF(AND(H8>='Intersection Mileposts'!$F$19,H8<='Intersection Mileposts'!$G$19),"Y",IF(AND(H8>='Intersection Mileposts'!$F$20,H8<='Intersection Mileposts'!$G$20),"Y",IF(AND(H8>='Intersection Mileposts'!$F$21,H8<='Intersection Mileposts'!$G$21),"Y",IF(AND(H8>='Intersection Mileposts'!$F$22,H8<='Intersection Mileposts'!$G$22),"Y",IF(AND(H8>='Intersection Mileposts'!$F$23,H8<='Intersection Mileposts'!$G$23),"Y",IF(AND(H8>='Intersection Mileposts'!$F$24,H8<='Intersection Mileposts'!$G$24),"Y",IF(AND(H8>='Intersection Mileposts'!$F$25,H8<='Intersection Mileposts'!$G$25),"Y",IF(AND(H8>='Intersection Mileposts'!$F$26,H8<='Intersection Mileposts'!$G$26),"Y",IF(AND(H8>='Intersection Mileposts'!$F$27,H8<='Intersection Mileposts'!$G$27),"Y",IF(AND(H8>='Intersection Mileposts'!$F$28,H8<='Intersection Mileposts'!$G$28),"Y",IF(AND(H8>='Intersection Mileposts'!$F$29,H8<='Intersection Mileposts'!$G$29),"Y", IF(AND(H8>='Intersection Mileposts'!$F$30,H8<='Intersection Mileposts'!$G$30),"Y",IF(AND(H8>='Intersection Mileposts'!$F$31,H8<='Intersection Mileposts'!$G$31),"Y",IF(AND(H8>='Intersection Mileposts'!$F$32,H8<='Intersection Mileposts'!$G$32),"Y",IF(AND(H8>='Intersection Mileposts'!$F$33,H8<='Intersection Mileposts'!$G$33),"Y",IF(AND(H8>='Intersection Mileposts'!$F$34,H8<='Intersection Mileposts'!$G$34),"Y",IF(AND(H8>='Intersection Mileposts'!$F$35,H8<='Intersection Mileposts'!$G$35),"Y",IF(AND(H8>='Intersection Mileposts'!$F$36,H8<='Intersection Mileposts'!$G$36),"Y",IF(AND(H8>='Intersection Mileposts'!$F$37,H8<='Intersection Mileposts'!$G$37),"Y",IF(AND(H8>='Intersection Mileposts'!$F$38,H8<='Intersection Mileposts'!$G$38),"Y",IF(AND(H8>='Intersection Mileposts'!$F$39,H8<='Intersection Mileposts'!$G$39),"Y","N")))))))))))))))))))))))))))))))))))) -> Y
A9: Example | B9: 42594 | C9: 21 | D9: 1 | E9: 7 | F9: 1 | G9: C | H9: 0.558 | P9: =IF(R9 = "", "", COUNT($R$4:R9)) -> 6 | Q9: =IF(B9="", "", YEAR(B9)) -> 2016 | R9: =IF(A9="", "", IF(G9="",1,IF(G9="O",1,IF(G9="C",8.4,IF(G9="B",8.4,IF(G9="A",76.8,IF(G9="K",76.8,"ERR"))))))) -> 8.4 | S9: =IF(M9="Y",R9,"") | T9: =IF(IF(M9="Y",G9,"")=0, "O", IF(M9="Y",G9,"")) | U9: =IF(N9="Y",R9,"") | V9: =IF(IF(N9="Y",G9,"")=0, "O", IF(N9="Y",G9,"")) | Y9: Total | Z9: =COUNTIF(P4:P1048576, ">0") -> 68 | AA9: =COUNT(S4:S1048576) -> 12 | AB9: =COUNT(U4:U1048576) -> 0 | AC9: =SUM(AC4:AC8) -> 12 | AR9: =IF(P9>0, P9, "") -> 6 | AS9: =IF(OR(M9="Y",N9="Y"),"Y","") | AT9: =IF(AR9="","",IF(AND(H9>='Intersection Mileposts'!$F$5,H9<='Intersection Mileposts'!$G$5),"Y",IF(AND(H9>='Intersection Mileposts'!$F$6,H9<='Intersection Mileposts'!$G$6),"Y",IF(AND(H9>='Intersection Mileposts'!$F$7,H9<='Intersection Mileposts'!$G$7),"Y",IF(AND(H9>='Intersection Mileposts'!$F$8,H9<='Intersection Mileposts'!$G$8),"Y",IF(AND(H9>='Intersection Mileposts'!$F$9,H9<='Intersection Mileposts'!$G$9),"Y",IF(AND(H9>='Intersection Mileposts'!$F$10,H9<='Intersection Mileposts'!$G$10),"Y",IF(AND(H9>='Intersection Mileposts'!$F$11,H9<='Intersection Mileposts'!$G$11),"Y",IF(AND(H9>='Intersection Mileposts'!$F$12,H9<='Intersection Mileposts'!$G$12),"Y",IF(AND(H9>='Intersection Mileposts'!$F$13,H9<='Intersection Mileposts'!$G$13),"Y",IF(AND(H9>='Intersection Mileposts'!$F$14,H9<='Intersection Mileposts'!$G$14),"Y",IF(AND(H9>='Intersection Mileposts'!$F$15,H9<='Intersection Mileposts'!$G$15),"Y",IF(AND(H9>='Intersection Mileposts'!$F$16,H9<='Intersection Mileposts'!$G$16),"Y",IF(AND(H9>='Intersection Mileposts'!$F$17,H9<='Intersection Mileposts'!$G$17),"Y",IF(AND(H9>='Intersection Mileposts'!$F$18,H9<='Intersection Mileposts'!$G$18),"Y",IF(AND(H9>='Intersection Mileposts'!$F$19,H9<='Intersection Mileposts'!$G$19),"Y",IF(AND(H9>='Intersection Mileposts'!$F$20,H9<='Intersection Mileposts'!$G$20),"Y",IF(AND(H9>='Intersection Mileposts'!$F$21,H9<='Intersection Mileposts'!$G$21),"Y",IF(AND(H9>='Intersection Mileposts'!$F$22,H9<='Intersection Mileposts'!$G$22),"Y",IF(AND(H9>='Intersection Mileposts'!$F$23,H9<='Intersection Mileposts'!$G$23),"Y",IF(AND(H9>='Intersection Mileposts'!$F$24,H9<='Intersection Mileposts'!$G$24),"Y",IF(AND(H9>='Intersection Mileposts'!$F$25,H9<='Intersection Mileposts'!$G$25),"Y",IF(AND(H9>='Intersection Mileposts'!$F$26,H9<='Intersection Mileposts'!$G$26),"Y",IF(AND(H9>='Intersection Mileposts'!$F$27,H9<='Intersection Mileposts'!$G$27),"Y",IF(AND(H9>='Intersection Mileposts'!$F$28,H9<='Intersection Mileposts'!$G$28),"Y",IF(AND(H9>='Intersection Mileposts'!$F$29,H9<='Intersection Mileposts'!$G$29),"Y", IF(AND(H9>='Intersection Mileposts'!$F$30,H9<='Intersection Mileposts'!$G$30),"Y",IF(AND(H9>='Intersection Mileposts'!$F$31,H9<='Intersection Mileposts'!$G$31),"Y",IF(AND(H9>='Intersection Mileposts'!$F$32,H9<='Intersection Mileposts'!$G$32),"Y",IF(AND(H9>='Intersection Mileposts'!$F$33,H9<='Intersection Mileposts'!$G$33),"Y",IF(AND(H9>='Intersection Mileposts'!$F$34,H9<='Intersection Mileposts'!$G$34),"Y",IF(AND(H9>='Intersection Mileposts'!$F$35,H9<='Intersection Mileposts'!$G$35),"Y",IF(AND(H9>='Intersection Mileposts'!$F$36,H9<='Intersection Mileposts'!$G$36),"Y",IF(AND(H9>='Intersection Mileposts'!$F$37,H9<='Intersection Mileposts'!$G$37),"Y",IF(AND(H9>='Intersection Mileposts'!$F$38,H9<='Intersection Mileposts'!$G$38),"Y",IF(AND(H9>='Intersection Mileposts'!$F$39,H9<='Intersection Mileposts'!$G$39),"Y","N")))))))))))))))))))))))))))))))))))) -> Y
A10: Example | B10: 43072 | C10: 24 | D10: 1 | F10: 4 | G10: O | H10: 0.558 | P10: =IF(R10 = "", "", COUNT($R$4:R10)) -> 7 | Q10: =IF(B10="", "", YEAR(B10)) -> 2017 | R10: =IF(A10="", "", IF(G10="",1,IF(G10="O",1,IF(G10="C",8.4,IF(G10="B",8.4,IF(G10="A",76.8,IF(G10="K",76.8,"ERR"))))))) -> 1 | S10: =IF(M10="Y",R10,"") | T10: =IF(IF(M10="Y",G10,"")=0, "O", IF(M10="Y",G10,"")) | U10: =IF(N10="Y",R10,"") | V10: =IF(IF(N10="Y",G10,"")=0, "O", IF(N10="Y",G10,"")) | Y10: SI | Z10: =IFERROR(AVERAGE(R4:R1048576), 0) -> 6.3029412 | AA10: =IFERROR(AVERAGE(S4:S1048576), 0) -> 21.8 | AB10: =IFERROR(AVERAGE(U4:U1048576), 0) -> 0 | AC10: =IFERROR(AVERAGEIF($AS$4:$AS$1048576,"Y", R4:R1048576 ), 0) -> 21.8 | AR10: =IF(P10>0, P10, "") -> 7 | AS10: =IF(OR(M10="Y",N10="Y"),"Y","") | AT10: =IF(AR10="","",IF(AND(H10>='Intersection Mileposts'!$F$5,H10<='Intersection Mileposts'!$G$5),"Y",IF(AND(H10>='Intersection Mileposts'!$F$6,H10<='Intersection Mileposts'!$G$6),"Y",IF(AND(H10>='Intersection Mileposts'!$F$7,H10<='Intersection Mileposts'!$G$7),"Y",IF(AND(H10>='Intersection Mileposts'!$F$8,H10<='Intersection Mileposts'!$G$8),"Y",IF(AND(H10>='Intersection Mileposts'!$F$9,H10<='Intersection Mileposts'!$G$9),"Y",IF(AND(H10>='Intersection Mileposts'!$F$10,H10<='Intersection Mileposts'!$G$10),"Y",IF(AND(H10>='Intersection Mileposts'!$F$11,H10<='Intersection Mileposts'!$G$11),"Y",IF(AND(H10>='Intersection Mileposts'!$F$12,H10<='Intersection Mileposts'!$G$12),"Y",IF(AND(H10>='Intersection Mileposts'!$F$13,H10<='Intersection Mileposts'!$G$13),"Y",IF(AND(H10>='Intersection Mileposts'!$F$14,H10<='Intersection Mileposts'!$G$14),"Y",IF(AND(H10>='Intersection Mileposts'!$F$15,H10<='Intersection Mileposts'!$G$15),"Y",IF(AND(H10>='Intersection Mileposts'!$F$16,H10<='Intersection Mileposts'!$G$16),"Y",IF(AND(H10>='Intersection Mileposts'!$F$17,H10<='Intersection Mileposts'!$G$17),"Y",IF(AND(H10>='Intersection Mileposts'!$F$18,H10<='Intersection Mileposts'!$G$18),"Y",IF(AND(H10>='Intersection Mileposts'!$F$19,H10<='Intersection Mileposts'!$G$19),"Y",IF(AND(H10>='Intersection Mileposts'!$F$20,H10<='Intersection Mileposts'!$G$20),"Y",IF(AND(H10>='Intersection Mileposts'!$F$21,H10<='Intersection Mileposts'!$G$21),"Y",IF(AND(H10>='Intersection Mileposts'!$F$22,H10<='Intersection Mileposts'!$G$22),"Y",IF(AND(H10>='Intersection Mileposts'!$F$23,H10<='Intersection Mileposts'!$G$23),"Y",IF(AND(H10>='Intersection Mileposts'!$F$24,H10<='Intersection Mileposts'!$G$24),"Y",IF(AND(H10>='Intersection Mileposts'!$F$25,H10<='Intersection Mileposts'!$G$25),"Y",IF(AND(H10>='Intersection Mileposts'!$F$26,H10<='Intersection Mileposts'!$G$26),"Y",IF(AND(H10>='Intersection Mileposts'!$F$27,H10<='Intersection Mileposts'!$G$27),"Y",IF(AND(H10>='Intersection Mileposts'!$F$28,H10<='Intersection Mileposts'!$G$28),"Y",IF(AND(H10>='Intersection Mileposts'!$F$29,H10<='Intersection Mileposts'!$G$29),"Y", IF(AND(H10>='Intersection Mileposts'!$F$30,H10<='Intersection Mileposts'!$G$30),"Y",IF(AND(H10>='Intersection Mileposts'!$F$31,H10<='Intersection Mileposts'!$G$31),"Y",IF(AND(H10>='Intersection Mileposts'!$F$32,H10<='Intersection Mileposts'!$G$32),"Y",IF(AND(H10>='Intersection Mileposts'!$F$33,H10<='Intersection Mileposts'!$G$33),"Y",IF(AND(H10>='Intersection Mileposts'!$F$34,H10<='Intersection Mileposts'!$G$34),"Y",IF(AND(H10>='Intersection Mileposts'!$F$35,H10<='Intersection Mileposts'!$G$35),"Y",IF(AND(H10>='Intersection Mileposts'!$F$36,H10<='Intersection Mileposts'!$G$36),"Y",IF(AND(H10>='Intersection Mileposts'!$F$37,H10<='Intersection Mileposts'!$G$37),"Y",IF(AND(H10>='Intersection Mileposts'!$F$38,H10<='Intersection Mileposts'!$G$38),"Y",IF(AND(H10>='Intersection Mileposts'!$F$39,H10<='Intersection Mileposts'!$G$39),"Y","N")))))))))))))))))))))))))))))))))))) -> Y
A11: Example | B11: 42817 | C11: 21 | D11: 1 | E11: 7 | F11: 1 | G11: C | H11: 0.56 | P11: =IF(R11 = "", "", COUNT($R$4:R11)) -> 8 | Q11: =IF(B11="", "", YEAR(B11)) -> 2017 | R11: =IF(A11="", "", IF(G11="",1,IF(G11="O",1,IF(G11="C",8.4,IF(G11="B",8.4,IF(G11="A",76.8,IF(G11="K",76.8,"ERR"))))))) -> 8.4 | S11: =IF(M11="Y",R11,"") | T11: =IF(IF(M11="Y",G11,"")=0, "O", IF(M11="Y",G11,"")) | U11: =IF(N11="Y",R11,"") | V11: =IF(IF(N11="Y",G11,"")=0, "O", IF(N11="Y",G11,"")) | AR11: =IF(P11>0, P11, "") -> 8 | AS11: =IF(OR(M11="Y",N11="Y"),"Y","") | AT11: =IF(AR11="","",IF(AND(H11>='Intersection Mileposts'!$F$5,H11<='Intersection Mileposts'!$G$5),"Y",IF(AND(H11>='Intersection Mileposts'!$F$6,H11<='Intersection Mileposts'!$G$6),"Y",IF(AND(H11>='Intersection Mileposts'!$F$7,H11<='Intersection Mileposts'!$G$7),"Y",IF(AND(H11>='Intersection Mileposts'!$F$8,H11<='Intersection Mileposts'!$G$8),"Y",IF(AND(H11>='Intersection Mileposts'!$F$9,H11<='Intersection Mileposts'!$G$9),"Y",IF(AND(H11>='Intersection Mileposts'!$F$10,H11<='Intersection Mileposts'!$G$10),"Y",IF(AND(H11>='Intersection Mileposts'!$F$11,H11<='Intersection Mileposts'!$G$11),"Y",IF(AND(H11>='Intersection Mileposts'!$F$12,H11<='Intersection Mileposts'!$G$12),"Y",IF(AND(H11>='Intersection Mileposts'!$F$13,H11<='Intersection Mileposts'!$G$13),"Y",IF(AND(H11>='Intersection Mileposts'!$F$14,H11<='Intersection Mileposts'!$G$14),"Y",IF(AND(H11>='Intersection Mileposts'!$F$15,H11<='Intersection Mileposts'!$G$15),"Y",IF(AND(H11>='Intersection Mileposts'!$F$16,H11<='Intersection Mileposts'!$G$16),"Y",IF(AND(H11>='Intersection Mileposts'!$F$17,H11<='Intersection Mileposts'!$G$17),"Y",IF(AND(H11>='Intersection Mileposts'!$F$18,H11<='Intersection Mileposts'!$G$18),"Y",IF(AND(H11>='Intersection Mileposts'!$F$19,H11<='Intersection Mileposts'!$G$19),"Y",IF(AND(H11>='Intersection Mileposts'!$F$20,H11<='Intersection Mileposts'!$G$20),"Y",IF(AND(H11>='Intersection Mileposts'!$F$21,H11<='Intersection Mileposts'!$G$21),"Y",IF(AND(H11>='Intersection Mileposts'!$F$22,H11<='Intersection Mileposts'!$G$22),"Y",IF(AND(H11>='Intersection Mileposts'!$F$23,H11<='Intersection Mileposts'!$G$23),"Y",IF(AND(H11>='Intersection Mileposts'!$F$24,H11<='Intersection Mileposts'!$G$24),"Y",IF(AND(H11>='Intersection Mileposts'!$F$25,H11<='Intersection Mileposts'!$G$25),"Y",IF(AND(H11>='Intersection Mileposts'!$F$26,H11<='Intersection Mileposts'!$G$26),"Y",IF(AND(H11>='Intersection Mileposts'!$F$27,H11<='Intersection Mileposts'!$G$27),"Y",IF(AND(H11>='Intersection Mileposts'!$F$28,H11<='Intersection Mileposts'!$G$28),"Y",IF(AND(H11>='Intersection Mileposts'!$F$29,H11<='Intersection Mileposts'!$G$29),"Y", IF(AND(H11>='Intersection Mileposts'!$F$30,H11<='Intersection Mileposts'!$G$30),"Y",IF(AND(H11>='Intersection Mileposts'!$F$31,H11<='Intersection Mileposts'!$G$31),"Y",IF(AND(H11>='Intersection Mileposts'!$F$32,H11<='Intersection Mileposts'!$G$32),"Y",IF(AND(H11>='Intersection Mileposts'!$F$33,H11<='Intersection Mileposts'!$G$33),"Y",IF(AND(H11>='Intersection Mileposts'!$F$34,H11<='Intersection Mileposts'!$G$34),"Y",IF(AND(H11>='Intersection Mileposts'!$F$35,H11<='Intersection Mileposts'!$G$35),"Y",IF(AND(H11>='Intersection Mileposts'!$F$36,H11<='Intersection Mileposts'!$G$36),"Y",IF(AND(H11>='Intersection Mileposts'!$F$37,H11<='Intersection Mileposts'!$G$37),"Y",IF(AND(H11>='Intersection Mileposts'!$F$38,H11<='Intersection Mileposts'!$G$38),"Y",IF(AND(H11>='Intersection Mileposts'!$F$39,H11<='Intersection Mileposts'!$G$39),"Y","N")))))))))))))))))))))))))))))))))))) -> Y
A12: Example | B12: 42227 | C12: 21 | D12: 1 | F12: 1 | G12: O | H12: 0.586 | P12: =IF(R12 = "", "", COUNT($R$4:R12)) -> 9 | Q12: =IF(B12="", "", YEAR(B12)) -> 2015 | R12: =IF(A12="", "", IF(G12="",1,IF(G12="O",1,IF(G12="C",8.4,IF(G12="B",8.4,IF(G12="A",76.8,IF(G12="K",76.8,"ERR"))))))) -> 1 | S12: =IF(M12="Y",R12,"") | T12: =IF(IF(M12="Y",G12,"")=0, "O", IF(M12="Y",G12,"")) | U12: =IF(N12="Y",R12,"") | V12: =IF(IF(N12="Y",G12,"")=0, "O", IF(N12="Y",G12,"")) | AR12: =IF(P12>0, P12, "") -> 9 | AS12: =IF(OR(M12="Y",N12="Y"),"Y","") | AT12: =IF(AR12="","",IF(AND(H12>='Intersection Mileposts'!$F$5,H12<='Intersection Mileposts'!$G$5),"Y",IF(AND(H12>='Intersection Mileposts'!$F$6,H12<='Intersection Mileposts'!$G$6),"Y",IF(AND(H12>='Intersection Mileposts'!$F$7,H12<='Intersection Mileposts'!$G$7),"Y",IF(AND(H12>='Intersection Mileposts'!$F$8,H12<='Intersection Mileposts'!$G$8),"Y",IF(AND(H12>='Intersection Mileposts'!$F$9,H12<='Intersection Mileposts'!$G$9),"Y",IF(AND(H12>='Intersection Mileposts'!$F$10,H12<='Intersection Mileposts'!$G$10),"Y",IF(AND(H12>='Intersection Mileposts'!$F$11,H12<='Intersection Mileposts'!$G$11),"Y",IF(AND(H12>='Intersection Mileposts'!$F$12,H12<='Intersection Mileposts'!$G$12),"Y",IF(AND(H12>='Intersection Mileposts'!$F$13,H12<='Intersection Mileposts'!$G$13),"Y",IF(AND(H12>='Intersection Mileposts'!$F$14,H12<='Intersection Mileposts'!$G$14),"Y",IF(AND(H12>='Intersection Mileposts'!$F$15,H12<='Intersection Mileposts'!$G$15),"Y",IF(AND(H12>='Intersection Mileposts'!$F$16,H12<='Intersection Mileposts'!$G$16),"Y",IF(AND(H12>='Intersection Mileposts'!$F$17,H12<='Intersection Mileposts'!$G$17),"Y",IF(AND(H12>='Intersection Mileposts'!$F$18,H12<='Intersection Mileposts'!$G$18),"Y",IF(AND(H12>='Intersection Mileposts'!$F$19,H12<='Intersection Mileposts'!$G$19),"Y",IF(AND(H12>='Intersection Mileposts'!$F$20,H12<='Intersection Mileposts'!$G$20),"Y",IF(AND(H12>='Intersection Mileposts'!$F$21,H12<='Intersection Mileposts'!$G$21),"Y",IF(AND(H12>='Intersection Mileposts'!$F$22,H12<='Intersection Mileposts'!$G$22),"Y",IF(AND(H12>='Intersection Mileposts'!$F$23,H12<='Intersection Mileposts'!$G$23),"Y",IF(AND(H12>='Intersection Mileposts'!$F$24,H12<='Intersection Mileposts'!$G$24),"Y",IF(AND(H12>='Intersection Mileposts'!$F$25,H12<='Intersection Mileposts'!$G$25),"Y",IF(AND(H12>='Intersection Mileposts'!$F$26,H12<='Intersection Mileposts'!$G$26),"Y",IF(AND(H12>='Intersection Mileposts'!$F$27,H12<='Intersection Mileposts'!$G$27),"Y",IF(AND(H12>='Intersection Mileposts'!$F$28,H12<='Intersection Mileposts'!$G$28),"Y",IF(AND(H12>='Intersection Mileposts'!$F$29,H12<='Intersection Mileposts'!$G$29),"Y", IF(AND(H12>='Intersection Mileposts'!$F$30,H12<='Intersection Mileposts'!$G$30),"Y",IF(AND(H12>='Intersection Mileposts'!$F$31,H12<='Intersection Mileposts'!$G$31),"Y",IF(AND(H12>='Intersection Mileposts'!$F$32,H12<='Intersection Mileposts'!$G$32),"Y",IF(AND(H12>='Intersection Mileposts'!$F$33,H12<='Intersection Mileposts'!$G$33),"Y",IF(AND(H12>='Intersection Mileposts'!$F$34,H12<='Intersection Mileposts'!$G$34),"Y",IF(AND(H12>='Intersection Mileposts'!$F$35,H12<='Intersection Mileposts'!$G$35),"Y",IF(AND(H12>='Intersection Mileposts'!$F$36,H12<='Intersection Mileposts'!$G$36),"Y",IF(AND(H12>='Intersection Mileposts'!$F$37,H12<='Intersection Mileposts'!$G$37),"Y",IF(AND(H12>='Intersection Mileposts'!$F$38,H12<='Intersection Mileposts'!$G$38),"Y",IF(AND(H12>='Intersection Mileposts'!$F$39,H12<='Intersection Mileposts'!$G$39),"Y","N")))))))))))))))))))))))))))))))))))) -> Y
A13: Example | B13: 41611 | C13: 17 | D13: 1 | F13: 5 | G13: O | H13: 0.681 | P13: =IF(R13 = "", "", COUNT($R$4:R13)) -> 10 | Q13: =IF(B13="", "", YEAR(B13)) -> 2013 | R13: =IF(A13="", "", IF(G13="",1,IF(G13="O",1,IF(G13="C",8.4,IF(G13="B",8.4,IF(G13="A",76.8,IF(G13="K",76.8,"ERR"))))))) -> 1 | S13: =IF(M13="Y",R13,"") | T13: =IF(IF(M13="Y",G13,"")=0, "O", IF(M13="Y",G13,"")) | U13: =IF(N13="Y",R13,"") | V13: =IF(IF(N13="Y",G13,"")=0, "O", IF(N13="Y",G13,"")) | AR13: =IF(P13>0, P13, "") -> 10 | AS13: =IF(OR(M13="Y",N13="Y"),"Y","") | AT13: =IF(AR13="","",IF(AND(H13>='Intersection Mileposts'!$F$5,H13<='Intersection Mileposts'!$G$5),"Y",IF(AND(H13>='Intersection Mileposts'!$F$6,H13<='Intersection Mileposts'!$G$6),"Y",IF(AND(H13>='Intersection Mileposts'!$F$7,H13<='Intersection Mileposts'!$G$7),"Y",IF(AND(H13>='Intersection Mileposts'!$F$8,H13<='Intersection Mileposts'!$G$8),"Y",IF(AND(H13>='Intersection Mileposts'!$F$9,H13<='Intersection Mileposts'!$G$9),"Y",IF(AND(H13>='Intersection Mileposts'!$F$10,H13<='Intersection Mileposts'!$G$10),"Y",IF(AND(H13>='Intersection Mileposts'!$F$11,H13<='Intersection Mileposts'!$G$11),"Y",IF(AND(H13>='Intersection Mileposts'!$F$12,H13<='Intersection Mileposts'!$G$12),"Y",IF(AND(H13>='Intersection Mileposts'!$F$13,H13<='Intersection Mileposts'!$G$13),"Y",IF(AND(H13>='Intersection Mileposts'!$F$14,H13<='Intersection Mileposts'!$G$14),"Y",IF(AND(H13>='Intersection Mileposts'!$F$15,H13<='Intersection Mileposts'!$G$15),"Y",IF(AND(H13>='Intersection Mileposts'!$F$16,H13<='Intersection Mileposts'!$G$16),"Y",IF(AND(H13>='Intersection Mileposts'!$F$17,H13<='Intersection Mileposts'!$G$17),"Y",IF(AND(H13>='Intersection Mileposts'!$F$18,H13<='Intersection Mileposts'!$G$18),"Y",IF(AND(H13>='Intersection Mileposts'!$F$19,H13<='Intersection Mileposts'!$G$19),"Y",IF(AND(H13>='Intersection Mileposts'!$F$20,H13<='Intersection Mileposts'!$G$20),"Y",IF(AND(H13>='Intersection Mileposts'!$F$21,H13<='Intersection Mileposts'!$G$21),"Y",IF(AND(H13>='Intersection Mileposts'!$F$22,H13<='Intersection Mileposts'!$G$22),"Y",IF(AND(H13>='Intersection Mileposts'!$F$23,H13<='Intersection Mileposts'!$G$23),"Y",IF(AND(H13>='Intersection Mileposts'!$F$24,H13<='Intersection Mileposts'!$G$24),"Y",IF(AND(H13>='Intersection Mileposts'!$F$25,H13<='Intersection Mileposts'!$G$25),"Y",IF(AND(H13>='Intersection Mileposts'!$F$26,H13<='Intersection Mileposts'!$G$26),"Y",IF(AND(H13>='Intersection Mileposts'!$F$27,H13<='Intersection Mileposts'!$G$27),"Y",IF(AND(H13>='Intersection Mileposts'!$F$28,H13<='Intersection Mileposts'!$G$28),"Y",IF(AND(H13>='Intersection Mileposts'!$F$29,H13<='Intersection Mileposts'!$G$29),"Y", IF(AND(H13>='Intersection Mileposts'!$F$30,H13<='Intersection Mileposts'!$G$30),"Y",IF(AND(H13>='Intersection Mileposts'!$F$31,H13<='Intersection Mileposts'!$G$31),"Y",IF(AND(H13>='Intersection Mileposts'!$F$32,H13<='Intersection Mileposts'!$G$32),"Y",IF(AND(H13>='Intersection Mileposts'!$F$33,H13<='Intersection Mileposts'!$G$33),"Y",IF(AND(H13>='Intersection Mileposts'!$F$34,H13<='Intersection Mileposts'!$G$34),"Y",IF(AND(H13>='Intersection Mileposts'!$F$35,H13<='Intersection Mileposts'!$G$35),"Y",IF(AND(H13>='Intersection Mileposts'!$F$36,H13<='Intersection Mileposts'!$G$36),"Y",IF(AND(H13>='Intersection Mileposts'!$F$37,H13<='Intersection Mileposts'!$G$37),"Y",IF(AND(H13>='Intersection Mileposts'!$F$38,H13<='Intersection Mileposts'!$G$38),"Y",IF(AND(H13>='Intersection Mileposts'!$F$39,H13<='Intersection Mileposts'!$G$39),"Y","N")))))))))))))))))))))))))))))))))))) -> N
A14: Example | B14: 42588 | C14: 1 | D14: 1 | F14: 5 | G14: O | H14: 0.758 | M14: Y | P14: =IF(R14 = "", "", COUNT($R$4:R14)) -> 11 | Q14: =IF(B14="", "", YEAR(B14)) -> 2016 | R14: =IF(A14="", "", IF(G14="",1,IF(G14="O",1,IF(G14="C",8.4,IF(G14="B",8.4,IF(G14="A",76.8,IF(G14="K",76.8,"ERR"))))))) -> 1 | S14: =IF(M14="Y",R14,"") -> 1 | T14: =IF(IF(M14="Y",G14,"")=0, "O", IF(M14="Y",G14,"")) -> O | U14: =IF(N14="Y",R14,"") | V14: =IF(IF(N14="Y",G14,"")=0, "O", IF(N14="Y",G14,"")) | X14: Steps | AR14: =IF(P14>0, P14, "") -> 11 | AS14: =IF(OR(M14="Y",N14="Y"),"Y","") -> Y | AT14: =IF(AR14="","",IF(AND(H14>='Intersection Mileposts'!$F$5,H14<='Intersection Mileposts'!$G$5),"Y",IF(AND(H14>='Intersection Mileposts'!$F$6,H14<='Intersection Mileposts'!$G$6),"Y",IF(AND(H14>='Intersection Mileposts'!$F$7,H14<='Intersection Mileposts'!$G$7),"Y",IF(AND(H14>='Intersection Mileposts'!$F$8,H14<='Intersection Mileposts'!$G$8),"Y",IF(AND(H14>='Intersection Mileposts'!$F$9,H14<='Intersection Mileposts'!$G$9),"Y",IF(AND(H14>='Intersection Mileposts'!$F$10,H14<='Intersection Mileposts'!$G$10),"Y",IF(AND(H14>='Intersection Mileposts'!$F$11,H14<='Intersection Mileposts'!$G$11),"Y",IF(AND(H14>='Intersection Mileposts'!$F$12,H14<='Intersection Mileposts'!$G$12),"Y",IF(AND(H14>='Intersection Mileposts'!$F$13,H14<='Intersection Mileposts'!$G$13),"Y",IF(AND(H14>='Intersection Mileposts'!$F$14,H14<='Intersection Mileposts'!$G$14),"Y",IF(AND(H14>='Intersection Mileposts'!$F$15,H14<='Intersection Mileposts'!$G$15),"Y",IF(AND(H14>='Intersection Mileposts'!$F$16,H14<='Intersection Mileposts'!$G$16),"Y",IF(AND(H14>='Intersection Mileposts'!$F$17,H14<='Intersection Mileposts'!$G$17),"Y",IF(AND(H14>='Intersection Mileposts'!$F$18,H14<='Intersection Mileposts'!$G$18),"Y",IF(AND(H14>='Intersection Mileposts'!$F$19,H14<='Intersection Mileposts'!$G$19),"Y",IF(AND(H14>='Intersection Mileposts'!$F$20,H14<='Intersection Mileposts'!$G$20),"Y",IF(AND(H14>='Intersection Mileposts'!$F$21,H14<='Intersection Mileposts'!$G$21),"Y",IF(AND(H14>='Intersection Mileposts'!$F$22,H14<='Intersection Mileposts'!$G$22),"Y",IF(AND(H14>='Intersection Mileposts'!$F$23,H14<='Intersection Mileposts'!$G$23),"Y",IF(AND(H14>='Intersection Mileposts'!$F$24,H14<='Intersection Mileposts'!$G$24),"Y",IF(AND(H14>='Intersection Mileposts'!$F$25,H14<='Intersection Mileposts'!$G$25),"Y",IF(AND(H14>='Intersection Mileposts'!$F$26,H14<='Intersection Mileposts'!$G$26),"Y",IF(AND(H14>='Intersection Mileposts'!$F$27,H14<='Intersection Mileposts'!$G$27),"Y",IF(AND(H14>='Intersection Mileposts'!$F$28,H14<='Intersection Mileposts'!$G$28),"Y",IF(AND(H14>='Intersection Mileposts'!$F$29,H14<='Intersection Mileposts'!$G$29),"Y", IF(AND(H14>='Intersection Mileposts'!$F$30,H14<='Intersection Mileposts'!$G$30),"Y",IF(AND(H14>='Intersection Mileposts'!$F$31,H14<='Intersection Mileposts'!$G$31),"Y",IF(AND(H14>='Intersection Mileposts'!$F$32,H14<='Intersection Mileposts'!$G$32),"Y",IF(AND(H14>='Intersection Mileposts'!$F$33,H14<='Intersection Mileposts'!$G$33),"Y",IF(AND(H14>='Intersection Mileposts'!$F$34,H14<='Intersection Mileposts'!$G$34),"Y",IF(AND(H14>='Intersection Mileposts'!$F$35,H14<='Intersection Mileposts'!$G$35),"Y",IF(AND(H14>='Intersection Mileposts'!$F$36,H14<='Intersection Mileposts'!$G$36),"Y",IF(AND(H14>='Intersection Mileposts'!$F$37,H14<='Intersection Mileposts'!$G$37),"Y",IF(AND(H14>='Intersection Mileposts'!$F$38,H14<='Intersection Mileposts'!$G$38),"Y",IF(AND(H14>='Intersection Mileposts'!$F$39,H14<='Intersection Mileposts'!$G$39),"Y","N")))))))))))))))))))))))))))))))))))) -> N
